<mujoco model="kbot-v2">
 <option iterations="50" timestep="0.001" solver="PGS" gravity="0 0 -9.81" />
  <compiler angle="radian" meshdir="meshes" eulerseq="zyx" autolimits="true" />

  <default>
    <joint limited="true" damping="0.01" armature="0.01" frictionloss="0.01" />
    <geom condim="4" contype="1" conaffinity="15" friction="0.9 0.2 0.2" solref="0.001 2" />
    <motor ctrllimited="true" />
    <equality solref="0.001 2" />
    <default class="visualgeom">
      <geom material="visualgeom" condim="1" contype="0" conaffinity="0" />
    </default>
  </default>

  <asset>
    <mesh name="KB_B_102B_TORSO_BOTTOM.collision" file="KB_B_102B_TORSO_BOTTOM.collision.stl"/>
    <mesh name="RS03_3.collision" file="RS03_3.collision.stl"/>
    <mesh name="RS03_4.collision" file="RS03_4.collision.stl"/>
    <mesh name="RS03_5.collision" file="RS03_5.collision.stl"/>
    <mesh name="RS03_6.collision" file="RS03_6.collision.stl"/>
    <mesh name="KB_D_401R_R_Shin_Drive.collision" file="KB_D_401R_R_Shin_Drive.collision.stl"/>
    <mesh name="KB_D_402L_L_Shin_Idle.collision" file="KB_D_402L_L_Shin_Idle.collision.stl"/>
    <mesh name="KB_C_501X_Bayonet_Adapter_Hard_Stop.collision" file="KB_C_501X_Bayonet_Adapter_Hard_Stop.collision.stl"/>
    <mesh name="KB_D_501R_R_LEG_FOOT.collision" file="KB_D_501R_R_LEG_FOOT.collision.stl"/>
    <mesh name="KB_D_501L_L_LEG_FOOT.collision" file="KB_D_501L_L_LEG_FOOT.collision.stl"/>
    <mesh name="KB_C_501X_Bayonet_Adapter_Hard_Stop_2.collision" file="KB_C_501X_Bayonet_Adapter_Hard_Stop_2.collision.stl"/>
  
      <texture name="texplane" type="2d" builtin="checker" rgb1=".0 .0 .0" rgb2=".8 .8 .8" width="100" height="100" />
    <material name="matplane" reflectance="0." texture="texplane" texrepeat="1 1" texuniform="true" />
    <material name='visualgeom'  rgba='0.5 0.9 0.2 1'/>
  </asset>

  <worldbody>

  <light directional="true" diffuse="0.4 0.4 0.4" specular="0.1 0.1 0.1" pos="0 0 5.0" dir="0 0 -1" castshadow="false" />
  <light directional="true" diffuse="0.6 0.6 0.6" specular="0.2 0.2 0.2" pos="0 0 4" dir="0 0 -1" />
  <geom name="ground" type="plane" size="0 0 1" pos="0.001 0 0" quat="1 0 0 0" material="matplane" condim="1" conaffinity='15'/>
  <camera name="fixed" pos="0 -3.0 1.3996921861577372" xyaxes="1 0 0 0 0 1" />
  <camera name="track" mode="trackcom" pos="0 -3.0 1.3996921861577372" xyaxes="1 0 0 0 0 1" />
  <body name="root" pos="0 0 0" quat="1 0 0 0">
    <freejoint name="root" />
    <site name="imu" size="0.01" pos="0 0 0" />
    <!-- -0.028807 -0.009800 0.452404 -->
    <geom name="KB_B_102B_TORSO_BOTTOM.collision" pos="0 0 0" quat="0.707107 0 0 -0.707107" type="mesh" rgba="0.615686 0.811765 0.929412 1" mesh="KB_B_102B_TORSO_BOTTOM.collision"/>
    <geom name="RS03.collision_5" pos="0.023513 -0.20095 0.337507" quat="-0.5 -0.5 -0.5 -0.5" type="mesh" rgba="0.615686 0.811765 0.929412 1" mesh="RS03_5.collision"/>
    <geom name="KB_C_501X_Bayonet_Adapter_Hard_Stop.collision" pos="-0.0140869 -0.21345 -0.049193" quat="-0.707107 1.22474e-07 1.22474e-07 -0.707107" type="mesh" rgba="0.917647 0.917647 0.917647 1" mesh="KB_C_501X_Bayonet_Adapter_Hard_Stop.collision"/>
    <geom name="RS03.collision_6" pos="0.023513 0.20095 0.337507" quat="0.5 0.5 0.5 0.5" type="mesh" rgba="0.615686 0.811765 0.929412 1" mesh="RS03_6.collision"/>
    <geom name="KB_C_501X_Bayonet_Adapter_Hard_Stop.collision_2" pos="-0.0140871 0.21345 -0.047993" quat="0 0.707107 0.707107 0" type="mesh" rgba="0.917647 0.917647 0.917647 1" mesh="KB_C_501X_Bayonet_Adapter_Hard_Stop_2.collision"/>
    <body name="KB_D_102R_R_Hip_Yoke_Drive" pos="-0.000736982 -0.056 -0.072993" quat="2.31079e-07 2.31079e-07 -0.707107 -0.707107">
      <inertial pos="-0.005187 -0.002374 -0.039157" quat="-0.395889 0.566471 0.00410024 0.722748" mass="0.710534" diaginertia="0.00190811 0.00146065 0.00119524"/>
      <joint name="right_hip_pitch_04" pos="0 0 0" axis="0 0 1" range="-1.91986 1.5708" actuatorfrcrange="-60 60"/>
      <body name="RS03_3" pos="-0.02825 -0.03 -0.071" quat="0.707107 0 -0.707107 0">
        <inertial pos="-0.000677 -0.058256 -0.028289" quat="0.499672 0.501995 -0.504281 0.493993" mass="2.59032" diaginertia="0.0115812 0.0110635 0.0038023"/>
        <joint name="right_hip_roll_03" pos="0 0 0" axis="0 0 -1" range="0 2.26893" actuatorfrcrange="-40 40"/>
        <geom name="RS03.collision_3" type="mesh" rgba="0.615686 0.811765 0.929412 1" mesh="RS03_3.collision"/>
        <body name="KB_D_301R_R_Femur_Lower_Drive" pos="0 -0.14275 -0.0298" quat="0.707107 0.707107 0 0">
          <inertial pos="0.000139 -0.010511 0.162474" quat="0.99584 0.0773449 -0.0449348 -0.0173773" mass="2.55683" diaginertia="0.0181446 0.016652 0.00432642"/>
          <joint name="right_hip_yaw_03" pos="0 0 0" axis="0 0 -1" range="-1.5708 1.5708" actuatorfrcrange="-40 40"/>
          <body name="KB_D_401R_R_Shin_Drive" pos="0.0206 -0.021 0.212" quat="0.5 0.5 -0.5 -0.5">
            <inertial pos="-0.026847 0.09556 0.020795" quat="0.695613 0.7129 0.075611 -0.046677" mass="2.01672" diaginertia="0.0176335 0.017275 0.00372758"/>
            <joint name="right_knee_04" pos="0 0 0" axis="0 0 1" range="-2.70526 0" actuatorfrcrange="-60 60"/>
            <geom name="KB_D_401R_R_Shin_Drive.collision" type="mesh" rgba="0.34902 0.376471 0.4 1" mesh="KB_D_401R_R_Shin_Drive.collision"/>
            <body name="KB_D_501R_R_LEG_FOOT" pos="-0.0313 0.2925 0.034">
              <inertial pos="-0.013265 0.028578 -0.016056" quat="0.55592 0.47087 0.536141 0.426365" mass="0.492747" diaginertia="0.00156892 0.00148212 0.000276961"/>
              <joint name="right_ankle_02" pos="0 0 0" axis="0 0 1" range="-0.296706 0.785398" actuatorfrcrange="-17 17" frictionloss="0.1"/>
              <geom name="KB_D_501R_R_LEG_FOOT.collision" type="mesh" rgba="0.972549 0.529412 0.003922 1" mesh="KB_D_501R_R_LEG_FOOT.collision"/>
            </body>
          </body>
        </body>
      </body>
    </body>
    <body name="KB_D_102L_L_Hip_Yoke_Drive" pos="-0.000737018 0.056 -0.072993" quat="2.31079e-07 -2.31079e-07 0.707107 -0.707107">
      <inertial pos="-0.005269 0.002433 -0.039157" quat="0.398596 0.562977 -0.0106233 0.723923" mass="0.710534" diaginertia="0.00190525 0.00145836 0.00119339"/>
      <joint name="left_hip_pitch_04" pos="0 0 0" axis="0 0 1" range="-1.5708 1.91986" actuatorfrcrange="-60 60"/>
      <body name="RS03_4" pos="-0.02825 0.03 -0.071" quat="-1.22475e-07 0.707107 -1.22474e-07 -0.707107">
        <inertial pos="0.000677 -0.058257 -0.028289" quat="0.494474 0.504766 -0.501509 0.499195" mass="2.59043" diaginertia="0.0115812 0.0110645 0.0038023"/>
        <joint name="left_hip_roll_03" pos="0 0 0" axis="0 0 -1" range="-2.26893 0" actuatorfrcrange="-40 40"/>
        <geom name="RS03.collision_4" type="mesh" rgba="0.615686 0.811765 0.929412 1" mesh="RS03_4.collision"/>
        <body name="KB_D_301L_L_Femur_Lower_Drive" pos="0 -0.14275 -0.0298" quat="0.707107 0.707107 0 0">
          <inertial pos="-0.000139 -0.010511 0.162476" quat="0.995846 0.0773264 0.0449548 0.0170496" mass="2.55677" diaginertia="0.0181435 0.0166511 0.00432545"/>
          <joint name="left_hip_yaw_03" pos="0 0 0" axis="0 0 -1" range="-1.5708 1.5708" actuatorfrcrange="-40 40"/>
          <body name="KB_D_402L_L_Shin_Idle" pos="0.0432 -0.021 0.212" quat="0.5 -0.5 0.5 -0.5">
            <inertial pos="-0.026848 -0.095563 -0.042713" quat="0.712206 0.695506 0.0511205 -0.0801289" mass="2.01657" diaginertia="0.0176072 0.0172738 0.00370099"/>
            <joint name="left_knee_04" pos="0 0 0" axis="0 0 1" range="0 2.70526" actuatorfrcrange="-60 60"/>
            <geom name="KB_D_402L_L_Shin_Idle.collision" type="mesh" rgba="0.34902 0.376471 0.4 1" mesh="KB_D_402L_L_Shin_Idle.collision"/>
            <body name="KB_D_501L_L_LEG_FOOT" pos="-0.0313 -0.2925 -0.0572">
              <inertial pos="-0.013265 -0.028578 0.011944" quat="0.426365 0.536141 0.47087 0.55592" mass="0.492748" diaginertia="0.00156892 0.00148212 0.000276961"/>
              <joint name="left_ankle_02" pos="0 0 0" axis="0 0 1" range="-0.785398 0.296706" actuatorfrcrange="-17 17" frictionloss="0.1"/>
              <geom name="KB_D_501L_L_LEG_FOOT.collision" type="mesh" rgba="0.972549 0.529412 0.003922 1" mesh="KB_D_501L_L_LEG_FOOT.collision"/>
            </body>
          </body>
        </body>
      </body>
    </body>

        </body>
  </worldbody>

    <actuator>
    <motor name="right_hip_pitch_04" joint="right_hip_pitch_04" ctrllimited="true" ctrlrange="-60 60" gear="1" />
    <motor name="right_hip_roll_03" joint="right_hip_roll_03" ctrllimited="true" ctrlrange="-40 40" gear="1" />
    <motor name="right_hip_yaw_03" joint="right_hip_yaw_03" ctrllimited="true" ctrlrange="-40 40" gear="1" />
    <motor name="right_knee_04" joint="right_knee_04" ctrllimited="true" ctrlrange="-60 60" gear="1" />
    <motor name="right_ankle_02" joint="right_ankle_02" ctrllimited="true" ctrlrange="-17 17" gear="1" />
  
    <motor name="left_hip_pitch_04" joint="left_hip_pitch_04" ctrllimited="true" ctrlrange="-60 60" gear="1" />
    <motor name="left_hip_roll_03" joint="left_hip_roll_03" ctrllimited="true" ctrlrange="-40 40" gear="1" />
    <motor name="left_hip_yaw_03" joint="left_hip_yaw_03" ctrllimited="true" ctrlrange="-40 40" gear="1" />
    <motor name="left_knee_04" joint="left_knee_04" ctrllimited="true" ctrlrange="-60 60" gear="1" />
    <motor name="left_ankle_02" joint="left_ankle_02" ctrllimited="true" ctrlrange="-17 17" gear="1" />
  </actuator>

  <sensor>
    <actuatorpos name="left_hip_pitch_04_p" actuator="left_hip_pitch_04" />
    <actuatorvel name="left_hip_pitch_04_v" actuator="left_hip_pitch_04" />
    <actuatorfrc name="left_hip_pitch_04_f" actuator="left_hip_pitch_04" noise="0.001" />
    <actuatorpos name="left_hip_roll_03_p" actuator="left_hip_roll_03" />
    <actuatorvel name="left_hip_roll_03_v" actuator="left_hip_roll_03" />
    <actuatorfrc name="left_hip_roll_03_f" actuator="left_hip_roll_03" noise="0.001" />
    <actuatorpos name="left_hip_yaw_03_p" actuator="left_hip_yaw_03" />
    <actuatorvel name="left_hip_yaw_03_v" actuator="left_hip_yaw_03" />
    <actuatorfrc name="left_hip_yaw_03_f" actuator="left_hip_yaw_03" noise="0.001" />
    <actuatorpos name="left_knee_04_p" actuator="left_knee_04" />
    <actuatorvel name="left_knee_04_v" actuator="left_knee_04" />
    <actuatorfrc name="left_knee_04_f" actuator="left_knee_04" noise="0.001" />
    <actuatorpos name="left_ankle_02_p" actuator="left_ankle_02" />
    <actuatorvel name="left_ankle_02_v" actuator="left_ankle_02" />
    <actuatorfrc name="left_ankle_02_f" actuator="left_ankle_02" noise="0.001" />
    <actuatorpos name="right_hip_pitch_04_p" actuator="right_hip_pitch_04" />
    <actuatorvel name="right_hip_pitch_04_v" actuator="right_hip_pitch_04" />
    <actuatorfrc name="right_hip_pitch_04_f" actuator="right_hip_pitch_04" noise="0.001" />
    <actuatorpos name="right_hip_roll_03_p" actuator="right_hip_roll_03" />
    <actuatorvel name="right_hip_roll_03_v" actuator="right_hip_roll_03" />
    <actuatorfrc name="right_hip_roll_03_f" actuator="right_hip_roll_03" noise="0.001" />
    <actuatorpos name="right_hip_yaw_03_p" actuator="right_hip_yaw_03" />
    <actuatorvel name="right_hip_yaw_03_v" actuator="right_hip_yaw_03" />
    <actuatorfrc name="right_hip_yaw_03_f" actuator="right_hip_yaw_03" noise="0.001" />
    <actuatorpos name="right_knee_04_p" actuator="right_knee_04" />
    <actuatorvel name="right_knee_04_v" actuator="right_knee_04" />
    <actuatorfrc name="right_knee_04_f" actuator="right_knee_04" noise="0.001" />
    <actuatorpos name="right_ankle_02_p" actuator="right_ankle_02" />
    <actuatorvel name="right_ankle_02_v" actuator="right_ankle_02" />
    <actuatorfrc name="right_ankle_02_f" actuator="right_ankle_02" noise="0.001" />
    <framequat name="orientation" objtype="site" noise="0.001" objname="imu" />
    <gyro name="angular-velocity" site="imu" noise="0.005" cutoff="34.9" />
  </sensor>
    <keyframe>
    <key name="default" qpos="0 0 0.795 1. 0.0 0.0 0.0 -0.23 0.0 0.0 -0.441 0.195 0.23 0.0 0.0 0.441 -0.195"/>
    <key name="standing" qpos="0 0 0.8 1. 0.0 0.0 0.0 0 0.0 0.0 0 0 0 0.0 0.0 0 0"/>
  </keyframe>
</mujoco>
