<mujoco model="opus">
  <option iterations="50" timestep="0.001" solver="PGS" gravity="0 0 -9.81" />

  <compiler angle="radian" meshdir="meshes" eulerseq="zyx" autolimits="true" />

  <default>
    <joint limited="true" damping="0.01" armature="0.01" frictionloss="0.01" />
    <geom condim="4" contype="1" conaffinity="15" friction="0.9 0.2 0.2" solref="0.001 2" />
    <motor ctrllimited="true" />
    <equality solref="0.001 2" />
    <default class="visualgeom">
      <geom material="visualgeom" condim="1" contype="0" conaffinity="0" />
    </default>
  </default>

  <asset>
    <mesh name="Torso" file="Torso.stl" />
    <mesh name="shoulder_yaw_right" file="shoulder_yaw_right.stl" />
    <mesh name="shoulder_yaw_left" file="shoulder_yaw_left.stl" />
    <mesh name="right_shoulder_yaw_motor" file="right_shoulder_yaw_motor.stl" />
    <mesh name="hip_yaw_right" file="hip_yaw_right.stl" />
    <mesh name="hip_yaw_left" file="hip_yaw_left.stl" />
    <mesh name="left_shoulder_yaw_motor" file="left_shoulder_yaw_motor.stl" />
    <mesh name="hip_roll_right" file="hip_roll_right.stl" />
    <mesh name="hip_roll_left" file="hip_roll_left.stl" />
    <mesh name="Left_Hand" file="Left_Hand.stl" />
    <mesh name="hand_right" file="hand_right.stl" />
    <mesh name="knee_pitch_right" file="knee_pitch_right.stl" />
    <mesh name="knee_pitch_right_2" file="knee_pitch_right_2.stl" />
    <mesh name="ankle_pitch_right" file="ankle_pitch_right.stl" />
    <mesh name="ankle_pitch_left" file="ankle_pitch_left.stl" />
    <mesh name="foot_right" file="foot_right.stl" />
    <mesh name="foot_left" file="foot_left.stl" />
    <texture name="texplane" type="2d" builtin="checker" rgb1=".0 .0 .0" rgb2=".8 .8 .8" width="100" height="100" />
    <material name="matplane" reflectance="0." texture="texplane" texrepeat="1 1" texuniform="true" />
    <material name="visualgeom" rgba="0.5 0.9 0.2 1" />
  </asset>

  <worldbody>
    <light directional="true" diffuse="0.4 0.4 0.4" specular="0.1 0.1 0.1" pos="0 0 5.0" dir="0 0 -1" castshadow="false" />
    <light directional="true" diffuse="0.6 0.6 0.6" specular="0.2 0.2 0.2" pos="0 0 4" dir="0 0 -1" />
    <geom name="ground" type="plane" pos="0 0 0" size="100 100 0.001" quat="1 0 0 0" material="matplane" condim="3" conaffinity="15" />
    <camera name="fixed" pos="0 -3.0 0.5375878" xyaxes="1 0 0 0 0 1" />
    <camera name="track" mode="trackcom" pos="0 -3.0 0.5375878" xyaxes="1 0 0 0 0 1" />
    <body name="root" pos="0 0 0" quat="0.0 0.0 0.0 1.0">
      <freejoint name="root" />
      <site name="imu" size="0.01" pos="0 0 0" />
      <geom type="mesh" rgba="0.972549 0.529412 0.00392157 1" mesh="Torso" contype="1" conaffinity="0" density="0" group="1" class="visualgeom" />
      <geom type="mesh" rgba="0.972549 0.529412 0.00392157 1" mesh="Torso" />
      <geom pos="-0.0781365 -0.000335556 0.0430533" quat="0.5 0.5 0.5 0.5" type="mesh" rgba="0.972549 0.529412 0.00392157 1" mesh="shoulder_yaw_right" contype="1" conaffinity="0" density="0" group="1" class="visualgeom" />
      <geom type="mesh" rgba="0.972549 0.529412 0.00392157 1" mesh="shoulder_yaw_right" pos="-0.0781365 -0.000335556 0.0430533" quat="0.5 0.5 0.5 0.5" />
      <geom pos="-0.108136 -0.0191606 0.0267541" quat="-0.707107 0.707107 9.47343e-09 9.47343e-09" type="mesh" rgba="0.4 0.4 0.4 1" mesh="right_shoulder_yaw_motor" contype="1" conaffinity="0" density="0" group="1" class="visualgeom" />
      <geom type="mesh" rgba="0.4 0.4 0.4 1" mesh="right_shoulder_yaw_motor" pos="-0.108136 -0.0191606 0.0267541" quat="-0.707107 0.707107 9.47343e-09 9.47343e-09" />
      <geom pos="-0.13814 -0.0189106 -0.0375878" quat="-0.690346 0.690345 -0.153046 -0.153046" type="mesh" rgba="0.972549 0.529412 0.00392157 1" mesh="Left_Hand" contype="1" conaffinity="0" density="0" group="1" class="visualgeom" />
      <geom type="mesh" rgba="0.972549 0.529412 0.00392157 1" mesh="Left_Hand" pos="-0.13814 -0.0189106 -0.0375878" quat="-0.690346 0.690345 -0.153046 -0.153046" />
      <geom pos="0.0781635 -0.000335556 0.0430533" quat="0.5 -0.5 -0.5 0.5" type="mesh" rgba="0.972549 0.529412 0.00392157 1" mesh="shoulder_yaw_left" contype="1" conaffinity="0" density="0" group="1" class="visualgeom" />
      <geom type="mesh" rgba="0.972549 0.529412 0.00392157 1" mesh="shoulder_yaw_left" pos="0.0781635 -0.000335556 0.0430533" quat="0.5 -0.5 -0.5 0.5" />
      <geom pos="0.108164 -0.0191606 0.0267541" quat="0.707107 0.707107 6.93506e-09 -6.93506e-09" type="mesh" rgba="0.4 0.4 0.4 1" mesh="left_shoulder_yaw_motor" contype="1" conaffinity="0" density="0" group="1" class="visualgeom" />
      <geom type="mesh" rgba="0.4 0.4 0.4 1" mesh="left_shoulder_yaw_motor" pos="0.108164 -0.0191606 0.0267541" quat="0.707107 0.707107 6.93506e-09 -6.93506e-09" />
      <geom pos="0.138167 -0.0189106 -0.0375878" quat="0.690346 -0.690345 -0.153046 -0.153046" type="mesh" rgba="0.972549 0.529412 0.00392157 1" mesh="hand_right" contype="1" conaffinity="0" density="0" group="1" class="visualgeom" />
      <geom type="mesh" rgba="0.972549 0.529412 0.00392157 1" mesh="hand_right" pos="0.138167 -0.0189106 -0.0375878" quat="0.690346 -0.690345 -0.153046 -0.153046" />
      <body name="hip_yaw_left" pos="0.0456635 -0.000335555 -0.0969467" quat="0.5 0.5 0.5 0.5">
        <inertial pos="-0.00777616 0.0101887 0.0152718" quat="0.45592 0.889889 0.0131744 -0.00779523" mass="0.103202" diaginertia="4.31891e-05 4.07457e-05 3.38951e-05" />
        <joint name="left_hip_pitch" pos="0 0 0" axis="0 0 -1" range="-1.5708 1.5708" />
        <geom type="mesh" rgba="0.972549 0.529412 0.00392157 1" mesh="hip_yaw_left" contype="1" conaffinity="0" density="0" group="1" class="visualgeom" />
        <geom type="mesh" rgba="0.972549 0.529412 0.00392157 1" mesh="hip_yaw_left" />
        <body name="hip_roll_left" pos="-0.0255 -0.0025 0.01936" quat="1.64085e-08 -0.707107 -1.64085e-08 -0.707107">
          <inertial pos="-5.22128e-05 0.0427184 0.0279626" quat="0.585474 0.810689 -0.00167161 -0.000214986" mass="0.111294" diaginertia="6.57191e-05 4.65391e-05 3.49746e-05" />
          <joint name="left_hip_yaw" pos="0 0 0" axis="0 0 1" range="-1.5708 0.0872665" />
          <geom type="mesh" rgba="0.972549 0.529412 0.00392157 1" mesh="hip_roll_left" contype="1" conaffinity="0" density="0" group="1" class="visualgeom" />
          <geom type="mesh" rgba="0.972549 0.529412 0.00392157 1" mesh="hip_roll_left" />
          <body name="knee_pitch_right_2" pos="0 0.06776 0.015" quat="0.707107 0.707107 0 0">
            <inertial pos="-0.000643821 -0.00237466 -0.0244388" quat="0.706931 0.0631453 -0.0485932 0.70278" mass="0.110612" diaginertia="7.52582e-05 6.81301e-05 2.60379e-05" />
            <joint name="left_hip_roll" pos="0 0 0" axis="0 0 1" range="-0.785398 0.785398" />
            <geom type="mesh" rgba="0.972549 0.529412 0.00392157 1" mesh="knee_pitch_right_2" contype="1" conaffinity="0" density="0" group="1" class="visualgeom" />
            <geom type="mesh" rgba="0.972549 0.529412 0.00392157 1" mesh="knee_pitch_right_2" />
            <body name="ankle_pitch_left" pos="-0.018775 9.39161e-10 -0.04596" quat="0.5 -0.5 -0.5 0.5">
              <inertial pos="2.15197e-06 0.0383739 -0.019579" quat="0.737365 0.675494 4.40773e-06 4.03788e-06" mass="0.109625" diaginertia="5.33242e-05 4.18066e-05 2.78814e-05" />
              <joint name="left_knee_pitch" pos="0 0 0" axis="0 0 -1" range="0 1.0472" />
              <geom type="mesh" rgba="0.972549 0.529412 0.00392157 1" mesh="ankle_pitch_left" contype="1" conaffinity="0" density="0" group="1" class="visualgeom" />
              <geom type="mesh" rgba="0.972549 0.529412 0.00392157 1" mesh="ankle_pitch_left" />
              <body name="foot_left" pos="1.3459e-09 0.05647 -0.000450004" quat="2.32051e-08 -1 4.64102e-08 0">
                <inertial pos="-0.00778227 -0.0161914 0.0178319" quat="0.488777 0.488777 0.510977 0.510977" mass="0.0406222" diaginertia="3.78658e-05 2.8894e-05 1.35969e-05" />
                <joint name="left_ankle_pitch" pos="0 0 0" axis="0 0 1" range="-1.0472 1.0472" />
                <geom type="mesh" rgba="0.972549 0.529412 0.00392157 1" mesh="foot_left" contype="1" conaffinity="0" density="0" group="1" class="visualgeom" />
                <geom type="mesh" rgba="0.972549 0.529412 0.00392157 1" mesh="foot_left" />
              </body>
            </body>
          </body>
        </body>
      </body>
        <body name="hip_yaw_right" pos="-0.0456365 -0.000335555 -0.0969467" quat="0.5 -0.5 -0.5 0.5">
        <inertial pos="-0.00777521 -0.0101889 0.0152725" quat="0.889874 0.455956 0.00767715 -0.0129746" mass="0.103196" diaginertia="4.3188e-05 4.07436e-05 3.38931e-05" />
        <joint name="right_hip_pitch" pos="0 0 0" axis="0 0 -1" range="-1.5708 1.5708" />
        <geom type="mesh" rgba="0.972549 0.529412 0.00392157 1" mesh="hip_yaw_right" contype="1" conaffinity="0" density="0" group="1" class="visualgeom" />
        <geom type="mesh" rgba="0.972549 0.529412 0.00392157 1" mesh="hip_yaw_right" />
        <body name="hip_roll_right" pos="-0.0255 0.0025 0.01936" quat="0.707107 3.2817e-08 0.707107 -3.2817e-08">
          <inertial pos="5.22112e-05 0.0427183 0.0279625" quat="0.585477 0.810687 0.0016716 0.000214999" mass="0.111293" diaginertia="6.5719e-05 4.6539e-05 3.49745e-05" />
          <joint name="right_hip_yaw" pos="0 0 0" axis="0 0 1" range="-0.0872665 1.5708" />
          <geom type="mesh" rgba="0.972549 0.529412 0.00392157 1" mesh="hip_roll_right" contype="1" conaffinity="0" density="0" group="1" class="visualgeom" />
          <geom type="mesh" rgba="0.972549 0.529412 0.00392157 1" mesh="hip_roll_right" />
          <body name="knee_pitch_right" pos="0 0.06776 0.015" quat="0.707107 0.707107 0 0">
            <inertial pos="0.000718952 -0.00237466 -0.0219131" quat="0.702278 0.0508037 -0.0647173 0.707132" mass="0.110612" diaginertia="6.96382e-05 6.25773e-05 2.61051e-05" />
            <joint name="right_hip_roll" pos="0 0 0" axis="0 0 1" range="-0.785398 0.785398" />
            <geom type="mesh" rgba="0.972549 0.529412 0.00392157 1" mesh="knee_pitch_right" contype="1" conaffinity="0" density="0" group="1" class="visualgeom" />
            <geom type="mesh" rgba="0.972549 0.529412 0.00392157 1" mesh="knee_pitch_right" />
            <body name="ankle_pitch_right" pos="0.018825 -9.39161e-10 -0.04221" quat="0.5 -0.5 -0.5 0.5">
              <inertial pos="-5.29027e-07 0.0409224 0.0178642" quat="0.709959 0.704243 3.3304e-05 3.30359e-05" mass="0.109625" diaginertia="5.75137e-05 4.60143e-05 2.78632e-05" />
              <joint name="right_knee_pitch" pos="0 0 0" axis="0 0 1" range="-1.0472 0" />
              <geom type="mesh" rgba="0.972549 0.529412 0.00392157 1" mesh="ankle_pitch_right" contype="1" conaffinity="0" density="0" group="1" class="visualgeom" />
              <geom type="mesh" rgba="0.972549 0.529412 0.00392157 1" mesh="ankle_pitch_right" />
              <body name="foot_right" pos="0 0.06022 -1.3e-08" quat="2.32051e-08 -1 0 0">
                <inertial pos="-0.00778227 -0.0161914 -0.0178319" quat="0.488777 0.488777 0.510977 0.510977" mass="0.0406222" diaginertia="3.78658e-05 2.8894e-05 1.35969e-05" />
                <joint name="right_ankle_pitch" pos="0 0 0" axis="0 0 -1" range="-1.0472 1.0472" />
                <geom type="mesh" rgba="0.972549 0.529412 0.00392157 1" mesh="foot_right" contype="1" conaffinity="0" density="0" group="1" class="visualgeom" />
                <geom type="mesh" rgba="0.972549 0.529412 0.00392157 1" mesh="foot_right" />
              </body>
            </body>
          </body>
        </body>
      </body>
    </body>
  </worldbody>

  <actuator>
    <motor name="left_hip_pitch" joint="left_hip_pitch" ctrllimited="true" ctrlrange="-100 100" gear="1" />
    <motor name="left_hip_yaw" joint="left_hip_yaw" ctrllimited="true" ctrlrange="-100 100" gear="1" />
    <motor name="left_hip_roll" joint="left_hip_roll" ctrllimited="true" ctrlrange="-100 100" gear="1" />
    <motor name="left_knee_pitch" joint="left_knee_pitch" ctrllimited="true" ctrlrange="-100 100" gear="1" />
    <motor name="left_ankle_pitch" joint="left_ankle_pitch" ctrllimited="true" ctrlrange="-100 100" gear="1" />
  
    <motor name="right_hip_pitch" joint="right_hip_pitch" ctrllimited="true" ctrlrange="-100 100" gear="1" />
    <motor name="right_hip_yaw" joint="right_hip_yaw" ctrllimited="true" ctrlrange="-100 100" gear="1" />
    <motor name="right_hip_roll" joint="right_hip_roll" ctrllimited="true" ctrlrange="-100 100" gear="1" />
    <motor name="right_knee_pitch" joint="right_knee_pitch" ctrllimited="true" ctrlrange="-100 100" gear="1" />
    <motor name="right_ankle_pitch" joint="right_ankle_pitch" ctrllimited="true" ctrlrange="-100 100" gear="1" />
  </actuator>

  <sensor>
    <actuatorpos name="right_hip_pitch_p" actuator="right_hip_pitch" />
    <actuatorvel name="right_hip_pitch_v" actuator="right_hip_pitch" />
    <actuatorfrc name="right_hip_pitch_f" actuator="right_hip_pitch" noise="0.001" />
    <actuatorpos name="right_hip_yaw_p" actuator="right_hip_yaw" />
    <actuatorvel name="right_hip_yaw_v" actuator="right_hip_yaw" />
    <actuatorfrc name="right_hip_yaw_f" actuator="right_hip_yaw" noise="0.001" />
    <actuatorpos name="right_hip_roll_p" actuator="right_hip_roll" />
    <actuatorvel name="right_hip_roll_v" actuator="right_hip_roll" />
    <actuatorfrc name="right_hip_roll_f" actuator="right_hip_roll" noise="0.001" />
    <actuatorpos name="right_knee_pitch_p" actuator="right_knee_pitch" />
    <actuatorvel name="right_knee_pitch_v" actuator="right_knee_pitch" />
    <actuatorfrc name="right_knee_pitch_f" actuator="right_knee_pitch" noise="0.001" />
    <actuatorpos name="right_ankle_pitch_p" actuator="right_ankle_pitch" />
    <actuatorvel name="right_ankle_pitch_v" actuator="right_ankle_pitch" />
    <actuatorfrc name="right_ankle_pitch_f" actuator="right_ankle_pitch" noise="0.001" />
    <actuatorpos name="left_hip_pitch_p" actuator="left_hip_pitch" />
    <actuatorvel name="left_hip_pitch_v" actuator="left_hip_pitch" />
    <actuatorfrc name="left_hip_pitch_f" actuator="left_hip_pitch" noise="0.001" />
    <actuatorpos name="left_hip_yaw_p" actuator="left_hip_yaw" />
    <actuatorvel name="left_hip_yaw_v" actuator="left_hip_yaw" />
    <actuatorfrc name="left_hip_yaw_f" actuator="left_hip_yaw" noise="0.001" />
    <actuatorpos name="left_hip_roll_p" actuator="left_hip_roll" />
    <actuatorvel name="left_hip_roll_v" actuator="left_hip_roll" />
    <actuatorfrc name="left_hip_roll_f" actuator="left_hip_roll" noise="0.001" />
    <actuatorpos name="left_knee_pitch_p" actuator="left_knee_pitch" />
    <actuatorvel name="left_knee_pitch_v" actuator="left_knee_pitch" />
    <actuatorfrc name="left_knee_pitch_f" actuator="left_knee_pitch" noise="0.001" />
    <actuatorpos name="left_ankle_pitch_p" actuator="left_ankle_pitch" />
    <actuatorvel name="left_ankle_pitch_v" actuator="left_ankle_pitch" />
    <actuatorfrc name="left_ankle_pitch_f" actuator="left_ankle_pitch" noise="0.001" />
    <framequat name="orientation" objtype="site" noise="0.001" objname="imu" />
    <gyro name="angular-velocity" site="imu" noise="0.005" cutoff="34.9" />
  </sensor>

  <keyframe>
    <key name="default" qpos="0.0 0.0 0.293 1.0 0.0 0.0 0.0 0.23 0.0 0.0 0.741 -0.5 -0.23 0.0 0.0 -0.741 0.5" />
  </keyframe>
</mujoco>
