<mujoco model="opus">
  <compiler angle="radian" meshdir="meshes" eulerseq="zyx" autolimits="true"/>
  <default>
    <joint limited="true" damping="0.53" armature="0.008793405204572328" frictionloss="0.001"/>
    <geom condim="4" contype="1" conaffinity="15" friction="0.9 0.2 0.2" solref="0.001 2"/>
    <motor ctrllimited="true"/>
    <equality solref="0.001 2"/>
    <default class="visualgeom">
      <geom material="visualgeom" condim="1" contype="0" conaffinity="0"/>
    </default>
  </default>
  <option iterations="50" timestep="0.001" solver="PGS" gravity="0 0 -9.81"/>

  <asset>
    <mesh name="Torso" file="Torso.stl"/>
    <mesh name="right_shoulder_yaw" file="right_shoulder_yaw.stl"/>
    <mesh name="left_shoulder_yaw" file="left_shoulder_yaw.stl"/>
    <mesh name="right_shoulder_yaw_motor" file="right_shoulder_yaw_motor.stl"/>
    <mesh name="hip_yaw_right" file="hip_yaw_right.stl"/>
    <mesh name="hip_yaw_left" file="hip_yaw_left.stl"/>
    <mesh name="left_shoulder_yaw_motor" file="left_shoulder_yaw_motor.stl"/>
    <mesh name="hip_roll_right" file="hip_roll_right.stl"/>
    <mesh name="hip_roll_left" file="hip_roll_left.stl"/>
    <mesh name="right_hand" file="right_hand.stl"/>
    <mesh name="left_hand" file="left_hand.stl"/>
    <mesh name="knee_pitch_left" file="knee_pitch_left.stl"/>
    <mesh name="knee_pitch_right" file="knee_pitch_right.stl"/>
    <mesh name="right_knee_pitch_motor" file="right_knee_pitch_motor.stl"/>
    <mesh name="left_knee_pitch_motor" file="left_knee_pitch_motor.stl"/>
    <mesh name="foot_right" file="foot_right.stl"/>
    <mesh name="foot_left" file="foot_left.stl"/>

    <texture name="texplane" type="2d" builtin="checker" rgb1=".0 .0 .0" rgb2=".8 .8 .8" width="100" height="108"/>
    <material name="matplane" reflectance="0." texture="texplane" texrepeat="1 1" texuniform="true"/>
    <material name="visualgeom" rgba="0.5 0.9 0.2 1"/>
  </asset>
  <worldbody>
    <geom name="ground" type="plane" pos="0.001 0 0" quat="1 0 0 0" material="matplane" condim="1" conaffinity="15" size="0 0 1"/>
    <light directional="true" diffuse="0.6 0.6 0.6" specular="0.2 0.2 0.2" pos="0 0 4" dir="0 0 -1"/>
    <light directional="true" diffuse="0.4 0.4 0.4" specular="0.1 0.1 0.1" pos="0 0 5.0" dir="0 0 -1" castshadow="false"/>
    <body name="root" pos="0 0 0" quat="0 0 0 1">
    <freejoint name="root"/>
    <camera name="front" pos="0 -3 1" xyaxes="1 0 0 0 1 2" mode="trackcom"/>
    <camera name="side" pos="-2.893 -1.330 0.757" xyaxes="0.405 -0.914 0.000 0.419 0.186 0.889" mode="trackcom"/>
    <site name="imu" size="0.01" pos="0 0 0"/>
    <geom type="mesh" rgba="0.972549 0.529412 0.00392157 1" mesh="Torso"/>
    <geom pos="-0.0782502 -0.000326898 0.0461512" quat="0.5 0.5 0.5 0.5" type="mesh" rgba="0.972549 0.529412 0.00392157 1" mesh="right_shoulder_yaw"/>
    <geom pos="-0.10825 -0.0191519 0.029852" quat="0.707107 0.707107 -9.47343e-09 9.47343e-09" type="mesh" rgba="0.4 0.4 0.4 1" mesh="right_shoulder_yaw_motor"/>
    <geom pos="-0.138253 -0.0190019 -0.0344899" quat="-0.153046 0.153046 0.690345 0.690346" type="mesh" rgba="0.980392 0.713726 0.00392157 1" mesh="right_hand"/>
    <geom pos="0.0780498 -0.000326898 0.0461512" quat="0.5 -0.5 -0.5 0.5" type="mesh" rgba="0.972549 0.529412 0.00392157 1" mesh="left_shoulder_yaw"/>
    <geom pos="0.10805 -0.0191519 0.029852" quat="0.707107 0.707107 6.93506e-09 -6.93506e-09" type="mesh" rgba="0.4 0.4 0.4 1" mesh="left_shoulder_yaw_motor"/>
    <geom pos="0.138053 -0.0190019 -0.0344899" quat="-0.153046 0.153046 -0.690346 -0.690346" type="mesh" rgba="0.980392 0.713726 0.00392157 1" mesh="left_hand"/>
    <body name="hip_yaw_right" pos="-0.0457502 -0.000326896 -0.103849" quat="0.5 -0.5 -0.5 0.5">
      <inertial pos="-0.00782957 -0.000315357 0.0163297" quat="0.73746 0.674698 0.0153223 -0.0264575" mass="0.0932053" diaginertia="3.59902e-05 3.36518e-05 3.07706e-05"/>
      <joint name="right_hip_pitch" pos="0 0 0" axis="0 0 -1" range="-1.5708 1.5708" actuatorfrcrange="-2 2"/>
      <geom type="mesh" rgba="0.972549 0.529412 0.00392157 1" mesh="hip_yaw_right"/>
      <body name="hip_roll_right" pos="-0.0255 0.0125 0.01936" quat="0.707107 3.2817e-08 0.707107 -3.2817e-08">
        <inertial pos="3.95624e-05 0.0445473 0.0271953" quat="0.557457 0.830204 0.00151221 0.000249092" mass="0.0992888" diaginertia="5.45822e-05 3.86078e-05 3.02163e-05"/>
        <joint name="right_hip_yaw" pos="0 0 0" axis="0 0 1" range="-0.0872665 1.5708" actuatorfrcrange="-2 2"/>
        <geom type="mesh" rgba="0.972549 0.529412 0.00392157 1" mesh="hip_roll_right"/>
        <body name="knee_pitch_left" pos="0 0.06776 0.015" quat="0.707107 -0.707107 0 0">
          <inertial pos="0.000832072 0.00663444 -0.00535636" quat="0.702263 0.0826207 -0.0826207 0.702263" mass="0.0174156" diaginertia="1.12064e-05 8.67796e-06 4.51663e-06"/>
          <joint name="right_hip_roll" pos="0 0 0" axis="0 0 -1" range="-0.785398 0.785398" actuatorfrcrange="-2 2"/>
          <geom type="mesh" rgba="0.972549 0.529412 0.00392157 1" mesh="knee_pitch_left"/>
          <body name="right_knee_pitch_motor" pos="0.018825 0 0.02221" quat="0.5 0.5 -0.5 -0.5">
            <inertial pos="5.2853e-11 0.03886 0.017678" quat="0.707107 0.707107 2.09986e-05 2.09986e-05" mass="0.164074" diaginertia="0.000175989 0.000161732 3.83967e-05"/>
            <joint name="right_knee_pitch" pos="0 0 0" axis="0 0 -1" range="0 1.0472" actuatorfrcrange="-2 2"/>
            <geom type="mesh" rgba="0.4 0.4 0.4 1" mesh="right_knee_pitch_motor"/>
            <body name="foot_right" pos="0 0.07772 2.08707e-09" quat="1 4.64102e-08 0 0">
              <inertial pos="-0.00909654 0.0229469 0.0186337" quat="0.505668 0.505668 0.494267 0.494267" mass="0.0743148" diaginertia="7.16309e-05 6.04794e-05 1.96043e-05"/>
              <joint name="right_ankle_pitch" pos="0 0 0" axis="0 0 1" range="-1.0472 1.0472" actuatorfrcrange="-2 2"/>
              <geom type="mesh" rgba="0.972549 0.529412 0.00392157 1" mesh="foot_right"/>
            </body>
          </body>
        </body>
      </body>
    </body>
    <body name="hip_yaw_left" pos="0.0455498 -0.000326896 -0.103849" quat="0.5 0.5 0.5 0.5">
      <inertial pos="-0.00782956 0.000315355 0.0163297" quat="0.674699 0.73746 0.0264579 -0.0153225" mass="0.0932053" diaginertia="3.59902e-05 3.36518e-05 3.07706e-05"/>
      <joint name="left_hip_pitch" pos="0 0 0" axis="0 0 -1" range="-1.5708 1.5708" actuatorfrcrange="-2 2"/>
      <geom type="mesh" rgba="0.972549 0.529412 0.00392157 1" mesh="hip_yaw_left"/>
      <body name="hip_roll_left" pos="-0.0255 -0.0125 0.01936" quat="1.64085e-08 -0.707107 -1.64085e-08 -0.707107">
        <inertial pos="-3.95635e-05 0.0445472 0.0271953" quat="0.557458 0.830204 -0.00151221 -0.000249094" mass="0.0992889" diaginertia="5.45823e-05 3.86079e-05 3.02163e-05"/>
        <joint name="left_hip_yaw" pos="0 0 0" axis="0 0 1" range="-1.5708 0.0872665" actuatorfrcrange="-2 2"/>
        <geom type="mesh" rgba="0.972549 0.529412 0.00392157 1" mesh="hip_roll_left"/>
        <body name="knee_pitch_right" pos="0 0.06776 0.015" quat="0.707107 -0.707107 0 0">
          <inertial pos="-0.000831894 0.00663441 -0.00535646" quat="0.702263 0.0826213 -0.0826213 0.702263" mass="0.0174154" diaginertia="1.12063e-05 8.67794e-06 4.51657e-06"/>
          <joint name="left_hip_roll" pos="0 0 0" axis="0 0 -1" range="-0.785398 0.785398" actuatorfrcrange="-2 2"/>
          <geom type="mesh" rgba="0.972549 0.529412 0.00392157 1" mesh="knee_pitch_right"/>
          <body name="left_knee_pitch_motor" pos="-0.018825 0 0.02221" quat="0.5 -0.5 0.5 -0.5">
            <inertial pos="-1.24277e-10 -0.03886 0.0174509" quat="0.704124 0.710078 -2.0918e-05 -2.10949e-05" mass="0.164074" diaginertia="0.000175991 0.00016174 3.83899e-05"/>
            <joint name="left_knee_pitch" pos="0 0 0" axis="0 0 -1" range="-1.0472 0" actuatorfrcrange="-2 2"/>
            <geom type="mesh" rgba="0.4 0.4 0.4 1" mesh="left_knee_pitch_motor"/>
            <body name="foot_left" pos="0 -0.07772 -0.000499991" quat="1 4.64102e-08 0 0">
              <inertial pos="-0.00909637 -0.0229469 0.0186334" quat="0.494267 0.494267 0.505668 0.505668" mass="0.0743146" diaginertia="7.16302e-05 6.04787e-05 1.96042e-05"/>
              <joint name="left_ankle_pitch" pos="0 0 0" axis="0 0 1" range="-1.0472 1.0472" actuatorfrcrange="-2 2"/>
              <geom type="mesh" rgba="0.972549 0.529412 0.00392157 1" mesh="foot_left"/>
            </body>
          </body>
        </body>
      </body>
    </body>

    </body>
  </worldbody>
  <actuator>
    <motor name="right_hip_pitch" joint="right_hip_pitch" ctrllimited="true" ctrlrange="-200 200" gear="1" />
    <motor name="right_hip_yaw" joint="right_hip_yaw" ctrllimited="true" ctrlrange="-200 200" gear="1" />
    <motor name="right_hip_roll" joint="right_hip_roll" ctrllimited="true" ctrlrange="-200 200" gear="1" />
    <motor name="right_knee_pitch" joint="right_knee_pitch" ctrllimited="true" ctrlrange="-200 200" gear="1" />
    <motor name="right_ankle_pitch" joint="right_ankle_pitch" ctrllimited="true" ctrlrange="-200 200" gear="1" />

    <motor name="left_hip_pitch" joint="left_hip_pitch" ctrllimited="true" ctrlrange="-200 200" gear="1" />
    <motor name="left_hip_yaw" joint="left_hip_yaw" ctrllimited="true" ctrlrange="-200 200" gear="1" />
    <motor name="left_hip_roll" joint="left_hip_roll" ctrllimited="true" ctrlrange="-200 200" gear="1" />
    <motor name="left_knee_pitch" joint="left_knee_pitch" ctrllimited="true" ctrlrange="-200 200" gear="1" />
    <motor name="left_ankle_pitch" joint="left_ankle_pitch" ctrllimited="true" ctrlrange="-200 200" gear="1" />
  </actuator>
  <sensor>
    <framequat name="orientation" objtype="site" noise="0.001" objname="imu"/>
    <gyro name="angular-velocity" site="imu" noise="0.005" cutoff="34.9"/>
  </sensor>

  <keyframe>
    <key name="default" qpos="0.0 0.0 0.32  1.0 0.0 0.0 0.0 -0.23 0.0 0.0 0.741 0.5 0.23 0.0 0.0 -0.741 -0.5   " />
  </keyframe>
</mujoco>