<mujoco model="robot_7dof_arm">
  <compiler angle="radian" meshdir="meshes/"/>
  <asset>
    <mesh name="upper_limb_assembly_7_dof_1_torso_1_top_skeleton_2_simple" file="upper_limb_assembly_7_dof_1_torso_1_top_skeleton_2_simple.stl"/>
    <mesh name="head_1_neck_2_simple" file="head_1_neck_2_simple.stl"/>
    <mesh name="upper_limb_assembly_7_dof_1_full_arm_7_dof_2_upper_left_arm_1_arm_part_1_1_simple" file="upper_limb_assembly_7_dof_1_full_arm_7_dof_2_upper_left_arm_1_arm_part_1_1_simple.stl"/>
    <mesh name="upper_limb_assembly_7_dof_1_full_arm_7_dof_1_upper_left_arm_1_arm_part_1_1_simple" file="upper_limb_assembly_7_dof_1_full_arm_7_dof_1_upper_left_arm_1_arm_part_1_1_simple.stl"/>
    <mesh name="upper_limb_assembly_7_dof_1_torso_1_bottom_skeleton_1_simple" file="upper_limb_assembly_7_dof_1_torso_1_bottom_skeleton_1_simple.stl"/>
    <mesh name="upper_limb_assembly_7_dof_1_torso_1_battery_case_base_1_simple" file="upper_limb_assembly_7_dof_1_torso_1_battery_case_base_1_simple.stl"/>
    <mesh name="head_1_skull_1_simple" file="head_1_skull_1_simple.stl"/>
    <mesh name="upper_limb_assembly_7_dof_1_full_arm_7_dof_2_upper_left_arm_1_rmd_x8_90_mock_1_outer_rmd_x8_90_1_simple" file="upper_limb_assembly_7_dof_1_full_arm_7_dof_2_upper_left_arm_1_rmd_x8_90_mock_1_outer_rmd_x8_90_1_simple.stl"/>
    <mesh name="upper_limb_assembly_7_dof_1_full_arm_7_dof_1_upper_left_arm_1_rmd_x8_90_mock_1_outer_rmd_x8_90_1_simple" file="upper_limb_assembly_7_dof_1_full_arm_7_dof_1_upper_left_arm_1_rmd_x8_90_mock_1_outer_rmd_x8_90_1_simple.stl"/>
    <mesh name="upper_limb_assembly_7_dof_1_torso_1_rmd_x8_90_mock_1_outer_rmd_x8_90_1_simple" file="upper_limb_assembly_7_dof_1_torso_1_rmd_x8_90_mock_1_outer_rmd_x8_90_1_simple.stl"/>
    <mesh name="upper_limb_assembly_7_dof_1_torso_1_batter_case_top_1_simple" file="upper_limb_assembly_7_dof_1_torso_1_batter_case_top_1_simple.stl"/>
    <mesh name="upper_limb_assembly_7_dof_1_torso_1_battery_1_simple" file="upper_limb_assembly_7_dof_1_torso_1_battery_1_simple.stl"/>
    <mesh name="upper_limb_assembly_7_dof_1_torso_1_battery_cap_2_simple" file="upper_limb_assembly_7_dof_1_torso_1_battery_cap_2_simple.stl"/>
    <mesh name="head_1_camera_speaker_holder_1_simple" file="head_1_camera_speaker_holder_1_simple.stl"/>
    <mesh name="head_1_neck_1_simple" file="head_1_neck_1_simple.stl"/>
    <mesh name="head_1_mic_holder_2_simple" file="head_1_mic_holder_2_simple.stl"/>
    <mesh name="head_1_head_back_2_simple" file="head_1_head_back_2_simple.stl"/>
    <mesh name="upper_limb_assembly_7_dof_1_full_arm_7_dof_2_upper_left_arm_1_rmd_x8_90_mock_1_inner_rmd_x8_90_1_simple" file="upper_limb_assembly_7_dof_1_full_arm_7_dof_2_upper_left_arm_1_rmd_x8_90_mock_1_inner_rmd_x8_90_1_simple.stl"/>
    <mesh name="upper_limb_assembly_7_dof_1_full_arm_7_dof_1_upper_left_arm_1_rmd_x8_90_mock_1_inner_rmd_x8_90_1_simple" file="upper_limb_assembly_7_dof_1_full_arm_7_dof_1_upper_left_arm_1_rmd_x8_90_mock_1_inner_rmd_x8_90_1_simple.stl"/>
    <mesh name="upper_limb_assembly_7_dof_1_torso_1_rmd_x8_90_mock_1_inner_rmd_x8_90_1_simple" file="upper_limb_assembly_7_dof_1_torso_1_rmd_x8_90_mock_1_inner_rmd_x8_90_1_simple.stl"/>
    <mesh name="head_1_head_front_1_simple" file="head_1_head_front_1_simple.stl"/>
    <mesh name="upper_limb_assembly_7_dof_1_full_arm_7_dof_2_upper_left_arm_1_arm_part_2_1_simple" file="upper_limb_assembly_7_dof_1_full_arm_7_dof_2_upper_left_arm_1_arm_part_2_1_simple.stl"/>
    <mesh name="upper_limb_assembly_7_dof_1_full_arm_7_dof_1_upper_left_arm_1_arm_part_2_1_simple" file="upper_limb_assembly_7_dof_1_full_arm_7_dof_1_upper_left_arm_1_arm_part_2_1_simple.stl"/>
    <mesh name="upper_limb_assembly_7_dof_1_torso_1_hip_mount_1_simple" file="upper_limb_assembly_7_dof_1_torso_1_hip_mount_1_simple.stl"/>
    <mesh name="upper_limb_assembly_7_dof_1_full_arm_7_dof_2_upper_left_arm_1_arm_part_3_1_simple" file="upper_limb_assembly_7_dof_1_full_arm_7_dof_2_upper_left_arm_1_arm_part_3_1_simple.stl"/>
    <mesh name="upper_limb_assembly_7_dof_1_full_arm_7_dof_1_upper_left_arm_1_arm_part_3_1_simple" file="upper_limb_assembly_7_dof_1_full_arm_7_dof_1_upper_left_arm_1_arm_part_3_1_simple.stl"/>
    <mesh name="lower_limbs_1_leg_assembly_right_1_leg_part_1_2_simple" file="lower_limbs_1_leg_assembly_right_1_leg_part_1_2_simple.stl"/>
    <mesh name="upper_limb_assembly_7_dof_1_full_arm_7_dof_2_upper_left_arm_1_rmd_x8_90_mock_2_outer_rmd_x8_90_1_simple" file="upper_limb_assembly_7_dof_1_full_arm_7_dof_2_upper_left_arm_1_rmd_x8_90_mock_2_outer_rmd_x8_90_1_simple.stl"/>
    <mesh name="upper_limb_assembly_7_dof_1_full_arm_7_dof_1_upper_left_arm_1_rmd_x8_90_mock_2_outer_rmd_x8_90_1_simple" file="upper_limb_assembly_7_dof_1_full_arm_7_dof_1_upper_left_arm_1_rmd_x8_90_mock_2_outer_rmd_x8_90_1_simple.stl"/>
    <mesh name="lower_limbs_1_leg_assembly_left_1_leg_part_1_2_simple" file="lower_limbs_1_leg_assembly_left_1_leg_part_1_2_simple.stl"/>
    <mesh name="lower_limbs_1_leg_assembly_right_1_rmd_x12_150_mock_1_outer_x12_150_1_simple" file="lower_limbs_1_leg_assembly_right_1_rmd_x12_150_mock_1_outer_x12_150_1_simple.stl"/>
    <mesh name="upper_limb_assembly_7_dof_1_full_arm_7_dof_2_upper_left_arm_1_rmd_x8_90_mock_2_inner_rmd_x8_90_1_simple" file="upper_limb_assembly_7_dof_1_full_arm_7_dof_2_upper_left_arm_1_rmd_x8_90_mock_2_inner_rmd_x8_90_1_simple.stl"/>
    <mesh name="upper_limb_assembly_7_dof_1_full_arm_7_dof_1_upper_left_arm_1_rmd_x8_90_mock_2_inner_rmd_x8_90_1_simple" file="upper_limb_assembly_7_dof_1_full_arm_7_dof_1_upper_left_arm_1_rmd_x8_90_mock_2_inner_rmd_x8_90_1_simple.stl"/>
    <mesh name="lower_limbs_1_part_1_1_simple" file="lower_limbs_1_part_1_1_simple.stl"/>
    <mesh name="lower_limbs_1_leg_assembly_left_1_rmd_x12_150_mock_1_outer_x12_150_1_simple" file="lower_limbs_1_leg_assembly_left_1_rmd_x12_150_mock_1_outer_x12_150_1_simple.stl"/>
    <mesh name="lower_limbs_1_leg_assembly_right_1_rmd_x12_150_mock_1_inner_x12_150_1_simple" file="lower_limbs_1_leg_assembly_right_1_rmd_x12_150_mock_1_inner_x12_150_1_simple.stl"/>
    <mesh name="upper_limb_assembly_7_dof_1_full_arm_7_dof_2_upper_left_arm_1_arm_part_4_1_simple" file="upper_limb_assembly_7_dof_1_full_arm_7_dof_2_upper_left_arm_1_arm_part_4_1_simple.stl"/>
    <mesh name="upper_limb_assembly_7_dof_1_full_arm_7_dof_1_upper_left_arm_1_arm_part_4_1_simple" file="upper_limb_assembly_7_dof_1_full_arm_7_dof_1_upper_left_arm_1_arm_part_4_1_simple.stl"/>
    <mesh name="lower_limbs_1_leg_assembly_left_1_rmd_x12_150_mock_1_inner_x12_150_1_simple" file="lower_limbs_1_leg_assembly_left_1_rmd_x12_150_mock_1_inner_x12_150_1_simple.stl"/>
    <mesh name="lower_limbs_1_leg_assembly_right_1_leg_part_2_right_1_simple" file="lower_limbs_1_leg_assembly_right_1_leg_part_2_right_1_simple.stl"/>
    <mesh name="upper_limb_assembly_7_dof_1_full_arm_7_dof_2_upper_left_arm_1_arm_coupler_1_simple" file="upper_limb_assembly_7_dof_1_full_arm_7_dof_2_upper_left_arm_1_arm_coupler_1_simple.stl"/>
    <mesh name="upper_limb_assembly_7_dof_1_full_arm_7_dof_2_upper_left_arm_1_arm_part_5_1_simple" file="upper_limb_assembly_7_dof_1_full_arm_7_dof_2_upper_left_arm_1_arm_part_5_1_simple.stl"/>
    <mesh name="upper_limb_assembly_7_dof_1_full_arm_7_dof_1_upper_left_arm_1_arm_coupler_1_simple" file="upper_limb_assembly_7_dof_1_full_arm_7_dof_1_upper_left_arm_1_arm_coupler_1_simple.stl"/>
    <mesh name="upper_limb_assembly_7_dof_1_full_arm_7_dof_1_upper_left_arm_1_arm_part_5_1_simple" file="upper_limb_assembly_7_dof_1_full_arm_7_dof_1_upper_left_arm_1_arm_part_5_1_simple.stl"/>
    <mesh name="lower_limbs_1_leg_assembly_left_1_leg_part_2_left_1_simple" file="lower_limbs_1_leg_assembly_left_1_leg_part_2_left_1_simple.stl"/>
    <mesh name="lower_limbs_1_leg_assembly_right_1_rmd_x8_90_mock_1_outer_rmd_x8_90_1_simple" file="lower_limbs_1_leg_assembly_right_1_rmd_x8_90_mock_1_outer_rmd_x8_90_1_simple.stl"/>
    <mesh name="upper_limb_assembly_7_dof_1_full_arm_7_dof_2_upper_left_arm_1_rmd_x4_24_mock_1_inner_rmd_x4_24_1_simple" file="upper_limb_assembly_7_dof_1_full_arm_7_dof_2_upper_left_arm_1_rmd_x4_24_mock_1_inner_rmd_x4_24_1_simple.stl"/>
    <mesh name="upper_limb_assembly_7_dof_1_full_arm_7_dof_1_upper_left_arm_1_rmd_x4_24_mock_1_inner_rmd_x4_24_1_simple" file="upper_limb_assembly_7_dof_1_full_arm_7_dof_1_upper_left_arm_1_rmd_x4_24_mock_1_inner_rmd_x4_24_1_simple.stl"/>
    <mesh name="lower_limbs_1_leg_assembly_left_1_rmd_x8_90_mock_1_outer_rmd_x8_90_1_simple" file="lower_limbs_1_leg_assembly_left_1_rmd_x8_90_mock_1_outer_rmd_x8_90_1_simple.stl"/>
    <mesh name="lower_limbs_1_leg_assembly_right_1_rmd_x8_90_mock_1_inner_rmd_x8_90_1_simple" file="lower_limbs_1_leg_assembly_right_1_rmd_x8_90_mock_1_inner_rmd_x8_90_1_simple.stl"/>
    <mesh name="upper_limb_assembly_7_dof_1_full_arm_7_dof_2_upper_left_arm_1_rmd_x4_24_mock_1_outer_rmd_x4_24_1_simple" file="upper_limb_assembly_7_dof_1_full_arm_7_dof_2_upper_left_arm_1_rmd_x4_24_mock_1_outer_rmd_x4_24_1_simple.stl"/>
    <mesh name="upper_limb_assembly_7_dof_1_full_arm_7_dof_1_upper_left_arm_1_rmd_x4_24_mock_1_outer_rmd_x4_24_1_simple" file="upper_limb_assembly_7_dof_1_full_arm_7_dof_1_upper_left_arm_1_rmd_x4_24_mock_1_outer_rmd_x4_24_1_simple.stl"/>
    <mesh name="lower_limbs_1_leg_assembly_left_1_rmd_x8_90_mock_1_inner_rmd_x8_90_1_simple" file="lower_limbs_1_leg_assembly_left_1_rmd_x8_90_mock_1_inner_rmd_x8_90_1_simple.stl"/>
    <mesh name="lower_limbs_1_leg_assembly_right_1_leg_part_3_1_simple" file="lower_limbs_1_leg_assembly_right_1_leg_part_3_1_simple.stl"/>
    <mesh name="upper_limb_assembly_7_dof_1_full_arm_7_dof_2_upper_left_arm_1_arm_part_6_1_simple" file="upper_limb_assembly_7_dof_1_full_arm_7_dof_2_upper_left_arm_1_arm_part_6_1_simple.stl"/>
    <mesh name="upper_limb_assembly_7_dof_1_full_arm_7_dof_1_upper_left_arm_1_arm_part_6_1_simple" file="upper_limb_assembly_7_dof_1_full_arm_7_dof_1_upper_left_arm_1_arm_part_6_1_simple.stl"/>
    <mesh name="lower_limbs_1_leg_assembly_left_1_leg_part_3_1_simple" file="lower_limbs_1_leg_assembly_left_1_leg_part_3_1_simple.stl"/>
    <mesh name="lower_limbs_1_leg_assembly_right_1_leg_part_4_1_simple" file="lower_limbs_1_leg_assembly_right_1_leg_part_4_1_simple.stl"/>
    <mesh name="lower_limbs_1_leg_assembly_right_1_rmd_x8_90_mock_2_outer_rmd_x8_90_1_simple" file="lower_limbs_1_leg_assembly_right_1_rmd_x8_90_mock_2_outer_rmd_x8_90_1_simple.stl"/>
    <mesh name="upper_limb_assembly_7_dof_1_full_arm_7_dof_2_upper_left_arm_1_arm_part_7_2_simple" file="upper_limb_assembly_7_dof_1_full_arm_7_dof_2_upper_left_arm_1_arm_part_7_2_simple.stl"/>
    <mesh name="upper_limb_assembly_7_dof_1_full_arm_7_dof_2_upper_left_arm_1_rmd_x4_24_mock_2_outer_rmd_x4_24_1_simple" file="upper_limb_assembly_7_dof_1_full_arm_7_dof_2_upper_left_arm_1_rmd_x4_24_mock_2_outer_rmd_x4_24_1_simple.stl"/>
    <mesh name="upper_limb_assembly_7_dof_1_full_arm_7_dof_1_upper_left_arm_1_arm_part_7_2_simple" file="upper_limb_assembly_7_dof_1_full_arm_7_dof_1_upper_left_arm_1_arm_part_7_2_simple.stl"/>
    <mesh name="upper_limb_assembly_7_dof_1_full_arm_7_dof_1_upper_left_arm_1_rmd_x4_24_mock_2_outer_rmd_x4_24_1_simple" file="upper_limb_assembly_7_dof_1_full_arm_7_dof_1_upper_left_arm_1_rmd_x4_24_mock_2_outer_rmd_x4_24_1_simple.stl"/>
    <mesh name="lower_limbs_1_leg_assembly_left_1_leg_part_4_1_simple" file="lower_limbs_1_leg_assembly_left_1_leg_part_4_1_simple.stl"/>
    <mesh name="lower_limbs_1_leg_assembly_left_1_rmd_x8_90_mock_2_outer_rmd_x8_90_1_simple" file="lower_limbs_1_leg_assembly_left_1_rmd_x8_90_mock_2_outer_rmd_x8_90_1_simple.stl"/>
    <mesh name="lower_limbs_1_leg_assembly_right_1_rmd_x8_90_mock_2_inner_rmd_x8_90_1_simple" file="lower_limbs_1_leg_assembly_right_1_rmd_x8_90_mock_2_inner_rmd_x8_90_1_simple.stl"/>
    <mesh name="upper_limb_assembly_7_dof_1_full_arm_7_dof_2_upper_left_arm_1_rmd_x4_24_mock_2_inner_rmd_x4_24_1_simple" file="upper_limb_assembly_7_dof_1_full_arm_7_dof_2_upper_left_arm_1_rmd_x4_24_mock_2_inner_rmd_x4_24_1_simple.stl"/>
    <mesh name="upper_limb_assembly_7_dof_1_full_arm_7_dof_1_upper_left_arm_1_rmd_x4_24_mock_2_inner_rmd_x4_24_1_simple" file="upper_limb_assembly_7_dof_1_full_arm_7_dof_1_upper_left_arm_1_rmd_x4_24_mock_2_inner_rmd_x4_24_1_simple.stl"/>
    <mesh name="lower_limbs_1_leg_assembly_left_1_rmd_x8_90_mock_2_inner_rmd_x8_90_1_simple" file="lower_limbs_1_leg_assembly_left_1_rmd_x8_90_mock_2_inner_rmd_x8_90_1_simple.stl"/>
    <mesh name="lower_limbs_1_leg_assembly_right_1_leg_part_5_right_2_simple" file="lower_limbs_1_leg_assembly_right_1_leg_part_5_right_2_simple.stl"/>
    <mesh name="upper_limb_assembly_7_dof_1_full_arm_7_dof_2_upper_left_arm_1_arm_part_8_3_simple" file="upper_limb_assembly_7_dof_1_full_arm_7_dof_2_upper_left_arm_1_arm_part_8_3_simple.stl"/>
    <mesh name="upper_limb_assembly_7_dof_1_full_arm_7_dof_1_upper_left_arm_1_arm_part_8_3_simple" file="upper_limb_assembly_7_dof_1_full_arm_7_dof_1_upper_left_arm_1_arm_part_8_3_simple.stl"/>
    <mesh name="lower_limbs_1_leg_assembly_left_1_let_part_5_left_1_simple" file="lower_limbs_1_leg_assembly_left_1_let_part_5_left_1_simple.stl"/>
    <mesh name="lower_limbs_1_leg_assembly_right_1_rmd_x8_90_mock_3_outer_rmd_x8_90_1_simple" file="lower_limbs_1_leg_assembly_right_1_rmd_x8_90_mock_3_outer_rmd_x8_90_1_simple.stl"/>
    <mesh name="upper_limb_assembly_7_dof_1_full_arm_7_dof_2_upper_left_arm_1_arm_coupler_2_simple" file="upper_limb_assembly_7_dof_1_full_arm_7_dof_2_upper_left_arm_1_arm_coupler_2_simple.stl"/>
    <mesh name="upper_limb_assembly_7_dof_1_full_arm_7_dof_2_upper_left_arm_1_arm_part_9_1_simple" file="upper_limb_assembly_7_dof_1_full_arm_7_dof_2_upper_left_arm_1_arm_part_9_1_simple.stl"/>
    <mesh name="upper_limb_assembly_7_dof_1_full_arm_7_dof_1_upper_left_arm_1_arm_coupler_2_simple" file="upper_limb_assembly_7_dof_1_full_arm_7_dof_1_upper_left_arm_1_arm_coupler_2_simple.stl"/>
    <mesh name="upper_limb_assembly_7_dof_1_full_arm_7_dof_1_upper_left_arm_1_arm_part_9_1_simple" file="upper_limb_assembly_7_dof_1_full_arm_7_dof_1_upper_left_arm_1_arm_part_9_1_simple.stl"/>
    <mesh name="lower_limbs_1_leg_assembly_left_1_rmd_x8_90_mock_3_outer_rmd_x8_90_1_simple" file="lower_limbs_1_leg_assembly_left_1_rmd_x8_90_mock_3_outer_rmd_x8_90_1_simple.stl"/>
    <mesh name="lower_limbs_1_leg_assembly_right_1_rmd_x8_90_mock_3_inner_rmd_x8_90_1_simple" file="lower_limbs_1_leg_assembly_right_1_rmd_x8_90_mock_3_inner_rmd_x8_90_1_simple.stl"/>
    <mesh name="upper_limb_assembly_7_dof_1_full_arm_7_dof_2_lower_arm_3_dof_1_rmd_x4_24_mock_1_inner_rmd_x4_24_1_simple" file="upper_limb_assembly_7_dof_1_full_arm_7_dof_2_lower_arm_3_dof_1_rmd_x4_24_mock_1_inner_rmd_x4_24_1_simple.stl"/>
    <mesh name="upper_limb_assembly_7_dof_1_full_arm_7_dof_1_lower_arm_3_dof_1_rmd_x4_24_mock_1_inner_rmd_x4_24_1_simple" file="upper_limb_assembly_7_dof_1_full_arm_7_dof_1_lower_arm_3_dof_1_rmd_x4_24_mock_1_inner_rmd_x4_24_1_simple.stl"/>
    <mesh name="lower_limbs_1_leg_assembly_left_1_rmd_x8_90_mock_3_inner_rmd_x8_90_1_simple" file="lower_limbs_1_leg_assembly_left_1_rmd_x8_90_mock_3_inner_rmd_x8_90_1_simple.stl"/>
    <mesh name="lower_limbs_1_leg_assembly_right_1_leg_part_6_2_simple" file="lower_limbs_1_leg_assembly_right_1_leg_part_6_2_simple.stl"/>
    <mesh name="upper_limb_assembly_7_dof_1_full_arm_7_dof_2_lower_arm_3_dof_1_rmd_x4_24_mock_1_outer_rmd_x4_24_1_simple" file="upper_limb_assembly_7_dof_1_full_arm_7_dof_2_lower_arm_3_dof_1_rmd_x4_24_mock_1_outer_rmd_x4_24_1_simple.stl"/>
    <mesh name="upper_limb_assembly_7_dof_1_full_arm_7_dof_1_lower_arm_3_dof_1_rmd_x4_24_mock_1_outer_rmd_x4_24_1_simple" file="upper_limb_assembly_7_dof_1_full_arm_7_dof_1_lower_arm_3_dof_1_rmd_x4_24_mock_1_outer_rmd_x4_24_1_simple.stl"/>
    <mesh name="lower_limbs_1_leg_assembly_left_1_leg_part_6_2_simple" file="lower_limbs_1_leg_assembly_left_1_leg_part_6_2_simple.stl"/>
    <mesh name="lower_limbs_1_leg_assembly_right_1_rmd_x4_24_mock_1_inner_rmd_x4_24_1_simple" file="lower_limbs_1_leg_assembly_right_1_rmd_x4_24_mock_1_inner_rmd_x4_24_1_simple.stl"/>
    <mesh name="lower_limbs_1_leg_assembly_right_1_leg_part_7_1_simple" file="lower_limbs_1_leg_assembly_right_1_leg_part_7_1_simple.stl"/>
    <mesh name="upper_limb_assembly_7_dof_1_full_arm_7_dof_2_lower_arm_3_dof_1_wrist_part_1_1_simple" file="upper_limb_assembly_7_dof_1_full_arm_7_dof_2_lower_arm_3_dof_1_wrist_part_1_1_simple.stl"/>
    <mesh name="upper_limb_assembly_7_dof_1_full_arm_7_dof_1_lower_arm_3_dof_1_wrist_part_1_1_simple" file="upper_limb_assembly_7_dof_1_full_arm_7_dof_1_lower_arm_3_dof_1_wrist_part_1_1_simple.stl"/>
    <mesh name="lower_limbs_1_leg_assembly_left_1_rmd_x4_24_mock_1_inner_rmd_x4_24_1_simple" file="lower_limbs_1_leg_assembly_left_1_rmd_x4_24_mock_1_inner_rmd_x4_24_1_simple.stl"/>
    <mesh name="lower_limbs_1_leg_assembly_left_1_leg_part_7_1_simple" file="lower_limbs_1_leg_assembly_left_1_leg_part_7_1_simple.stl"/>
    <mesh name="lower_limbs_1_leg_assembly_right_1_rmd_x4_24_mock_1_outer_rmd_x4_24_1_simple" file="lower_limbs_1_leg_assembly_right_1_rmd_x4_24_mock_1_outer_rmd_x4_24_1_simple.stl"/>
    <mesh name="upper_limb_assembly_7_dof_1_full_arm_7_dof_2_lower_arm_3_dof_1_rmd_x4_24_mock_2_outer_rmd_x4_24_1_simple" file="upper_limb_assembly_7_dof_1_full_arm_7_dof_2_lower_arm_3_dof_1_rmd_x4_24_mock_2_outer_rmd_x4_24_1_simple.stl"/>
    <mesh name="upper_limb_assembly_7_dof_1_full_arm_7_dof_1_lower_arm_3_dof_1_rmd_x4_24_mock_2_outer_rmd_x4_24_1_simple" file="upper_limb_assembly_7_dof_1_full_arm_7_dof_1_lower_arm_3_dof_1_rmd_x4_24_mock_2_outer_rmd_x4_24_1_simple.stl"/>
    <mesh name="lower_limbs_1_leg_assembly_left_1_rmd_x4_24_mock_1_outer_rmd_x4_24_1_simple" file="lower_limbs_1_leg_assembly_left_1_rmd_x4_24_mock_1_outer_rmd_x4_24_1_simple.stl"/>
    <mesh name="lower_limbs_1_right_foot_1_ankle_half_2_right_2_simple" file="lower_limbs_1_right_foot_1_ankle_half_2_right_2_simple.stl"/>
    <mesh name="upper_limb_assembly_7_dof_1_full_arm_7_dof_2_lower_arm_3_dof_1_rmd_x4_24_mock_2_inner_rmd_x4_24_1_simple" file="upper_limb_assembly_7_dof_1_full_arm_7_dof_2_lower_arm_3_dof_1_rmd_x4_24_mock_2_inner_rmd_x4_24_1_simple.stl"/>
    <mesh name="upper_limb_assembly_7_dof_1_full_arm_7_dof_1_lower_arm_3_dof_1_rmd_x4_24_mock_2_inner_rmd_x4_24_1_simple" file="upper_limb_assembly_7_dof_1_full_arm_7_dof_1_lower_arm_3_dof_1_rmd_x4_24_mock_2_inner_rmd_x4_24_1_simple.stl"/>
    <mesh name="lower_limbs_1_left_foot_1_ankle_half_2_left_1_simple" file="lower_limbs_1_left_foot_1_ankle_half_2_left_1_simple.stl"/>
    <mesh name="lower_limbs_1_right_foot_1_ankle_half_1_right_1_simple" file="lower_limbs_1_right_foot_1_ankle_half_1_right_1_simple.stl"/>
    <mesh name="lower_limbs_1_right_foot_1_rmd_x4_24_mock_1_outer_rmd_x4_24_1_simple" file="lower_limbs_1_right_foot_1_rmd_x4_24_mock_1_outer_rmd_x4_24_1_simple.stl"/>
    <mesh name="upper_limb_assembly_7_dof_1_full_arm_7_dof_2_lower_arm_3_dof_1_wrist_part_2_1_simple" file="upper_limb_assembly_7_dof_1_full_arm_7_dof_2_lower_arm_3_dof_1_wrist_part_2_1_simple.stl"/>
    <mesh name="upper_limb_assembly_7_dof_1_full_arm_7_dof_1_lower_arm_3_dof_1_wrist_part_2_1_simple" file="upper_limb_assembly_7_dof_1_full_arm_7_dof_1_lower_arm_3_dof_1_wrist_part_2_1_simple.stl"/>
    <mesh name="lower_limbs_1_left_foot_1_rmd_x4_24_mock_1_outer_rmd_x4_24_1_simple" file="lower_limbs_1_left_foot_1_rmd_x4_24_mock_1_outer_rmd_x4_24_1_simple.stl"/>
    <mesh name="lower_limbs_1_left_foot_1_ankle_half_1_left_2_simple" file="lower_limbs_1_left_foot_1_ankle_half_1_left_2_simple.stl"/>
    <mesh name="lower_limbs_1_right_foot_1_rmd_x4_24_mock_1_inner_rmd_x4_24_1_simple" file="lower_limbs_1_right_foot_1_rmd_x4_24_mock_1_inner_rmd_x4_24_1_simple.stl"/>
    <mesh name="upper_limb_assembly_7_dof_1_full_arm_7_dof_2_lower_arm_3_dof_1_rmd_x4_24_mock_3_outer_rmd_x4_24_1_simple" file="upper_limb_assembly_7_dof_1_full_arm_7_dof_2_lower_arm_3_dof_1_rmd_x4_24_mock_3_outer_rmd_x4_24_1_simple.stl"/>
    <mesh name="upper_limb_assembly_7_dof_1_full_arm_7_dof_1_lower_arm_3_dof_1_rmd_x4_24_mock_3_outer_rmd_x4_24_1_simple" file="upper_limb_assembly_7_dof_1_full_arm_7_dof_1_lower_arm_3_dof_1_rmd_x4_24_mock_3_outer_rmd_x4_24_1_simple.stl"/>
    <mesh name="lower_limbs_1_left_foot_1_rmd_x4_24_mock_1_inner_rmd_x4_24_1_simple" file="lower_limbs_1_left_foot_1_rmd_x4_24_mock_1_inner_rmd_x4_24_1_simple.stl"/>
    <mesh name="lower_limbs_1_right_foot_1_foot_1_simple" file="lower_limbs_1_right_foot_1_foot_1_simple.stl"/>
    <mesh name="upper_limb_assembly_7_dof_1_full_arm_7_dof_2_lower_arm_3_dof_1_rmd_x4_24_mock_3_inner_rmd_x4_24_1_simple" file="upper_limb_assembly_7_dof_1_full_arm_7_dof_2_lower_arm_3_dof_1_rmd_x4_24_mock_3_inner_rmd_x4_24_1_simple.stl"/>
    <mesh name="upper_limb_assembly_7_dof_1_full_arm_7_dof_1_lower_arm_3_dof_1_rmd_x4_24_mock_3_inner_rmd_x4_24_1_simple" file="upper_limb_assembly_7_dof_1_full_arm_7_dof_1_lower_arm_3_dof_1_rmd_x4_24_mock_3_inner_rmd_x4_24_1_simple.stl"/>
    <mesh name="lower_limbs_1_left_foot_1_foot_1_simple" file="lower_limbs_1_left_foot_1_foot_1_simple.stl"/>
    <mesh name="lower_limbs_1_right_foot_1_rubber_grip_3_simple" file="lower_limbs_1_right_foot_1_rubber_grip_3_simple.stl"/>
    <mesh name="upper_limb_assembly_7_dof_1_full_arm_7_dof_2_lower_arm_3_dof_1_wrist_part_3_1_simple" file="upper_limb_assembly_7_dof_1_full_arm_7_dof_2_lower_arm_3_dof_1_wrist_part_3_1_simple.stl"/>
    <mesh name="upper_limb_assembly_7_dof_1_full_arm_7_dof_1_lower_arm_3_dof_1_wrist_part_3_1_simple" file="upper_limb_assembly_7_dof_1_full_arm_7_dof_1_lower_arm_3_dof_1_wrist_part_3_1_simple.stl"/>
    <mesh name="lower_limbs_1_left_foot_1_rubber_grip_1_simple" file="lower_limbs_1_left_foot_1_rubber_grip_1_simple.stl"/>
    <mesh name="upper_limb_assembly_7_dof_1_full_arm_7_dof_2_lower_arm_3_dof_1_hand_left_1_rmd_x4_24_mock_1_outer_rmd_x4_24_1_simple" file="upper_limb_assembly_7_dof_1_full_arm_7_dof_2_lower_arm_3_dof_1_hand_left_1_rmd_x4_24_mock_1_outer_rmd_x4_24_1_simple.stl"/>
    <mesh name="upper_limb_assembly_7_dof_1_full_arm_7_dof_1_lower_arm_3_dof_1_hand_left_1_rmd_x4_24_mock_1_outer_rmd_x4_24_1_simple" file="upper_limb_assembly_7_dof_1_full_arm_7_dof_1_lower_arm_3_dof_1_hand_left_1_rmd_x4_24_mock_1_outer_rmd_x4_24_1_simple.stl"/>
    <mesh name="upper_limb_assembly_7_dof_1_full_arm_7_dof_2_lower_arm_3_dof_1_hand_left_1_gripper_housing_1_simple" file="upper_limb_assembly_7_dof_1_full_arm_7_dof_2_lower_arm_3_dof_1_hand_left_1_gripper_housing_1_simple.stl"/>
    <mesh name="upper_limb_assembly_7_dof_1_full_arm_7_dof_2_lower_arm_3_dof_1_hand_left_1_rmd_x4_24_mock_1_inner_rmd_x4_24_1_simple" file="upper_limb_assembly_7_dof_1_full_arm_7_dof_2_lower_arm_3_dof_1_hand_left_1_rmd_x4_24_mock_1_inner_rmd_x4_24_1_simple.stl"/>
    <mesh name="upper_limb_assembly_7_dof_1_full_arm_7_dof_1_lower_arm_3_dof_1_hand_left_1_gripper_housing_1_simple" file="upper_limb_assembly_7_dof_1_full_arm_7_dof_1_lower_arm_3_dof_1_hand_left_1_gripper_housing_1_simple.stl"/>
    <mesh name="upper_limb_assembly_7_dof_1_full_arm_7_dof_1_lower_arm_3_dof_1_hand_left_1_rmd_x4_24_mock_1_inner_rmd_x4_24_1_simple" file="upper_limb_assembly_7_dof_1_full_arm_7_dof_1_lower_arm_3_dof_1_hand_left_1_rmd_x4_24_mock_1_inner_rmd_x4_24_1_simple.stl"/>
    <mesh name="upper_limb_assembly_7_dof_1_full_arm_7_dof_2_lower_arm_3_dof_1_hand_left_1_slide_rail_1_simple" file="upper_limb_assembly_7_dof_1_full_arm_7_dof_2_lower_arm_3_dof_1_hand_left_1_slide_rail_1_simple.stl"/>
    <mesh name="upper_limb_assembly_7_dof_1_full_arm_7_dof_1_lower_arm_3_dof_1_hand_left_1_slide_rail_1_simple" file="upper_limb_assembly_7_dof_1_full_arm_7_dof_1_lower_arm_3_dof_1_hand_left_1_slide_rail_1_simple.stl"/>
    <mesh name="upper_limb_assembly_7_dof_1_full_arm_7_dof_2_lower_arm_3_dof_1_hand_left_1_slide_1_simple" file="upper_limb_assembly_7_dof_1_full_arm_7_dof_2_lower_arm_3_dof_1_hand_left_1_slide_1_simple.stl"/>
    <mesh name="upper_limb_assembly_7_dof_1_full_arm_7_dof_2_lower_arm_3_dof_1_hand_left_1_slide_2_simple" file="upper_limb_assembly_7_dof_1_full_arm_7_dof_2_lower_arm_3_dof_1_hand_left_1_slide_2_simple.stl"/>
    <mesh name="upper_limb_assembly_7_dof_1_full_arm_7_dof_1_lower_arm_3_dof_1_hand_left_1_slide_1_simple" file="upper_limb_assembly_7_dof_1_full_arm_7_dof_1_lower_arm_3_dof_1_hand_left_1_slide_1_simple.stl"/>
    <mesh name="upper_limb_assembly_7_dof_1_full_arm_7_dof_1_lower_arm_3_dof_1_hand_left_1_slide_2_simple" file="upper_limb_assembly_7_dof_1_full_arm_7_dof_1_lower_arm_3_dof_1_hand_left_1_slide_2_simple.stl"/>
    <mesh name="upper_limb_assembly_7_dof_1_full_arm_7_dof_2_lower_arm_3_dof_1_hand_left_1_rack_3_simple" file="upper_limb_assembly_7_dof_1_full_arm_7_dof_2_lower_arm_3_dof_1_hand_left_1_rack_3_simple.stl"/>
    <mesh name="upper_limb_assembly_7_dof_1_full_arm_7_dof_2_lower_arm_3_dof_1_hand_left_1_rack_4_simple" file="upper_limb_assembly_7_dof_1_full_arm_7_dof_2_lower_arm_3_dof_1_hand_left_1_rack_4_simple.stl"/>
    <mesh name="upper_limb_assembly_7_dof_1_full_arm_7_dof_1_lower_arm_3_dof_1_hand_left_1_rack_3_simple" file="upper_limb_assembly_7_dof_1_full_arm_7_dof_1_lower_arm_3_dof_1_hand_left_1_rack_3_simple.stl"/>
    <mesh name="upper_limb_assembly_7_dof_1_full_arm_7_dof_1_lower_arm_3_dof_1_hand_left_1_rack_4_simple" file="upper_limb_assembly_7_dof_1_full_arm_7_dof_1_lower_arm_3_dof_1_hand_left_1_rack_4_simple.stl"/>
    <mesh name="upper_limb_assembly_7_dof_1_full_arm_7_dof_2_lower_arm_3_dof_1_hand_left_1_outer_gripper_1_simple" file="upper_limb_assembly_7_dof_1_full_arm_7_dof_2_lower_arm_3_dof_1_hand_left_1_outer_gripper_1_simple.stl"/>
    <mesh name="upper_limb_assembly_7_dof_1_full_arm_7_dof_2_lower_arm_3_dof_1_hand_left_1_inner_gripper_2_simple" file="upper_limb_assembly_7_dof_1_full_arm_7_dof_2_lower_arm_3_dof_1_hand_left_1_inner_gripper_2_simple.stl"/>
    <mesh name="upper_limb_assembly_7_dof_1_full_arm_7_dof_1_lower_arm_3_dof_1_hand_left_1_outer_gripper_1_simple" file="upper_limb_assembly_7_dof_1_full_arm_7_dof_1_lower_arm_3_dof_1_hand_left_1_outer_gripper_1_simple.stl"/>
    <mesh name="upper_limb_assembly_7_dof_1_full_arm_7_dof_1_lower_arm_3_dof_1_hand_left_1_inner_gripper_2_simple" file="upper_limb_assembly_7_dof_1_full_arm_7_dof_1_lower_arm_3_dof_1_hand_left_1_inner_gripper_2_simple.stl"/>
  </asset>
  <worldbody>
    <body name="root">
      <geom type="mesh" rgba="0.615686 0.811765 0.929412 1" mesh="upper_limb_assembly_7_dof_1_torso_1_top_skeleton_2_simple"/>
      <geom pos="0.0247487 -0.0243116 0.0684379" quat="0 -2.32051e-08 1 -2.32051e-08" type="mesh" rgba="0.654902 0.823529 0.576471 1" mesh="head_1_neck_2_simple"/>
      <geom pos="-2.41486e-08 0.000437103 0.183438" quat="2.32051e-08 0 -4.64102e-08 -1" type="mesh" rgba="0.8 0.74902 0.913725 1" mesh="head_1_skull_1_simple"/>
      <geom pos="-2.08349e-08 -0.0709629 0.206124" quat="0.707107 0.707107 3.2817e-08 3.2817e-08" type="mesh" rgba="0.647059 0.647059 0.647059 1" mesh="head_1_camera_speaker_holder_1_simple"/>
      <geom pos="-2.41486e-08 0.000437103 0.183438" quat="2.32051e-08 0 -4.64102e-08 -1" type="mesh" rgba="0.654902 0.823529 0.576471 1" mesh="head_1_neck_1_simple"/>
      <geom pos="-2.17406e-08 -0.0514473 0.216624" quat="2.32051e-08 1 4.64102e-08 0" type="mesh" rgba="0.647059 0.647059 0.647059 1" mesh="head_1_mic_holder_2_simple"/>
      <geom pos="-2.785e-08 0.0801922 0.200031" quat="0.707107 0.707107 3.2817e-08 3.2817e-08" type="mesh" rgba="0.615686 0.811765 0.929412 1" mesh="head_1_head_back_2_simple"/>
      <geom pos="-2.0569e-08 0.00175039 0.278184" quat="0.707107 0.707107 3.2817e-08 3.2817e-08" type="mesh" rgba="0.615686 0.811765 0.929412 1" mesh="head_1_head_front_1_simple"/>
      <geom pos="0.0779324 -0.0437571 0.0461914" quat="0.422593 0.566935 -0.566935 -0.422593" type="mesh" rgba="0.647059 0.647059 0.647059 1" mesh="upper_limb_assembly_7_dof_1_full_arm_7_dof_2_upper_left_arm_1_arm_part_1_1_simple"/>
      <geom pos="0.11869 0.0189972 -0.0345317" quat="0.422593 0.566935 -0.566935 -0.422593" type="mesh" rgba="0.498039 0.498039 0.498039 1" mesh="upper_limb_assembly_7_dof_1_full_arm_7_dof_2_upper_left_arm_1_rmd_x8_90_mock_1_outer_rmd_x8_90_1_simple"/>
      <geom pos="-0.0779325 -0.0437571 0.0461914" quat="0.422593 0.566935 0.566935 0.422593" type="mesh" rgba="0.647059 0.647059 0.647059 1" mesh="upper_limb_assembly_7_dof_1_full_arm_7_dof_1_upper_left_arm_1_arm_part_1_1_simple"/>
      <geom pos="-0.11869 -0.018123 -0.0345317" quat="0.422593 0.566935 0.566935 0.422593" type="mesh" rgba="0.498039 0.498039 0.498039 1" mesh="upper_limb_assembly_7_dof_1_full_arm_7_dof_1_upper_left_arm_1_rmd_x8_90_mock_1_outer_rmd_x8_90_1_simple"/>
      <geom pos="-0.0751688 -0.0175629 -0.0781621" type="mesh" rgba="0.615686 0.811765 0.929412 1" mesh="upper_limb_assembly_7_dof_1_torso_1_bottom_skeleton_1_simple"/>
      <geom pos="-0.0448082 -0.018123 -0.304062" quat="0.707107 0 0 -0.707107" type="mesh" rgba="0.498039 0.498039 0.498039 1" mesh="upper_limb_assembly_7_dof_1_torso_1_rmd_x8_90_mock_1_outer_rmd_x8_90_1_simple"/>
      <geom pos="0 0.0004371 -0.0581621" type="mesh" rgba="0.647059 0.647059 0.647059 1" mesh="upper_limb_assembly_7_dof_1_torso_1_battery_case_base_1_simple"/>
      <geom pos="-0.0535 -0.0425629 -0.263227" quat="0.707107 -0.707107 0 0" type="mesh" rgba="0.647059 0.647059 0.647059 1" mesh="upper_limb_assembly_7_dof_1_torso_1_batter_case_top_1_simple"/>
      <geom pos="0 0.0279371 -0.279062" quat="0.707107 0.707107 0 0" type="mesh" rgba="0.764706 0.545098 0.803922 1" mesh="upper_limb_assembly_7_dof_1_torso_1_battery_1_simple"/>
      <geom pos="0.0535 -0.0175629 -0.0581621" type="mesh" rgba="0.231373 0.380392 0.705882 1" mesh="upper_limb_assembly_7_dof_1_torso_1_battery_cap_2_simple"/>
      <body name="link_upper_limb_assembly_7_dof_1_full_arm_7_dof_2_upper_left_arm_1_rmd_x8_90_mock_1_inner_rmd_x8_90_1" pos="0.151411 0.000437102 0.0219782" quat="-0.566935 0.422593 -0.422593 0.566935">
        <inertial pos="0.00362208 -0.00209121 0.0506706" quat="0.965513 0.00756478 0.0282321 -0.258708" mass="1.00767" diaginertia="0.00337297 0.00283973 0.00106851"/>
        <joint name="left shoulder pitch" pos="0 0 0" axis="0 0 -1" range="-3.14159 3.14159" actuatorfrcrange="-90 90"/>
        <geom type="mesh" rgba="0.980392 0.713726 0.00392157 1" mesh="upper_limb_assembly_7_dof_1_full_arm_7_dof_2_upper_left_arm_1_rmd_x8_90_mock_1_inner_rmd_x8_90_1_simple"/>
        <geom pos="0 -0.025 0.0035" quat="-2.00962e-08 0.866025 0.5 -1.16026e-08" type="mesh" rgba="0.647059 0.647059 0.647059 1" mesh="upper_limb_assembly_7_dof_1_full_arm_7_dof_2_upper_left_arm_1_arm_part_2_1_simple"/>
        <geom pos="0.0374168 0.0277078 0.0315911" quat="-0.612372 0.612372 0.353553 -0.353553" type="mesh" rgba="0.231373 0.380392 0.705882 1" mesh="upper_limb_assembly_7_dof_1_full_arm_7_dof_2_upper_left_arm_1_arm_part_3_1_simple"/>
        <geom pos="0.0438382 0.02643 0.0684399" quat="-0.183013 -0.683013 0.183013 -0.683013" type="mesh" rgba="0.498039 0.498039 0.498039 1" mesh="upper_limb_assembly_7_dof_1_full_arm_7_dof_2_upper_left_arm_1_rmd_x8_90_mock_2_outer_rmd_x8_90_1_simple"/>
        <body name="link_upper_limb_assembly_7_dof_1_full_arm_7_dof_2_upper_left_arm_1_rmd_x8_90_mock_2_inner_rmd_x8_90_1" pos="-0.0197021 0.011375 0.087" quat="0.683013 -0.183013 -0.683013 -0.183013">
          <inertial pos="-0.0619224 -1.0414e-09 -0.0204847" quat="0.523808 0.475 0.475 0.523808" mass="0.808661" diaginertia="0.00484805 0.00456608 0.000854709"/>
          <joint name="left shoulder yaw" pos="0 0 0" axis="0 0 -1" range="0.977384 5.3058" actuatorfrcrange="-90 90"/>
          <geom type="mesh" rgba="0.980392 0.713726 0.00392157 1" mesh="upper_limb_assembly_7_dof_1_full_arm_7_dof_2_upper_left_arm_1_rmd_x8_90_mock_2_inner_rmd_x8_90_1_simple"/>
          <geom pos="-0.0216506 -0.0125 0.0035" quat="-1.64085e-08 0.707107 -0.707107 1.64085e-08" type="mesh" rgba="0.917647 0.917647 0.917647 1" mesh="upper_limb_assembly_7_dof_1_full_arm_7_dof_2_upper_left_arm_1_arm_part_4_1_simple"/>
          <geom pos="-0.095 -1.96539e-09 -0.02275" quat="-9.47343e-09 0.707107 -9.47343e-09 0.707107" type="mesh" rgba="0.615686 0.811765 0.929412 1" mesh="upper_limb_assembly_7_dof_1_full_arm_7_dof_2_upper_left_arm_1_arm_coupler_1_simple"/>
          <geom pos="-0.1648 -1.96539e-09 -0.02275" quat="-9.47343e-09 0.707107 -9.47343e-09 0.707107" type="mesh" rgba="0.768627 0.886275 0.952941 1" mesh="upper_limb_assembly_7_dof_1_full_arm_7_dof_2_upper_left_arm_1_rmd_x4_24_mock_1_inner_rmd_x4_24_1_simple"/>
          <geom pos="-0.135 -0.029 -0.02275" quat="-1.64085e-08 0.707107 -0.707107 1.64085e-08" type="mesh" rgba="0.768627 0.886275 0.952941 1" mesh="upper_limb_assembly_7_dof_1_full_arm_7_dof_2_upper_left_arm_1_arm_part_5_1_simple"/>
          <body name="link_upper_limb_assembly_7_dof_1_full_arm_7_dof_2_upper_left_arm_1_rmd_x4_24_mock_1_outer_rmd_x4_24_1" pos="-0.1898 -1.96539e-09 -0.02275" quat="-0.707107 -2.58819e-08 0.707107 -6.93506e-09">
            <inertial pos="9.11379e-07 -0.000769418 0.0655721" quat="0.9986 0.0528986 -2.65007e-06 -7.65809e-06" mass="0.773406" diaginertia="0.00330582 0.00309 0.000660751"/>
            <joint name="left shoulder roll" pos="0 0 0" axis="0 0 -1" range="-4.71239 4.71239" actuatorfrcrange="-24 24"/>
            <geom type="mesh" rgba="0.917647 0.917647 0.917647 1" mesh="upper_limb_assembly_7_dof_1_full_arm_7_dof_2_upper_left_arm_1_rmd_x4_24_mock_1_outer_rmd_x4_24_1_simple"/>
            <geom pos="-0.0245 0 -0.02" quat="0.707107 0 0 0.707107" type="mesh" rgba="0.231373 0.380392 0.705882 1" mesh="upper_limb_assembly_7_dof_1_full_arm_7_dof_2_upper_left_arm_1_arm_part_6_1_simple"/>
            <geom pos="0.0195 -0.029 0.08" quat="0.5 -0.5 -0.5 -0.5" type="mesh" rgba="0.647059 0.647059 0.647059 1" mesh="upper_limb_assembly_7_dof_1_full_arm_7_dof_2_upper_left_arm_1_arm_part_7_2_simple"/>
            <geom pos="0.01225 0.029 0.112782" quat="1.89469e-08 1.89469e-08 0.707107 0.707107" type="mesh" rgba="0.917647 0.917647 0.917647 1" mesh="upper_limb_assembly_7_dof_1_full_arm_7_dof_2_upper_left_arm_1_rmd_x4_24_mock_2_outer_rmd_x4_24_1_simple"/>
            <body name="link_upper_limb_assembly_7_dof_1_full_arm_7_dof_2_upper_left_arm_1_rmd_x4_24_mock_2_inner_rmd_x4_24_1" pos="-2.94744e-10 0.009 0.134" quat="-1.89469e-08 1.89469e-08 0.707107 -0.707107">
              <inertial pos="0.0214253 0.0669344 0.00352238" quat="0.6367 0.754518 -0.137786 -0.0795613" mass="0.629871" diaginertia="0.00314523 0.00223199 0.00124483"/>
              <joint name="left elbow pitch" pos="0 0 0" axis="0 0 -1" range="1.44862 5.44543" actuatorfrcrange="-24 24"/>
              <geom type="mesh" rgba="0.768627 0.886275 0.952941 1" mesh="upper_limb_assembly_7_dof_1_full_arm_7_dof_2_upper_left_arm_1_rmd_x4_24_mock_2_inner_rmd_x4_24_1_simple"/>
              <geom pos="-0.00962342 -0.00874013 -0.025" quat="0.589549 0 0 -0.807733" type="mesh" rgba="0.647059 0.647059 0.647059 1" mesh="upper_limb_assembly_7_dof_1_full_arm_7_dof_2_upper_left_arm_1_arm_part_8_3_simple"/>
              <geom pos="0.0210351 0.065716 0.009" quat="-0.571153 -0.416874 0.571153 -0.416874" type="mesh" rgba="0.615686 0.811765 0.929412 1" mesh="upper_limb_assembly_7_dof_1_full_arm_7_dof_2_upper_left_arm_1_arm_coupler_2_simple"/>
              <geom pos="0.0423146 0.132193 0.009" quat="-0.109092 0.109092 0.698641 -0.698641" type="mesh" rgba="0.768627 0.886275 0.952941 1" mesh="upper_limb_assembly_7_dof_1_full_arm_7_dof_2_lower_arm_3_dof_1_rmd_x4_24_mock_1_inner_rmd_x4_24_1_simple"/>
              <geom pos="0.0603729 0.0951232 0.009" quat="1.87435e-08 0.807733 0.589549 1.36805e-08" type="mesh" rgba="0.768627 0.886275 0.952941 1" mesh="upper_limb_assembly_7_dof_1_full_arm_7_dof_2_upper_left_arm_1_arm_part_9_1_simple"/>
              <body name="link_upper_limb_assembly_7_dof_1_full_arm_7_dof_2_lower_arm_3_dof_1_rmd_x4_24_mock_1_outer_rmd_x4_24_1" pos="0.0499362 0.156003 0.009" quat="-0.109092 -0.109092 -0.698641 -0.698641">
                <inertial pos="0.0614777 -2.62982e-09 0.041711" quat="0.631438 0.318255 0.318255 0.631438" mass="0.61252" diaginertia="0.00341262 0.00325796 0.000511076"/>
                <joint name="left wrist roll" pos="0 0 0" axis="0 0 -1" range="-4.71239 4.71239" actuatorfrcrange="-24 24"/>
                <geom type="mesh" rgba="0.917647 0.917647 0.917647 1" mesh="upper_limb_assembly_7_dof_1_full_arm_7_dof_2_lower_arm_3_dof_1_rmd_x4_24_mock_1_outer_rmd_x4_24_1_simple"/>
                <geom pos="0.0245 0 -0.02" quat="-2.32051e-08 1 0 0" type="mesh" rgba="0.647059 0.647059 0.647059 1" mesh="upper_limb_assembly_7_dof_1_full_arm_7_dof_2_lower_arm_3_dof_1_wrist_part_1_1_simple"/>
                <geom pos="0.0935 -0.0245 0.0895" quat="-0.5 0.5 0.5 -0.5" type="mesh" rgba="0.917647 0.917647 0.917647 1" mesh="upper_limb_assembly_7_dof_1_full_arm_7_dof_2_lower_arm_3_dof_1_rmd_x4_24_mock_2_outer_rmd_x4_24_1_simple"/>
                <body name="link_upper_limb_assembly_7_dof_1_full_arm_7_dof_2_lower_arm_3_dof_1_rmd_x4_24_mock_2_inner_rmd_x4_24_1" pos="0.1135 -5.61782e-09 0.0895" quat="-0.5 -0.5 -0.5 -0.5">
                  <inertial pos="-0.0619363 1.65958e-09 -0.0757756" quat="0.64542 0.288847 0.288847 0.64542" mass="0.489895" diaginertia="0.0023977 0.00238024 0.00026235"/>
                  <joint name="left wrist pitch" pos="0 0 0" axis="0 0 -1" range="-4.71239 4.71239" actuatorfrcrange="-24 24"/>
                  <geom type="mesh" rgba="0.768627 0.886275 0.952941 1" mesh="upper_limb_assembly_7_dof_1_full_arm_7_dof_2_lower_arm_3_dof_1_rmd_x4_24_mock_2_inner_rmd_x4_24_1_simple"/>
                  <geom pos="0 0 -0.025" quat="0.707107 0 0 0.707107" type="mesh" rgba="0.647059 0.647059 0.647059 1" mesh="upper_limb_assembly_7_dof_1_full_arm_7_dof_2_lower_arm_3_dof_1_wrist_part_2_1_simple"/>
                  <geom pos="-0.0785 2.1034e-09 -0.138" quat="0.5 -0.5 -0.5 0.5" type="mesh" rgba="0.917647 0.917647 0.917647 1" mesh="upper_limb_assembly_7_dof_1_full_arm_7_dof_2_lower_arm_3_dof_1_rmd_x4_24_mock_3_outer_rmd_x4_24_1_simple"/>
                  <body name="link_upper_limb_assembly_7_dof_1_full_arm_7_dof_2_lower_arm_3_dof_1_rmd_x4_24_mock_3_inner_rmd_x4_24_1" pos="-0.0985 2.6393e-09 -0.1135" quat="1.89469e-08 -0.707107 0 0.707107">
                    <inertial pos="0.0256483 -1.23773e-09 -0.0791271" quat="0.363801 0.606341 0.606341 0.363801" mass="0.704325" diaginertia="0.00249627 0.0022896 0.00155994"/>
                    <joint name="left wrist yaw" pos="0 0 0" axis="0 0 -1" range="-4.71239 4.71239" actuatorfrcrange="-24 24"/>
                    <geom type="mesh" rgba="0.768627 0.886275 0.952941 1" mesh="upper_limb_assembly_7_dof_1_full_arm_7_dof_2_lower_arm_3_dof_1_rmd_x4_24_mock_3_inner_rmd_x4_24_1_simple"/>
                    <geom pos="0 0 -0.025" type="mesh" rgba="0.615686 0.811765 0.929412 1" mesh="upper_limb_assembly_7_dof_1_full_arm_7_dof_2_lower_arm_3_dof_1_wrist_part_3_1_simple"/>
                    <geom pos="0.0235 0 -0.074" quat="-1.64085e-08 -0.707107 1.64085e-08 -0.707107" type="mesh" rgba="0.917647 0.917647 0.917647 1" mesh="upper_limb_assembly_7_dof_1_full_arm_7_dof_2_lower_arm_3_dof_1_hand_left_1_rmd_x4_24_mock_1_outer_rmd_x4_24_1_simple"/>
                    <geom pos="0.0435 -9.28204e-10 -0.123" quat="-4.92255e-08 0.707107 -1.64085e-08 -0.707107" type="mesh" rgba="0.647059 0.647059 0.647059 1" mesh="upper_limb_assembly_7_dof_1_full_arm_7_dof_2_lower_arm_3_dof_1_hand_left_1_gripper_housing_1_simple"/>
                    <geom pos="0.0725 0.0875 -0.0985" quat="-0.707107 -6.56339e-08 -0.707107 3.2817e-08" type="mesh" rgba="0.615686 0.811765 0.929412 1" mesh="upper_limb_assembly_7_dof_1_full_arm_7_dof_2_lower_arm_3_dof_1_hand_left_1_slide_rail_1_simple"/>
                    <body name="link_upper_limb_assembly_7_dof_1_full_arm_7_dof_2_lower_arm_3_dof_1_hand_left_1_slide_1" pos="0.0805 -0.1 -0.0985" quat="4.92255e-08 -4.92255e-08 -0.707107 0.707107">
                      <inertial pos="-0.0125996 -0.00418261 -0.0307388" quat="0.356162 0.799069 0.449275 0.181078" mass="0.0616325" diaginertia="7.29328e-05 5.26091e-05 4.35012e-05"/>
                      <joint name="joint_upper_limb_assembly_7_dof_1_full_arm_7_dof_2_lower_arm_3_dof_1_hand_left_1_slider_1" pos="0 0 0" axis="0 0 -1" type="slide" range="0 0.051" actuatorfrcrange="-80 80"/>
                      <geom type="mesh" rgba="0.615686 0.811765 0.929412 1" mesh="upper_limb_assembly_7_dof_1_full_arm_7_dof_2_lower_arm_3_dof_1_hand_left_1_slide_1_simple"/>
                      <geom pos="-0.00499 0.01 -0.033" quat="0.707107 0 -0.707107 0" type="mesh" rgba="0.615686 0.811765 0.929412 1" mesh="upper_limb_assembly_7_dof_1_full_arm_7_dof_2_lower_arm_3_dof_1_hand_left_1_rack_3_simple"/>
                      <geom pos="-0.01749 -0.0130006 -0.004" type="mesh" rgba="0.231373 0.380392 0.705882 1" mesh="upper_limb_assembly_7_dof_1_full_arm_7_dof_2_lower_arm_3_dof_1_hand_left_1_outer_gripper_1_simple"/>
                    </body>
                    <body name="link_upper_limb_assembly_7_dof_1_full_arm_7_dof_2_lower_arm_3_dof_1_hand_left_1_slide_2" pos="0.0805 0.1 -0.0985" quat="-4.92255e-08 -4.92255e-08 -0.707107 -0.707107">
                      <inertial pos="-0.0125996 -0.00716962 -0.0307388" quat="0.703418 -0.339904 -0.119607 0.612668" mass="0.0616325" diaginertia="6.99359e-05 6.34474e-05 3.1296e-05"/>
                      <joint name="joint_upper_limb_assembly_7_dof_1_full_arm_7_dof_2_lower_arm_3_dof_1_hand_left_1_slider_2" pos="0 0 0" axis="0 0 -1" type="slide" range="-0.051 0" actuatorfrcrange="-80 80"/>
                      <geom type="mesh" rgba="0.615686 0.811765 0.929412 1" mesh="upper_limb_assembly_7_dof_1_full_arm_7_dof_2_lower_arm_3_dof_1_hand_left_1_slide_2_simple"/>
                      <geom pos="-0.00499 0.01 -0.033" quat="-1.64085e-08 -0.707107 -1.64085e-08 0.707107" type="mesh" rgba="0.615686 0.811765 0.929412 1" mesh="upper_limb_assembly_7_dof_1_full_arm_7_dof_2_lower_arm_3_dof_1_hand_left_1_rack_4_simple"/>
                      <geom pos="-0.01749 0.0135 -0.004" quat="-1 2.32051e-08 0 -2.32051e-08" type="mesh" rgba="0.231373 0.380392 0.705882 1" mesh="upper_limb_assembly_7_dof_1_full_arm_7_dof_2_lower_arm_3_dof_1_hand_left_1_inner_gripper_2_simple"/>
                    </body>
                    <body name="link_upper_limb_assembly_7_dof_1_full_arm_7_dof_2_lower_arm_3_dof_1_hand_left_1_rmd_x4_24_mock_1_inner_rmd_x4_24_1" pos="0.0035 9.28204e-10 -0.0985" quat="0.707107 0 -0.707107 0">
                      <inertial pos="0 0 -0.012407" quat="0.5 0.5 -0.5 0.5" mass="0.14016" diaginertia="2.14331e-05 1.79936e-05 1.79936e-05"/>
                      <joint name="joint_upper_limb_assembly_7_dof_1_full_arm_7_dof_2_lower_arm_3_dof_1_hand_left_1_rmd_x4_24_mock_1_dof_x4" pos="0 0 0" axis="0 0 -1" range="-1.32645 1.32645" actuatorfrcrange="-24 24"/>
                      <geom type="mesh" rgba="0.768627 0.886275 0.952941 1" mesh="upper_limb_assembly_7_dof_1_full_arm_7_dof_2_lower_arm_3_dof_1_hand_left_1_rmd_x4_24_mock_1_inner_rmd_x4_24_1_simple"/>
                    </body>
                  </body>
                </body>
              </body>
            </body>
          </body>
        </body>
      </body>
      <body name="link_upper_limb_assembly_7_dof_1_full_arm_7_dof_1_upper_left_arm_1_rmd_x8_90_mock_1_inner_rmd_x8_90_1" pos="-0.151411 0.000437101 0.0219782" quat="-0.566935 0.422593 0.422593 -0.566935">
        <inertial pos="0.00362208 -0.00209121 0.0506706" quat="0.965513 0.00756478 0.0282321 -0.258708" mass="1.00767" diaginertia="0.00337297 0.00283973 0.00106851"/>
        <joint name="right shoulder pitch" pos="0 0 0" axis="0 0 -1" range="-3.14159 3.14159" actuatorfrcrange="-90 90"/>
        <geom type="mesh" rgba="0.980392 0.713726 0.00392157 1" mesh="upper_limb_assembly_7_dof_1_full_arm_7_dof_1_upper_left_arm_1_rmd_x8_90_mock_1_inner_rmd_x8_90_1_simple"/>
        <geom pos="0 -0.025 0.0035" quat="-2.00962e-08 0.866025 0.5 -1.16026e-08" type="mesh" rgba="0.647059 0.647059 0.647059 1" mesh="upper_limb_assembly_7_dof_1_full_arm_7_dof_1_upper_left_arm_1_arm_part_2_1_simple"/>
        <geom pos="0.0374168 0.0277078 0.0315911" quat="-0.612372 0.612372 0.353553 -0.353553" type="mesh" rgba="0.231373 0.380392 0.705882 1" mesh="upper_limb_assembly_7_dof_1_full_arm_7_dof_1_upper_left_arm_1_arm_part_3_1_simple"/>
        <geom pos="0.0438382 0.02643 0.0684399" quat="-0.183013 -0.683013 0.183013 -0.683013" type="mesh" rgba="0.498039 0.498039 0.498039 1" mesh="upper_limb_assembly_7_dof_1_full_arm_7_dof_1_upper_left_arm_1_rmd_x8_90_mock_2_outer_rmd_x8_90_1_simple"/>
        <body name="link_upper_limb_assembly_7_dof_1_full_arm_7_dof_1_upper_left_arm_1_rmd_x8_90_mock_2_inner_rmd_x8_90_1" pos="-0.0197021 0.011375 0.087" quat="0.683013 -0.183013 -0.683013 -0.183013">
          <inertial pos="-0.0619224 -1.0414e-09 -0.0204847" quat="0.523808 0.475 0.475 0.523808" mass="0.808661" diaginertia="0.00484805 0.00456608 0.000854709"/>
          <joint name="right shoulder yaw" pos="0 0 0" axis="0 0 -1" range="0.977384 5.3058" actuatorfrcrange="-90 90"/>
          <geom type="mesh" rgba="0.980392 0.713726 0.00392157 1" mesh="upper_limb_assembly_7_dof_1_full_arm_7_dof_1_upper_left_arm_1_rmd_x8_90_mock_2_inner_rmd_x8_90_1_simple"/>
          <geom pos="-0.0216506 -0.0125 0.0035" quat="-1.64085e-08 0.707107 -0.707107 1.64085e-08" type="mesh" rgba="0.917647 0.917647 0.917647 1" mesh="upper_limb_assembly_7_dof_1_full_arm_7_dof_1_upper_left_arm_1_arm_part_4_1_simple"/>
          <geom pos="-0.095 -1.96539e-09 -0.02275" quat="-9.47343e-09 0.707107 -9.47343e-09 0.707107" type="mesh" rgba="0.615686 0.811765 0.929412 1" mesh="upper_limb_assembly_7_dof_1_full_arm_7_dof_1_upper_left_arm_1_arm_coupler_1_simple"/>
          <geom pos="-0.1648 -1.96539e-09 -0.02275" quat="-9.47343e-09 0.707107 -9.47343e-09 0.707107" type="mesh" rgba="0.768627 0.886275 0.952941 1" mesh="upper_limb_assembly_7_dof_1_full_arm_7_dof_1_upper_left_arm_1_rmd_x4_24_mock_1_inner_rmd_x4_24_1_simple"/>
          <geom pos="-0.135 -0.029 -0.02275" quat="-1.64085e-08 0.707107 -0.707107 1.64085e-08" type="mesh" rgba="0.768627 0.886275 0.952941 1" mesh="upper_limb_assembly_7_dof_1_full_arm_7_dof_1_upper_left_arm_1_arm_part_5_1_simple"/>
          <body name="link_upper_limb_assembly_7_dof_1_full_arm_7_dof_1_upper_left_arm_1_rmd_x4_24_mock_1_outer_rmd_x4_24_1" pos="-0.1898 -1.96539e-09 -0.02275" quat="-0.707107 -2.58819e-08 0.707107 -6.93506e-09">
            <inertial pos="9.11379e-07 -0.000769418 0.0655721" quat="0.9986 0.0528986 -2.65007e-06 -7.65809e-06" mass="0.773406" diaginertia="0.00330582 0.00309 0.000660751"/>
            <joint name="right shoulder roll" pos="0 0 0" axis="0 0 -1" range="-4.71239 4.71239" actuatorfrcrange="-24 24"/>
            <geom type="mesh" rgba="0.917647 0.917647 0.917647 1" mesh="upper_limb_assembly_7_dof_1_full_arm_7_dof_1_upper_left_arm_1_rmd_x4_24_mock_1_outer_rmd_x4_24_1_simple"/>
            <geom pos="-0.0245 0 -0.02" quat="0.707107 0 0 0.707107" type="mesh" rgba="0.231373 0.380392 0.705882 1" mesh="upper_limb_assembly_7_dof_1_full_arm_7_dof_1_upper_left_arm_1_arm_part_6_1_simple"/>
            <geom pos="0.0195 -0.029 0.08" quat="0.5 -0.5 -0.5 -0.5" type="mesh" rgba="0.647059 0.647059 0.647059 1" mesh="upper_limb_assembly_7_dof_1_full_arm_7_dof_1_upper_left_arm_1_arm_part_7_2_simple"/>
            <geom pos="0.01225 0.029 0.112782" quat="1.89469e-08 1.89469e-08 0.707107 0.707107" type="mesh" rgba="0.917647 0.917647 0.917647 1" mesh="upper_limb_assembly_7_dof_1_full_arm_7_dof_1_upper_left_arm_1_rmd_x4_24_mock_2_outer_rmd_x4_24_1_simple"/>
            <body name="link_upper_limb_assembly_7_dof_1_full_arm_7_dof_1_upper_left_arm_1_rmd_x4_24_mock_2_inner_rmd_x4_24_1" pos="-2.94744e-10 0.009 0.134" quat="-1.89469e-08 1.89469e-08 0.707107 -0.707107">
              <inertial pos="0.0214253 0.0669344 0.00352238" quat="0.6367 0.754518 -0.137786 -0.0795613" mass="0.629871" diaginertia="0.00314523 0.00223199 0.00124483"/>
              <joint name="right elbow pitch" pos="0 0 0" axis="0 0 -1" range="1.44862 5.44543" actuatorfrcrange="-24 24"/>
              <geom type="mesh" rgba="0.768627 0.886275 0.952941 1" mesh="upper_limb_assembly_7_dof_1_full_arm_7_dof_1_upper_left_arm_1_rmd_x4_24_mock_2_inner_rmd_x4_24_1_simple"/>
              <geom pos="-0.00962342 -0.00874013 -0.025" quat="0.589549 0 0 -0.807733" type="mesh" rgba="0.647059 0.647059 0.647059 1" mesh="upper_limb_assembly_7_dof_1_full_arm_7_dof_1_upper_left_arm_1_arm_part_8_3_simple"/>
              <geom pos="0.0210351 0.065716 0.009" quat="-0.571153 -0.416874 0.571153 -0.416874" type="mesh" rgba="0.615686 0.811765 0.929412 1" mesh="upper_limb_assembly_7_dof_1_full_arm_7_dof_1_upper_left_arm_1_arm_coupler_2_simple"/>
              <geom pos="0.0423146 0.132193 0.009" quat="-0.109092 0.109092 0.698641 -0.698641" type="mesh" rgba="0.768627 0.886275 0.952941 1" mesh="upper_limb_assembly_7_dof_1_full_arm_7_dof_1_lower_arm_3_dof_1_rmd_x4_24_mock_1_inner_rmd_x4_24_1_simple"/>
              <geom pos="0.0603729 0.0951232 0.009" quat="1.87435e-08 0.807733 0.589549 1.36805e-08" type="mesh" rgba="0.768627 0.886275 0.952941 1" mesh="upper_limb_assembly_7_dof_1_full_arm_7_dof_1_upper_left_arm_1_arm_part_9_1_simple"/>
              <body name="link_upper_limb_assembly_7_dof_1_full_arm_7_dof_1_lower_arm_3_dof_1_rmd_x4_24_mock_1_outer_rmd_x4_24_1" pos="0.0499362 0.156003 0.009" quat="-0.109092 -0.109092 -0.698641 -0.698641">
                <inertial pos="0.0614777 -2.62982e-09 0.041711" quat="0.631438 0.318255 0.318255 0.631438" mass="0.61252" diaginertia="0.00341262 0.00325796 0.000511076"/>
                <joint name="right wrist roll" pos="0 0 0" axis="0 0 -1" range="-4.71239 4.71239" actuatorfrcrange="-24 24"/>
                <geom type="mesh" rgba="0.917647 0.917647 0.917647 1" mesh="upper_limb_assembly_7_dof_1_full_arm_7_dof_1_lower_arm_3_dof_1_rmd_x4_24_mock_1_outer_rmd_x4_24_1_simple"/>
                <geom pos="0.0245 0 -0.02" quat="-2.32051e-08 1 0 0" type="mesh" rgba="0.647059 0.647059 0.647059 1" mesh="upper_limb_assembly_7_dof_1_full_arm_7_dof_1_lower_arm_3_dof_1_wrist_part_1_1_simple"/>
                <geom pos="0.0935 -0.0245 0.0895" quat="-0.5 0.5 0.5 -0.5" type="mesh" rgba="0.917647 0.917647 0.917647 1" mesh="upper_limb_assembly_7_dof_1_full_arm_7_dof_1_lower_arm_3_dof_1_rmd_x4_24_mock_2_outer_rmd_x4_24_1_simple"/>
                <body name="link_upper_limb_assembly_7_dof_1_full_arm_7_dof_1_lower_arm_3_dof_1_rmd_x4_24_mock_2_inner_rmd_x4_24_1" pos="0.1135 -5.61782e-09 0.0895" quat="-0.5 -0.5 -0.5 -0.5">
                  <inertial pos="-0.0619363 1.65958e-09 -0.0757756" quat="0.64542 0.288847 0.288847 0.64542" mass="0.489895" diaginertia="0.0023977 0.00238024 0.00026235"/>
                  <joint name="right wrist pitch" pos="0 0 0" axis="0 0 -1" range="-4.71239 4.71239" actuatorfrcrange="-24 24"/>
                  <geom type="mesh" rgba="0.768627 0.886275 0.952941 1" mesh="upper_limb_assembly_7_dof_1_full_arm_7_dof_1_lower_arm_3_dof_1_rmd_x4_24_mock_2_inner_rmd_x4_24_1_simple"/>
                  <geom pos="0 0 -0.025" quat="0.707107 0 0 0.707107" type="mesh" rgba="0.647059 0.647059 0.647059 1" mesh="upper_limb_assembly_7_dof_1_full_arm_7_dof_1_lower_arm_3_dof_1_wrist_part_2_1_simple"/>
                  <geom pos="-0.0785 2.1034e-09 -0.138" quat="0.5 -0.5 -0.5 0.5" type="mesh" rgba="0.917647 0.917647 0.917647 1" mesh="upper_limb_assembly_7_dof_1_full_arm_7_dof_1_lower_arm_3_dof_1_rmd_x4_24_mock_3_outer_rmd_x4_24_1_simple"/>
                  <body name="link_upper_limb_assembly_7_dof_1_full_arm_7_dof_1_lower_arm_3_dof_1_rmd_x4_24_mock_3_inner_rmd_x4_24_1" pos="-0.0985 2.6393e-09 -0.1135" quat="1.89469e-08 -0.707107 0 0.707107">
                    <inertial pos="0.0256483 -1.23773e-09 -0.0791271" quat="0.363801 0.606341 0.606341 0.363801" mass="0.704325" diaginertia="0.00249627 0.0022896 0.00155994"/>
                    <joint name="right wrist yaw" pos="0 0 0" axis="0 0 -1" range="-4.71239 4.71239" actuatorfrcrange="-24 24"/>
                    <geom type="mesh" rgba="0.768627 0.886275 0.952941 1" mesh="upper_limb_assembly_7_dof_1_full_arm_7_dof_1_lower_arm_3_dof_1_rmd_x4_24_mock_3_inner_rmd_x4_24_1_simple"/>
                    <geom pos="0 0 -0.025" type="mesh" rgba="0.615686 0.811765 0.929412 1" mesh="upper_limb_assembly_7_dof_1_full_arm_7_dof_1_lower_arm_3_dof_1_wrist_part_3_1_simple"/>
                    <geom pos="0.0235 0 -0.074" quat="-1.64085e-08 -0.707107 1.64085e-08 -0.707107" type="mesh" rgba="0.917647 0.917647 0.917647 1" mesh="upper_limb_assembly_7_dof_1_full_arm_7_dof_1_lower_arm_3_dof_1_hand_left_1_rmd_x4_24_mock_1_outer_rmd_x4_24_1_simple"/>
                    <geom pos="0.0435 -9.28204e-10 -0.123" quat="-4.92255e-08 0.707107 -1.64085e-08 -0.707107" type="mesh" rgba="0.647059 0.647059 0.647059 1" mesh="upper_limb_assembly_7_dof_1_full_arm_7_dof_1_lower_arm_3_dof_1_hand_left_1_gripper_housing_1_simple"/>
                    <geom pos="0.0725 0.0875 -0.0985" quat="-0.707107 -6.56339e-08 -0.707107 3.2817e-08" type="mesh" rgba="0.615686 0.811765 0.929412 1" mesh="upper_limb_assembly_7_dof_1_full_arm_7_dof_1_lower_arm_3_dof_1_hand_left_1_slide_rail_1_simple"/>
                    <body name="link_upper_limb_assembly_7_dof_1_full_arm_7_dof_1_lower_arm_3_dof_1_hand_left_1_slide_1" pos="0.0805 -0.1 -0.0985" quat="4.92255e-08 -4.92255e-08 -0.707107 0.707107">
                      <inertial pos="-0.0125996 -0.00418261 -0.0307388" quat="0.356162 0.799069 0.449275 0.181078" mass="0.0616325" diaginertia="7.29328e-05 5.26091e-05 4.35012e-05"/>
                      <joint name="joint_upper_limb_assembly_7_dof_1_full_arm_7_dof_1_lower_arm_3_dof_1_hand_left_1_slider_1" pos="0 0 0" axis="0 0 -1" type="slide" range="0 0.051" actuatorfrcrange="-80 80"/>
                      <geom type="mesh" rgba="0.615686 0.811765 0.929412 1" mesh="upper_limb_assembly_7_dof_1_full_arm_7_dof_1_lower_arm_3_dof_1_hand_left_1_slide_1_simple"/>
                      <geom pos="-0.00499 0.01 -0.033" quat="0.707107 0 -0.707107 0" type="mesh" rgba="0.615686 0.811765 0.929412 1" mesh="upper_limb_assembly_7_dof_1_full_arm_7_dof_1_lower_arm_3_dof_1_hand_left_1_rack_3_simple"/>
                      <geom pos="-0.01749 -0.0130006 -0.004" type="mesh" rgba="0.231373 0.380392 0.705882 1" mesh="upper_limb_assembly_7_dof_1_full_arm_7_dof_1_lower_arm_3_dof_1_hand_left_1_outer_gripper_1_simple"/>
                    </body>
                    <body name="link_upper_limb_assembly_7_dof_1_full_arm_7_dof_1_lower_arm_3_dof_1_hand_left_1_slide_2" pos="0.0805 0.1 -0.0985" quat="-4.92255e-08 -4.92255e-08 -0.707107 -0.707107">
                      <inertial pos="-0.0125996 -0.00716962 -0.0307388" quat="0.703418 -0.339904 -0.119607 0.612668" mass="0.0616325" diaginertia="6.99359e-05 6.34474e-05 3.1296e-05"/>
                      <joint name="joint_upper_limb_assembly_7_dof_1_full_arm_7_dof_1_lower_arm_3_dof_1_hand_left_1_slider_2" pos="0 0 0" axis="0 0 -1" type="slide" range="-0.051 0" actuatorfrcrange="-80 80"/>
                      <geom type="mesh" rgba="0.615686 0.811765 0.929412 1" mesh="upper_limb_assembly_7_dof_1_full_arm_7_dof_1_lower_arm_3_dof_1_hand_left_1_slide_2_simple"/>
                      <geom pos="-0.00499 0.01 -0.033" quat="-1.64085e-08 -0.707107 -1.64085e-08 0.707107" type="mesh" rgba="0.615686 0.811765 0.929412 1" mesh="upper_limb_assembly_7_dof_1_full_arm_7_dof_1_lower_arm_3_dof_1_hand_left_1_rack_4_simple"/>
                      <geom pos="-0.01749 0.0135 -0.004" quat="-1 2.32051e-08 0 -2.32051e-08" type="mesh" rgba="0.231373 0.380392 0.705882 1" mesh="upper_limb_assembly_7_dof_1_full_arm_7_dof_1_lower_arm_3_dof_1_hand_left_1_inner_gripper_2_simple"/>
                    </body>
                    <body name="link_upper_limb_assembly_7_dof_1_full_arm_7_dof_1_lower_arm_3_dof_1_hand_left_1_rmd_x4_24_mock_1_inner_rmd_x4_24_1" pos="0.0035 9.28204e-10 -0.0985" quat="0.707107 0 -0.707107 0">
                      <inertial pos="0 0 -0.012407" quat="0.5 0.5 -0.5 0.5" mass="0.14016" diaginertia="2.14331e-05 1.79936e-05 1.79936e-05"/>
                      <joint name="joint_upper_limb_assembly_7_dof_1_full_arm_7_dof_1_lower_arm_3_dof_1_hand_left_1_rmd_x4_24_mock_1_dof_x4" pos="0 0 0" axis="0 0 -1" range="-1.32645 1.32645" actuatorfrcrange="-24 24"/>
                      <geom type="mesh" rgba="0.768627 0.886275 0.952941 1" mesh="upper_limb_assembly_7_dof_1_full_arm_7_dof_1_lower_arm_3_dof_1_hand_left_1_rmd_x4_24_mock_1_inner_rmd_x4_24_1_simple"/>
                    </body>
                  </body>
                </body>
              </body>
            </body>
          </body>
        </body>
      </body>
      <body name="link_upper_limb_assembly_7_dof_1_torso_1_rmd_x8_90_mock_1_inner_rmd_x8_90_1" pos="-2.34973e-08 0.000437101 -0.351562" quat="-1.64085e-08 0.707107 -0.707107 1.64085e-08">
        <inertial pos="2.30704e-06 -1.32985e-06 0.103274" quat="0.965836 0.0104293 0.00200204 -0.258937" mass="3.20487" diaginertia="0.0166657 0.0122398 0.00799955"/>
        <joint name="torso roll" pos="0 0 0" axis="0 0 -1" range="-4.36332 4.36332" actuatorfrcrange="-90 90"/>
        <geom type="mesh" rgba="0.980392 0.713726 0.00392157 1" mesh="upper_limb_assembly_7_dof_1_torso_1_rmd_x8_90_mock_1_inner_rmd_x8_90_1_simple"/>
        <geom pos="0.0216506 -0.0125 0.0035" quat="-2.00962e-08 0.866025 0.5 -1.16026e-08" type="mesh" rgba="0.647059 0.647059 0.647059 1" mesh="upper_limb_assembly_7_dof_1_torso_1_hip_mount_1_simple"/>
        <geom pos="-0.0178585 0.0666489 0.0285" quat="-2.00962e-08 0.866025 0.5 -1.16026e-08" type="mesh" rgba="0.615686 0.811765 0.929412 1" mesh="lower_limbs_1_leg_assembly_right_1_leg_part_1_2_simple"/>
        <geom pos="0.0597558 -0.0345 0.062" quat="0.183013 0.183013 0.683013 0.683013" type="mesh" rgba="0.615686 0.811765 0.929412 1" mesh="lower_limbs_1_leg_assembly_left_1_leg_part_1_2_simple"/>
        <geom pos="0.0178585 -0.0666489 0.0285" quat="-0.965926 1.387e-08 -5.17638e-08 0.258819" type="mesh" rgba="0.615686 0.811765 0.929412 1" mesh="lower_limbs_1_part_1_1_simple"/>
        <geom pos="-0.0162005 -0.0137407 0.0734436" quat="-0.183013 0.183013 0.683013 -0.683013" type="mesh" rgba="0.647059 0.647059 0.647059 1" mesh="lower_limbs_1_leg_assembly_left_1_rmd_x12_150_mock_1_outer_x12_150_1_simple"/>
        <geom pos="0.0162005 0.0137407 0.0734436" quat="-0.683013 0.683013 -0.183013 0.183013" type="mesh" rgba="0.647059 0.647059 0.647059 1" mesh="lower_limbs_1_leg_assembly_right_1_rmd_x12_150_mock_1_outer_x12_150_1_simple"/>
        <body name="link_lower_limbs_1_leg_assembly_left_1_rmd_x12_150_mock_1_inner_x12_150_1" pos="-0.02225 -0.0385381 0.131" quat="0.353553 -0.612372 -0.353553 -0.612372">
          <inertial pos="0.00368751 -0.00038695 -0.0822654" quat="0.999973 -0.00682216 -0.000925822 -0.00236834" mass="0.882229" diaginertia="0.00274654 0.00217518 0.00103649"/>
          <joint name="right hip pitch" pos="0 0 0" axis="0 0 -1" range="-4.71239 4.71239" actuatorfrcrange="-80 80"/>
          <geom type="mesh" rgba="0.231373 0.380392 0.705882 1" mesh="lower_limbs_1_leg_assembly_left_1_rmd_x12_150_mock_1_inner_x12_150_1_simple"/>
          <geom pos="0 -0.0185 -0.023" type="mesh" rgba="0.647059 0.647059 0.647059 1" mesh="lower_limbs_1_leg_assembly_left_1_leg_part_2_left_1_simple"/>
          <geom pos="0.0230618 0.0179298 -0.146308" quat="0.5 -0.5 0.5 -0.5" type="mesh" rgba="0.498039 0.498039 0.498039 1" mesh="lower_limbs_1_leg_assembly_left_1_rmd_x8_90_mock_1_outer_rmd_x8_90_1_simple"/>
          <body name="link_lower_limbs_1_leg_assembly_left_1_rmd_x8_90_mock_1_inner_rmd_x8_90_1" pos="-0.0244382 -0.000630373 -0.1015" quat="0.5 0.5 -0.5 -0.5">
            <inertial pos="-0.0374104 -0.0647967 -0.0203372" quat="0.672393 0.693469 -0.185815 -0.180167" mass="1.13448" diaginertia="0.00509764 0.00496223 0.00182477"/>
            <joint name="right hip yaw" pos="0 0 0" axis="0 0 -1" range="-1.0472 2.0944" actuatorfrcrange="-90 90"/>
            <geom type="mesh" rgba="0.980392 0.713726 0.00392157 1" mesh="lower_limbs_1_leg_assembly_left_1_rmd_x8_90_mock_1_inner_rmd_x8_90_1_simple"/>
            <geom pos="0.0216506 0.0125 0.0035" quat="-1.16026e-08 0.5 -0.866025 2.00962e-08" type="mesh" rgba="0.231373 0.380392 0.705882 1" mesh="lower_limbs_1_leg_assembly_left_1_leg_part_3_1_simple"/>
            <geom pos="0.00446153 -0.112272 -0.072" quat="-0.5 -2.32051e-08 4.01924e-08 0.866025" type="mesh" rgba="0.647059 0.647059 0.647059 1" mesh="lower_limbs_1_leg_assembly_left_1_leg_part_4_1_simple"/>
            <geom pos="-0.016195 -0.117667 -0.00108985" quat="-0.683013 0.683013 -0.183013 0.183013" type="mesh" rgba="0.498039 0.498039 0.498039 1" mesh="lower_limbs_1_leg_assembly_left_1_rmd_x8_90_mock_2_outer_rmd_x8_90_1_simple"/>
            <body name="link_lower_limbs_1_leg_assembly_left_1_rmd_x8_90_mock_2_inner_rmd_x8_90_1" pos="-0.07875 -0.136399 -0.01965" quat="-0.683013 -0.683013 0.183013 0.183013">
              <inertial pos="-0.00746487 0.000314022 0.0700513" quat="0.999887 0.00425496 -0.0141971 0.00261844" mass="1.13901" diaginertia="0.00601017 0.0051407 0.00158734"/>
              <joint name="right hip roll" pos="0 0 0" axis="0 0 -1" range="-3.14159 0" actuatorfrcrange="-90 90"/>
              <geom type="mesh" rgba="0.980392 0.713726 0.00392157 1" mesh="lower_limbs_1_leg_assembly_left_1_rmd_x8_90_mock_2_inner_rmd_x8_90_1_simple"/>
              <geom pos="0 0 0.0035" quat="0 -2.32051e-08 1 -2.32051e-08" type="mesh" rgba="0.647059 0.647059 0.647059 1" mesh="lower_limbs_1_leg_assembly_left_1_let_part_5_left_1_simple"/>
              <geom pos="-0.02685 0.0448082 0.10844" quat="-4.92255e-08 -0.707107 -1.64085e-08 0.707107" type="mesh" rgba="0.498039 0.498039 0.498039 1" mesh="lower_limbs_1_leg_assembly_left_1_rmd_x8_90_mock_3_outer_rmd_x8_90_1_simple"/>
              <body name="link_lower_limbs_1_leg_assembly_left_1_rmd_x8_90_mock_3_inner_rmd_x8_90_1" pos="0.02065 8.89452e-09 0.127" quat="0.707107 -3.2817e-08 0.707107 0">
                <inertial pos="0.0449624 -0.0780024 -0.0105593" quat="0.691941 0.674006 0.18614 0.179682" mass="0.88694" diaginertia="0.00985766 0.00713533 0.00349125"/>
                <joint name="right knee pitch" pos="0 0 0" axis="0 0 -1" range="-4.71239 4.71239" actuatorfrcrange="-90 90"/>
                <geom type="mesh" rgba="0.980392 0.713726 0.00392157 1" mesh="lower_limbs_1_leg_assembly_left_1_rmd_x8_90_mock_3_inner_rmd_x8_90_1_simple"/>
                <geom pos="0.0216506 0.0125 0.0035" quat="-2.00962e-08 0.866025 -0.5 1.16026e-08" type="mesh" rgba="0.647059 0.647059 0.647059 1" mesh="lower_limbs_1_leg_assembly_left_1_leg_part_6_2_simple"/>
                <geom pos="0.111714 -0.219494 0.0121" quat="-0.104528 -2.36245e-08 1.36396e-08 0.994522" type="mesh" rgba="0.768627 0.886275 0.952941 1" mesh="lower_limbs_1_leg_assembly_left_1_rmd_x4_24_mock_1_inner_rmd_x4_24_1_simple"/>
                <geom pos="0.0825 -0.142894 -0.074" quat="-2.00962e-08 0.866025 -0.5 1.16026e-08" type="mesh" rgba="0.647059 0.647059 0.647059 1" mesh="lower_limbs_1_leg_assembly_left_1_leg_part_7_1_simple"/>
                <body name="link_lower_limbs_1_leg_assembly_left_1_rmd_x4_24_mock_1_outer_rmd_x4_24_1" pos="0.123 -0.213042 -0.0129" quat="2.60501e-08 -0.104528 0.994522 -3.67176e-08">
                  <inertial pos="0.000520119 -0.0339665 0.0111351" quat="0.447691 0.46851 -0.533493 0.543559" mass="0.60771" diaginertia="0.00111303 0.00101075 0.000571984"/>
                  <joint name="right ankle pitch" pos="0 0 0" axis="0 0 -1" range="-1.5708 2.18166" actuatorfrcrange="-24 24"/>
                  <geom type="mesh" rgba="0.917647 0.917647 0.917647 1" mesh="lower_limbs_1_leg_assembly_left_1_rmd_x4_24_mock_1_outer_rmd_x4_24_1_simple"/>
                  <geom pos="0.01225 -0.0212176 -0.02" type="mesh" rgba="0.615686 0.811765 0.929412 1" mesh="lower_limbs_1_left_foot_1_ankle_half_2_left_1_simple"/>
                  <geom pos="0.0335 -0.04705 0.01055" quat="-1.64085e-08 0.707107 -1.64085e-08 -0.707107" type="mesh" rgba="0.917647 0.917647 0.917647 1" mesh="lower_limbs_1_left_foot_1_rmd_x4_24_mock_1_outer_rmd_x4_24_1_simple"/>
                  <geom pos="0 0.0145 0.04735" quat="0.707107 0 0.707107 0" type="mesh" rgba="0.615686 0.811765 0.929412 1" mesh="lower_limbs_1_left_foot_1_ankle_half_1_left_2_simple"/>
                  <body name="link_lower_limbs_1_left_foot_1_rmd_x4_24_mock_1_inner_rmd_x4_24_1" pos="0.0135 -0.07155 0.01055" quat="-0.5 0.5 0.5 -0.5">
                    <inertial pos="0.00584595 -0.0275033 -0.0114478" quat="0.994413 -0.0147465 -0.00155004 0.104511" mass="0.422846" diaginertia="0.00136272 0.00135059 0.000429099"/>
                    <joint name="left ankle roll" pos="0 0 0" axis="0 0 -1" range="-2.26893 -1.22173" actuatorfrcrange="-24 24"/>
                    <geom type="mesh" rgba="0.768627 0.886275 0.952941 1" mesh="lower_limbs_1_left_foot_1_rmd_x4_24_mock_1_inner_rmd_x4_24_1_simple"/>
                    <geom pos="0.00275746 -0.0127042 -0.025" quat="0.994522 0 0 0.104528" type="mesh" rgba="0.615686 0.811765 0.929412 1" mesh="lower_limbs_1_left_foot_1_foot_1_simple"/>
                    <geom pos="0.0103956 -0.0489074 -0.0147699" quat="0.703233 -0.703233 -0.0739128 0.0739128" type="mesh" rgba="0.647059 0.647059 0.647059 1" mesh="lower_limbs_1_left_foot_1_rubber_grip_1_simple"/>
                  </body>
                </body>
              </body>
            </body>
          </body>
        </body>
        <body name="link_lower_limbs_1_leg_assembly_right_1_rmd_x12_150_mock_1_inner_x12_150_1" pos="0.02225 0.0385381 0.131" quat="-0.612372 -0.353553 0.612372 -0.353553">
          <inertial pos="0.000136577 0.00766442 -0.0822654" quat="0.704842 0.013927 -0.00859086 0.709175" mass="0.882229" diaginertia="0.00274825 0.00218315 0.00104302"/>
          <joint name="left hip pitch" pos="0 0 0" axis="0 0 -1" range="-4.71239 4.71239" actuatorfrcrange="-80 80"/>
          <geom type="mesh" rgba="0.231373 0.380392 0.705882 1" mesh="lower_limbs_1_leg_assembly_right_1_rmd_x12_150_mock_1_inner_x12_150_1_simple"/>
          <geom pos="0 0 -0.023" quat="0.707107 0 0 0.707107" type="mesh" rgba="0.647059 0.647059 0.647059 1" mesh="lower_limbs_1_leg_assembly_right_1_leg_part_2_right_1_simple"/>
          <geom pos="-0.0185601 0.02785 -0.0566918" quat="0.707107 -0.707107 0 0" type="mesh" rgba="0.498039 0.498039 0.498039 1" mesh="lower_limbs_1_leg_assembly_right_1_rmd_x8_90_mock_1_outer_rmd_x8_90_1_simple"/>
          <body name="link_lower_limbs_1_leg_assembly_right_1_rmd_x8_90_mock_1_inner_rmd_x8_90_1" pos="7.46238e-10 -0.01965 -0.1015" quat="0.707107 0.707107 0 0">
            <inertial pos="-0.0374104 -0.0647967 -0.0203372" quat="0.672393 0.693469 -0.185815 -0.180167" mass="1.13448" diaginertia="0.00509764 0.00496223 0.00182477"/>
            <joint name="left hip yaw" pos="0 0 0" axis="0 0 -1" range="-4.71239 4.71239" actuatorfrcrange="-90 90"/>
            <geom type="mesh" rgba="0.980392 0.713726 0.00392157 1" mesh="lower_limbs_1_leg_assembly_right_1_rmd_x8_90_mock_1_inner_rmd_x8_90_1_simple"/>
            <geom pos="0.0216506 0.0125 0.0035" quat="-1.16026e-08 0.5 -0.866025 2.00962e-08" type="mesh" rgba="0.231373 0.380392 0.705882 1" mesh="lower_limbs_1_leg_assembly_right_1_leg_part_3_1_simple"/>
            <geom pos="0.00446153 -0.112272 -0.072" quat="-0.5 -2.32051e-08 4.01924e-08 0.866025" type="mesh" rgba="0.647059 0.647059 0.647059 1" mesh="lower_limbs_1_leg_assembly_right_1_leg_part_4_1_simple"/>
            <geom pos="-0.016195 -0.117667 -0.00108985" quat="-0.683013 0.683013 -0.183013 0.183013" type="mesh" rgba="0.498039 0.498039 0.498039 1" mesh="lower_limbs_1_leg_assembly_right_1_rmd_x8_90_mock_2_outer_rmd_x8_90_1_simple"/>
            <body name="link_lower_limbs_1_leg_assembly_right_1_rmd_x8_90_mock_2_inner_rmd_x8_90_1" pos="-0.07875 -0.136399 -0.01965" quat="-0.683013 -0.683013 0.183013 0.183013">
              <inertial pos="0.000314021 -0.00746488 0.0700513" quat="0.708878 0.00703016 -0.0130476 0.705175" mass="1.13901" diaginertia="0.00601017 0.0051407 0.00158734"/>
              <joint name="left hip roll" pos="0 0 0" axis="0 0 -1" range="-3.14159 3.14159" actuatorfrcrange="-90 90"/>
              <geom type="mesh" rgba="0.980392 0.713726 0.00392157 1" mesh="lower_limbs_1_leg_assembly_right_1_rmd_x8_90_mock_2_inner_rmd_x8_90_1_simple"/>
              <geom pos="-0.0216506 -0.0125 0.0035" quat="-1.64085e-08 0.707107 0.707107 -1.64085e-08" type="mesh" rgba="0.647059 0.647059 0.647059 1" mesh="lower_limbs_1_leg_assembly_right_1_leg_part_5_right_2_simple"/>
              <geom pos="0.0448082 -0.02685 0.10844" quat="0.5 0.5 0.5 -0.5" type="mesh" rgba="0.498039 0.498039 0.498039 1" mesh="lower_limbs_1_leg_assembly_right_1_rmd_x8_90_mock_3_outer_rmd_x8_90_1_simple"/>
              <body name="link_lower_limbs_1_leg_assembly_right_1_rmd_x8_90_mock_3_inner_rmd_x8_90_1" pos="6.61991e-09 0.02065 0.127" quat="-0.5 0.5 -0.5 -0.5">
                <inertial pos="0.0449624 -0.0780024 -0.0105593" quat="0.691941 0.674006 0.18614 0.179682" mass="0.88694" diaginertia="0.00985766 0.00713533 0.00349125"/>
                <joint name="left knee pitch" pos="0 0 0" axis="0 0 -1" range="-4.71239 4.71239" actuatorfrcrange="-90 90"/>
                <geom type="mesh" rgba="0.980392 0.713726 0.00392157 1" mesh="lower_limbs_1_leg_assembly_right_1_rmd_x8_90_mock_3_inner_rmd_x8_90_1_simple"/>
                <geom pos="0.0216506 0.0125 0.0035" quat="-2.00962e-08 0.866025 -0.5 1.16026e-08" type="mesh" rgba="0.647059 0.647059 0.647059 1" mesh="lower_limbs_1_leg_assembly_right_1_leg_part_6_2_simple"/>
                <geom pos="0.111714 -0.219494 0.0121" quat="-0.104528 -2.36245e-08 1.36396e-08 0.994522" type="mesh" rgba="0.768627 0.886275 0.952941 1" mesh="lower_limbs_1_leg_assembly_right_1_rmd_x4_24_mock_1_inner_rmd_x4_24_1_simple"/>
                <geom pos="0.0825 -0.142894 -0.074" quat="-2.00962e-08 0.866025 -0.5 1.16026e-08" type="mesh" rgba="0.647059 0.647059 0.647059 1" mesh="lower_limbs_1_leg_assembly_right_1_leg_part_7_1_simple"/>
                <body name="link_lower_limbs_1_leg_assembly_right_1_rmd_x4_24_mock_1_outer_rmd_x4_24_1" pos="0.123 -0.213042 -0.0129" quat="2.60501e-08 -0.104528 0.994522 -3.67176e-08">
                  <inertial pos="-0.000520129 -0.0339665 0.0111351" quat="0.530142 0.546765 -0.472492 0.443563" mass="0.607709" diaginertia="0.0011141 0.00101039 0.00057127"/>
                  <joint name="left ankle pitch" pos="0 0 0" axis="0 0 -1" range="-1.5708 2.18166" actuatorfrcrange="-24 24"/>
                  <geom type="mesh" rgba="0.917647 0.917647 0.917647 1" mesh="lower_limbs_1_leg_assembly_right_1_rmd_x4_24_mock_1_outer_rmd_x4_24_1_simple"/>
                  <geom pos="-0.01225 -0.0212176 -0.02" type="mesh" rgba="0.615686 0.811765 0.929412 1" mesh="lower_limbs_1_right_foot_1_ankle_half_2_right_2_simple"/>
                  <geom pos="0 -0.038 -0.02845" quat="-1.64085e-08 -0.707107 -1.64085e-08 0.707107" type="mesh" rgba="0.615686 0.811765 0.929412 1" mesh="lower_limbs_1_right_foot_1_ankle_half_1_right_1_simple"/>
                  <geom pos="-0.0335 -0.04705 0.01055" quat="0.707107 0 0.707107 0" type="mesh" rgba="0.917647 0.917647 0.917647 1" mesh="lower_limbs_1_right_foot_1_rmd_x4_24_mock_1_outer_rmd_x4_24_1_simple"/>
                  <body name="link_lower_limbs_1_right_foot_1_rmd_x4_24_mock_1_inner_rmd_x4_24_1" pos="-0.0135 -0.07155 0.01055" quat="0.5 0.5 0.5 0.5">
                    <inertial pos="0.00584595 -0.0275033 -0.0114478" quat="0.994413 -0.0147465 -0.00155005 0.10451" mass="0.422846" diaginertia="0.00136272 0.00135059 0.000429099"/>
                    <joint name="right ankle roll" pos="0 0 0" axis="0 0 -1" range="-2.26893 -1.22173" actuatorfrcrange="-24 24"/>
                    <geom type="mesh" rgba="0.768627 0.886275 0.952941 1" mesh="lower_limbs_1_right_foot_1_rmd_x4_24_mock_1_inner_rmd_x4_24_1_simple"/>
                    <geom pos="0.00275746 -0.0127042 -0.025" quat="0.994522 0 0 0.104528" type="mesh" rgba="0.615686 0.811765 0.929412 1" mesh="lower_limbs_1_right_foot_1_foot_1_simple"/>
                    <geom pos="0.0103956 -0.0489074 -0.0147699" quat="-0.0739128 -0.0739128 0.703233 0.703233" type="mesh" rgba="0.647059 0.647059 0.647059 1" mesh="lower_limbs_1_right_foot_1_rubber_grip_3_simple"/>
                  </body>
                </body>
              </body>
            </body>
          </body>
        </body>
      </body>
    </body>
  </worldbody>
</mujoco>
