<mujoco model="robot">
  <compiler angle="radian" meshdir="meshes" eulerseq="zyx" autolimits="true"/>
  <default>
    <joint limited="true" damping="0.01" stiffness="0" armature="0.01" frictionloss="0.01"/>
    <geom condim="4" contype="1" conaffinity="15" friction="0.9 0.2 0.2" solref="0.001 2"/>
    <motor ctrllimited="true"/>
    <equality solref="0.001 2"/>
    <default class="visualgeom">
      <geom material="visualgeom" condim="1" contype="0" conaffinity="0"/>
    </default>
  </default>
  <option iterations="50" timestep="0.001" solver="PGS" gravity="0 0 -9.81"/>
  <asset>
    <mesh name="trunk" file="trunk.stl" scale="0.001 0.001 0.001"/>
    <mesh name="buttock" file="buttock.stl" scale="0.001 0.001 0.001"/>
    <mesh name="leg" file="leg.stl" scale="0.001 0.001 0.001"/>
    <mesh name="mthigh" file="mthigh.stl" scale="0.001 0.001 0.001"/>
    <mesh name="mcalf" file="mcalf.stl" scale="0.001 0.001 0.001"/>
    <mesh name="thigh" file="thigh.stl" scale="0.001 0.001 0.001"/>
    <mesh name="calf" file="calf.stl" scale="0.001 0.001 0.001"/>
    <mesh name="clav" file="clav.stl" scale="0.001 0.001 0.001"/>
    <mesh name="scap" file="scap.stl" scale="0.001 0.001 0.001"/>
    <mesh name="uarm" file="uarm.stl" scale="0.001 0.001 0.001"/>
    <mesh name="farm" file="farm.stl" scale="0.001 0.001 0.001"/>
    <texture name="texplane" type="2d" builtin="checker" rgb1=".0 .0 .0" rgb2=".8 .8 .8" width="100" height="108"/>
    <material name="matplane" reflectance="0." texture="texplane" texrepeat="1 1" texuniform="true"/>
    <material name="visualgeom" rgba="0.5 0.9 0.2 1"/>
  </asset>
  <worldbody>
    <geom name="ground" type="plane" pos="0.001 0 0" quat="1 0 0 0" material="matplane" condim="1" conaffinity="15" size="0 0 1"/>
    <light directional="true" diffuse="0.6 0.6 0.6" specular="0.2 0.2 0.2" pos="0 0 4" dir="0 0 -1"/>
    <light directional="true" diffuse="0.4 0.4 0.4" specular="0.1 0.1 0.1" pos="0 0 5.0" dir="0 0 -1" castshadow="false"/>
    <geom type="mesh" mesh="trunk" class="visualgeom"/>
    <geom type="mesh" rgba="" mesh="trunk" contype="0" conaffinity="0" group="1" density="0"/>
    <camera name="front" pos="0 -3 1" xyaxes="1 0 0 0 1 2" mode="trackcom"/>
    <camera name="side" pos="-2.893 -1.330 0.757" xyaxes="0.405 -0.914 0.000 0.419 0.186 0.889" mode="trackcom"/>
    <site name="imu" size="0.01" pos="0 0 0"/>
    <body name="L_buttock" pos="0 0.1577 0">
      <inertial pos="0.00129183 -0.00184328 2.27946e-05" quat="0.706341 0.707841 -0.00498313 -0.00434939" mass="1.29909" diaginertia="0.00209325 0.00150009 0.00131174"/>
      <joint name="L_hip_y" pos="0 0 0" axis="0 1 0" range="-3.14 3.14"/>
      <geom quat="2.67949e-08 1 0 0" type="mesh" mesh="buttock" class="visualgeom"/>
      <geom type="mesh" rgba="" mesh="buttock" quat="2.67949e-08 1 0 0" contype="0" conaffinity="0" group="1" density="0"/>
      <body name="L_leg">
        <inertial pos="0.000708602 -2.24355e-05 -0.110352" quat="0.706876 0.0329943 0.0330587 0.705794" mass="1.33983" diaginertia="0.00375341 0.00352246 0.00184361"/>
        <joint name="L_hip_x" pos="0 0 0" axis="1 0 0" range="-0.523 2.093"/>
        <geom type="mesh" mesh="leg" class="visualgeom"/>
        <geom type="mesh" rgba="" mesh="leg" contype="0" conaffinity="0" group="1" density="0"/>
        <body name="L_thigh">
          <inertial pos="-0.000407357 0.00130538 -0.291653" quat="0.711843 -0.00549725 0.000501512 0.702317" mass="1.93995" diaginertia="0.00607631 0.0044935 0.00293511"/>
          <joint name="L_hip_z" pos="0 0 0" axis="0 0 1" range="-3.14 3.14"/>
          <geom type="mesh" mesh="mthigh" class="visualgeom"/>
          <geom type="mesh" rgba="" mesh="mthigh" contype="0" conaffinity="0" group="1" density="0"/>
          <body name="L_calf" pos="0 0 -0.3">
            <inertial pos="-0.00195352 -0.00434338 -0.134048" quat="0.599799 -0.00402307 0.025204 0.799743" mass="1.54477" diaginertia="0.00986297 0.00971929 0.00143814"/>
            <joint name="L_knee" pos="0 0 0" axis="0 1 0" range="-1.919 1.919"/>
            <geom type="mesh" mesh="mcalf" class="visualgeom"/>
            <geom type="mesh" rgba="" mesh="mcalf" contype="0" conaffinity="0" group="1" density="0"/>
            <body name="L_foot" pos="0 0 -0.3">
              <inertial pos="0.0233665 0.014827 -0.0165314" quat="-0.00182247 0.713608 0.0126839 0.700428" mass="0.542373" diaginertia="0.00215059 0.00196588 0.000256086"/>
              <joint name="L_ankle_y" pos="0 0 0" axis="0 1 0" range="-0.698 0.698"/>
              <geom size="0.11 0.04 0.0075" pos="0.03 -0.011 -0.02" type="box" class="visualgeom"/>
              <geom type="box" rgba="" mesh="" pos="0.03 -0.011 -0.02" contype="0" conaffinity="0" group="1" density="0"/>
            </body>
          </body>
        </body>
      </body>
    </body>
    <body name="R_buttock" pos="0 -0.1577 0">
      <inertial pos="0.00129183 0.00184328 2.27946e-05" quat="0.707841 0.706341 0.00434939 0.00498313" mass="1.29909" diaginertia="0.00209325 0.00150009 0.00131174"/>
      <joint name="R_hip_y" pos="0 0 0" axis="0 1 0" range="-3.14 3.14"/>
      <geom type="mesh" mesh="buttock" class="visualgeom"/>
      <geom type="mesh" rgba="" mesh="buttock" contype="0" conaffinity="0" group="1" density="0"/>
      <body name="R_leg">
        <inertial pos="0.000708602 2.24355e-05 -0.110352" quat="0.705794 0.0330587 0.0329943 0.706876" mass="1.33983" diaginertia="0.00375341 0.00352246 0.00184361"/>
        <joint name="R_hip_x" pos="0 0 0" axis="1 0 0" range="-2.093 0.523"/>
        <geom type="mesh" mesh="leg" class="visualgeom"/>
        <geom type="mesh" rgba="" mesh="leg" contype="0" conaffinity="0" group="1" density="0"/>
        <body name="R_thigh">
          <inertial pos="-0.000407357 -0.00130538 -0.291653" quat="0.702317 0.000501512 -0.00549725 0.711843" mass="1.93995" diaginertia="0.00607631 0.0044935 0.00293511"/>
          <joint name="R_hip_z" pos="0 0 0" axis="0 0 1" range="-3.14 3.14"/>
          <geom type="mesh" mesh="thigh" class="visualgeom"/>
          <geom type="mesh" rgba="" mesh="thigh" contype="0" conaffinity="0" group="1" density="0"/>
          <body name="R_calf" pos="0 0 -0.3">
            <inertial pos="-0.00195352 0.00434338 -0.134048" quat="0.799743 0.025204 -0.00402307 0.599799" mass="1.54477" diaginertia="0.00986297 0.00971929 0.00143814"/>
            <joint name="R_knee" pos="0 0 0" axis="0 1 0" range="-1.919 1.919"/>
            <geom type="mesh" mesh="calf" class="visualgeom"/>
            <geom type="mesh" rgba="" mesh="calf" contype="0" conaffinity="0" group="1" density="0"/>
            <body name="R_foot" pos="0 0 -0.3">
              <inertial pos="0.0233665 0.014827 -0.0165314" quat="-0.00182247 0.713608 0.0126839 0.700428" mass="0.542373" diaginertia="0.00215059 0.00196588 0.000256086"/>
              <joint name="R_ankle_y" pos="0 0 0" axis="0 1 0" range="-0.698 0.698"/>
              <geom size="0.11 0.04 0.0075" pos="0.03 0.011 -0.02" type="box" class="visualgeom"/>
              <geom type="box" rgba="" mesh="" pos="0.03 0.011 -0.02" contype="0" conaffinity="0" group="1" density="0"/>
            </body>
          </body>
        </body>
      </body>
    </body>
    <body name="L_clav" pos="0 0.255 0.45">
      <inertial pos="0.00121221 -0.00150959 -9.36775e-05" quat="0.705125 0.709057 0.00277488 -0.00539434" mass="1.12469" diaginertia="0.00170716 0.00112244 0.00105955"/>
      <joint name="L_shoulder_y" pos="0 0 0" axis="0 1 0" range="-3.1416 3.1416"/>
      <geom quat="2.67949e-08 -1 0 0" type="mesh" mesh="clav" class="visualgeom"/>
      <geom type="mesh" rgba="" mesh="clav" quat="2.67949e-08 -1 0 0" contype="0" conaffinity="0" group="1" density="0"/>
      <body name="L_scapula">
        <inertial pos="0.00381061 -0.000164243 -0.0952191" quat="0.977216 -0.0243503 0.168365 -0.126921" mass="0.654545" diaginertia="0.001202 0.00118685 0.000510654"/>
        <joint name="L_shoulder_x" pos="0 0 0" axis="1 0 0" range="0 3.1416"/>
        <geom type="mesh" mesh="scap" class="visualgeom"/>
        <geom type="mesh" rgba="" mesh="scap" contype="0" conaffinity="0" group="1" density="0"/>
        <body name="L_uarm">
          <inertial pos="-0.00390883 0.000170725 -0.222231" quat="0.99999 -0.00442843 -3.97402e-07 -0.000281596" mass="0.582444" diaginertia="0.000838613 0.000676077 0.000361492"/>
          <joint name="L_shoulder_z" pos="0 0 0" axis="0 0 1" range="-3.14 3.14"/>
          <geom type="mesh" mesh="uarm" class="visualgeom"/>
          <geom type="mesh" rgba="" mesh="uarm" contype="0" conaffinity="0" group="1" density="0"/>
          <body name="L_farm" pos="0 0 -0.23">
            <inertial pos="-0.00240827 0.000170918 -0.140696" quat="0.790729 -0.0380089 -0.0507167 0.608876" mass="0.660026" diaginertia="0.00165272 0.00163667 0.000523563"/>
            <joint name="L_elbow_x" pos="0 0 0" axis="1 0 0" range="-1.9199 1.9199"/>
            <geom type="mesh" mesh="farm" class="visualgeom"/>
            <geom type="mesh" rgba="" mesh="farm" contype="0" conaffinity="0" group="1" density="0"/>
          </body>
        </body>
      </body>
    </body>
    <body name="R_clav" pos="0 -0.255 0.45">
      <inertial pos="0.00121221 0.00150959 -9.36775e-05" quat="0.709057 0.705125 0.00539434 -0.00277488" mass="1.12469" diaginertia="0.00170716 0.00112244 0.00105955"/>
      <joint name="R_shoulder_y" pos="0 0 0" axis="0 1 0" range="-3.1416 3.1416"/>
      <geom type="mesh" mesh="clav" class="visualgeom"/>
      <geom type="mesh" rgba="" mesh="clav" contype="0" conaffinity="0" group="1" density="0"/>
      <body name="R_scapula">
        <inertial pos="0.00381061 -0.000164243 -0.0952191" quat="0.977216 -0.0243503 0.168365 -0.126921" mass="0.654545" diaginertia="0.001202 0.00118685 0.000510654"/>
        <joint name="R_shoulder_x" pos="0 0 0" axis="1 0 0" range="-3.1416 0"/>
        <geom type="mesh" mesh="scap" class="visualgeom"/>
        <geom type="mesh" rgba="" mesh="scap" contype="0" conaffinity="0" group="1" density="0"/>
        <body name="R_uarm">
          <inertial pos="-0.00390883 -0.000170725 -0.222231" quat="0.99999 0.00442843 -3.97402e-07 0.000281596" mass="0.582444" diaginertia="0.000838613 0.000676077 0.000361492"/>
          <joint name="R_shoulder_z" pos="0 0 0" axis="0 0 1" range="-3.14 3.14"/>
          <geom type="mesh" mesh="uarm" class="visualgeom"/>
          <geom type="mesh" rgba="" mesh="uarm" contype="0" conaffinity="0" group="1" density="0"/>
          <body name="R_farm" pos="0 0 -0.23">
            <inertial pos="-0.00240827 -0.000170918 -0.140696" quat="0.608876 -0.0507167 -0.0380089 0.790729" mass="0.660026" diaginertia="0.00165272 0.00163667 0.000523563"/>
            <joint name="R_elbow_x" pos="0 0 0" axis="1 0 0" range="-1.9199 1.9199"/>
            <geom type="mesh" mesh="farm" class="visualgeom"/>
            <geom type="mesh" rgba="" mesh="farm" contype="0" conaffinity="0" group="1" density="0"/>
          </body>
        </body>
      </body>
    </body>
  </worldbody>
  <actuator>
    <motor name="left shoulder pitch" joint="left shoulder pitch" ctrllimited="true" ctrlrange="-120 120" gear="1"/>
    <motor name="left shoulder yaw" joint="left shoulder yaw" ctrllimited="true" ctrlrange="-17 17" gear="1"/>
    <motor name="left shoulder roll" joint="left shoulder roll" ctrllimited="true" ctrlrange="-17 17" gear="1"/>
    <motor name="left elbow pitch" joint="left elbow pitch" ctrllimited="true" ctrlrange="-17 17" gear="1"/>
    <motor name="left hand roll" joint="left hand roll" ctrllimited="true" ctrlrange="-17 17" gear="1"/>
    <motor name="left hand gripper" joint="left hand gripper" ctrllimited="true" ctrlrange="-17 17" gear="1"/>
    <motor name="right shoulder pitch" joint="right shoulder pitch" ctrllimited="true" ctrlrange="-120 120" gear="1"/>
    <motor name="right shoulder yaw" joint="right shoulder yaw" ctrllimited="true" ctrlrange="-17 17" gear="1"/>
    <motor name="right shoulder roll" joint="right shoulder roll" ctrllimited="true" ctrlrange="-17 17" gear="1"/>
    <motor name="right elbow pitch" joint="right elbow pitch" ctrllimited="true" ctrlrange="-17 17" gear="1"/>
    <motor name="right hand roll" joint="right hand roll" ctrllimited="true" ctrlrange="-17 17" gear="1"/>
    <motor name="right hand gripper" joint="right hand gripper" ctrllimited="true" ctrlrange="-17 17" gear="1"/>
    <motor name="left hip pitch" joint="left hip pitch" ctrllimited="true" ctrlrange="-120 120" gear="1"/>
    <motor name="left hip roll" joint="left hip roll" ctrllimited="true" ctrlrange="-17 17" gear="1"/>
    <motor name="left hip yaw" joint="left hip yaw" ctrllimited="true" ctrlrange="-120 120" gear="1"/>
    <motor name="left knee pitch" joint="left knee pitch" ctrllimited="true" ctrlrange="-120 120" gear="1"/>
    <motor name="left ankle pitch" joint="left ankle pitch" ctrllimited="true" ctrlrange="-17 17" gear="1"/>
    <motor name="right hip pitch" joint="right hip pitch" ctrllimited="true" ctrlrange="-120 120" gear="1"/>
    <motor name="right hip roll" joint="right hip roll" ctrllimited="true" ctrlrange="-17 17" gear="1"/>
    <motor name="right hip yaw" joint="right hip yaw" ctrllimited="true" ctrlrange="-120 120" gear="1"/>
    <motor name="right knee pitch" joint="right knee pitch" ctrllimited="true" ctrlrange="-120 120" gear="1"/>
    <motor name="right ankle pitch" joint="right ankle pitch" ctrllimited="true" ctrlrange="-17 17" gear="1"/>
  </actuator>
  <sensor>
    <actuatorpos name="left shoulder pitch_p" actuator="left shoulder pitch" user="13"/>
    <actuatorpos name="left shoulder yaw_p" actuator="left shoulder yaw" user="13"/>
    <actuatorpos name="left shoulder roll_p" actuator="left shoulder roll" user="13"/>
    <actuatorpos name="left elbow pitch_p" actuator="left elbow pitch" user="13"/>
    <actuatorpos name="left hand roll_p" actuator="left hand roll" user="13"/>
    <actuatorpos name="left hand gripper_p" actuator="left hand gripper" user="13"/>
    <actuatorpos name="right shoulder pitch_p" actuator="right shoulder pitch" user="13"/>
    <actuatorpos name="right shoulder yaw_p" actuator="right shoulder yaw" user="13"/>
    <actuatorpos name="right shoulder roll_p" actuator="right shoulder roll" user="13"/>
    <actuatorpos name="right elbow pitch_p" actuator="right elbow pitch" user="13"/>
    <actuatorpos name="right hand roll_p" actuator="right hand roll" user="13"/>
    <actuatorpos name="right hand gripper_p" actuator="right hand gripper" user="13"/>
    <actuatorpos name="left hip pitch_p" actuator="left hip pitch" user="13"/>
    <actuatorpos name="left hip roll_p" actuator="left hip roll" user="13"/>
    <actuatorpos name="left hip yaw_p" actuator="left hip yaw" user="13"/>
    <actuatorpos name="left knee pitch_p" actuator="left knee pitch" user="13"/>
    <actuatorpos name="left ankle pitch_p" actuator="left ankle pitch" user="13"/>
    <actuatorpos name="right hip pitch_p" actuator="right hip pitch" user="13"/>
    <actuatorpos name="right hip roll_p" actuator="right hip roll" user="13"/>
    <actuatorpos name="right hip yaw_p" actuator="right hip yaw" user="13"/>
    <actuatorpos name="right knee pitch_p" actuator="right knee pitch" user="13"/>
    <actuatorpos name="right ankle pitch_p" actuator="right ankle pitch" user="13"/>
    <actuatorvel name="left shoulder pitch_v" actuator="left shoulder pitch" user="13"/>
    <actuatorvel name="left shoulder yaw_v" actuator="left shoulder yaw" user="13"/>
    <actuatorvel name="left shoulder roll_v" actuator="left shoulder roll" user="13"/>
    <actuatorvel name="left elbow pitch_v" actuator="left elbow pitch" user="13"/>
    <actuatorvel name="left hand roll_v" actuator="left hand roll" user="13"/>
    <actuatorvel name="left hand gripper_v" actuator="left hand gripper" user="13"/>
    <actuatorvel name="right shoulder pitch_v" actuator="right shoulder pitch" user="13"/>
    <actuatorvel name="right shoulder yaw_v" actuator="right shoulder yaw" user="13"/>
    <actuatorvel name="right shoulder roll_v" actuator="right shoulder roll" user="13"/>
    <actuatorvel name="right elbow pitch_v" actuator="right elbow pitch" user="13"/>
    <actuatorvel name="right hand roll_v" actuator="right hand roll" user="13"/>
    <actuatorvel name="right hand gripper_v" actuator="right hand gripper" user="13"/>
    <actuatorvel name="left hip pitch_v" actuator="left hip pitch" user="13"/>
    <actuatorvel name="left hip roll_v" actuator="left hip roll" user="13"/>
    <actuatorvel name="left hip yaw_v" actuator="left hip yaw" user="13"/>
    <actuatorvel name="left knee pitch_v" actuator="left knee pitch" user="13"/>
    <actuatorvel name="left ankle pitch_v" actuator="left ankle pitch" user="13"/>
    <actuatorvel name="right hip pitch_v" actuator="right hip pitch" user="13"/>
    <actuatorvel name="right hip roll_v" actuator="right hip roll" user="13"/>
    <actuatorvel name="right hip yaw_v" actuator="right hip yaw" user="13"/>
    <actuatorvel name="right knee pitch_v" actuator="right knee pitch" user="13"/>
    <actuatorvel name="right ankle pitch_v" actuator="right ankle pitch" user="13"/>
    <actuatorfrc name="left shoulder pitch_f" actuator="left shoulder pitch" user="13" noise="0.001"/>
    <actuatorfrc name="left shoulder yaw_f" actuator="left shoulder yaw" user="13" noise="0.001"/>
    <actuatorfrc name="left shoulder roll_f" actuator="left shoulder roll" user="13" noise="0.001"/>
    <actuatorfrc name="left elbow pitch_f" actuator="left elbow pitch" user="13" noise="0.001"/>
    <actuatorfrc name="left hand roll_f" actuator="left hand roll" user="13" noise="0.001"/>
    <actuatorfrc name="left hand gripper_f" actuator="left hand gripper" user="13" noise="0.001"/>
    <actuatorfrc name="right shoulder pitch_f" actuator="right shoulder pitch" user="13" noise="0.001"/>
    <actuatorfrc name="right shoulder yaw_f" actuator="right shoulder yaw" user="13" noise="0.001"/>
    <actuatorfrc name="right shoulder roll_f" actuator="right shoulder roll" user="13" noise="0.001"/>
    <actuatorfrc name="right elbow pitch_f" actuator="right elbow pitch" user="13" noise="0.001"/>
    <actuatorfrc name="right hand roll_f" actuator="right hand roll" user="13" noise="0.001"/>
    <actuatorfrc name="right hand gripper_f" actuator="right hand gripper" user="13" noise="0.001"/>
    <actuatorfrc name="left hip pitch_f" actuator="left hip pitch" user="13" noise="0.001"/>
    <actuatorfrc name="left hip roll_f" actuator="left hip roll" user="13" noise="0.001"/>
    <actuatorfrc name="left hip yaw_f" actuator="left hip yaw" user="13" noise="0.001"/>
    <actuatorfrc name="left knee pitch_f" actuator="left knee pitch" user="13" noise="0.001"/>
    <actuatorfrc name="left ankle pitch_f" actuator="left ankle pitch" user="13" noise="0.001"/>
    <actuatorfrc name="right hip pitch_f" actuator="right hip pitch" user="13" noise="0.001"/>
    <actuatorfrc name="right hip roll_f" actuator="right hip roll" user="13" noise="0.001"/>
    <actuatorfrc name="right hip yaw_f" actuator="right hip yaw" user="13" noise="0.001"/>
    <actuatorfrc name="right knee pitch_f" actuator="right knee pitch" user="13" noise="0.001"/>
    <actuatorfrc name="right ankle pitch_f" actuator="right ankle pitch" user="13" noise="0.001"/>
    <framequat name="orientation" objtype="site" noise="0.001" objname="imu"/>
    <gyro name="angular-velocity" site="imu" noise="0.005" cutoff="34.9"/>
  </sensor>
  <keyframe>
    <key name="default" qpos="0 0 0.92 0.5 -0.4996 -0.5 0.5004 2.25 1.57 3.14 -1.61 -1.56 -0.1 3.45 -0.1 -1.61 -1.49 0 0.1 0.33 -1.52 4.67 -0.61 1.88 2.91 3.24 3.22 0.65 -0.54"/>
  </keyframe>
</mujoco>