<robot
  name="k-bot">
  <link
    name="base">
    <inertial>
      <origin
        xyz="0.00869060899104187 0.00018398436014374 0.27790581320309"
        rpy="0 0 0" />
      <mass
        value="8.62540645323623" />
      <inertia
        ixx="0.0676285585152038"
        ixy="1.93043971084301E-05"
        ixz="-0.000347302451011878"
        iyy="0.0334307390510559"
        iyz="2.85176929765698E-05"
        izz="0.0436069035650796" />
    </inertial>
    <visual>
      <origin
        xyz="0 0 0"
        rpy="0 0 0" />
      <geometry>
        <mesh
          filename="meshes/body_base.STL" />
      </geometry>
      <material
        name="">
        <color
          rgba="0.752941176470588 0.752941176470588 0.752941176470588 1" />
      </material>
    </visual>
    <collision>
      <origin
        xyz="0 0 0"
        rpy="0 0 0" />
      <geometry>
        <mesh
          filename="meshes/body_base.STL" />
      </geometry>
    </collision>
  </link>
  <link
    name="imu_link">
    <visual>
      <geometry>
        <box
          size="0.1 0.1 0.1" />
      </geometry>
      <material
        name="red">
        <color
          rgba="1 0 0 1" />
      </material>
    </visual>
  </link>
  <joint
    name="imu_joint"
    type="fixed"
    dont_collapse="true">
    <origin
      xyz="0.0 0.0 0.35"
      rpy="0 0 0" />
    <parent
      link="base" />
    <child
      link="imu_link" />
  </joint>
  <link
    name="R_buttock">
    <inertial>
      <origin
        xyz="-0.00819709342548599 0.00031820866790877 0.00252304986715471"
        rpy="0 0 0" />
      <mass
        value="0.716812635597912" />
      <inertia
        ixx="0.00128014305619278"
        ixy="-1.43073173318794E-05"
        ixz="2.90385704293737E-06"
        iyy="0.000912114056874006"
        iyz="-1.1074851599526E-07"
        izz="0.000793918800796738" />
    </inertial>
    <visual>
      <origin
        xyz="0 0 0"
        rpy="0 0 0" />
      <geometry>
        <mesh
          filename="meshes/R_buttock.STL" />
      </geometry>
      <material
        name="">
        <color
          rgba="0.898039215686275 0.917647058823529 0.929411764705882 1" />
      </material>
    </visual>
    <collision>
      <origin
        xyz="0 0 0"
        rpy="0 0 0" />
      <geometry>
        <mesh
          filename="meshes/R_buttock.STL" />
      </geometry>
    </collision>
  </link>
  <joint
    name="R_hip_y"
    type="revolute">
    <origin
      xyz="0.00525 -0.1572 0"
      rpy="-1.5707963267949 0.0387975271824028 0" />
    <parent
      link="base" />
    <child
      link="R_buttock" />
    <axis
      xyz="0 0 1" />
    <limit effort="250" lower="-3.14" upper="3.14" velocity="10" />
      <dynamics damping="0" friction="0" />
  </joint>
  <link
    name="R_leg">
    <inertial>
      <origin
        xyz="-0.00346046212680811 0.0922193129069941 -0.00067309440670843"
        rpy="0 0 0" />
      <mass
        value="0.827134269923993" />
      <inertia
        ixx="0.00136874043970098"
        ixy="0.000155251708308535"
        ixz="-4.53133194582764E-06"
        iyy="0.000966522515954523"
        iyz="3.51492190177776E-06"
        izz="0.0013412220053142" />
    </inertial>
    <visual>
      <origin
        xyz="0 0 0"
        rpy="0 0 0" />
      <geometry>
        <mesh
          filename="meshes/R_leg.STL" />
      </geometry>
      <material
        name="">
        <color
          rgba="0.898039215686275 0.917647058823529 0.929411764705882 1" />
      </material>
    </visual>
    <collision>
      <origin
        xyz="0 0 0"
        rpy="0 0 0" />
      <geometry>
        <mesh
          filename="meshes/R_leg.STL" />
      </geometry>
    </collision>
  </link>
  <joint
    name="R_hip_x"
    type="revolute">
    <origin
      xyz="0 0 0"
      rpy="0 0 0" />
    <parent
      link="R_buttock" />
    <child
      link="R_leg" />
    <axis
      xyz="0.999247470344691 -0.0387877945974834 0" />
    <limit effort="100" lower="-2.093" upper="0.523" velocity="10" />
        <dynamics damping="0" friction="0" />
  </joint>
  <link
    name="R_thigh">
    <inertial>
      <origin
        xyz="-0.152975413159304 9.16615043838684E-07 -0.00192310101177529"
        rpy="0 0 0" />
      <mass
        value="0.79742290295527" />
      <inertia
        ixx="0.000928367022232089"
        ixy="4.72987865407845E-08"
        ixz="-5.04802948364786E-05"
        iyy="0.00170898550375536"
        iyz="4.19086194100164E-09"
        izz="0.00226111074590077" />
    </inertial>
    <visual>
      <origin
        xyz="0 0 0"
        rpy="0 0 0" />
      <geometry>
        <mesh
          filename="meshes/R_thigh.STL" />
      </geometry>
      <material
        name="">
        <color
          rgba="0.898039215686275 0.917647058823529 0.929411764705882 1" />
      </material>
    </visual>
    <collision>
      <origin
        xyz="0 0 0"
        rpy="0 0 0" />
      <geometry>
        <mesh
          filename="meshes/R_thigh.STL" />
      </geometry>
    </collision>
  </link>
  <joint
    name="R_hip_z"
    type="revolute">
    <origin
      xyz="0 0.135351856285756 0"
      rpy="0 0 -1.6095938539773" />
    <parent
      link="R_leg" />
    <child
      link="R_thigh" />
    <axis
      xyz="-1 0 0" />
    <limit effort="100" lower="-3.14" upper="3.14" velocity="10" />
        <dynamics damping="0" friction="0" />
  </joint>
  <link
    name="R_calf">
    <inertial>
      <origin
        xyz="-0.0022121892692254 0.128163697384151 -0.00158119322561899"
        rpy="0 0 0" />
      <mass
        value="1.01514022175102" />
      <inertia
        ixx="0.00569735691913715"
        ixy="0.000510336798392953"
        ixz="8.14248936760696E-06"
        iyy="0.000646036105939999"
        iyz="6.00188033232376E-05"
        izz="0.00538781385413709" />
    </inertial>
    <visual>
      <origin
        xyz="0 0 0"
        rpy="0 0 0" />
      <geometry>
        <mesh
          filename="meshes/R_calf.STL" />
      </geometry>
      <material
        name="">
        <color
          rgba="0.898039215686275 0.917647058823529 0.929411764705882 1" />
      </material>
    </visual>
    <collision>
      <origin
        xyz="0 0 0"
        rpy="0 0 0" />
      <geometry>
        <mesh
          filename="meshes/R_calf.STL" />
      </geometry>
    </collision>
  </link>
  <joint
    name="R_knee"
    type="revolute">
    <origin
      xyz="-0.16475 0 0.00650000000000001"
      rpy="1.5707963267949 -1.55913018940661 0" />
    <parent
      link="R_thigh" />
    <child
      link="R_calf" />
    <axis
      xyz="-0.999931951391002 -0.0116658727656092 0" />
    <limit effort="250" lower="-1.919" upper="1.919" velocity="10" />
        <dynamics damping="0" friction="0" />
  </joint>
  <link
    name="R_foot">
    <inertial>
      <origin
        xyz="-0.00369306196610797 -0.0204478246002952 0.0179803976831033"
        rpy="0 0 0" />
      <mass
        value="0.549121604771221" />
      <inertia
        ixx="0.0017845435413145"
        ixy="-2.89252172490551E-05"
        ixz="2.44607696760944E-06"
        iyy="0.000242006231673787"
        iyz="1.22379570008845E-05"
        izz="0.00195776862825295" />
    </inertial>
    <visual>
      <origin
        xyz="0 0 0"
        rpy="0 0 0" />
      <geometry>
        <mesh
          filename="meshes/R_foot.STL" />
      </geometry>
      <material
        name="">
        <color
          rgba="0.898039215686275 0.917647058823529 0.929411764705882 1" />
      </material>
    </visual>
    <collision>
      <origin
        xyz="0 0 0"
        rpy="0 0 0" />
      <geometry>
        <mesh
          filename="meshes/R_foot.STL" />
      </geometry>
    </collision>
  </link>
  <joint
    name="R_ankle_y"
    type="revolute">
    <origin
      xyz="0 0.300020415972074 0"
      rpy="1.57079634708826 0 -3.12992651620125" />
    <parent
      link="R_calf" />
    <child
      link="R_foot" />
    <axis
      xyz="-1 0 0" />
    <limit effort="17" lower="-0.698" upper="0.698" velocity="10" />
      <dynamics damping="0" friction="0.1" />
  </joint>
  <link
    name="L_buttock">
    <inertial>
      <origin
        xyz="0.00251606934185414 1.91491733581017E-09 0.00298061791756006"
        rpy="0 0 0" />
      <mass
        value="0.717874293135761" />
      <inertia
        ixx="0.000795076262097125"
        ixy="-2.58472142390298E-09"
        ixz="-2.8045550408513E-06"
        iyy="0.000912888945648462"
        iyz="-1.64876298177798E-10"
        izz="0.00128256631531027" />
    </inertial>
    <visual>
      <origin
        xyz="0 0 0"
        rpy="0 0 0" />
      <geometry>
        <mesh
          filename="meshes/L_buttock.STL" />
      </geometry>
      <material
        name="">
        <color
          rgba="0.898039215686275 0.917647058823529 0.929411764705882 1" />
      </material>
    </visual>
    <collision>
      <origin
        xyz="0 0 0"
        rpy="0 0 0" />
      <geometry>
        <mesh
          filename="meshes/L_buttock.STL" />
      </geometry>
    </collision>
  </link>
  <joint
    name="L_hip_y"
    type="revolute">
    <origin
      xyz="0 0.1572 0"
      rpy="1.5707963267949 0 -1.5707963267949" />
    <parent
      link="base" />
    <child
      link="L_buttock" />
    <axis
      xyz="-1 0 0" />
    <limit effort="250" lower="-3.14" upper="3.14" velocity="10" />
      <dynamics damping="0" friction="0" />
  </joint>
  <link
    name="L_hip">
    <inertial>
      <origin
        xyz="-0.000667769259253964 -0.0912836471993543 0.00207385707119066"
        rpy="0 0 0" />
      <mass
        value="0.83376821073388" />
      <inertia
        ixx="0.00134348143558515"
        ixy="-3.33631436405025E-06"
        ixz="4.66471294740668E-06"
        iyy="0.00098141854350441"
        iyz="0.000170373268251156"
        izz="0.00136057315841125" />
    </inertial>
    <visual>
      <origin
        xyz="0 0 0"
        rpy="0 0 0" />
      <geometry>
        <mesh
          filename="meshes/L_hip.STL" />
      </geometry>
      <material
        name="">
        <color
          rgba="0.898039215686275 0.917647058823529 0.929411764705882 1" />
      </material>
    </visual>
    <collision>
      <origin
        xyz="0 0 0"
        rpy="0 0 0" />
      <geometry>
        <mesh
          filename="meshes/L_hip.STL" />
      </geometry>
    </collision>
  </link>
  <joint
    name="L_hip_x"
    type="revolute">
    <origin
      xyz="0 0 0"
      rpy="0 0 0" />
    <parent
      link="L_buttock" />
    <child
      link="L_hip" />
    <axis
      xyz="0 0 1" />
    <limit effort="100" lower="-2.093" upper="0.523" velocity="10" />
        <dynamics damping="0" friction="0" />
  </joint>
  <link
    name="L_thigh">
    <inertial>
      <origin
        xyz="-0.153001423082827 -9.16713591912393E-07 -0.00195251154509679"
        rpy="0 0 0" />
      <mass
        value="0.798828442920691" />
      <inertia
        ixx="0.000930131700251727"
        ixy="6.35059492460908E-08"
        ixz="-5.09593709107672E-05"
        iyy="0.00171269143605417"
        iyz="1.97243744431119E-08"
        izz="0.00226615534608931" />
    </inertial>
    <visual>
      <origin
        xyz="0 0 0"
        rpy="0 0 0" />
      <geometry>
        <mesh
          filename="meshes/L_thigh.STL" />
      </geometry>
      <material
        name="">
        <color
          rgba="0.898039215686275 0.917647058823529 0.929411764705882 1" />
      </material>
    </visual>
    <collision>
      <origin
        xyz="0 0 0"
        rpy="0 0 0" />
      <geometry>
        <mesh
          filename="meshes/L_thigh.STL" />
      </geometry>
    </collision>
  </link>
  <joint
    name="L_hip_z"
    type="revolute">
    <origin
      xyz="0 -0.13525 0"
      rpy="1.5707963267949 0 1.5707963267949" />
    <parent
      link="L_hip" />
    <child
      link="L_thigh" />
    <axis
      xyz="-1 0 0" />
    <limit effort="100" lower="-3.14" upper="3.14" velocity="10" />
        <dynamics damping="0" friction="0" />
  </joint>
  <link
    name="L_calf">
    <inertial>
      <origin
        xyz="0.00209422855516889 0.127651742650085 -0.000719675197477855"
        rpy="0 0 0" />
      <mass
        value="1.01528348517359" />
      <inertia
        ixx="0.00569392008279194"
        ixy="-0.000530849220828081"
        ixz="-9.11056701790541E-07"
        iyy="0.000651162654910767"
        iyz="5.80759947394378E-05"
        izz="0.00538640132090609" />
    </inertial>
    <visual>
      <origin
        xyz="0 0 0"
        rpy="0 0 0" />
      <geometry>
        <mesh
          filename="meshes/L_calf.STL" />
      </geometry>
      <material
        name="">
        <color
          rgba="0.898039215686275 0.917647058823529 0.929411764705882 1" />
      </material>
    </visual>
    <collision>
      <origin
        xyz="0 0 0"
        rpy="0 0 0" />
      <geometry>
        <mesh
          filename="meshes/L_calf.STL" />
      </geometry>
    </collision>
  </link>
  <joint
    name="L_knee"
    type="revolute">
    <origin
      xyz="-0.16475 0 0.00650000000000001"
      rpy="1.5707963267949 1.55579745164248 3.14159265358946" />
    <parent
      link="L_thigh" />
    <child
      link="L_calf" />
    <axis
      xyz="-0.999887518980808 0.0149983127852693 0" />
    <limit effort="250" lower="-1.919" upper="1.919" velocity="10" />
        <dynamics damping="0" friction="0" />
  </joint>
  <link
    name="L_foot">
    <inertial>
      <origin
        xyz="-0.0036888833109778 -0.0203246465635116 -0.0179364027331766"
        rpy="0 0 0" />
      <mass
        value="0.550460500951221" />
      <inertia
        ixx="0.00178454226432877"
        ixy="-2.89108031399026E-05"
        ixz="-2.44610136404159E-06"
        iyy="0.000242083665010665"
        iyz="-1.22384833452327E-05"
        izz="0.00195782985487944" />
    </inertial>
    <visual>
      <origin
        xyz="0 0 0"
        rpy="0 0 0" />
      <geometry>
        <mesh
          filename="meshes/L_foot.STL" />
      </geometry>
      <material
        name="">
        <color
          rgba="0.898039215686275 0.917647058823529 0.929411764705882 1" />
      </material>
    </visual>
    <collision>
      <origin
        xyz="0 0 0"
        rpy="0 0 0" />
      <geometry>
        <mesh
          filename="meshes/L_foot.STL" />
      </geometry>
    </collision>
  </link>
  <joint
    name="L_ankle_y"
    type="revolute">
    <origin
      xyz="0 0.300033748101774 0"
      rpy="1.57079632679433 0 -0.0149988751526712" />
    <parent
      link="L_calf" />
    <child
      link="L_foot" />
    <axis
      xyz="-1 0 0" />
    <limit effort="17" lower="-0.698" upper="0.698" velocity="10" />
        <dynamics damping="0" friction="0.1" />
  </joint>
  <link
    name="R_clav">
    <inertial>
      <origin
        xyz="-0.000143593484141218 -2.52850121296166E-06 0.00204971076662924"
        rpy="0 0 0" />
      <mass
        value="0.556580211071974" />
      <inertia
        ixx="0.000918749480557891"
        ixy="1.19695034926272E-08"
        ixz="-9.80979449697258E-06"
        iyy="0.000590741903833593"
        iyz="8.47391309132212E-08"
        izz="0.000541431489019214" />
    </inertial>
    <visual>
      <origin
        xyz="0 0 0"
        rpy="0 0 0" />
      <geometry>
        <mesh
          filename="meshes/R_clav.STL" />
      </geometry>
      <material
        name="">
        <color
          rgba="0.898039215686275 0.917647058823529 0.929411764705882 1" />
      </material>
    </visual>
    <collision>
      <origin
        xyz="0 0 0"
        rpy="0 0 0" />
      <geometry>
        <mesh
          filename="meshes/R_clav.STL" />
      </geometry>
    </collision>
  </link>
  <joint
    name="R_shoulder_y"
    type="fixed">
    <origin
      xyz="0.000261964373661241 -0.255 0.4500562784516"
      rpy="1.5707963267949 0 3.14159265358979" />
    <parent
      link="base" />
    <child
      link="R_clav" />
    <axis
      xyz="0 0 1" />
  </joint>
  <link
    name="R_scapula">
    <inertial>
      <origin
        xyz="1.90371364772179E-06 -0.0818853539414398 -0.00716785527427103"
        rpy="0 0 0" />
      <mass
        value="0.33855519445856" />
      <inertia
        ixx="0.000403438165666412"
        ixy="2.69892994749061E-08"
        ixz="-1.36522522756737E-08"
        iyy="0.000260428180698103"
        iyz="7.70862704683445E-05"
        izz="0.000388850592995521" />
    </inertial>
    <visual>
      <origin
        xyz="0 0 0"
        rpy="0 0 0" />
      <geometry>
        <mesh
          filename="meshes/R_scapula.STL" />
      </geometry>
      <material
        name="">
        <color
          rgba="0.898039215686275 0.917647058823529 0.929411764705882 1" />
      </material>
    </visual>
    <collision>
      <origin
        xyz="0 0 0"
        rpy="0 0 0" />
      <geometry>
        <mesh
          filename="meshes/R_scapula.STL" />
      </geometry>
    </collision>
  </link>
  <joint
    name="R_shoulder_x"
    type="fixed">
    <origin
      xyz="0 0 0"
      rpy="0 1.5707963267949 0" />
    <parent
      link="R_clav" />
    <child
      link="R_scapula" />
    <axis
      xyz="0 0 -1" />
  </joint>
  <link
    name="R_uarm">
    <inertial>
      <origin
        xyz="-0.10163579177938 0.00377324438002611 -4.03410402066706E-06"
        rpy="0 0 0" />
      <mass
        value="0.277293520071397" />
      <inertia
        ixx="0.000146051204275246"
        ixy="1.1841812309581E-05"
        ixz="-1.28332816180229E-08"
        iyy="0.000404910973903622"
        iyz="-9.16450363895878E-08"
        izz="0.000319519397766819" />
    </inertial>
    <visual>
      <origin
        xyz="0 0 0"
        rpy="0 0 0" />
      <geometry>
        <mesh
          filename="meshes/R_uarm.STL" />
      </geometry>
      <material
        name="">
        <color
          rgba="0.898039215686275 0.917647058823529 0.929411764705882 1" />
      </material>
    </visual>
    <collision>
      <origin
        xyz="0 0 0"
        rpy="0 0 0" />
      <geometry>
        <mesh
          filename="meshes/R_uarm.STL" />
      </geometry>
    </collision>
  </link>
  <joint
    name="R_shoulder_z"
    type="fixed">
    <origin
      xyz="0 -0.114 0.000249999999999991"
      rpy="1.57186970427954 0 1.5707963267949" />
    <parent
      link="R_scapula" />
    <child
      link="R_uarm" />
    <axis
      xyz="-1 0 0" />
  </joint>
  <link
    name="R_farm">
    <inertial>
      <origin
        xyz="-0.000384371888902809 0.126015259322794 3.32331253760643E-06"
        rpy="0 0 0" />
      <mass
        value="0.333434347202916" />
      <inertia
        ixx="0.000593803796844833"
        ixy="8.4183735474947E-05"
        ixz="-9.13261797491675E-10"
        iyy="0.000240487078579545"
        iyz="-6.18128406949413E-08"
        izz="0.000605414769156374" />
    </inertial>
    <visual>
      <origin
        xyz="0 0 0"
        rpy="0 0 0" />
      <geometry>
        <mesh
          filename="meshes/R_farm.STL" />
      </geometry>
      <material
        name="">
        <color
          rgba="0.898039215686275 0.917647058823529 0.929411764705882 1" />
      </material>
    </visual>
    <collision>
      <origin
        xyz="0 0 0"
        rpy="0 0 0" />
      <geometry>
        <mesh
          filename="meshes/R_farm.STL" />
      </geometry>
    </collision>
  </link>
  <joint
    name="R_elbow_x"
    type="fixed">
    <origin
      xyz="-0.1155 0.00349999798375654 0"
      rpy="0 0.0010733774846464 1.5707963267949" />
    <parent
      link="R_uarm" />
    <child
      link="R_farm" />
    <axis
      xyz="-1 0 0" />
  </joint>
  <link
    name="R_finger">
    <inertial>
      <origin
        xyz="-0.102913251983861 -0.00064094341598759 4.97149951063647E-05"
        rpy="0 0 0" />
      <mass
        value="0.869674405890661" />
      <inertia
        ixx="0.00101788297690525"
        ixy="1.9236265071043E-05"
        ixz="3.91779231913425E-07"
        iyy="0.000547835337735813"
        iyz="3.181659665818E-06"
        izz="0.00120085765940685" />
    </inertial>
    <visual>
      <origin
        xyz="0 0 0"
        rpy="0 0 0" />
      <geometry>
        <mesh
          filename="meshes/R_finger.STL" />
      </geometry>
      <material
        name="">
        <color
          rgba="0.898039215686275 0.917647058823529 0.929411764705882 1" />
      </material>
    </visual>
    <collision>
      <origin
        xyz="0 0 0"
        rpy="0 0 0" />
      <geometry>
        <mesh
          filename="meshes/R_finger.STL" />
      </geometry>
    </collision>
  </link>
  <joint
    name="R_hand_x"
    type="fixed">
    <origin
      xyz="-0.00399999999999999 0.164 0"
      rpy="0.00107337749648937 0 -1.5707963267949" />
    <parent
      link="R_farm" />
    <child
      link="R_finger" />
    <axis
      xyz="-1 0 0" />
  </joint>
  <link
    name="L_clav">
    <inertial>
      <origin
        xyz="0.00204974123064106 0.00040552140731295 5.37452160951912E-05"
        rpy="0 0 0" />
      <mass
        value="0.556581229687908" />
      <inertia
        ixx="0.000541432147976552"
        ixy="9.81082673090891E-06"
        ixz="8.47945656984269E-08"
        iyy="0.000918749741828425"
        iyz="-1.16981752586656E-08"
        izz="0.000590741595747391" />
    </inertial>
    <visual>
      <origin
        xyz="0 0 0"
        rpy="0 0 0" />
      <geometry>
        <mesh
          filename="meshes/L_clav.STL" />
      </geometry>
      <material
        name="">
        <color
          rgba="0.898039215686275 0.917647058823529 0.929411764705882 1" />
      </material>
    </visual>
    <collision>
      <origin
        xyz="0 0 0"
        rpy="0 0 0" />
      <geometry>
        <mesh
          filename="meshes/L_clav.STL" />
      </geometry>
    </collision>
  </link>
  <joint
    name="L_shoulder_y"
    type="fixed">
    <origin
      xyz="0 0.255 0.45"
      rpy="0 0 -1.5707963267949" />
    <parent
      link="base" />
    <child
      link="L_clav" />
    <axis
      xyz="-1 0 0" />
  </joint>
  <link
    name="L_scapula">
    <inertial>
      <origin
        xyz="0.00742970428570218 -2.11353168433348E-06 0.0818289301952277"
        rpy="0 0 0" />
      <mass
        value="0.338558086149021" />
      <inertia
        ixx="0.000388852490451829"
        ixy="-2.02973428828894E-08"
        ixz="7.7086298540035E-05"
        iyy="0.000403439318190825"
        iyz="2.7806287227712E-08"
        izz="0.000260429932693617" />
    </inertial>
    <visual>
      <origin
        xyz="0 0 0"
        rpy="0 0 0" />
      <geometry>
        <mesh
          filename="meshes/L_scapula.STL" />
      </geometry>
      <material
        name="">
        <color
          rgba="0.898039215686275 0.917647058823529 0.929411764705882 1" />
      </material>
    </visual>
    <collision>
      <origin
        xyz="0 0 0"
        rpy="0 0 0" />
      <geometry>
        <mesh
          filename="meshes/L_scapula.STL" />
      </geometry>
    </collision>
  </link>
  <joint
    name="L_shoulder_x"
    type="fixed">
    <origin
      xyz="0 0 0"
      rpy="3.14159265358979 0 1.5707963267949" />
    <parent
      link="L_clav" />
    <child
      link="L_scapula" />
    <axis
      xyz="-1 0 0" />
  </joint>
  <link
    name="L_uarm">
    <inertial>
      <origin
        xyz="-0.102135713901053 -0.00377319271402148 -4.05228474770203E-06"
        rpy="0 0 0" />
      <mass
        value="0.277294237289419" />
      <inertia
        ixx="0.000146051525972404"
        ixy="-1.18420163495659E-05"
        ixz="-1.26703333539301E-08"
        iyy="0.000404911466442681"
        iyz="9.16477445157888E-08"
        izz="0.000319519768287632" />
    </inertial>
    <visual>
      <origin
        xyz="0 0 0"
        rpy="0 0 0" />
      <geometry>
        <mesh
          filename="meshes/L_uarm.STL" />
      </geometry>
      <material
        name="">
        <color
          rgba="0.898039215686275 0.917647058823529 0.929411764705882 1" />
      </material>
    </visual>
    <collision>
      <origin
        xyz="0 0 0"
        rpy="0 0 0" />
      <geometry>
        <mesh
          filename="meshes/L_uarm.STL" />
      </geometry>
    </collision>
  </link>
  <joint
    name="L_shoulder_z"
    type="fixed">
    <origin
      xyz="1.19643736612081E-05 0 0.113943721548401"
      rpy="1.56972294932056 1.5707963267949 0" />
    <parent
      link="L_scapula" />
    <child
      link="L_uarm" />
    <axis
      xyz="-1 0 0" />
  </joint>
  <link
    name="L_farm">
    <inertial>
      <origin
        xyz="-0.00346386776846992 0.125742816389133 7.82442342583956E-08"
        rpy="0 0 0" />
      <mass
        value="0.344651145281825" />
      <inertia
        ixx="0.000628119112760929"
        ixy="-8.66949561502983E-05"
        ixz="-5.89280156760109E-10"
        iyy="0.000256184138709623"
        iyz="1.23385046734753E-11"
        izz="0.00064469721165604" />
    </inertial>
    <visual>
      <origin
        xyz="0 0 0"
        rpy="0 0 0" />
      <geometry>
        <mesh
          filename="meshes/L_farm.STL" />
      </geometry>
      <material
        name="">
        <color
          rgba="0.898039215686275 0.917647058823529 0.929411764705882 1" />
      </material>
    </visual>
    <collision>
      <origin
        xyz="0 0 0"
        rpy="0 0 0" />
      <geometry>
        <mesh
          filename="meshes/L_farm.STL" />
      </geometry>
    </collision>
  </link>
  <joint
    name="L_elbow_x"
    type="fixed">
    <origin
      xyz="-0.116 0 0"
      rpy="0 -0.00107337747433267 1.5707963267949" />
    <parent
      link="L_uarm" />
    <child
      link="L_farm" />
    <axis
      xyz="-1 0 0" />
  </joint>
  <link
    name="L_finger">
    <inertial>
      <origin
        xyz="-0.102230529103313 0.000186443259723335 -0.000756093150034419"
        rpy="0 0 0" />
      <mass
        value="0.737286180296128" />
      <inertia
        ixx="0.000960819713709726"
        ixy="4.12416028504993E-07"
        ixz="1.92357889467287E-05"
        iyy="0.00114207922949134"
        iyz="2.37959845568235E-06"
        izz="0.000544892735100743" />
    </inertial>
    <visual>
      <origin
        xyz="0 0 0"
        rpy="0 0 0" />
      <geometry>
        <mesh
          filename="meshes/L_finger.STL" />
      </geometry>
      <material
        name="">
        <color
          rgba="1 1 1 1" />
      </material>
    </visual>
    <collision>
      <origin
        xyz="0 0 0"
        rpy="0 0 0" />
      <geometry>
        <mesh
          filename="meshes/L_finger.STL" />
      </geometry>
    </collision>
  </link>
  <joint
    name="L_hand_x"
    type="fixed">
    <origin
      xyz="0 0.164 0"
      rpy="1.5707963267949 0 -1.5707963267949" />
    <parent
      link="L_farm" />
    <child
      link="L_finger" />
    <axis
      xyz="-1 0 0" />
  </joint>
</robot>
