<robot name="k-bot_sim">
  <joint name="imu_link" type="fixed">
    <origin xyz="0.040000 0 -0.131000" rpy="0 0 0"/>
    <parent link="body1-part"/>
    <child link="imu"/>
  </joint>
  <joint name="left_shoulder_pitch_03" type="revolute">
    <origin xyz="0.000002 -0.191000 0.019999" rpy="1.570000 0 -3.140000"/>
    <parent link="body1-part"/>
    <child link="shoulder"/>
    <limit effort="60" velocity="6.283" lower="0" upper="3.141593"/>
    <axis xyz="0 0 1"/>
  </joint>
  <joint name="right_shoulder_pitch_03" type="revolute">
    <origin xyz="-0.000002 0.191000 0.019999" rpy="-1.570000 0 -3.140000"/>
    <parent link="body1-part"/>
    <child link="shoulder_2"/>
    <limit effort="60" velocity="6.283" lower="-3.141593" upper="0"/>
    <axis xyz="0 0 1"/>
  </joint>
  <joint name="left_shoulder_roll_03" type="revolute">
    <origin xyz="0.023512 0.000056 -0.067500" rpy="1.570796 0 1.570796"/>
    <parent link="shoulder"/>
    <child link="arm1_top"/>
    <limit effort="60" velocity="6.283" lower="-3.630285" upper="0.479966"/>
    <axis xyz="0 0 -1"/>
  </joint>
  <joint name="right_shoulder_roll_03" type="revolute">
    <origin xyz="0.023512 -0.000056 -0.067500" rpy="1.570796 0 -1.570796"/>
    <parent link="shoulder_2"/>
    <child link="arm1_top_2"/>
    <limit effort="60" velocity="6.283" lower="-0.479966" upper="3.630285"/>
    <axis xyz="0 0 1"/>
  </joint>
  <joint name="left_hip_pitch_04" type="revolute">
    <origin xyz="-0.000002 -0.091000 -0.430001" rpy="1.570000 0 3.140000"/>
    <parent link="body1-part"/>
    <child link="leg0_shell"/>
    <limit effort="120" velocity="6.283" lower="-1.570796" upper="1.570796"/>
    <axis xyz="0 0 1"/>
  </joint>
  <joint name="right_hip_pitch_04" type="revolute">
    <origin xyz="0.000002 0.091000 -0.430001" rpy="-1.570000 0 3.140000"/>
    <parent link="body1-part"/>
    <child link="leg0_shell_2"/>
    <limit effort="120" velocity="6.283" lower="-1.570796" upper="1.570796"/>
    <axis xyz="0 0 1"/>
  </joint>
  <joint name="left_shoulder_yaw_02" type="revolute">
    <origin xyz="-0.140500 0 -0.023500" rpy="-1.570796 0 -1.570796"/>
    <parent link="arm1_top"/>
    <child link="arm2_shell"/>
    <limit effort="17" velocity="12.566" lower="-1.570796" upper="1.570796"/>
    <axis xyz="0 0 1"/>
  </joint>
  <joint name="right_shoulder_yaw_02" type="revolute">
    <origin xyz="-0.140500 0 0.022500" rpy="-3.141593 1.570796 0"/>
    <parent link="arm1_top_2"/>
    <child link="arm2_shell_2"/>
    <limit effort="17" velocity="12.566" lower="-1.570796" upper="1.570796"/>
    <axis xyz="0 0 -1"/>
  </joint>
  <joint name="left_hip_roll_03" type="revolute">
    <origin xyz="0.027500 0 -0.069500" rpy="-1.570796 0 1.570796"/>
    <parent link="leg0_shell"/>
    <child link="leg1_shell"/>
    <limit effort="60" velocity="6.283" lower="-3.185226" upper="0.349066"/>
    <axis xyz="0 0 1"/>
  </joint>
  <joint name="right_hip_roll_03" type="revolute">
    <origin xyz="0.027500 0 -0.069000" rpy="1.570796 0 -1.570796"/>
    <parent link="leg0_shell_2"/>
    <child link="leg1_shell3"/>
    <limit effort="60" velocity="6.283" lower="-0.349066" upper="3.185226"/>
    <axis xyz="0 0 1"/>
  </joint>
  <joint name="left_elbow_02" type="revolute">
    <origin xyz="-0.027000 0 -0.098000" rpy="-3.141593 -1.570796 0"/>
    <parent link="arm2_shell"/>
    <child link="arm3_shell"/>
    <limit effort="17" velocity="12.566" lower="-2.530727" upper="0"/>
    <axis xyz="0 0 1"/>
  </joint>
  <joint name="right_elbow_02" type="revolute">
    <origin xyz="0 -0.027000 0.097500" rpy="-1.570796 1.570796 0"/>
    <parent link="arm2_shell_2"/>
    <child link="arm3_shell2"/>
    <limit effort="17" velocity="12.566" lower="0" upper="2.530727"/>
    <axis xyz="0 0 1"/>
  </joint>
  <joint name="left_hip_yaw_03" type="revolute">
    <origin xyz="-0.157500 0.000120 0.027500" rpy="0 1.570796 0"/>
    <parent link="leg1_shell"/>
    <child link="leg2_shell"/>
    <limit effort="60" velocity="6.283" lower="-1.570796" upper="1.570796"/>
    <axis xyz="0 0 1"/>
  </joint>
  <joint name="right_hip_yaw_03" type="revolute">
    <origin xyz="-0.157500 -0.000120 0.027500" rpy="-3.141593 -1.570796 0"/>
    <parent link="leg1_shell3"/>
    <child link="leg2_shell_2"/>
    <limit effort="60" velocity="6.283" lower="-1.570796" upper="1.570796"/>
    <axis xyz="0 0 1"/>
  </joint>
  <joint name="left_wrist_02" type="revolute">
    <origin xyz="-0.182500 0 0.021500" rpy="-1.570796 0 -1.570796"/>
    <parent link="arm3_shell"/>
    <child link="hand_shell"/>
    <limit effort="17" velocity="12.566" lower="-3.141593" upper="3.141593"/>
    <axis xyz="0 0 1"/>
  </joint>
  <joint name="right_wrist_02" type="revolute">
    <origin xyz="-0.182500 0 0.021500" rpy="1.570796 0 1.570796"/>
    <parent link="arm3_shell2"/>
    <child link="hand_shell_2"/>
    <limit effort="17" velocity="12.566" lower="-3.141593" upper="3.141593"/>
    <axis xyz="0 0 1"/>
  </joint>
  <joint name="left_knee_04" type="revolute">
    <origin xyz="0 -0.027000 -0.142500" rpy="1.570796 0 0"/>
    <parent link="leg2_shell"/>
    <child link="leg3_shell1"/>
    <limit effort="120" velocity="6.283" lower="0" upper="2.094395"/>
    <axis xyz="0 0 -1"/>
  </joint>
  <joint name="right_knee_04" type="revolute">
    <origin xyz="0 -0.027000 -0.142500" rpy="1.570796 0 0"/>
    <parent link="leg2_shell_2"/>
    <child link="leg3_shell11"/>
    <limit effort="120" velocity="6.283" lower="-2.094395" upper="0"/>
    <axis xyz="0 0 -1"/>
  </joint>
  <joint name="right_ankle_02" type="revolute">
    <origin xyz="0 -0.300000 -0.035500" rpy="3.141593 0 3.141593"/>
    <parent link="leg3_shell11"/>
    <child link="foot3"/>
    <limit effort="17" velocity="12.566" lower="-0.698132" upper="0.698132"/>
    <axis xyz="0 0 1.0"/>
  </joint>
  <joint name="left_ankle_02" type="revolute">
    <origin xyz="0 -0.300000 0.009500" rpy="0 0 0"/>
    <parent link="leg3_shell1"/>
    <child link="foot1"/>
    <limit effort="17" velocity="12.566" lower="-0.698132" upper="0.698132"/>
    <axis xyz="0 0 -1"/>
  </joint>
  <link name="body1-part">
    <visual name="body1-part_visual">
      <origin xyz="0 0 0" rpy="1.570000 0 0"/>
      <geometry name="body1-part_geometry">
        <mesh filename="meshes/body1-part.stl"/>
      </geometry>
      <material name="body1-part_material">
        <color rgba="1 1 1 1"/>
      </material>
    </visual>
    <collision name="body1-part.collision">
      <origin xyz="0 0 0" rpy="1.570000 0 0"/>
      <geometry name="body1-part_collision_geometry">
        <mesh filename="meshes/body1-part.collision.stl"/>
      </geometry>
    </collision>
    <inertial name="body1-part_inertial">
      <mass value="9.415838"/>
      <inertia ixx="0.406102" iyy="0.096732" izz="0.321504" ixy="0.001018" ixz="0.000014" iyz="-0.000180"/>
      <origin xyz="-0.000153 -0.214129 -0.000094" rpy="1.570000 0 0"/>
    </inertial>
  </link>
  <link name="imu">
    <visual name="imu_visual">
      <origin xyz="0 0 0" rpy="0 0 0"/>
      <geometry name="imu_geometry">
        <mesh filename="meshes/imu.stl"/>
      </geometry>
      <material name="imu_material">
        <color rgba="0.615686 0.811765 0.929412 1"/>
      </material>
    </visual>
    <inertial name="imu_inertial">
      <mass value="0.010000"/>
      <inertia ixx="0.000001" iyy="0.000001" izz="0.000002" ixy="0" ixz="0" iyz="0"/>
      <origin xyz="-0.007500 0 0.006000" rpy="0 0 0"/>
    </inertial>
  </link>
  <link name="shoulder">
    <visual name="shoulder_visual">
      <origin xyz="0 0 0" rpy="0 0 0"/>
      <geometry name="shoulder_geometry">
        <mesh filename="meshes/shoulder.stl"/>
      </geometry>
      <material name="shoulder_material">
        <color rgba="1 1 1 1"/>
      </material>
    </visual>
    <collision name="shoulder.collision">
      <origin xyz="0 0 0" rpy="0 0 0"/>
      <geometry name="shoulder_collision_geometry">
        <mesh filename="meshes/shoulder.collision.stl"/>
      </geometry>
    </collision>
    <inertial name="shoulder_inertial">
      <mass value="1.107356"/>
      <inertia ixx="0.001481" iyy="0.001039" izz="0.000986" ixy="0" ixz="-0.000003" iyz="0"/>
      <origin xyz="-0.002144 0.000055 -0.066483" rpy="0 0 0"/>
    </inertial>
  </link>
  <link name="shoulder_2">
    <visual name="shoulder_visual_2">
      <origin xyz="0 0 0" rpy="0 0 0"/>
      <geometry name="shoulder_geometry_2">
        <mesh filename="meshes/shoulder_2.stl"/>
      </geometry>
      <material name="shoulder_material_2">
        <color rgba="1 1 1 1"/>
      </material>
    </visual>
    <collision name="shoulder.collision_2">
      <origin xyz="0 0 0" rpy="0 0 0"/>
      <geometry name="shoulder_collision_geometry_2">
        <mesh filename="meshes/shoulder_2.collision.stl"/>
      </geometry>
    </collision>
    <inertial name="shoulder_inertial_2">
      <mass value="1.107354"/>
      <inertia ixx="0.001481" iyy="0.001039" izz="0.000986" ixy="0" ixz="-0.000003" iyz="0"/>
      <origin xyz="-0.002144 -0.000055 -0.066483" rpy="0 0 0"/>
    </inertial>
  </link>
  <link name="arm1_top">
    <visual name="arm1_top_visual">
      <origin xyz="0 0 0" rpy="0 0 0"/>
      <geometry name="arm1_top_geometry">
        <mesh filename="meshes/arm1_top.stl"/>
      </geometry>
      <material name="arm1_top_material">
        <color rgba="0.898039 0.917647 0.929412 1"/>
      </material>
    </visual>
    <inertial name="arm1_top_inertial">
      <mass value="0.572732"/>
      <inertia ixx="0.000453" iyy="0.001076" izz="0.001035" ixy="0" ixz="-0.000195" iyz="0"/>
      <origin xyz="-0.099486 -0.000001 -0.019082" rpy="0 0 0"/>
    </inertial>
  </link>
  <link name="arm1_top_2">
    <visual name="arm1_top_2_visual">
      <origin xyz="0 0 0" rpy="0 0 0"/>
      <geometry name="arm1_top_2_geometry">
        <mesh filename="meshes/arm1_top_2.stl"/>
      </geometry>
      <material name="arm1_top_2_material">
        <color rgba="0.898039 0.917647 0.929412 1"/>
      </material>
    </visual>
    <inertial name="arm1_top_2_inertial">
      <mass value="0.572732"/>
      <inertia ixx="0.000453" iyy="0.001076" izz="0.001035" ixy="0" ixz="0.000195" iyz="0"/>
      <origin xyz="-0.099486 -0.000001 0.018082" rpy="0 0 0"/>
    </inertial>
  </link>
  <link name="leg0_shell">
    <visual name="leg0_shell_visual">
      <origin xyz="0 0 0" rpy="0 0 0"/>
      <geometry name="leg0_shell_geometry">
        <mesh filename="meshes/leg0_shell.stl"/>
      </geometry>
      <material name="leg0_shell_material">
        <color rgba="0.898039 0.917647 0.929412 1"/>
      </material>
    </visual>
    <collision name="leg0_shell.collision">
      <origin xyz="0 0 0" rpy="0 0 0"/>
      <geometry name="leg0_shell_collision_geometry">
        <mesh filename="meshes/leg0_shell.collision.stl"/>
      </geometry>
    </collision>
    <inertial name="leg0_shell_inertial">
      <mass value="1.323448"/>
      <inertia ixx="0.001886" iyy="0.001425" izz="0.001300" ixy="0" ixz="0.000007" iyz="0"/>
      <origin xyz="-0.003746 0 -0.068125" rpy="0 0 0"/>
    </inertial>
  </link>
  <link name="leg0_shell_2">
    <visual name="leg0_shell_visual_2">
      <origin xyz="0 0 0" rpy="0 0 0"/>
      <geometry name="leg0_shell_geometry_2">
        <mesh filename="meshes/leg0_shell_2.stl"/>
      </geometry>
      <material name="leg0_shell_material_2">
        <color rgba="0.898039 0.917647 0.929412 1"/>
      </material>
    </visual>
    <collision name="leg0_shell.collision_2">
      <origin xyz="0 0 0" rpy="0 0 0"/>
      <geometry name="leg0_shell_collision_geometry_2">
        <mesh filename="meshes/leg0_shell_2.collision.stl"/>
      </geometry>
    </collision>
    <inertial name="leg0_shell_inertial_2">
      <mass value="1.323448"/>
      <inertia ixx="0.001886" iyy="0.001425" izz="0.001300" ixy="0" ixz="0.000007" iyz="0"/>
      <origin xyz="-0.003746 0 -0.067625" rpy="0 0 0"/>
    </inertial>
  </link>
  <link name="arm2_shell">
    <visual name="arm2_shell_visual">
      <origin xyz="0 0 0" rpy="0 0 0"/>
      <geometry name="arm2_shell_geometry">
        <mesh filename="meshes/arm2_shell.stl"/>
      </geometry>
      <material name="arm2_shell_material">
        <color rgba="0.898039 0.917647 0.929412 1"/>
      </material>
    </visual>
    <collision name="arm2_shell.collision">
      <origin xyz="0 0 0" rpy="0 0 0"/>
      <geometry name="arm2_shell_collision_geometry">
        <mesh filename="meshes/arm2_shell.collision.stl"/>
      </geometry>
    </collision>
    <inertial name="arm2_shell_inertial">
      <mass value="0.510678"/>
      <inertia ixx="0.000675" iyy="0.000532" izz="0.000255" ixy="0" ixz="-0.000006" iyz="0"/>
      <origin xyz="-0.006339 0 -0.090482" rpy="0 0 0"/>
    </inertial>
  </link>
  <link name="arm2_shell_2">
    <visual name="arm2_shell_visual_2">
      <origin xyz="0 0 0" rpy="0 0 0"/>
      <geometry name="arm2_shell_geometry_2">
        <mesh filename="meshes/arm2_shell_2.stl"/>
      </geometry>
      <material name="arm2_shell_material_2">
        <color rgba="0.898039 0.917647 0.929412 1"/>
      </material>
    </visual>
    <collision name="arm2_shell.collision_2">
      <origin xyz="0 0 0" rpy="0 0 0"/>
      <geometry name="arm2_shell_collision_geometry_2">
        <mesh filename="meshes/arm2_shell_2.collision.stl"/>
      </geometry>
    </collision>
    <inertial name="arm2_shell_inertial_2">
      <mass value="0.510678"/>
      <inertia ixx="0.000532" iyy="0.000675" izz="0.000255" ixy="0" ixz="0" iyz="0.000006"/>
      <origin xyz="0 -0.006339 0.089982" rpy="0 0 0"/>
    </inertial>
  </link>
  <link name="leg1_shell">
    <visual name="leg1_shell_visual">
      <origin xyz="0 0 0" rpy="0 0 0"/>
      <geometry name="leg1_shell_geometry">
        <mesh filename="meshes/leg1_shell.stl"/>
      </geometry>
      <material name="leg1_shell_material">
        <color rgba="0.898039 0.917647 0.929412 1"/>
      </material>
    </visual>
    <inertial name="leg1_shell_inertial">
      <mass value="1.264352"/>
      <inertia ixx="0.001481" iyy="0.002486" izz="0.002413" ixy="-0.000018" ixz="0.000290" iyz="-0.000002"/>
      <origin xyz="-0.112524 0.000529 0.025259" rpy="0 0 0"/>
    </inertial>
  </link>
  <link name="leg1_shell3">
    <visual name="leg1_shell3_visual">
      <origin xyz="0 0 0" rpy="0 0 0"/>
      <geometry name="leg1_shell3_geometry">
        <mesh filename="meshes/leg1_shell3.stl"/>
      </geometry>
      <material name="leg1_shell3_material">
        <color rgba="0.898039 0.917647 0.929412 1"/>
      </material>
    </visual>
    <inertial name="leg1_shell3_inertial">
      <mass value="1.264352"/>
      <inertia ixx="0.001481" iyy="0.002486" izz="0.002413" ixy="0.000018" ixz="0.000290" iyz="0.000002"/>
      <origin xyz="-0.112524 -0.000529 0.025259" rpy="0 0 0"/>
    </inertial>
  </link>
  <link name="arm3_shell">
    <visual name="arm3_shell_visual">
      <origin xyz="0 0 0" rpy="0 0 0"/>
      <geometry name="arm3_shell_geometry">
        <mesh filename="meshes/arm3_shell.stl"/>
      </geometry>
      <material name="arm3_shell_material">
        <color rgba="0.898039 0.917647 0.929412 1"/>
      </material>
    </visual>
    <inertial name="arm3_shell_inertial">
      <mass value="0.578536"/>
      <inertia ixx="0.000428" iyy="0.001354" izz="0.001332" ixy="0" ixz="0.000144" iyz="0"/>
      <origin xyz="-0.140169 0 0.019433" rpy="0 0 0"/>
    </inertial>
  </link>
  <link name="arm3_shell2">
    <visual name="arm3_shell2_visual">
      <origin xyz="0 0 0" rpy="0 0 0"/>
      <geometry name="arm3_shell2_geometry">
        <mesh filename="meshes/arm3_shell2.stl"/>
      </geometry>
      <material name="arm3_shell2_material">
        <color rgba="0.898039 0.917647 0.929412 1"/>
      </material>
    </visual>
    <inertial name="arm3_shell2_inertial">
      <mass value="0.578536"/>
      <inertia ixx="0.000428" iyy="0.001354" izz="0.001332" ixy="0" ixz="0.000144" iyz="0"/>
      <origin xyz="-0.140169 0 0.019433" rpy="0 0 0"/>
    </inertial>
  </link>
  <link name="leg2_shell">
    <visual name="leg2_shell_visual">
      <origin xyz="0 0 0" rpy="0 0 0"/>
      <geometry name="leg2_shell_geometry">
        <mesh filename="meshes/leg2_shell.stl"/>
      </geometry>
      <material name="leg2_shell_material">
        <color rgba="0.898039 0.917647 0.929412 1"/>
      </material>
    </visual>
    <inertial name="leg2_shell_inertial">
      <mass value="1.820923"/>
      <inertia ixx="0.003118" iyy="0.004225" izz="0.002064" ixy="0" ixz="0" iyz="-0.000034"/>
      <origin xyz="0 0.000532 -0.137308" rpy="0 0 0"/>
    </inertial>
  </link>
  <link name="leg2_shell_2">
    <visual name="leg2_shell_visual_2">
      <origin xyz="0 0 0" rpy="0 0 0"/>
      <geometry name="leg2_shell_geometry_2">
        <mesh filename="meshes/leg2_shell_2.stl"/>
      </geometry>
      <material name="leg2_shell_material_2">
        <color rgba="0.898039 0.917647 0.929412 1"/>
      </material>
    </visual>
    <inertial name="leg2_shell_inertial_2">
      <mass value="1.820923"/>
      <inertia ixx="0.003118" iyy="0.004225" izz="0.002064" ixy="0" ixz="0" iyz="-0.000034"/>
      <origin xyz="0 0.000532 -0.137308" rpy="0 0 0"/>
    </inertial>
  </link>
  <link name="hand_shell">
    <visual name="hand_shell_visual">
      <origin xyz="0 0 0" rpy="0 0 0"/>
      <geometry name="hand_shell_geometry">
        <mesh filename="meshes/hand_shell.stl"/>
      </geometry>
      <material name="hand_shell_material">
        <color rgba="0.898039 0.917647 0.929412 1"/>
      </material>
    </visual>
    <collision name="hand_shell.collision">
      <origin xyz="0 0 0" rpy="0 0 0"/>
      <geometry name="hand_shell_collision_geometry">
        <mesh filename="meshes/hand_shell.collision.stl"/>
      </geometry>
    </collision>
    <inertial name="hand_shell_inertial">
      <mass value="0.793063"/>
      <inertia ixx="0.002034" iyy="0.002869" izz="0.001280" ixy="0" ixz="-0.000023" iyz="0.000004"/>
      <origin xyz="0.000709 0.000130 -0.074657" rpy="0 0 0"/>
    </inertial>
  </link>
  <link name="hand_shell_2">
    <visual name="hand_shell_visual_2">
      <origin xyz="0 0 0" rpy="0 0 0"/>
      <geometry name="hand_shell_geometry_2">
        <mesh filename="meshes/hand_shell_2.stl"/>
      </geometry>
      <material name="hand_shell_material_2">
        <color rgba="0.898039 0.917647 0.929412 1"/>
      </material>
    </visual>
    <collision name="hand_shell.collision_2">
      <origin xyz="0 0 0" rpy="0 0 0"/>
      <geometry name="hand_shell_collision_geometry_2">
        <mesh filename="meshes/hand_shell_2.collision.stl"/>
      </geometry>
    </collision>
    <inertial name="hand_shell_inertial_2">
      <mass value="0.793063"/>
      <inertia ixx="0.002034" iyy="0.002869" izz="0.001280" ixy="0" ixz="-0.000023" iyz="0.000004"/>
      <origin xyz="0.000709 0.000130 -0.074657" rpy="0 0 0"/>
    </inertial>
  </link>
  <link name="leg3_shell1">
    <visual name="leg3_shell1_visual">
      <origin xyz="0 0 0" rpy="0 0 0"/>
      <geometry name="leg3_shell1_geometry">
        <mesh filename="meshes/leg3_shell1.stl"/>
      </geometry>
      <material name="leg3_shell1_material">
        <color rgba="0.898039 0.917647 0.929412 1"/>
      </material>
    </visual>
    <collision name="leg3_shell1.collision">
      <origin xyz="0 0 0" rpy="0 0 0"/>
      <geometry name="leg3_shell1_collision_geometry">
        <mesh filename="meshes/leg3_shell1.collision.stl"/>
      </geometry>
    </collision>
    <inertial name="leg3_shell1_inertial">
      <mass value="1.109955"/>
      <inertia ixx="0.006740" iyy="0.001013" izz="0.006746" ixy="0.000062" ixz="-0.000017" iyz="0.000013"/>
      <origin xyz="0.001098 -0.131322 -0.023162" rpy="0 0 0"/>
    </inertial>
  </link>
  <link name="leg3_shell11">
    <visual name="leg3_shell11_visual">
      <origin xyz="0 0 0" rpy="0 0 0"/>
      <geometry name="leg3_shell11_geometry">
        <mesh filename="meshes/leg3_shell11.stl"/>
      </geometry>
      <material name="leg3_shell11_material">
        <color rgba="0.898039 0.917647 0.929412 1"/>
      </material>
    </visual>
    <collision name="leg3_shell11.collision">
      <origin xyz="0 0 0" rpy="0 0 0"/>
      <geometry name="leg3_shell11_collision_geometry">
        <mesh filename="meshes/leg3_shell11.collision.stl"/>
      </geometry>
    </collision>
    <inertial name="leg3_shell11_inertial">
      <mass value="1.109962"/>
      <inertia ixx="0.006740" iyy="0.001013" izz="0.006746" ixy="-0.000062" ixz="0.000017" iyz="0.000013"/>
      <origin xyz="-0.001098 -0.131322 -0.023162" rpy="0 0 0"/>
    </inertial>
  </link>
  <link name="foot3">
    <visual name="foot3_visual">
      <origin xyz="0 0 0" rpy="0 0 0"/>
      <geometry name="foot3_geometry">
        <mesh filename="meshes/foot3.stl"/>
      </geometry>
      <material name="foot3_material">
        <color rgba="0.898039 0.917647 0.929412 1"/>
      </material>
    </visual>
    <collision name="foot3.collision">
      <origin xyz="0 0 0" rpy="0 0 0"/>
      <geometry name="foot3_collision_geometry">
        <mesh filename="meshes/foot3.collision.stl"/>
      </geometry>
    </collision>
    <inertial name="foot3_inertial">
      <mass value="0.582091"/>
      <inertia ixx="0.000284" iyy="0.002188" izz="0.002024" ixy="0.000040" ixz="0.000033" iyz="-0.000004"/>
      <origin xyz="0.021350 -0.019419 -0.023724" rpy="0 0 0"/>
    </inertial>
  </link>
  <link name="foot1">
    <visual name="foot1_visual">
      <origin xyz="0 0 0" rpy="0 0 0"/>
      <geometry name="foot1_geometry">
        <mesh filename="meshes/foot1.stl"/>
      </geometry>
      <material name="foot1_material">
        <color rgba="0.898039 0.917647 0.929412 1"/>
      </material>
    </visual>
    <collision name="foot1.collision">
      <origin xyz="0 0 0" rpy="0 0 0"/>
      <geometry name="foot1_collision_geometry">
        <mesh filename="meshes/foot1.collision.stl"/>
      </geometry>
    </collision>
    <inertial name="foot1_inertial">
      <mass value="0.582091"/>
      <inertia ixx="0.000284" iyy="0.002188" izz="0.002024" ixy="0.000040" ixz="-0.000033" iyz="0.000004"/>
      <origin xyz="0.021350 -0.019419 -0.019276" rpy="0 0 0"/>
    </inertial>
  </link>
</robot>
