<robot name="kbot">
  <link name="base">
    <inertial>
      <origin rpy="0 0 0" xyz="0 0 0"/>
      <mass value="0.001"/>
      <inertia ixx="1e-06" ixy="0" ixz="0" iyy="1e-06" iyz="0" izz="1e-06"/>
    </inertial>
  </link>
<joint name="floating_base" type="fixed">
    <origin rpy="-1.57 3.14 0" xyz="0 0 0" />
    <parent link="base" />
    <child link="body1-part" />
  </joint>
  <link name="body1-part">
    <visual name="body1-part_visual">
      <origin xyz="0 0 0" rpy="0 0 0"/>
      <geometry name="body1-part_geometry">
        <mesh filename="meshes/body1-part.stl"/>
      </geometry>
      <material name="body1-part_material">
        <color rgba="1 1 1 1"/>
      </material>
    </visual>
    <collision name="body1-part_collision">
      <origin xyz="0 0 0" rpy="0 0 0"/>
      <geometry name="body1-part_collision_geometry">
        <mesh filename="meshes/body1-part.stl"/>
      </geometry>
    </collision>
    <inertial name="body1-part_inertial">
      <mass value="9.415837554000001"/>
      <inertia ixx="0.40610156546882353" iyy="0.09673200062926605" izz="0.3215044394247909" ixy="-0.001017932971477293" ixz="1.4138167186401825e-05" iyz="0.00018025410223227248"/>
      <origin xyz="-0.006984352029976769 0.05467015743419366 0.0004881578569769504" rpy="0 0 0"/>
    </inertial>
  </link>
  <joint name="imu_link" type="fixed" dont_collapse="true">
    <origin xyz="-0.047126255760769356 0.14188879185640826 0.0003937090896153101" rpy="1.5707963999999994 0.0 3.1415926071795863"/>
    <parent link="body1-part"/>
    <child link="imu"/>
  </joint>
  <link name="imu">
    <visual name="imu_visual">
      <origin xyz="0 0 0" rpy="0 0 0"/>
      <geometry name="imu_geometry">
        <mesh filename="meshes/imu.stl"/>
      </geometry>
      <material name="imu_material">
        <color rgba="0.61568627 0.81176471 0.92941176 1"/>
      </material>
    </visual>
    <collision name="imu_collision">
      <origin xyz="0 0 0" rpy="0 0 0"/>
      <geometry name="imu_collision_geometry">
        <mesh filename="meshes/imu.stl"/>
      </geometry>
    </collision>
    <inertial name="imu_inertial">
      <mass value="0.01"/>
      <inertia ixx="1.1408333e-06" iyy="1.1408333e-06" izz="2.0416667e-06" ixy="0" ixz="0" iyz="0"/>
      <origin xyz="-0.0075 0 0.006" rpy="0 0 0"/>
    </inertial>
  </link>
  <joint name="left_hip_pitch_04" type="revolute">
    <origin xyz="-0.0071262559999999975 -0.16321120617636828 -0.08730629129474379" rpy="1.0000000028043132e-07 0.0 0.0"/>
    <parent link="body1-part"/>
    <child link="leg0_shell"/>
    <limit effort="120" velocity="6.283" lower="-1.5707963" upper="1.5707963"/>
    <axis xyz="0 0 1"/>
  </joint>
  <link name="leg0_shell">
    <visual name="leg0_shell_visual">
      <origin xyz="0 0 0" rpy="0 0 0"/>
      <geometry name="leg0_shell_geometry">
        <mesh filename="meshes/leg0_shell.stl"/>
      </geometry>
      <material name="leg0_shell_material">
        <color rgba="0.89803922 0.91764706 0.92941176 1"/>
      </material>
    </visual>
    <collision name="leg0_shell_collision">
      <origin xyz="0 0 0" rpy="0 0 0"/>
      <geometry name="leg0_shell_collision_geometry">
        <mesh filename="meshes/leg0_shell.stl"/>
      </geometry>
    </collision>
    <inertial name="leg0_shell_inertial">
      <mass value="1.3234480570000002"/>
      <inertia ixx="0.0018858182013085161" iyy="0.001424832171389183" izz="0.0012997049050806671" ixy="-4.528695728174104e-12" ixz="7.006193648128378e-06" iyz="-9.656589772176694e-13"/>
      <origin xyz="-0.003746324486178213 -5.30704079226868e-10 -0.06812512159159122" rpy="0 0 0"/>
    </inertial>
  </link>
  <joint name="right_hip_pitch_04" type="revolute">
    <origin xyz="-0.0071262559999999975 -0.16321121297959254 0.08859370870525608" rpy="-3.141592599999999 0.0 0.0"/>
    <parent link="body1-part"/>
    <child link="leg0_shell_2"/>
    <limit effort="120" velocity="6.283" lower="-1.5707963" upper="1.5707963"/>
    <axis xyz="0 0 1"/>
  </joint>
  <link name="leg0_shell_2">
    <visual name="leg0_shell_visual_2">
      <origin xyz="0 0 0" rpy="0 0 0"/>
      <geometry name="leg0_shell_geometry_2">
        <mesh filename="meshes/leg0_shell_2.stl"/>
      </geometry>
      <material name="leg0_shell_material_2">
        <color rgba="0.89803922 0.91764706 0.92941176 1"/>
      </material>
    </visual>
    <collision name="leg0_shell_collision_2">
      <origin xyz="0 0 0" rpy="0 0 0"/>
      <geometry name="leg0_shell_collision_geometry_2">
        <mesh filename="meshes/leg0_shell_2.stl"/>
      </geometry>
    </collision>
    <inertial name="leg0_shell_inertial_2">
      <mass value="1.3234480570000002"/>
      <inertia ixx="0.0018858182013085161" iyy="0.001424832171389183" izz="0.0012997049050806671" ixy="-4.528695728174104e-12" ixz="7.006193648128378e-06" iyz="-9.656589772176694e-13"/>
      <origin xyz="-0.003746324486178213 -5.30704079226868e-10 -0.06762512159159122" rpy="0 0 0"/>
    </inertial>
  </link>
  <joint name="left_shoulder_pitch_03" type="fixed">
    <origin xyz="-0.0071262490312895945 0.2868887861013424 -0.1871062947956447" rpy="-2.220446049250311e-16 0.0 1.9915984595047395e-16"/>
    <parent link="body1-part"/>
    <child link="shoulder"/>
    <limit effort="60" velocity="6.283" lower="0" upper="3.1415927"/>
    <axis xyz="0 0 1"/>
  </joint>
  <link name="shoulder">
    <visual name="shoulder_visual">
      <origin xyz="0 0 0" rpy="0 0 0"/>
      <geometry name="shoulder_geometry">
        <mesh filename="meshes/shoulder.stl"/>
      </geometry>
      <material name="shoulder_material">
        <color rgba="1 1 1 1"/>
      </material>
    </visual>
    <collision name="shoulder_collision">
      <origin xyz="0 0 0" rpy="0 0 0"/>
      <geometry name="shoulder_collision_geometry">
        <mesh filename="meshes/shoulder.stl"/>
      </geometry>
    </collision>
    <inertial name="shoulder_inertial">
      <mass value="1.10769407"/>
      <inertia ixx="0.0014821199757753395" iyy="0.001040851235294" izz="0.0009860091656447962" ixy="1.624746856405567e-08" ixz="-3.127980791901951e-06" iyz="6.45482418632759e-09"/>
      <origin xyz="-0.002143291631555541 5.49830379711586e-05 -0.06646243607358847" rpy="0 0 0"/>
    </inertial>
  </link>
  <joint name="right_shoulder_pitch_03" type="fixed">
    <origin xyz="-0.007126249031289128 0.28688879614942864 0.18789370520435525" rpy="3.1415925999999996 -2.4424906541753444e-15 -9.282041357749904e-08"/>
    <parent link="body1-part"/>
    <child link="shoulder_2"/>
    <limit effort="60" velocity="6.283" lower="-3.1415927" upper="0"/>
    <axis xyz="0 0 1"/>
  </joint>
  <link name="shoulder_2">
    <visual name="shoulder_visual_2">
      <origin xyz="0 0 0" rpy="0 0 0"/>
      <geometry name="shoulder_geometry_2">
        <mesh filename="meshes/shoulder_2.stl"/>
      </geometry>
      <material name="shoulder_material_2">
        <color rgba="1 1 1 1"/>
      </material>
    </visual>
    <collision name="shoulder_collision_2">
      <origin xyz="0 0 0" rpy="0 0 0"/>
      <geometry name="shoulder_collision_geometry_2">
        <mesh filename="meshes/shoulder_2.stl"/>
      </geometry>
    </collision>
    <inertial name="shoulder_inertial_2">
      <mass value="1.10769287"/>
      <inertia ixx="0.0014821176689157926" iyy="0.0010408501146374899" izz="0.0009860087317400208" ixy="-1.619311060167335e-08" ixz="-3.127966468857877e-06" iyz="-6.433007602964532e-09"/>
      <origin xyz="-0.0021432871527224747 -5.498738075250827e-05 -0.0664624713194008" rpy="0 0 0"/>
    </inertial>
  </link>
  <joint name="left_hip_roll_03" type="revolute">
    <origin xyz="0.02649999999999997 -1.5165911463888016e-09 -0.06950000151659115" rpy="-1.5707963 0.0 1.5707963"/>
    <parent link="leg0_shell"/>
    <child link="leg1_shell"/>
    <limit effort="60" velocity="6.283" lower="-3.1852259" upper="0.34906585"/>
    <axis xyz="0 0 1"/>
  </joint>
  <link name="leg1_shell">
    <visual name="leg1_shell_visual">
      <origin xyz="0 0 0" rpy="0 0 0"/>
      <geometry name="leg1_shell_geometry">
        <mesh filename="meshes/leg1_shell.stl"/>
      </geometry>
      <material name="leg1_shell_material">
        <color rgba="0.89803922 0.91764706 0.92941176 1"/>
      </material>
    </visual>
    <collision name="leg1_shell_collision">
      <origin xyz="0 0 0" rpy="0 0 0"/>
      <geometry name="leg1_shell_collision_geometry">
        <mesh filename="meshes/leg1_shell.stl"/>
      </geometry>
    </collision>
    <inertial name="leg1_shell_inertial">
      <mass value="1.360769512"/>
      <inertia ixx="0.0016616954886228494" iyy="0.002821853448229639" izz="0.0028458063036535123" ixy="0.0001758148701161061" ixz="0.0003020245997305346" iyz="-9.512452832907178e-06"/>
      <origin xyz="-0.11647102759639934 0.0032311720350168987 0.025411038661602842" rpy="0 0 0"/>
    </inertial>
  </link>
  <joint name="right_hip_roll_03" type="revolute">
    <origin xyz="0.02649999999999997 -1.5165911463888016e-09 -0.06900000151659115" rpy="1.5707963 -4.641020634466031e-08 -1.5707963535897922"/>
    <parent link="leg0_shell_2"/>
    <child link="leg1_shell3"/>
    <limit effort="60" velocity="6.283" lower="-0.34906585" upper="3.1852259"/>
    <axis xyz="0 0 1"/>
  </joint>
  <link name="leg1_shell3">
    <visual name="leg1_shell3_visual">
      <origin xyz="0 0 0" rpy="0 0 0"/>
      <geometry name="leg1_shell3_geometry">
        <mesh filename="meshes/leg1_shell3.stl"/>
      </geometry>
      <material name="leg1_shell3_material">
        <color rgba="0.89803922 0.91764706 0.92941176 1"/>
      </material>
    </visual>
    <collision name="leg1_shell3_collision">
      <origin xyz="0 0 0" rpy="0 0 0"/>
      <geometry name="leg1_shell3_collision_geometry">
        <mesh filename="meshes/leg1_shell3.stl"/>
      </geometry>
    </collision>
    <inertial name="leg1_shell3_inertial">
      <mass value="1.360769362"/>
      <inertia ixx="0.0016616952587461729" iyy="0.0027972595171853708" izz="0.002821212254479024" ixy="-0.0001672703462506645" ixz="0.00030152306354767384" iyz="9.512542262690967e-06"/>
      <origin xyz="-0.11629451715520467 -0.0032311805394316345 0.02541103395361007" rpy="0 0 0"/>
    </inertial>
  </link>
  <joint name="left_shoulder_roll_03" type="fixed">
    <origin xyz="0.022511964 5.627838501275855e-05 -0.06749999993301277" rpy="1.5707963 0.0 1.5707963"/>
    <parent link="shoulder"/>
    <child link="arm1_top"/>
    <limit effort="60" velocity="6.283" lower="-0.47996554" upper="3.6302848"/>
    <axis xyz="0 0 1"/>
  </joint>
  <link name="arm1_top">
    <visual name="arm1_top_visual">
      <origin xyz="0 0 0" rpy="0 0 0"/>
      <geometry name="arm1_top_geometry">
        <mesh filename="meshes/arm1_top.stl"/>
      </geometry>
      <material name="arm1_top_material">
        <color rgba="0.89803922 0.91764706 0.92941176 1"/>
      </material>
    </visual>
    <collision name="arm1_top_collision">
      <origin xyz="0 0 0" rpy="0 0 0"/>
      <geometry name="arm1_top_collision_geometry">
        <mesh filename="meshes/arm1_top.stl"/>
      </geometry>
    </collision>
    <inertial name="arm1_top_inertial">
      <mass value="0.6485195170000001"/>
      <inertia ixx="0.0005534340544495192" iyy="0.0012949315041653874" izz="0.0012122867763442189" ixy="2.7431748015214958e-09" ixz="-0.00029349734411603833" iyz="-1.2020658865463657e-08"/>
      <origin xyz="-0.1049167323389295 -2.224482447295856e-06 -0.02270232245867197" rpy="0 0 0"/>
    </inertial>
  </link>
  <joint name="right_shoulder_roll_03" type="fixed">
    <origin xyz="0.022511964 -5.627838501275855e-05 -0.06749999993301277" rpy="1.5707963999999996 -2.220446049250313e-16 -1.5707963000000003"/>
    <parent link="shoulder_2"/>
    <child link="arm1_top_2"/>
    <limit effort="60" velocity="6.283" lower="-0.47996554" upper="3.6302848"/>
    <axis xyz="0 0 1"/>
  </joint>
  <link name="arm1_top_2">
    <visual name="arm1_top_2_visual">
      <origin xyz="0 0 0" rpy="0 0 0"/>
      <geometry name="arm1_top_2_geometry">
        <mesh filename="meshes/arm1_top_2.stl"/>
      </geometry>
      <material name="arm1_top_2_material">
        <color rgba="0.89803922 0.91764706 0.92941176 1"/>
      </material>
    </visual>
    <collision name="arm1_top_2_collision">
      <origin xyz="0 0 0" rpy="0 0 0"/>
      <geometry name="arm1_top_2_collision_geometry">
        <mesh filename="meshes/arm1_top_2.stl"/>
      </geometry>
    </collision>
    <inertial name="arm1_top_2_inertial">
      <mass value="0.648518913"/>
      <inertia ixx="0.0005534337229653212" iyy="0.0012949301697574233" izz="0.0012122856241893294" ixy="3.9483970889106803e-10" ixz="0.0002934980412719184" iyz="1.2665017999276955e-08"/>
      <origin xyz="-0.10491675895909988 -2.1578500229648204e-06 0.021702291176927773" rpy="0 0 0"/>
    </inertial>
  </link>
  <joint name="left_hip_yaw_03" type="revolute">
    <origin xyz="-0.15649999999999997 0.00011981393 0.027499998483408852" rpy="-0.0 1.5707963 0.0"/>
    <parent link="leg1_shell"/>
    <child link="leg2_shell"/>
    <limit effort="60" velocity="6.283" lower="-1.5707963" upper="1.5707963"/>
    <axis xyz="0 0 1"/>
  </joint>
  <link name="leg2_shell">
    <visual name="leg2_shell_visual">
      <origin xyz="0 0 0" rpy="0 0 0"/>
      <geometry name="leg2_shell_geometry">
        <mesh filename="meshes/leg2_shell.stl"/>
      </geometry>
      <material name="leg2_shell_material">
        <color rgba="0.89803922 0.91764706 0.92941176 1"/>
      </material>
    </visual>
    <collision name="leg2_shell_collision">
      <origin xyz="0 0 0" rpy="0 0 0"/>
      <geometry name="leg2_shell_collision_geometry">
        <mesh filename="meshes/leg2_shell.stl"/>
      </geometry>
    </collision>
    <inertial name="leg2_shell_inertial">
      <mass value="1.820922667"/>
      <inertia ixx="0.003118121982315594" iyy="0.004225341330146898" izz="0.0020643672406963944" ixy="-6.676045962463134e-09" ixz="-2.2416298133304992e-08" iyz="-3.3507405748121275e-05"/>
      <origin xyz="4.0855477721508534e-07 0.0005316844118462806 -0.13730778343676694" rpy="0 0 0"/>
    </inertial>
  </link>
  <joint name="right_hip_yaw_03" type="revolute">
    <origin xyz="-0.15649999999999997 -0.00011981393 0.027499998483408852" rpy="-3.1415926535897922 -1.5707962732050302 0.0"/>
    <parent link="leg1_shell3"/>
    <child link="leg2_shell_2"/>
    <limit effort="60" velocity="6.283" lower="-1.5707963" upper="1.5707963"/>
    <axis xyz="0 0 1"/>
  </joint>
  <link name="leg2_shell_2">
    <visual name="leg2_shell_visual_2">
      <origin xyz="0 0 0" rpy="0 0 0"/>
      <geometry name="leg2_shell_geometry_2">
        <mesh filename="meshes/leg2_shell_2.stl"/>
      </geometry>
      <material name="leg2_shell_material_2">
        <color rgba="0.89803922 0.91764706 0.92941176 1"/>
      </material>
    </visual>
    <collision name="leg2_shell_collision_2">
      <origin xyz="0 0 0" rpy="0 0 0"/>
      <geometry name="leg2_shell_collision_geometry_2">
        <mesh filename="meshes/leg2_shell_2.stl"/>
      </geometry>
    </collision>
    <inertial name="leg2_shell_inertial_2">
      <mass value="1.820922667"/>
      <inertia ixx="0.003118121982315594" iyy="0.004225341330146898" izz="0.0020643672406963944" ixy="-6.676045962463134e-09" ixz="-2.2416298133304992e-08" iyz="-3.3507405748121275e-05"/>
      <origin xyz="4.0855477721508534e-07 0.0005316844118462806 -0.13730778343676694" rpy="0 0 0"/>
    </inertial>
  </link>
  <joint name="left_shoulder_yaw_02" type="fixed">
    <origin xyz="-0.13949999999999996 -1.4619215099879723e-09 -0.02349999915596076" rpy="-4.641020604450649e-08 1.5707962732050293 0.0"/>
    <parent link="arm1_top"/>
    <child link="arm2_shell"/>
    <limit effort="17" velocity="12.566" lower="-1.5707963" upper="1.5707963"/>
    <axis xyz="0 0 1"/>
  </joint>
  <link name="arm2_shell">
    <visual name="arm2_shell_visual">
      <origin xyz="0 0 0" rpy="0 0 0"/>
      <geometry name="arm2_shell_geometry">
        <mesh filename="meshes/arm2_shell.stl"/>
      </geometry>
      <material name="arm2_shell_material">
        <color rgba="0.89803922 0.91764706 0.92941176 1"/>
      </material>
    </visual>
    <collision name="arm2_shell_collision">
      <origin xyz="0 0 0" rpy="0 0 0"/>
      <geometry name="arm2_shell_collision_geometry">
        <mesh filename="meshes/arm2_shell.stl"/>
      </geometry>
    </collision>
    <inertial name="arm2_shell_inertial">
      <mass value="0.51101595"/>
      <inertia ixx="0.0006782501033956834" iyy="0.0005353980560191654" izz="0.000254883921623482" ixy="0.0" ixz="-6.066717667565765e-06" iyz="0.0"/>
      <origin xyz="-0.0063350323524262436 0.0 -0.09042107492219607" rpy="0 0 0"/>
    </inertial>
  </link>
  <joint name="right_shoulder_yaw_02" type="fixed">
    <origin xyz="-0.13949999999999999 0.0 0.022499999155960758" rpy="-3.1415926071795863 1.5707963 0.0"/>
    <parent link="arm1_top_2"/>
    <child link="arm2_shell_2"/>
    <limit effort="17" velocity="12.566" lower="-1.5707963" upper="1.5707963"/>
    <axis xyz="0 0 1"/>
  </joint>
  <link name="arm2_shell_2">
    <visual name="arm2_shell_visual_2">
      <origin xyz="0 0 0" rpy="0 0 0"/>
      <geometry name="arm2_shell_geometry_2">
        <mesh filename="meshes/arm2_shell_2.stl"/>
      </geometry>
      <material name="arm2_shell_material_2">
        <color rgba="0.89803922 0.91764706 0.92941176 1"/>
      </material>
    </visual>
    <collision name="arm2_shell_collision_2">
      <origin xyz="0 0 0" rpy="0 0 0"/>
      <geometry name="arm2_shell_collision_geometry_2">
        <mesh filename="meshes/arm2_shell_2.stl"/>
      </geometry>
    </collision>
    <inertial name="arm2_shell_inertial_2">
      <mass value="0.51101595"/>
      <inertia ixx="0.0006782500996314132" iyy="0.0005353980522548952" izz="0.000254883921623482" ixy="0.0" ixz="-6.066712483597219e-06" iyz="0.0"/>
      <origin xyz="0.0063350323524262436 0.0 0.08992107443622689" rpy="0 0 0"/>
    </inertial>
  </link>
  <joint name="left_knee_04" type="revolute">
    <origin xyz="0.0 0.0342 -0.14250000009378214" rpy="1.5707963000000003 0.0 0.0"/>
    <parent link="leg2_shell"/>
    <child link="leg3_shell2"/>
    <limit effort="120" velocity="6.283" lower="-2.0943951" upper="0"/>
    <axis xyz="0 0 1"/>
  </joint>
  <link name="leg3_shell2">
    <visual name="leg3_shell2_visual">
      <origin xyz="0 0 0" rpy="0 0 0"/>
      <geometry name="leg3_shell2_geometry">
        <mesh filename="meshes/leg3_shell2.stl"/>
      </geometry>
      <material name="leg3_shell2_material">
        <color rgba="0.89803922 0.91764706 0.92941176 1"/>
      </material>
    </visual>
    <collision name="leg3_shell2_collision">
      <origin xyz="0 0 0" rpy="0 0 0"/>
      <geometry name="leg3_shell2_collision_geometry">
        <mesh filename="meshes/leg3_shell2.stl"/>
      </geometry>
    </collision>
    <inertial name="leg3_shell2_inertial">
      <mass value="1.179677561"/>
      <inertia ixx="0.0075280219401663686" iyy="0.0011236273981275156" izz="0.007505076656997992" ixy="6.871058258502185e-05" ixz="-1.92682149888721e-05" iyz="0.00022981113471710275"/>
      <origin xyz="0.0010329853873719736 -0.1254795525920513 0.03667110282750395" rpy="0 0 0"/>
    </inertial>
  </link>
  <joint name="right_knee_04" type="revolute">
    <origin xyz="0.0 0.0342 -0.14250000009378214" rpy="1.5707963000000003 0.0 0.0"/>
    <parent link="leg2_shell_2"/>
    <child link="leg3_shell22"/>
    <limit effort="120" velocity="6.283" lower="0" upper="2.0943951"/>
    <axis xyz="0 0 1"/>
  </joint>
  <link name="leg3_shell22">
    <visual name="leg3_shell22_visual">
      <origin xyz="0 0 0" rpy="0 0 0"/>
      <geometry name="leg3_shell22_geometry">
        <mesh filename="meshes/leg3_shell22.stl"/>
      </geometry>
      <material name="leg3_shell22_material">
        <color rgba="0.89803922 0.91764706 0.92941176 1"/>
      </material>
    </visual>
    <collision name="leg3_shell22_collision">
      <origin xyz="0 0 0" rpy="0 0 0"/>
      <geometry name="leg3_shell22_collision_geometry">
        <mesh filename="meshes/leg3_shell22.stl"/>
      </geometry>
    </collision>
    <inertial name="leg3_shell22_inertial">
      <mass value="1.179683991"/>
      <inertia ixx="0.007528039668357469" iyy="0.0011236329917092309" izz="0.007505094295682783" ixy="-6.871642858641452e-05" ixz="1.92691896999385e-05" iyz="0.0002298128355131914"/>
      <origin xyz="-0.0010330286803835712 -0.12547979367732118 0.036671195513248635" rpy="0 0 0"/>
    </inertial>
  </link>
  <joint name="left_elbow_02" type="fixed">
    <origin xyz="-0.026000000000000002 0.0 -0.09799999977224338" rpy="-3.1415926071795863 -1.5707963 0.0"/>
    <parent link="arm2_shell"/>
    <child link="arm3_shell"/>
    <limit effort="17" velocity="12.566" lower="-2.5307274" upper="0"/>
    <axis xyz="0 0 1"/>
  </joint>
  <link name="arm3_shell">
    <visual name="arm3_shell_visual">
      <origin xyz="0 0 0" rpy="0 0 0"/>
      <geometry name="arm3_shell_geometry">
        <mesh filename="meshes/arm3_shell.stl"/>
      </geometry>
      <material name="arm3_shell_material">
        <color rgba="0.89803922 0.91764706 0.92941176 1"/>
      </material>
    </visual>
    <collision name="arm3_shell_collision">
      <origin xyz="0 0 0" rpy="0 0 0"/>
      <geometry name="arm3_shell_collision_geometry">
        <mesh filename="meshes/arm3_shell.stl"/>
      </geometry>
    </collision>
    <inertial name="arm3_shell_inertial">
      <mass value="0.57887479"/>
      <inertia ixx="0.00042824885963562435" iyy="0.0013607750713956906" izz="0.001338486101760066" ixy="-4.3783991313169864e-14" ixz="0.0001451523224848915" iyz="4.4680616691403507e-13"/>
      <origin xyz="-0.14008673576280925 -3.715266367753274e-10 0.019422482836149137" rpy="0 0 0"/>
    </inertial>
  </link>
  <joint name="right_elbow_02" type="fixed">
    <origin xyz="0.026000000000000002 0.0 0.09750000022775662" rpy="-3.1415926071795863 1.5707963 0.0"/>
    <parent link="arm2_shell_2"/>
    <child link="arm3_shell2"/>
    <limit effort="17" velocity="12.566" lower="0" upper="2.5307274"/>
    <axis xyz="0 0 1"/>
  </joint>
  <link name="arm3_shell2">
    <visual name="arm3_shell2_visual">
      <origin xyz="0 0 0" rpy="0 0 0"/>
      <geometry name="arm3_shell2_geometry">
        <mesh filename="meshes/arm3_shell2.stl"/>
      </geometry>
      <material name="arm3_shell2_material">
        <color rgba="0.89803922 0.91764706 0.92941176 1"/>
      </material>
    </visual>
    <collision name="arm3_shell2_collision">
      <origin xyz="0 0 0" rpy="0 0 0"/>
      <geometry name="arm3_shell2_collision_geometry">
        <mesh filename="meshes/arm3_shell2.stl"/>
      </geometry>
    </collision>
    <inertial name="arm3_shell2_inertial">
      <mass value="0.57887479"/>
      <inertia ixx="0.00042824885963562435" iyy="0.0013607750713956906" izz="0.001338486101760066" ixy="-4.3783991313169864e-14" ixz="0.0001451523224848915" iyz="4.4680616691403507e-13"/>
      <origin xyz="-0.14008673576280925 -3.715266367753274e-10 0.019422482836149137" rpy="0 0 0"/>
    </inertial>
  </link>
  <joint name="right_ankle_02" type="revolute">
    <origin xyz="1.0767167917674625e-08 -0.2999999986541038 0.027200000000000002" rpy="-3.1415926071795868 2.220446049250313e-16 -3.1415926071795868"/>
    <parent link="leg3_shell22"/>
    <child link="foot3"/>
    <limit effort="17" velocity="12.566" lower="-0.6981317" upper="0.6981317"/>
    <axis xyz="0 0 1"/>
  </joint>
  <link name="foot3">
    <visual name="foot3_visual">
      <origin xyz="0 0 0" rpy="0 0 0"/>
      <geometry name="foot3_geometry">
        <mesh filename="meshes/foot3.stl"/>
      </geometry>
      <material name="foot3_material">
        <color rgba="0.89803922 0.91764706 0.92941176 1"/>
      </material>
    </visual>
    <collision name="foot3_collision">
      <origin xyz="0 0 0" rpy="0 0 0"/>
      <geometry name="foot3_collision_geometry">
        <mesh filename="meshes/foot3.stl"/>
      </geometry>
    </collision>
    <inertial name="foot3_inertial">
      <mass value="0.58209108"/>
      <inertia ixx="0.0002838753748975717" iyy="0.00218822676565083" izz="0.002023734835894537" ixy="3.9780111288661e-05" ixz="3.349573310652279e-05" iyz="-3.862324128656251e-06"/>
      <origin xyz="0.02134992304317914 -0.019418963220724724 -0.023723771995791686" rpy="0 0 0"/>
    </inertial>
  </link>
  <joint name="left_wrist_02" type="fixed">
    <origin xyz="-0.18149999999999997 -1.4619215099879723e-09 0.02150000084403924" rpy="-4.641020604450649e-08 1.5707962732050293 0.0"/>
    <parent link="arm3_shell"/>
    <child link="hand_shell"/>
    <limit effort="17" velocity="12.566" lower="0" upper="6.2831853"/>
    <axis xyz="0 0 1"/>
  </joint>
  <link name="hand_shell">
    <visual name="hand_shell_visual">
      <origin xyz="0 0 0" rpy="0 0 0"/>
      <geometry name="hand_shell_geometry">
        <mesh filename="meshes/hand_shell.stl"/>
      </geometry>
      <material name="hand_shell_material">
        <color rgba="0.89803922 0.91764706 0.92941176 1"/>
      </material>
    </visual>
    <collision name="hand_shell_collision">
      <origin xyz="0 0 0" rpy="0 0 0"/>
      <geometry name="hand_shell_collision_geometry">
        <mesh filename="meshes/hand_shell.stl"/>
      </geometry>
    </collision>
    <inertial name="hand_shell_inertial">
      <mass value="0.7933517460000001"/>
      <inertia ixx="0.002035289036126633" iyy="0.002871100617981697" izz="0.001279636245454222" ixy="-5.17436396981902e-07" ixz="-2.321711817641572e-05" iyz="3.5513831423904115e-06"/>
      <origin xyz="0.0007087169571505621 0.0001297102192049248 -0.07462970584649938" rpy="0 0 0"/>
    </inertial>
  </link>
  <joint name="right_wrist_02" type="fixed">
    <origin xyz="-0.18149999999999997 -1.4619215099879723e-09 0.02150000084403924" rpy="-4.641020604450649e-08 1.5707962732050293 0.0"/>
    <parent link="arm3_shell2"/>
    <child link="hand_shell_2"/>
    <limit effort="17" velocity="12.566" lower="0" upper="6.2831853"/>
    <axis xyz="0 0 1"/>
  </joint>
  <link name="hand_shell_2">
    <visual name="hand_shell_visual_2">
      <origin xyz="0 0 0" rpy="0 0 0"/>
      <geometry name="hand_shell_geometry_2">
        <mesh filename="meshes/hand_shell_2.stl"/>
      </geometry>
      <material name="hand_shell_material_2">
        <color rgba="0.89803922 0.91764706 0.92941176 1"/>
      </material>
    </visual>
    <collision name="hand_shell_collision_2">
      <origin xyz="0 0 0" rpy="0 0 0"/>
      <geometry name="hand_shell_collision_geometry_2">
        <mesh filename="meshes/hand_shell_2.stl"/>
      </geometry>
    </collision>
    <inertial name="hand_shell_inertial_2">
      <mass value="0.7933517460000001"/>
      <inertia ixx="0.002035289036126633" iyy="0.002871100617981697" izz="0.001279636245454222" ixy="-5.17436396981902e-07" ixz="-2.321711817641572e-05" iyz="3.5513831423904115e-06"/>
      <origin xyz="0.0007087169571505621 0.0001297102192049248 -0.07462970584649938" rpy="0 0 0"/>
    </inertial>
  </link>
  <joint name="left_ankle_02" type="revolute">
    <origin xyz="0.0 -0.30000000004641003 0.07019999118206069" rpy="9.282041357749903e-08 0.0 0.0"/>
    <parent link="leg3_shell2"/>
    <child link="foot1"/>
    <limit effort="17" velocity="12.566" lower="-0.6981317" upper="0.6981317"/>
    <axis xyz="0 0 1"/>
  </joint>
  <link name="foot1">
    <visual name="foot1_visual">
      <origin xyz="0 0 0" rpy="0 0 0"/>
      <geometry name="foot1_geometry">
        <mesh filename="meshes/foot1.stl"/>
      </geometry>
      <material name="foot1_material">
        <color rgba="0.89803922 0.91764706 0.92941176 1"/>
      </material>
    </visual>
    <collision name="foot1_collision">
      <origin xyz="0 0 0" rpy="0 0 0"/>
      <geometry name="foot1_collision_geometry">
        <mesh filename="meshes/foot1.stl"/>
      </geometry>
    </collision>
    <inertial name="foot1_inertial">
      <mass value="0.58209124"/>
      <inertia ixx="0.0002838753702978436" iyy="0.002188226940492543" izz="0.0020237350419067264" ixy="3.9780235731382326e-05" ixz="-3.349583633130496e-05" iyz="3.862347414317424e-06"/>
      <origin xyz="0.02134990704811795 -0.019418958531554592 -0.019276222305656024" rpy="0 0 0"/>
    </inertial>
  </link>
</robot>
