<mujoco model="gpr">
  <option iterations="50" timestep="0.001" solver="PGS" gravity="0 0 -9.81" />

  <compiler angle="radian" meshdir="meshes" eulerseq="zyx" autolimits="true" />

  <default>
    <joint limited="true" damping="0.01" armature="0.01" frictionloss="0.01" />
    <geom condim="4" contype="1" conaffinity="15" friction="0.9 0.2 0.2" solref="0.001 2" />
    <motor ctrllimited="true" />
    <equality solref="0.001 2" />
    <default class="visualgeom">
      <geom material="visualgeom" condim="1" contype="0" conaffinity="0" />
    </default>
  </default>

  <asset>
    <mesh name="body1-part" file="body1-part.stl" />
    <mesh name="shoulder" file="shoulder.stl" />
    <mesh name="shoulder_2" file="shoulder_2.stl" />
    <mesh name="arm1_top" file="arm1_top.stl" />
    <mesh name="arm1_top_2" file="arm1_top_2.stl" />
    <mesh name="leg0_shell" file="leg0_shell.stl" />
    <mesh name="leg0_shell_2" file="leg0_shell_2.stl" />
    <mesh name="arm2_shell" file="arm2_shell.stl" />
    <mesh name="arm2_shell_2" file="arm2_shell_2.stl" />
    <mesh name="leg1_shell" file="leg1_shell.stl" />
    <mesh name="leg1_shell3" file="leg1_shell3.stl" />
    <mesh name="arm3_shell" file="arm3_shell.stl" />
    <mesh name="arm3_shell2" file="arm3_shell2.stl" />
    <mesh name="leg2_shell" file="leg2_shell.stl" />
    <mesh name="leg2_shell_2" file="leg2_shell_2.stl" />
    <mesh name="hand_shell" file="hand_shell.stl" />
    <mesh name="hand_shell_2" file="hand_shell_2.stl" />
    <mesh name="leg3_shell2" file="leg3_shell2.stl" />
    <mesh name="leg3_shell22" file="leg3_shell22.stl" />
    <mesh name="foot3" file="foot3.stl" />
    <mesh name="foot1" file="foot1.stl" />
    <texture name="texplane" type="2d" builtin="checker" rgb1=".0 .0 .0" rgb2=".8 .8 .8" width="100" height="100" />
    <material name="matplane" reflectance="0." texture="texplane" texrepeat="1 1" texuniform="true" />
    <material name="visualgeom" rgba="0.5 0.9 0.2 1" />
  </asset>

  <worldbody>
    <light directional="true" diffuse="0.4 0.4 0.4" specular="0.1 0.1 0.1" pos="0 0 5.0" dir="0 0 -1" castshadow="false" />
    <light directional="true" diffuse="0.6 0.6 0.6" specular="0.2 0.2 0.2" pos="0 0 4" dir="0 0 -1" />
    <geom name="ground" type="plane" pos="0 0 0" size="100 100 0.001" quat="1 0 0 0" material="matplane" condim="3" conaffinity="15" />
    <camera name="fixed" pos="0 -3.0 0.901051" xyaxes="1 0 0 0 0 1" />
    <camera name="track" mode="trackcom" pos="0 -3.0 0.901051" xyaxes="1 0 0 0 0 1" />
    <body name="root" pos="0 0 0.411051" quat="1 0 0 0">
      <freejoint name="root" />
      <site name="imu" size="0.01" rgba="1 0 0 1" pos="0.03 0 0" />
      <geom pos="0 0 0" quat="0.000563312 -0.000562864 0.707388 0.706825" type="mesh" rgba="1 1 1 1" mesh="body1-part" contype="1" conaffinity="0" density="0" group="1" class="visualgeom" />
      <geom type="mesh" rgba="1 1 1 1" mesh="body1-part" pos="0 0 0" quat="0.000563312 -0.000562864 0.707388 0.706825" />
      <geom pos="-1.79688e-05 0.187514 0.0179402" quat="-0.707388 -0.706825 0.000563329 -0.00056288" type="mesh" rgba="1 1 1 1" mesh="shoulder" contype="1" conaffinity="0" density="0" group="1" class="visualgeom" />
      <geom type="mesh" rgba="1 1 1 1" mesh="shoulder" pos="-1.79688e-05 0.187514 0.0179402" quat="-0.707388 -0.706825 0.000563329 -0.00056288" />
      <geom pos="0.022494 0.255014 0.0179786" quat="-0.000281794 -0.706543 -0.000281327 -0.70767" type="mesh" rgba="0.898039 0.917647 0.929412 1" mesh="arm1_top" contype="1" conaffinity="0" density="0" group="1" class="visualgeom" />
      <geom type="mesh" rgba="0.898039 0.917647 0.929412 1" mesh="arm1_top" pos="0.022494 0.255014 0.0179786" quat="-0.000281794 -0.706543 -0.000281327 -0.70767" />
      <geom pos="-0.000783829 0.254903 -0.121559" quat="-3.30472e-07 0.00079631 -0.000398163 -1" type="mesh" rgba="0.898039 0.917647 0.929412 1" mesh="arm2_shell" contype="1" conaffinity="0" density="0" group="1" class="visualgeom" />
      <geom type="mesh" rgba="0.898039 0.917647 0.929412 1" mesh="arm2_shell" pos="-0.000783829 0.254903 -0.121559" quat="-3.30472e-07 0.00079631 -0.000398163 -1" />
      <geom pos="0.0253722 0.254825 -0.219517" quat="-0.706543 0.000281761 0.70767 -0.000281327" type="mesh" rgba="0.898039 0.917647 0.929412 1" mesh="arm3_shell" contype="1" conaffinity="0" density="0" group="1" class="visualgeom" />
      <geom type="mesh" rgba="0.898039 0.917647 0.929412 1" mesh="arm3_shell" pos="0.0253722 0.254825 -0.219517" quat="-0.706543 0.000281761 0.70767 -0.000281327" />
      <geom pos="0.00416131 0.254681 -0.401051" quat="-1 0.000398186 0.00079635 3.0727e-07" type="mesh" rgba="0.898039 0.917647 0.929412 1" mesh="hand_shell" contype="1" conaffinity="0" density="0" group="1" class="visualgeom" />
      <geom type="mesh" rgba="0.898039 0.917647 0.929412 1" mesh="hand_shell" pos="0.00416131 0.254681 -0.401051" quat="-1 0.000398186 0.00079635 3.0727e-07" />
      <geom pos="-1.84444e-05 -0.187486 0.0182389" quat="0.706825 -0.707388 -0.000562847 -0.000563296" type="mesh" rgba="1 1 1 1" mesh="shoulder_2" contype="1" conaffinity="0" density="0" group="1" class="visualgeom" />
      <geom type="mesh" rgba="1 1 1 1" mesh="shoulder_2" pos="-1.84444e-05 -0.187486 0.0182389" quat="0.706825 -0.707388 -0.000562847 -0.000563296" />
      <geom pos="0.0224933 -0.254986 0.0183847" quat="0.706543 -0.000281742 -0.70767 0.000281346" type="mesh" rgba="0.898039 0.917647 0.929412 1" mesh="arm1_top_2" contype="1" conaffinity="0" density="0" group="1" class="visualgeom" />
      <geom type="mesh" rgba="0.898039 0.917647 0.929412 1" mesh="arm1_top_2" pos="0.0224933 -0.254986 0.0183847" quat="0.706543 -0.000281742 -0.70767 0.000281346" />
      <geom pos="0.00021551 -0.255097 -0.121151" quat="-0.00039814 -1 2.80456e-07 -0.000796303" type="mesh" rgba="0.898039 0.917647 0.929412 1" mesh="arm2_shell_2" contype="1" conaffinity="0" density="0" group="1" class="visualgeom" />
      <geom type="mesh" rgba="0.898039 0.917647 0.929412 1" mesh="arm2_shell_2" pos="0.00021551 -0.255097 -0.121151" quat="-0.00039814 -1 2.80456e-07 -0.000796303" />
      <geom pos="0.0263708 -0.255174 -0.218609" quat="-0.706543 0.000281709 0.70767 -0.000281346" type="mesh" rgba="0.898039 0.917647 0.929412 1" mesh="arm3_shell2" contype="1" conaffinity="0" density="0" group="1" class="visualgeom" />
      <geom type="mesh" rgba="0.898039 0.917647 0.929412 1" mesh="arm3_shell2" pos="0.0263708 -0.255174 -0.218609" quat="-0.706543 0.000281709 0.70767 -0.000281346" />
      <geom pos="0.00515984 -0.255319 -0.400143" quat="-1 0.000398163 0.000796317 2.57264e-07" type="mesh" rgba="0.898039 0.917647 0.929412 1" mesh="hand_shell_2" contype="1" conaffinity="0" density="0" group="1" class="visualgeom" />
      <geom type="mesh" rgba="0.898039 0.917647 0.929412 1" mesh="hand_shell_2" pos="0.00515984 -0.255319 -0.400143" quat="-1 0.000398163 0.000796317 2.57264e-07" />
      <geom size="0.05 0.05 0.05" pos="0.03 0 -0.08" type="box" rgba="1 0 0 1" contype="1" conaffinity="0" density="0" group="1" class="visualgeom" />
      <geom type="box" rgba="1 0 0 1" size="0.05 0.05 0.05" pos="0.03 0 -0.08" />
      <body name="leg0_shell" pos="0.000698762 0.087356 -0.43208" quat="-0.707388 -0.706825 0.000563329 -0.000562847">
        <inertial pos="-0.00374632 -5.30704e-10 -0.0681251" quat="0.999982 0 -0.00597565 0" mass="1.32345" diaginertia="0.0018859 0.00142483 0.00129962" />
        <joint name="L_hip_y" pos="0 0 0" axis="0 0 1" range="-1.5708 1.5708" actuatorfrcrange="-100 100" />
        <geom type="mesh" rgba="0.898039 0.917647 0.929412 1" mesh="leg0_shell" contype="1" conaffinity="0" density="0" group="1" class="visualgeom" />
        <geom type="mesh" rgba="0.898039 0.917647 0.929412 1" mesh="leg0_shell" />
        <body name="leg1_shell" pos="0.0265 -1.51659e-09 -0.0695" quat="0.5 -0.5 -0.5 0.5">
          <inertial pos="-0.116471 0.00323117 0.025411" quat="0.162954 0.777613 0.0974626 0.599387" mass="1.36077" diaginertia="0.00293018 0.00283394 0.00156523" />
          <joint name="L_hip_x" pos="0 0 0" axis="0 0 1" range="-0.349066 3.18523" actuatorfrcrange="-40 40" />
          <geom type="mesh" rgba="0.898039 0.917647 0.929412 1" mesh="leg1_shell" contype="1" conaffinity="0" density="0" group="1" class="visualgeom" />
          <geom type="mesh" rgba="0.898039 0.917647 0.929412 1" mesh="leg1_shell" />
          <body name="leg2_shell" pos="-0.1565 0.000119814 0.0275" quat="0.707107 0 0.707107 0">
            <inertial pos="4.08555e-07 0.000531684 -0.137308" quat="0.707084 -0.00547271 0.00548785 0.707088" mass="1.82092" diaginertia="0.00422586 0.00311812 0.00206385" />
            <joint name="L_hip_z" pos="0 0 0" axis="0 0 1" range="-1.5708 1.5708" actuatorfrcrange="-40 40" />
            <geom type="mesh" rgba="0.898039 0.917647 0.929412 1" mesh="leg2_shell" contype="1" conaffinity="0" density="0" group="1" class="visualgeom" />
            <geom type="mesh" rgba="0.898039 0.917647 0.929412 1" mesh="leg2_shell" />
            <body name="leg3_shell2" pos="0 0.0342 -0.1425" quat="0.707107 0.707107 0 0">
              <inertial pos="0.00103299 -0.12548 0.0366711" quat="0.691727 0.665165 0.198925 -0.19874" mass="1.17968" diaginertia="0.00753953 0.00750258 0.00111461" />
              <joint name="L_knee" pos="0 0 0" axis="0 0 1" range="-1.57 0" actuatorfrcrange="-100 100" />
              <geom type="mesh" rgba="0.898039 0.917647 0.929412 1" mesh="leg3_shell2" contype="1" conaffinity="0" density="0" group="1" class="visualgeom" />
              <geom type="mesh" rgba="0.898039 0.917647 0.929412 1" mesh="leg3_shell2" />
              <body name="foot1" pos="0 -0.3 0.0702" quat="1 4.64102e-08 0 0">
                <inertial pos="0.0210264 -0.018472 -0.0193043" quat="0.505269 0.504957 0.48518 0.504304" mass="0.545747" diaginertia="0.00202977 0.00187214 0.000259286" />
                <joint name="L_ankle" pos="0 0 0" axis="0 0 -1" range="-0.698132 0.698132" actuatorfrcrange="-80 80" frictionloss="0.1" />
                <geom type="mesh" rgba="0.898039 0.917647 0.929412 1" mesh="foot1" contype="1" conaffinity="0" density="0" group="1" class="visualgeom" />
                <geom type="mesh" rgba="0.898039 0.917647 0.929412 1" mesh="foot1" />
              </body>
            </body>
          </body>
        </body>
      </body>
      <body name="leg0_shell_2" pos="0.000698531 -0.088544 -0.43194" quat="0.706825 -0.707388 -0.000562847 -0.000563329">
        <inertial pos="-0.00374632 -5.30704e-10 -0.0676251" quat="0.999982 0 -0.00597565 0" mass="1.32345" diaginertia="0.0018859 0.00142483 0.00129962" />
        <joint name="R_hip_y" pos="0 0 0" axis="0 0 1" range="-1.5708 1.5708" actuatorfrcrange="-100 100" />
        <geom type="mesh" rgba="0.898039 0.917647 0.929412 1" mesh="leg0_shell_2" contype="1" conaffinity="0" density="0" group="1" class="visualgeom" />
        <geom type="mesh" rgba="0.898039 0.917647 0.929412 1" mesh="leg0_shell_2" />
        <body name="leg1_shell3" pos="0.0265 -1.51659e-09 -0.069" quat="0.5 0.5 -0.5 -0.5">
          <inertial pos="-0.116295 -0.00323118 0.025411" quat="-0.155155 0.779695 -0.0910895 0.599754" mass="1.36077" diaginertia="0.00290553 0.00280871 0.00156592" />
          <joint name="R_hip_x" pos="0 0 0" axis="0 0 1" range="-0.349066 3.18523" actuatorfrcrange="-40 40" />
          <geom type="mesh" rgba="0.898039 0.917647 0.929412 1" mesh="leg1_shell3" contype="1" conaffinity="0" density="0" group="1" class="visualgeom" />
          <geom type="mesh" rgba="0.898039 0.917647 0.929412 1" mesh="leg1_shell3" />
          <body name="leg2_shell_2" pos="-0.1565 -0.000119814 0.0275" quat="0 -0.707107 0 -0.707107">
            <inertial pos="4.08555e-07 0.000531684 -0.137308" quat="0.707084 -0.00547271 0.00548785 0.707088" mass="1.82092" diaginertia="0.00422586 0.00311812 0.00206385" />
            <joint name="R_hip_z" pos="0 0 0" axis="0 0 1" range="-1.5708 1.5708" actuatorfrcrange="-40 40" />
            <geom type="mesh" rgba="0.898039 0.917647 0.929412 1" mesh="leg2_shell_2" contype="1" conaffinity="0" density="0" group="1" class="visualgeom" />
            <geom type="mesh" rgba="0.898039 0.917647 0.929412 1" mesh="leg2_shell_2" />
            <body name="leg3_shell22" pos="0 0.0342 -0.1425" quat="0.707107 0.707107 0 0">
              <inertial pos="-0.00103303 -0.12548 0.0366712" quat="0.691727 0.665164 -0.198928 0.198742" mass="1.17968" diaginertia="0.00753955 0.0075026 0.00111462" />
              <joint name="R_knee" pos="0 0 0" axis="0 0 -1" range="0 1.57" actuatorfrcrange="-100 100" />
              <geom type="mesh" rgba="0.898039 0.917647 0.929412 1" mesh="leg3_shell22" contype="1" conaffinity="0" density="0" group="1" class="visualgeom" />
              <geom type="mesh" rgba="0.898039 0.917647 0.929412 1" mesh="leg3_shell22" />
              <body name="foot3" pos="1.07672e-08 -0.3 0.0272" quat="0 -2.32051e-08 1 -2.32051e-08">
                <inertial pos="0.0210264 -0.018472 -0.0236957" quat="0.504957 0.505269 0.504304 0.48518" mass="0.545747" diaginertia="0.00202977 0.00187214 0.000259286" />
                <joint name="R_ankle" pos="0 0 0" axis="0 0 -1" range="-0.698132 0.698132" actuatorfrcrange="-80 80" frictionloss="0.1" />
                <geom type="mesh" rgba="0.898039 0.917647 0.929412 1" mesh="foot3" contype="1" conaffinity="0" density="0" group="1" class="visualgeom" />
                <geom type="mesh" rgba="0.898039 0.917647 0.929412 1" mesh="foot3" />
              </body>
            </body>
          </body>
        </body>
      </body>
    </body>
  </worldbody>

  <actuator>
    <motor name="L_hip_y" joint="L_hip_y" ctrllimited="true" ctrlrange="-100 100" gear="1" />
    <motor name="L_hip_x" joint="L_hip_x" ctrllimited="true" ctrlrange="-40 40" gear="1" />
    <motor name="L_hip_z" joint="L_hip_z" ctrllimited="true" ctrlrange="-40 40" gear="1" />
    <motor name="L_knee" joint="L_knee" ctrllimited="true" ctrlrange="-100 100" gear="1" />
    <motor name="L_ankle" joint="L_ankle" ctrllimited="true" ctrlrange="-80 80" gear="1" />
    <motor name="R_hip_y" joint="R_hip_y" ctrllimited="true" ctrlrange="-100 100" gear="1" />
    <motor name="R_hip_x" joint="R_hip_x" ctrllimited="true" ctrlrange="-40 40" gear="1" />
    <motor name="R_hip_z" joint="R_hip_z" ctrllimited="true" ctrlrange="-40 40" gear="1" />
    <motor name="R_knee" joint="R_knee" ctrllimited="true" ctrlrange="-100 100" gear="1" />
    <motor name="R_ankle" joint="R_ankle" ctrllimited="true" ctrlrange="-80 80" gear="1" />
  </actuator>

  <sensor>
    <actuatorpos name="L_hip_y_p" actuator="L_hip_y" />
    <actuatorvel name="L_hip_y_v" actuator="L_hip_y" />
    <actuatorfrc name="L_hip_y_f" actuator="L_hip_y" noise="0.001" />
    <actuatorpos name="L_hip_x_p" actuator="L_hip_x" />
    <actuatorvel name="L_hip_x_v" actuator="L_hip_x" />
    <actuatorfrc name="L_hip_x_f" actuator="L_hip_x" noise="0.001" />
    <actuatorpos name="L_hip_z_p" actuator="L_hip_z" />
    <actuatorvel name="L_hip_z_v" actuator="L_hip_z" />
    <actuatorfrc name="L_hip_z_f" actuator="L_hip_z" noise="0.001" />
    <actuatorpos name="L_knee_p" actuator="L_knee" />
    <actuatorvel name="L_knee_v" actuator="L_knee" />
    <actuatorfrc name="L_knee_f" actuator="L_knee" noise="0.001" />
    <actuatorpos name="L_ankle_p" actuator="L_ankle" />
    <actuatorvel name="L_ankle_v" actuator="L_ankle" />
    <actuatorfrc name="L_ankle_f" actuator="L_ankle" noise="0.001" />
    <actuatorpos name="R_hip_y_p" actuator="R_hip_y" />
    <actuatorvel name="R_hip_y_v" actuator="R_hip_y" />
    <actuatorfrc name="R_hip_y_f" actuator="R_hip_y" noise="0.001" />
    <actuatorpos name="R_hip_x_p" actuator="R_hip_x" />
    <actuatorvel name="R_hip_x_v" actuator="R_hip_x" />
    <actuatorfrc name="R_hip_x_f" actuator="R_hip_x" noise="0.001" />
    <actuatorpos name="R_hip_z_p" actuator="R_hip_z" />
    <actuatorvel name="R_hip_z_v" actuator="R_hip_z" />
    <actuatorfrc name="R_hip_z_f" actuator="R_hip_z" noise="0.001" />
    <actuatorpos name="R_knee_p" actuator="R_knee" />
    <actuatorvel name="R_knee_v" actuator="R_knee" />
    <actuatorfrc name="R_knee_f" actuator="R_knee" noise="0.001" />
    <actuatorpos name="R_ankle_p" actuator="R_ankle" />
    <actuatorvel name="R_ankle_v" actuator="R_ankle" />
    <actuatorfrc name="R_ankle_f" actuator="R_ankle" noise="0.001" />
    <framequat name="orientation" objtype="site" noise="0.001" objname="imu" />
    <gyro name="angular-velocity" site="imu" noise="0.005" cutoff="34.9" />
  </sensor>
</mujoco>
