<mujoco model="k-bot_sim">
  <compiler angle="radian"/>

  <asset>
    <mesh name="body1-part.collision" file="body1-part.collision.stl"/>
    <mesh name="shoulder.collision" file="shoulder.collision.stl"/>
    <mesh name="shoulder_2.collision" file="shoulder_2.collision.stl"/>
    <mesh name="leg0_shell.collision" file="leg0_shell.collision.stl"/>
    <mesh name="leg0_shell_2.collision" file="leg0_shell_2.collision.stl"/>
    <mesh name="arm2_shell.collision" file="arm2_shell.collision.stl"/>
    <mesh name="arm2_shell_2.collision" file="arm2_shell_2.collision.stl"/>
    <mesh name="hand_shell.collision" file="hand_shell.collision.stl"/>
    <mesh name="hand_shell_2.collision" file="hand_shell_2.collision.stl"/>
    <mesh name="leg3_shell1.collision" file="leg3_shell1.collision.stl"/>
    <mesh name="leg3_shell11.collision" file="leg3_shell11.collision.stl"/>
    <mesh name="foot3.collision" file="foot3.collision.stl"/>
    <mesh name="foot1.collision" file="foot1.collision.stl"/>
  </asset>

  <worldbody>
    <geom name="body1-part.collision" pos="0 0 0" quat="0.000563312 0.000562864 0.706825 0.707388" type="mesh" rgba="1 1 1 1" mesh="body1-part.collision"/>
    <geom name="shoulder.collision" pos="0.000302197 0.191 0.019999" quat="0.707388 0.706825 0 0" type="mesh" rgba="1 1 1 1" mesh="shoulder.collision"/>
    <geom name="arm2_shell.collision" pos="0.000314151 0.258388 -0.120499" quat="0.707107 -0.000281197 0.00028166 0.707107" type="mesh" rgba="0.898039 0.917647 0.929412 1" mesh="arm2_shell.collision"/>
    <geom name="hand_shell.collision" pos="0.000313973 0.252665 -0.400994" quat="-3.36798e-07 -4.90058e-07 -0.000398327 -1" type="mesh" rgba="0.898039 0.917647 0.929412 1" mesh="hand_shell.collision"/>
    <geom name="shoulder.collision_2" pos="-0.000302197 -0.191 0.019999" quat="0.707388 -0.706825 0 0" type="mesh" rgba="1 1 1 1" mesh="shoulder_2.collision"/>
    <geom name="arm2_shell.collision_2" pos="0.000709757 -0.258388 -0.120499" quat="0.00039799 -1 1.63397e-07 6.50873e-11" type="mesh" rgba="0.898039 0.917647 0.929412 1" mesh="arm2_shell_2.collision"/>
    <geom name="hand_shell.collision_2" pos="0.000709707 -0.252665 -0.400494" quat="1.30008e-10 -3.26795e-07 0.000398154 -1" type="mesh" rgba="0.898039 0.917647 0.929412 1" mesh="hand_shell_2.collision"/>
    <body name="leg0_shell" pos="0.000146931 0.0909999 -0.430001" quat="-0.707387 -0.706824 0.00112573 0.00112662">
      <inertial pos="-0.003746 0 -0.068125" quat="0.999982 0 -0.00597152 0" mass="1.32345" diaginertia="0.00188608 0.001425 0.00129992"/>
      <joint name="left_hip_pitch_04" pos="0 0 0" axis="0 0 1" range="-1.5708 1.5708" actuatorfrcrange="-60 60"/>
      <geom name="leg0_shell.collision" type="mesh" rgba="0.898039 0.917647 0.929412 1" mesh="leg0_shell.collision"/>
      <body name="leg1_shell" pos="0.0275 0 -0.0695" quat="0.5 -0.5 -0.5 0.5">
        <inertial pos="-0.112524 0.000529 0.025259" quat="-0.149163 0.776513 -0.185318 0.583469" mass="1.26435" diaginertia="0.00249944 0.00248268 0.00139787"/>
        <joint name="left_hip_roll_03" pos="0 0 0" axis="0 0 1" range="-3.18523 0.349066" actuatorfrcrange="-40 40"/>
        <body name="leg2_shell" pos="-0.1575 0.00012 0.0275" quat="0.707107 0 0.707107 0">
          <inertial pos="0 0.000532 -0.137308" quat="0.707085 -0.00556072 0.00556072 0.707085" mass="1.82092" diaginertia="0.00422553 0.003118 0.00206347"/>
          <joint name="left_hip_yaw_03" pos="0 0 0" axis="0 0 1" range="-1.5708 1.5708" actuatorfrcrange="-40 40"/>
          <body name="leg3_shell1" pos="0 -0.027 -0.1425" quat="0.707107 0.707107 0 0">
            <inertial pos="0.001098 -0.131322 -0.023162" quat="0.29298 0.299254 -0.639764 0.644447" mass="1.10996" diaginertia="0.00676042 0.00672628 0.0010123"/>
            <joint name="left_knee_04" pos="0 0 0" axis="0 0 -1" range="0 2.0944" actuatorfrcrange="-60 60"/>
            <geom name="leg3_shell1.collision" type="mesh" rgba="0.898039 0.917647 0.929412 1" mesh="leg3_shell1.collision"/>
            <body name="foot1" pos="0 -0.3 0.0095">
              <inertial pos="0.02135 -0.019419 -0.019276" quat="0.504954 0.505314 0.484937 0.504496" mass="0.582091" diaginertia="0.00218891 0.00202456 0.000282532"/>
              <joint name="left_ankle_02" pos="0 0 0" axis="0 0 -1" range="-0.698132 0.698132" actuatorfrcrange="-17 17" frictionloss="0.1"/>
              <geom name="foot1.collision" type="mesh" rgba="0.898039 0.917647 0.929412 1" mesh="foot1.collision"/>
            </body>
          </body>
        </body>
      </body>
    </body>
    <body name="leg0_shell_2" pos="-0.000146931 -0.0909999 -0.430001" quat="-0.707387 0.706824 -0.00112573 0.00112662">
      <inertial pos="-0.003746 0 -0.067625" quat="0.999982 0 -0.00597152 0" mass="1.32345" diaginertia="0.00188608 0.001425 0.00129992"/>
      <joint name="right_hip_pitch_04" pos="0 0 0" axis="0 0 1" range="-1.5708 1.5708" actuatorfrcrange="-60 60"/>
      <geom name="leg0_shell.collision_2" type="mesh" rgba="0.898039 0.917647 0.929412 1" mesh="leg0_shell_2.collision"/>
      <body name="leg1_shell3" pos="0.0275 0 -0.069" quat="0.5 0.5 -0.5 -0.5">
        <inertial pos="-0.112524 -0.000529 0.025259" quat="0.149163 0.776513 0.185318 0.583469" mass="1.26435" diaginertia="0.00249944 0.00248268 0.00139787"/>
        <joint name="right_hip_roll_03" pos="0 0 0" axis="0 0 1" range="-0.349066 3.18523" actuatorfrcrange="-40 40"/>
        <body name="leg2_shell_2" pos="-0.1575 -0.00012 0.0275" quat="-1.22475e-07 -0.707107 1.22474e-07 -0.707107">
          <inertial pos="0 0.000532 -0.137308" quat="0.707085 -0.00556072 0.00556072 0.707085" mass="1.82092" diaginertia="0.00422553 0.003118 0.00206347"/>
          <joint name="right_hip_yaw_03" pos="0 0 0" axis="0 0 1" range="-1.5708 1.5708" actuatorfrcrange="-40 40"/>
          <body name="leg3_shell11" pos="0 -0.027 -0.1425" quat="0.707107 0.707107 0 0">
            <inertial pos="-0.001098 -0.131322 -0.023162" quat="0.644447 0.639764 -0.299254 0.29298" mass="1.10996" diaginertia="0.00676042 0.00672628 0.0010123"/>
            <joint name="right_knee_04" pos="0 0 0" axis="0 0 -1" range="-2.0944 0" actuatorfrcrange="-60 60"/>
            <geom name="leg3_shell11.collision" type="mesh" rgba="0.898039 0.917647 0.929412 1" mesh="leg3_shell11.collision"/>
            <body name="foot3" pos="0 -0.3 -0.0355" quat="0 -1.73205e-07 1 -1.73205e-07">
              <inertial pos="0.02135 -0.019419 -0.023724" quat="0.505314 0.504954 0.504496 0.484937" mass="0.582091" diaginertia="0.00218891 0.00202456 0.000282532"/>
              <joint name="right_ankle_02" pos="0 0 0" axis="0 0 1" range="-0.698132 0.698132" actuatorfrcrange="-17 17" frictionloss="0.1"/>
              <geom name="foot3.collision" type="mesh" rgba="0.898039 0.917647 0.929412 1" mesh="foot3.collision"/>
            </body>
          </body>
        </body>
      </body>
    </body>
  </worldbody>
</mujoco>
