<mujoco model="k-bot_sim">
  <option iterations="50" timestep="0.001" solver="PGS" gravity="0 0 -9.81" />

  <compiler angle="radian" meshdir="meshes" eulerseq="zyx" autolimits="true" />

  <default>
    <joint limited="true" damping="0.01" armature="0.01" frictionloss="0.01" />
    <geom condim="4" contype="1" conaffinity="15" friction="0.9 0.2 0.2" solref="0.001 2" />
    <motor ctrllimited="true" />
    <equality solref="0.001 2" />
    <default class="visualgeom">
      <geom material="visualgeom" condim="1" contype="0" conaffinity="0" />
    </default>
  </default>

  <asset>
    <mesh name="body1-part_collision" file="body1-part_collision.stl" />
    <mesh name="shoulder.convex" file="shoulder.convex.stl" />
    <mesh name="shoulder_2.convex" file="shoulder_2.convex.stl" />
    <mesh name="arm1_top_collision" file="arm1_top_collision.stl" />
    <mesh name="arm1_top_2_collision" file="arm1_top_2_collision.stl" />
    <mesh name="leg0_shell.convex" file="leg0_shell.convex.stl" />
    <mesh name="leg0_shell_2.convex" file="leg0_shell_2.convex.stl" />
    <mesh name="arm2_shell_collision" file="arm2_shell_collision.stl" />
    <mesh name="arm2_shell_2_collision" file="arm2_shell_2_collision.stl" />
    <mesh name="leg1_shell_collision" file="leg1_shell_collision.stl" />
    <mesh name="leg1_shell3_collision" file="leg1_shell3_collision.stl" />
    <mesh name="arm3_shell.convex" file="arm3_shell.convex.stl" />
    <mesh name="arm3_shell2.convex" file="arm3_shell2.convex.stl" />
    <mesh name="leg2_shell_collision" file="leg2_shell_collision.stl" />
    <mesh name="leg2_shell_2_collision" file="leg2_shell_2_collision.stl" />
    <mesh name="hand_shell.convex" file="hand_shell.convex.stl" />
    <mesh name="hand_shell_2.convex" file="hand_shell_2.convex.stl" />
    <mesh name="leg3_shell1_collision" file="leg3_shell1_collision.stl" />
    <mesh name="leg3_shell11_collision" file="leg3_shell11_collision.stl" />
    <mesh name="foot3.convex" file="foot3.convex.stl" />
    <mesh name="foot1.convex" file="foot1.convex.stl" />
    <texture name="texplane" type="2d" builtin="checker" rgb1=".0 .0 .0" rgb2=".8 .8 .8" width="100" height="100" />
    <material name="matplane" reflectance="0." texture="texplane" texrepeat="1 1" texuniform="true" />
    <material name="visualgeom" rgba="0.5 0.9 0.2 1" />
  </asset>

  <worldbody>
    <light directional="true" diffuse="0.4 0.4 0.4" specular="0.1 0.1 0.1" pos="0 0 5.0" dir="0 0 -1" castshadow="false" />
    <light directional="true" diffuse="0.6 0.6 0.6" specular="0.2 0.2 0.2" pos="0 0 4" dir="0 0 -1" />
    <geom name="ground" type="plane" pos="0 0 0" size="100 100 0.001" quat="1 0 0 0" material="matplane" condim="3" conaffinity="15" />
    <camera name="fixed" pos="0 -3.0 1.6662098533463137" xyaxes="1 0 0 0 0 1" />
    <camera name="track" mode="trackcom" pos="0 -3.0 1.6662098533463137" xyaxes="1 0 0 0 0 1" />
    <body name="root" pos="0 0 1.1662098533463137" quat="1 0 0 0">
      <freejoint name="root" />
      <site name="imu" size="0.01" pos="0 0 0" />
      <geom name="body1-part_collision" pos="0 0.001 -7.96327e-07" quat="0.707388 0.706825 0 0" type="mesh" rgba="1 1 1 1" mesh="body1-part_collision" contype="1" conaffinity="0" density="0" group="1" class="visualgeom" />
      <geom type="mesh" rgba="1 1 1 1" mesh="body1-part_collision" pos="0 0.001 -7.96327e-07" quat="0.707388 0.706825 0 0" />
      <body name="shoulder" pos="-1.06038e-05 -0.187485 0.0182389" quat="-1.6402e-08 1.6415e-08 0.707388 0.706825">
        <inertial pos="-0.00214395 5.49827e-05 -0.0664833" quat="0.999995 6.04035e-05 0.00311182 1.82004e-05" mass="1.10736" diaginertia="0.00148053 0.00103924 0.00098591" />
        <joint name="left_shoulder_pitch_03" pos="0 0 0" axis="0 0 1" range="0 3.14159" actuatorfrcrange="-60 60" />
        <geom name="shoulder_collision" type="mesh" rgba="1 1 1 1" mesh="shoulder.convex" contype="1" conaffinity="0" density="0" group="1" class="visualgeom" />
        <geom type="mesh" rgba="1 1 1 1" mesh="shoulder.convex" />
        <body name="arm1_top" pos="0.023512 5.62784e-05 -0.0675" quat="0.5 0.5 0.5 0.5">
          <inertial pos="-0.099486 -1.16302e-06 -0.0190825" quat="-3.9537e-05 0.595255 -5.81411e-05 0.803537" mass="0.572732" diaginertia="0.00109446 0.00107552 0.000393301" />
          <joint name="left_shoulder_roll_03" pos="0 0 0" axis="0 0 -1" range="-3.63028 0.479966" actuatorfrcrange="-60 60" />
          <geom name="arm1_top_collision" type="mesh" rgba="0.898039 0.917647 0.929412 1" mesh="arm1_top_collision" contype="1" conaffinity="0" density="0" group="1" class="visualgeom" />
          <geom type="mesh" rgba="0.898039 0.917647 0.929412 1" mesh="arm1_top_collision" />
          <body name="arm2_shell" pos="-0.1405 -1.50833e-09 -0.0235" quat="0.5 -0.5 0.5 -0.5">
            <inertial pos="-0.00633923 0 -0.0904821" quat="0.999976 0 0.00697634 0" mass="0.510678" diaginertia="0.000675434 0.000532486 0.000254739" />
            <joint name="left_shoulder_yaw_02" pos="0 0 0" axis="0 0 1" range="-1.5708 1.5708" actuatorfrcrange="-17 17" />
            <geom name="arm2_shell_collision" type="mesh" rgba="0.898039 0.917647 0.929412 1" mesh="arm2_shell_collision" contype="1" conaffinity="0" density="0" group="1" class="visualgeom" />
            <geom type="mesh" rgba="0.898039 0.917647 0.929412 1" mesh="arm2_shell_collision" />
            <body name="arm3_shell" pos="-0.027 -4.64102e-11 -0.098" quat="1.64085e-08 -0.707107 -1.64085e-08 -0.707107">
              <inertial pos="-0.140169 -3.71744e-10 0.0194329" quat="0 0.759592 0 0.6504" mass="0.578536" diaginertia="0.00135428 0.001354 0.000405631" />
              <joint name="left_elbow_02" pos="0 0 0" axis="0 0 1" range="-2.53073 0" actuatorfrcrange="-17 17" />
              <geom name="arm3_shell_collision" type="mesh" rgba="0.898039 0.917647 0.929412 1" mesh="arm3_shell.convex" contype="1" conaffinity="0" density="0" group="1" class="visualgeom" />
              <geom type="mesh" rgba="0.898039 0.917647 0.929412 1" mesh="arm3_shell.convex" />
              <body name="hand_shell" pos="-0.1825 -1.50833e-09 0.0215" quat="0.5 -0.5 0.5 -0.5">
                <inertial pos="0.000708975 0.000129757 -0.0746574" quat="0.706769 0.0116683 0.0100891 0.707276" mass="0.793063" diaginertia="0.00286942 0.00203431 0.00127887" />
                <joint name="left_wrist_02" pos="0 0 0" axis="0 0 1" range="-3.14159 3.14159" actuatorfrcrange="-17 17" />
                <geom name="hand_shell_collision" type="mesh" rgba="0.898039 0.917647 0.929412 1" mesh="hand_shell.convex" contype="1" conaffinity="0" density="0" group="1" class="visualgeom" />
                <geom type="mesh" rgba="0.898039 0.917647 0.929412 1" mesh="hand_shell.convex" />
              </body>
            </body>
          </body>
        </body>
      </body>
      <body name="shoulder_2" pos="-1.06038e-05 0.189515 0.0179387" quat="1.6415e-08 1.6402e-08 0.706825 -0.707388">
        <inertial pos="-0.00214395 -5.49871e-05 -0.0664833" quat="0.999995 -6.01965e-05 0.00311183 -1.81385e-05" mass="1.10735" diaginertia="0.00148052 0.00103924 0.000985909" />
        <joint name="right_shoulder_pitch_03" pos="0 0 0" axis="0 0 1" range="-3.14159 0" actuatorfrcrange="-60 60" />
        <geom name="shoulder_collision_2" type="mesh" rgba="1 1 1 1" mesh="shoulder_2.convex" contype="1" conaffinity="0" density="0" group="1" class="visualgeom" />
        <geom type="mesh" rgba="1 1 1 1" mesh="shoulder_2.convex" />
        <body name="arm1_top_2" pos="0.023512 -5.62784e-05 -0.0675" quat="0.5 0.5 -0.5 -0.5">
          <inertial pos="-0.0994861 -1.08549e-06 0.0180825" quat="5.42664e-05 0.803537 3.68912e-05 0.595255" mass="0.572732" diaginertia="0.00109446 0.00107552 0.0003933" />
          <joint name="right_shoulder_roll_03" pos="0 0 0" axis="0 0 1" range="-0.479966 3.63028" actuatorfrcrange="-60 60" />
          <geom name="arm1_top_2_collision" type="mesh" rgba="0.898039 0.917647 0.929412 1" mesh="arm1_top_2_collision" contype="1" conaffinity="0" density="0" group="1" class="visualgeom" />
          <geom type="mesh" rgba="0.898039 0.917647 0.929412 1" mesh="arm1_top_2_collision" />
          <body name="arm2_shell_2" pos="-0.1405 4.64102e-11 0.0225" quat="1.64085e-08 -0.707107 1.64085e-08 0.707107">
            <inertial pos="-2.43146e-10 -0.00633923 0.0899821" quat="0.70709 0.00493302 -0.00493302 0.70709" mass="0.510678" diaginertia="0.000675434 0.000532486 0.000254739" />
            <joint name="right_shoulder_yaw_02" pos="0 0 0" axis="0 0 -1" range="-1.5708 1.5708" actuatorfrcrange="-17 17" />
            <geom name="arm2_shell_collision_2" type="mesh" rgba="0.898039 0.917647 0.929412 1" mesh="arm2_shell_2_collision" contype="1" conaffinity="0" density="0" group="1" class="visualgeom" />
            <geom type="mesh" rgba="0.898039 0.917647 0.929412 1" mesh="arm2_shell_2_collision" />
            <body name="arm3_shell2" pos="2.08141e-10 -0.027 0.0975" quat="0.5 -0.5 0.5 0.5">
              <inertial pos="-0.140169 -3.71744e-10 0.0194329" quat="0 0.759592 0 0.6504" mass="0.578536" diaginertia="0.00135428 0.001354 0.000405631" />
              <joint name="right_elbow_02" pos="0 0 0" axis="0 0 1" range="0 2.53073" actuatorfrcrange="-17 17" />
              <geom name="arm3_shell2_collision" type="mesh" rgba="0.898039 0.917647 0.929412 1" mesh="arm3_shell2.convex" contype="1" conaffinity="0" density="0" group="1" class="visualgeom" />
              <geom type="mesh" rgba="0.898039 0.917647 0.929412 1" mesh="arm3_shell2.convex" />
              <body name="hand_shell_2" pos="-0.1825 -1.50833e-09 0.0215" quat="0.5 0.5 0.5 0.5">
                <inertial pos="0.000708975 0.000129757 -0.0746574" quat="0.706769 0.0116683 0.0100891 0.707276" mass="0.793063" diaginertia="0.00286942 0.00203431 0.00127887" />
                <joint name="right_wrist_02" pos="0 0 0" axis="0 0 1" range="-3.14159 3.14159" actuatorfrcrange="-17 17" />
                <geom name="hand_shell_collision_2" type="mesh" rgba="0.898039 0.917647 0.929412 1" mesh="hand_shell_2.convex" contype="1" conaffinity="0" density="0" group="1" class="visualgeom" />
                <geom type="mesh" rgba="0.898039 0.917647 0.929412 1" mesh="hand_shell_2.convex" />
              </body>
            </body>
          </body>
        </body>
      </body>
      <body name="leg0_shell" pos="-1.06086e-05 -0.088044 -0.43194" quat="1.6415e-08 1.6402e-08 0.707388 0.706825">
        <inertial pos="-0.00374632 -5.30704e-10 -0.0681251" quat="0.999982 0 -0.00597565 0" mass="1.32345" diaginertia="0.0018859 0.00142483 0.00129962" />
        <joint name="left_hip_pitch_04" pos="0 0 0" axis="0 0 1" range="-1.5708 1.5708" actuatorfrcrange="-120 120" />
        <geom name="leg0_shell_collision" type="mesh" rgba="0.898039 0.917647 0.929412 1" mesh="leg0_shell.convex" contype="1" conaffinity="0" density="0" group="1" class="visualgeom" />
        <geom type="mesh" rgba="0.898039 0.917647 0.929412 1" mesh="leg0_shell.convex" />
        <body name="leg1_shell" pos="0.0275 -1.54339e-09 -0.0695" quat="0.5 -0.5 -0.5 0.5">
          <inertial pos="-0.112524 0.000528881 0.0252586" quat="-0.145364 0.777648 -0.180161 0.584529" mass="1.26435" diaginertia="0.0024993 0.00248263 0.00139772" />
          <joint name="left_hip_roll_03" pos="0 0 0" axis="0 0 1" range="-3.18523 0.349066" actuatorfrcrange="-60 60" />
          <geom name="leg1_shell_collision" type="mesh" rgba="0.898039 0.917647 0.929412 1" mesh="leg1_shell_collision" contype="1" conaffinity="0" density="0" group="1" class="visualgeom" />
          <geom type="mesh" rgba="0.898039 0.917647 0.929412 1" mesh="leg1_shell_collision" />
          <body name="leg2_shell" pos="-0.1575 0.000119814 0.0275" quat="0.707107 0 0.707107 0">
            <inertial pos="4.08555e-07 0.000531684 -0.137308" quat="0.707084 -0.00547271 0.00548785 0.707088" mass="1.82092" diaginertia="0.00422586 0.00311812 0.00206385" />
            <joint name="left_hip_yaw_03" pos="0 0 0" axis="0 0 1" range="-1.5708 1.5708" actuatorfrcrange="-60 60" />
            <geom name="leg2_shell_collision" type="mesh" rgba="0.898039 0.917647 0.929412 1" mesh="leg2_shell_collision" contype="1" conaffinity="0" density="0" group="1" class="visualgeom" />
            <geom type="mesh" rgba="0.898039 0.917647 0.929412 1" mesh="leg2_shell_collision" />
            <body name="leg3_shell1" pos="0 -0.027 -0.1425" quat="0.707107 0.707107 0 0">
              <inertial pos="0.00109787 -0.131322 -0.0231623" quat="0.291798 0.298031 -0.640329 0.644988" mass="1.10996" diaginertia="0.0067601 0.00672601 0.00101204" />
              <joint name="left_knee_04" pos="0 0 0" axis="0 0 -1" range="0 2.0944" actuatorfrcrange="-120 120" />
              <geom name="leg3_shell1_collision" type="mesh" rgba="0.898039 0.917647 0.929412 1" mesh="leg3_shell1_collision" contype="1" conaffinity="0" density="0" group="1" class="visualgeom" />
              <geom type="mesh" rgba="0.898039 0.917647 0.929412 1" mesh="leg3_shell1_collision" />
              <body name="foot1" pos="0 -0.3 0.00949999" quat="1 4.64102e-08 0 0">
                <inertial pos="0.0213499 -0.019419 -0.0192762" quat="0.505229 0.504986 0.485131 0.504362" mass="0.582091" diaginertia="0.00218912 0.00202432 0.000282398" />
                <joint name="left_ankle_02" pos="0 0 0" axis="0 0 -1" range="-0.698132 0.698132" actuatorfrcrange="-17 17" />
                <geom name="foot1_collision" type="mesh" rgba="0.898039 0.917647 0.929412 1" mesh="foot1.convex" contype="1" conaffinity="0" density="0" group="1" class="visualgeom" />
                <geom type="mesh" rgba="0.898039 0.917647 0.929412 1" mesh="foot1.convex" />
              </body>
            </body>
          </body>
        </body>
      </body>
      <body name="leg0_shell_2" pos="-1.06003e-05 0.0898559 -0.432082" quat="-1.6402e-08 1.6415e-08 0.706825 -0.707388">
        <inertial pos="-0.00374632 -5.30704e-10 -0.0676251" quat="0.999982 0 -0.00597565 0" mass="1.32345" diaginertia="0.0018859 0.00142483 0.00129962" />
        <joint name="right_hip_pitch_04" pos="0 0 0" axis="0 0 1" range="-1.5708 1.5708" actuatorfrcrange="-120 120" />
        <geom name="leg0_shell_collision_2" type="mesh" rgba="0.898039 0.917647 0.929412 1" mesh="leg0_shell_2.convex" contype="1" conaffinity="0" density="0" group="1" class="visualgeom" />
        <geom type="mesh" rgba="0.898039 0.917647 0.929412 1" mesh="leg0_shell_2.convex" />
        <body name="leg1_shell3" pos="0.0275 -1.54339e-09 -0.069" quat="0.5 0.5 -0.5 -0.5">
          <inertial pos="-0.112524 -0.000528888 0.0252586" quat="0.145366 0.777648 0.180163 0.584529" mass="1.26435" diaginertia="0.0024993 0.00248263 0.00139772" />
          <joint name="right_hip_roll_03" pos="0 0 0" axis="0 0 1" range="-0.349066 3.18523" actuatorfrcrange="-60 60" />
          <geom name="leg1_shell3_collision" type="mesh" rgba="0.898039 0.917647 0.929412 1" mesh="leg1_shell3_collision" contype="1" conaffinity="0" density="0" group="1" class="visualgeom" />
          <geom type="mesh" rgba="0.898039 0.917647 0.929412 1" mesh="leg1_shell3_collision" />
          <body name="leg2_shell_2" pos="-0.1575 -0.000119814 0.0275" quat="0 -0.707107 0 -0.707107">
            <inertial pos="4.08555e-07 0.000531684 -0.137308" quat="0.707084 -0.00547271 0.00548785 0.707088" mass="1.82092" diaginertia="0.00422586 0.00311812 0.00206385" />
            <joint name="right_hip_yaw_03" pos="0 0 0" axis="0 0 1" range="-1.5708 1.5708" actuatorfrcrange="-60 60" />
            <geom name="leg2_shell_collision_2" type="mesh" rgba="0.898039 0.917647 0.929412 1" mesh="leg2_shell_2_collision" contype="1" conaffinity="0" density="0" group="1" class="visualgeom" />
            <geom type="mesh" rgba="0.898039 0.917647 0.929412 1" mesh="leg2_shell_2_collision" />
            <body name="leg3_shell11" pos="0 -0.027 -0.1425" quat="0.707107 0.707107 0 0">
              <inertial pos="-0.00109792 -0.131322 -0.0231622" quat="0.644988 0.640329 -0.298032 0.291798" mass="1.10996" diaginertia="0.00676011 0.00672603 0.00101204" />
              <joint name="right_knee_04" pos="0 0 0" axis="0 0 -1" range="-2.0944 0" actuatorfrcrange="-120 120" />
              <geom name="leg3_shell11_collision" type="mesh" rgba="0.898039 0.917647 0.929412 1" mesh="leg3_shell11_collision" contype="1" conaffinity="0" density="0" group="1" class="visualgeom" />
              <geom type="mesh" rgba="0.898039 0.917647 0.929412 1" mesh="leg3_shell11_collision" />
              <body name="foot3" pos="0 -0.3 -0.0355" quat="0 -2.32051e-08 1 -2.32051e-08">
                <inertial pos="0.0213499 -0.019419 -0.0237238" quat="0.504986 0.505229 0.504361 0.485132" mass="0.582091" diaginertia="0.00218912 0.00202432 0.000282398" />
                <joint name="right_ankle_02" pos="0 0 0" axis="0 0 -1" range="-0.698132 0.698132" actuatorfrcrange="-17 17" />
                <geom name="foot3_collision" type="mesh" rgba="0.898039 0.917647 0.929412 1" mesh="foot3.convex" contype="1" conaffinity="0" density="0" group="1" class="visualgeom" />
                <geom type="mesh" rgba="0.898039 0.917647 0.929412 1" mesh="foot3.convex" />
              </body>
            </body>
          </body>
        </body>
      </body>
    </body>
  </worldbody>

  <actuator>
    <motor name="left_shoulder_pitch_03" joint="left_shoulder_pitch_03" ctrllimited="true" ctrlrange="-60 60" gear="1" />
    <motor name="left_shoulder_roll_03" joint="left_shoulder_roll_03" ctrllimited="true" ctrlrange="-60 60" gear="1" />
    <motor name="left_shoulder_yaw_02" joint="left_shoulder_yaw_02" ctrllimited="true" ctrlrange="-17 17" gear="1" />
    <motor name="left_elbow_02" joint="left_elbow_02" ctrllimited="true" ctrlrange="-17 17" gear="1" />
    <motor name="left_wrist_02" joint="left_wrist_02" ctrllimited="true" ctrlrange="-17 17" gear="1" />
    <motor name="right_shoulder_pitch_03" joint="right_shoulder_pitch_03" ctrllimited="true" ctrlrange="-60 60" gear="1" />
    <motor name="right_shoulder_roll_03" joint="right_shoulder_roll_03" ctrllimited="true" ctrlrange="-60 60" gear="1" />
    <motor name="right_shoulder_yaw_02" joint="right_shoulder_yaw_02" ctrllimited="true" ctrlrange="-17 17" gear="1" />
    <motor name="right_elbow_02" joint="right_elbow_02" ctrllimited="true" ctrlrange="-17 17" gear="1" />
    <motor name="right_wrist_02" joint="right_wrist_02" ctrllimited="true" ctrlrange="-17 17" gear="1" />
    <motor name="left_hip_pitch_04" joint="left_hip_pitch_04" ctrllimited="true" ctrlrange="-120 120" gear="1" />
    <motor name="left_hip_roll_03" joint="left_hip_roll_03" ctrllimited="true" ctrlrange="-60 60" gear="1" />
    <motor name="left_hip_yaw_03" joint="left_hip_yaw_03" ctrllimited="true" ctrlrange="-60 60" gear="1" />
    <motor name="left_knee_04" joint="left_knee_04" ctrllimited="true" ctrlrange="-120 120" gear="1" />
    <motor name="left_ankle_02" joint="left_ankle_02" ctrllimited="true" ctrlrange="-17 17" gear="1" />
    <motor name="right_hip_pitch_04" joint="right_hip_pitch_04" ctrllimited="true" ctrlrange="-120 120" gear="1" />
    <motor name="right_hip_roll_03" joint="right_hip_roll_03" ctrllimited="true" ctrlrange="-60 60" gear="1" />
    <motor name="right_hip_yaw_03" joint="right_hip_yaw_03" ctrllimited="true" ctrlrange="-60 60" gear="1" />
    <motor name="right_knee_04" joint="right_knee_04" ctrllimited="true" ctrlrange="-120 120" gear="1" />
    <motor name="right_ankle_02" joint="right_ankle_02" ctrllimited="true" ctrlrange="-17 17" gear="1" />
  </actuator>

  <sensor>
    <actuatorpos name="left_shoulder_pitch_03_p" actuator="left_shoulder_pitch_03" />
    <actuatorvel name="left_shoulder_pitch_03_v" actuator="left_shoulder_pitch_03" />
    <actuatorfrc name="left_shoulder_pitch_03_f" actuator="left_shoulder_pitch_03" noise="0.001" />
    <actuatorpos name="left_shoulder_roll_03_p" actuator="left_shoulder_roll_03" />
    <actuatorvel name="left_shoulder_roll_03_v" actuator="left_shoulder_roll_03" />
    <actuatorfrc name="left_shoulder_roll_03_f" actuator="left_shoulder_roll_03" noise="0.001" />
    <actuatorpos name="left_shoulder_yaw_02_p" actuator="left_shoulder_yaw_02" />
    <actuatorvel name="left_shoulder_yaw_02_v" actuator="left_shoulder_yaw_02" />
    <actuatorfrc name="left_shoulder_yaw_02_f" actuator="left_shoulder_yaw_02" noise="0.001" />
    <actuatorpos name="left_elbow_02_p" actuator="left_elbow_02" />
    <actuatorvel name="left_elbow_02_v" actuator="left_elbow_02" />
    <actuatorfrc name="left_elbow_02_f" actuator="left_elbow_02" noise="0.001" />
    <actuatorpos name="left_wrist_02_p" actuator="left_wrist_02" />
    <actuatorvel name="left_wrist_02_v" actuator="left_wrist_02" />
    <actuatorfrc name="left_wrist_02_f" actuator="left_wrist_02" noise="0.001" />
    <actuatorpos name="right_shoulder_pitch_03_p" actuator="right_shoulder_pitch_03" />
    <actuatorvel name="right_shoulder_pitch_03_v" actuator="right_shoulder_pitch_03" />
    <actuatorfrc name="right_shoulder_pitch_03_f" actuator="right_shoulder_pitch_03" noise="0.001" />
    <actuatorpos name="right_shoulder_roll_03_p" actuator="right_shoulder_roll_03" />
    <actuatorvel name="right_shoulder_roll_03_v" actuator="right_shoulder_roll_03" />
    <actuatorfrc name="right_shoulder_roll_03_f" actuator="right_shoulder_roll_03" noise="0.001" />
    <actuatorpos name="right_shoulder_yaw_02_p" actuator="right_shoulder_yaw_02" />
    <actuatorvel name="right_shoulder_yaw_02_v" actuator="right_shoulder_yaw_02" />
    <actuatorfrc name="right_shoulder_yaw_02_f" actuator="right_shoulder_yaw_02" noise="0.001" />
    <actuatorpos name="right_elbow_02_p" actuator="right_elbow_02" />
    <actuatorvel name="right_elbow_02_v" actuator="right_elbow_02" />
    <actuatorfrc name="right_elbow_02_f" actuator="right_elbow_02" noise="0.001" />
    <actuatorpos name="right_wrist_02_p" actuator="right_wrist_02" />
    <actuatorvel name="right_wrist_02_v" actuator="right_wrist_02" />
    <actuatorfrc name="right_wrist_02_f" actuator="right_wrist_02" noise="0.001" />
    <actuatorpos name="left_hip_pitch_04_p" actuator="left_hip_pitch_04" />
    <actuatorvel name="left_hip_pitch_04_v" actuator="left_hip_pitch_04" />
    <actuatorfrc name="left_hip_pitch_04_f" actuator="left_hip_pitch_04" noise="0.001" />
    <actuatorpos name="left_hip_roll_03_p" actuator="left_hip_roll_03" />
    <actuatorvel name="left_hip_roll_03_v" actuator="left_hip_roll_03" />
    <actuatorfrc name="left_hip_roll_03_f" actuator="left_hip_roll_03" noise="0.001" />
    <actuatorpos name="left_hip_yaw_03_p" actuator="left_hip_yaw_03" />
    <actuatorvel name="left_hip_yaw_03_v" actuator="left_hip_yaw_03" />
    <actuatorfrc name="left_hip_yaw_03_f" actuator="left_hip_yaw_03" noise="0.001" />
    <actuatorpos name="left_knee_04_p" actuator="left_knee_04" />
    <actuatorvel name="left_knee_04_v" actuator="left_knee_04" />
    <actuatorfrc name="left_knee_04_f" actuator="left_knee_04" noise="0.001" />
    <actuatorpos name="left_ankle_02_p" actuator="left_ankle_02" />
    <actuatorvel name="left_ankle_02_v" actuator="left_ankle_02" />
    <actuatorfrc name="left_ankle_02_f" actuator="left_ankle_02" noise="0.001" />
    <actuatorpos name="right_hip_pitch_04_p" actuator="right_hip_pitch_04" />
    <actuatorvel name="right_hip_pitch_04_v" actuator="right_hip_pitch_04" />
    <actuatorfrc name="right_hip_pitch_04_f" actuator="right_hip_pitch_04" noise="0.001" />
    <actuatorpos name="right_hip_roll_03_p" actuator="right_hip_roll_03" />
    <actuatorvel name="right_hip_roll_03_v" actuator="right_hip_roll_03" />
    <actuatorfrc name="right_hip_roll_03_f" actuator="right_hip_roll_03" noise="0.001" />
    <actuatorpos name="right_hip_yaw_03_p" actuator="right_hip_yaw_03" />
    <actuatorvel name="right_hip_yaw_03_v" actuator="right_hip_yaw_03" />
    <actuatorfrc name="right_hip_yaw_03_f" actuator="right_hip_yaw_03" noise="0.001" />
    <actuatorpos name="right_knee_04_p" actuator="right_knee_04" />
    <actuatorvel name="right_knee_04_v" actuator="right_knee_04" />
    <actuatorfrc name="right_knee_04_f" actuator="right_knee_04" noise="0.001" />
    <actuatorpos name="right_ankle_02_p" actuator="right_ankle_02" />
    <actuatorvel name="right_ankle_02_v" actuator="right_ankle_02" />
    <actuatorfrc name="right_ankle_02_f" actuator="right_ankle_02" noise="0.001" />
    <framequat name="orientation" objtype="site" noise="0.001" objname="imu" />
    <gyro name="angular-velocity" site="imu" noise="0.005" cutoff="34.9" />
  </sensor>
</mujoco>