<mujoco model="lower_limbs">
  <compiler angle="radian" autolimits="true"/>
  <statistic meansize="0.175584" extent="1.11801" center="-0.0355216 -0.0520159 -0.12411"/>
  <asset>
    <mesh name="leg_assembly_left_1_leg_part_1_2_simple" file="leg_assembly_left_1_leg_part_1_2_simple.stl"/>
    <mesh name="leg_assembly_right_1_leg_part_1_2_simple" file="leg_assembly_right_1_leg_part_1_2_simple.stl"/>
    <mesh name="part_1_1_simple" file="part_1_1_simple.stl"/>
    <mesh name="leg_assembly_left_1_rmd_x12_150_mock_1_outer_x12_150_1_simple" file="leg_assembly_left_1_rmd_x12_150_mock_1_outer_x12_150_1_simple.stl"/>
    <mesh name="leg_assembly_right_1_rmd_x12_150_mock_1_outer_x12_150_1_simple" file="leg_assembly_right_1_rmd_x12_150_mock_1_outer_x12_150_1_simple.stl"/>
    <mesh name="leg_assembly_left_1_rmd_x12_150_mock_1_inner_x12_150_1_simple" file="leg_assembly_left_1_rmd_x12_150_mock_1_inner_x12_150_1_simple.stl"/>
    <mesh name="leg_assembly_right_1_rmd_x12_150_mock_1_inner_x12_150_1_simple" file="leg_assembly_right_1_rmd_x12_150_mock_1_inner_x12_150_1_simple.stl"/>
    <mesh name="leg_assembly_left_1_leg_part_2_left_1_simple" file="leg_assembly_left_1_leg_part_2_left_1_simple.stl"/>
    <mesh name="leg_assembly_right_1_leg_part_2_right_1_simple" file="leg_assembly_right_1_leg_part_2_right_1_simple.stl"/>
    <mesh name="leg_assembly_left_1_rmd_x8_90_mock_1_outer_rmd_x8_90_1_simple" file="leg_assembly_left_1_rmd_x8_90_mock_1_outer_rmd_x8_90_1_simple.stl"/>
    <mesh name="leg_assembly_right_1_rmd_x8_90_mock_1_outer_rmd_x8_90_1_simple" file="leg_assembly_right_1_rmd_x8_90_mock_1_outer_rmd_x8_90_1_simple.stl"/>
    <mesh name="leg_assembly_left_1_rmd_x8_90_mock_1_inner_rmd_x8_90_1_simple" file="leg_assembly_left_1_rmd_x8_90_mock_1_inner_rmd_x8_90_1_simple.stl"/>
    <mesh name="leg_assembly_right_1_rmd_x8_90_mock_1_inner_rmd_x8_90_1_simple" file="leg_assembly_right_1_rmd_x8_90_mock_1_inner_rmd_x8_90_1_simple.stl"/>
    <mesh name="leg_assembly_left_1_leg_part_3_1_simple" file="leg_assembly_left_1_leg_part_3_1_simple.stl"/>
    <mesh name="leg_assembly_right_1_leg_part_3_1_simple" file="leg_assembly_right_1_leg_part_3_1_simple.stl"/>
    <mesh name="leg_assembly_left_1_leg_part_4_1_simple" file="leg_assembly_left_1_leg_part_4_1_simple.stl"/>
    <mesh name="leg_assembly_left_1_rmd_x8_90_mock_2_outer_rmd_x8_90_1_simple" file="leg_assembly_left_1_rmd_x8_90_mock_2_outer_rmd_x8_90_1_simple.stl"/>
    <mesh name="leg_assembly_right_1_leg_part_4_1_simple" file="leg_assembly_right_1_leg_part_4_1_simple.stl"/>
    <mesh name="leg_assembly_right_1_rmd_x8_90_mock_2_outer_rmd_x8_90_1_simple" file="leg_assembly_right_1_rmd_x8_90_mock_2_outer_rmd_x8_90_1_simple.stl"/>
    <mesh name="leg_assembly_left_1_rmd_x8_90_mock_2_inner_rmd_x8_90_1_simple" file="leg_assembly_left_1_rmd_x8_90_mock_2_inner_rmd_x8_90_1_simple.stl"/>
    <mesh name="leg_assembly_right_1_rmd_x8_90_mock_2_inner_rmd_x8_90_1_simple" file="leg_assembly_right_1_rmd_x8_90_mock_2_inner_rmd_x8_90_1_simple.stl"/>
    <mesh name="leg_assembly_left_1_let_part_5_left_1_simple" file="leg_assembly_left_1_let_part_5_left_1_simple.stl"/>
    <mesh name="leg_assembly_right_1_leg_part_5_right_2_simple" file="leg_assembly_right_1_leg_part_5_right_2_simple.stl"/>
    <mesh name="leg_assembly_left_1_rmd_x8_90_mock_3_outer_rmd_x8_90_1_simple" file="leg_assembly_left_1_rmd_x8_90_mock_3_outer_rmd_x8_90_1_simple.stl"/>
    <mesh name="leg_assembly_right_1_rmd_x8_90_mock_3_outer_rmd_x8_90_1_simple" file="leg_assembly_right_1_rmd_x8_90_mock_3_outer_rmd_x8_90_1_simple.stl"/>
    <mesh name="leg_assembly_left_1_rmd_x8_90_mock_3_inner_rmd_x8_90_1_simple" file="leg_assembly_left_1_rmd_x8_90_mock_3_inner_rmd_x8_90_1_simple.stl"/>
    <mesh name="leg_assembly_right_1_rmd_x8_90_mock_3_inner_rmd_x8_90_1_simple" file="leg_assembly_right_1_rmd_x8_90_mock_3_inner_rmd_x8_90_1_simple.stl"/>
    <mesh name="leg_assembly_left_1_leg_part_6_2_simple" file="leg_assembly_left_1_leg_part_6_2_simple.stl"/>
    <mesh name="leg_assembly_right_1_leg_part_6_2_simple" file="leg_assembly_right_1_leg_part_6_2_simple.stl"/>
    <mesh name="leg_assembly_left_1_rmd_x4_24_mock_1_inner_rmd_x4_24_1_simple" file="leg_assembly_left_1_rmd_x4_24_mock_1_inner_rmd_x4_24_1_simple.stl"/>
    <mesh name="leg_assembly_left_1_leg_part_7_1_simple" file="leg_assembly_left_1_leg_part_7_1_simple.stl"/>
    <mesh name="leg_assembly_right_1_rmd_x4_24_mock_1_inner_rmd_x4_24_1_simple" file="leg_assembly_right_1_rmd_x4_24_mock_1_inner_rmd_x4_24_1_simple.stl"/>
    <mesh name="leg_assembly_right_1_leg_part_7_1_simple" file="leg_assembly_right_1_leg_part_7_1_simple.stl"/>
    <mesh name="leg_assembly_left_1_rmd_x4_24_mock_1_outer_rmd_x4_24_1_simple" file="leg_assembly_left_1_rmd_x4_24_mock_1_outer_rmd_x4_24_1_simple.stl"/>
    <mesh name="leg_assembly_right_1_rmd_x4_24_mock_1_outer_rmd_x4_24_1_simple" file="leg_assembly_right_1_rmd_x4_24_mock_1_outer_rmd_x4_24_1_simple.stl"/>
    <mesh name="left_foot_1_ankle_half_2_left_1_simple" file="left_foot_1_ankle_half_2_left_1_simple.stl"/>
    <mesh name="right_foot_1_ankle_half_2_right_2_simple" file="right_foot_1_ankle_half_2_right_2_simple.stl"/>
    <mesh name="left_foot_1_rmd_x4_24_mock_1_outer_rmd_x4_24_1_simple" file="left_foot_1_rmd_x4_24_mock_1_outer_rmd_x4_24_1_simple.stl"/>
    <mesh name="left_foot_1_ankle_half_1_left_2_simple" file="left_foot_1_ankle_half_1_left_2_simple.stl"/>
    <mesh name="right_foot_1_ankle_half_1_right_1_simple" file="right_foot_1_ankle_half_1_right_1_simple.stl"/>
    <mesh name="right_foot_1_rmd_x4_24_mock_1_outer_rmd_x4_24_1_simple" file="right_foot_1_rmd_x4_24_mock_1_outer_rmd_x4_24_1_simple.stl"/>
    <mesh name="left_foot_1_rmd_x4_24_mock_1_inner_rmd_x4_24_1_simple" file="left_foot_1_rmd_x4_24_mock_1_inner_rmd_x4_24_1_simple.stl"/>
    <mesh name="right_foot_1_rmd_x4_24_mock_1_inner_rmd_x4_24_1_simple" file="right_foot_1_rmd_x4_24_mock_1_inner_rmd_x4_24_1_simple.stl"/>
    <mesh name="left_foot_1_foot_1_simple" file="left_foot_1_foot_1_simple.stl"/>
    <mesh name="right_foot_1_foot_1_simple" file="right_foot_1_foot_1_simple.stl"/>
    <mesh name="left_foot_1_rubber_grip_1_simple" file="left_foot_1_rubber_grip_1_simple.stl"/>
    <mesh name="right_foot_1_rubber_grip_3_simple" file="right_foot_1_rubber_grip_3_simple.stl"/>
  </asset>
  <worldbody>
    <body name="link_leg_assembly_left_1_leg_part_1_2">
      <inertial pos="-0.0209987 -9.78348e-08 -0.0446469" quat="-0.0229216 0.694022 -0.025113 0.71915" mass="2.67685" diaginertia="0.00887839 0.00772181 0.00489941"/>
      <joint name="link_leg_assembly_left_1_leg_part_1_2_free_joint" type="free"/>
      <geom type="mesh" rgba="0.615686 0.811765 0.929412 1" mesh="leg_assembly_left_1_leg_part_1_2_simple"/>
      <geom pos="-0.0209987 -0.0690001 0.0170241" quat="0.5 -0.5 -0.5 0.5" type="mesh" rgba="0.615686 0.811765 0.929412 1" mesh="leg_assembly_right_1_leg_part_1_2_simple"/>
      <geom pos="-0.0409987 -0.0071598 0.0055805" quat="-0.5 -0.5 0.5 0.5" type="mesh" rgba="0.647059 0.647059 0.647059 1" mesh="leg_assembly_right_1_rmd_x12_150_mock_1_outer_x12_150_1_simple"/>
      <geom pos="0.0277917 -0.0487905 0.0505241" quat="-1.64085e-08 0.707107 -0.707107 1.64085e-08" type="mesh" rgba="0.615686 0.811765 0.929412 1" mesh="part_1_1_simple"/>
      <geom pos="-0.000998677 0.0071596 0.0055805" quat="0.5 0.5 0.5 0.5" type="mesh" rgba="0.647059 0.647059 0.647059 1" mesh="leg_assembly_left_1_rmd_x12_150_mock_1_outer_x12_150_1_simple"/>
      <body name="link_leg_assembly_right_1_rmd_x12_150_mock_1_inner_x12_150_1" pos="-0.0654987 -9.85788e-08 -0.0519759" quat="0.707107 0 0.707107 -5.17638e-08">
        <inertial pos="0.000136577 0.00766442 -0.0822654" quat="0.999515 0.0116071 -0.000919827 0.0288764" mass="0.882229" diaginertia="0.00247019 0.00245661 0.00104762"/>
        <joint name="right hip pitch" pos="0 0 0" axis="0 0 -1" range="-4.71239 4.71239"/>
        <geom type="mesh" rgba="0.231373 0.380392 0.705882 1" mesh="leg_assembly_right_1_rmd_x12_150_mock_1_inner_x12_150_1_simple"/>
        <geom pos="0 0 -0.023" quat="0.707107 0 0 0.707107" type="mesh" rgba="0.647059 0.647059 0.647059 1" mesh="leg_assembly_right_1_leg_part_2_right_1_simple"/>
        <geom pos="-0.0185601 0.02785 -0.0566918" quat="0.707107 -0.707107 0 0" type="mesh" rgba="0.498039 0.498039 0.498039 1" mesh="leg_assembly_right_1_rmd_x8_90_mock_1_outer_rmd_x8_90_1_simple"/>
        <body name="link_leg_assembly_right_1_rmd_x8_90_mock_1_inner_rmd_x8_90_1" pos="7.46238e-10 -0.01965 -0.1015" quat="0.707107 0.707107 0 0">
          <inertial pos="-0.0374104 -0.0647967 -0.0203372" quat="0.673291 0.692606 -0.185564 -0.180396" mass="1.13448" diaginertia="0.00538424 0.00496198 0.00153842"/>
          <joint name="right hip yaw" pos="0 0 0" axis="0 0 -1" range="-4.71239 4.71239"/>
          <geom type="mesh" rgba="0.980392 0.713726 0.00392157 1" mesh="leg_assembly_right_1_rmd_x8_90_mock_1_inner_rmd_x8_90_1_simple"/>
          <geom pos="0.0216506 0.0125 0.0035" quat="-1.16026e-08 0.5 -0.866025 2.00962e-08" type="mesh" rgba="0.231373 0.380392 0.705882 1" mesh="leg_assembly_right_1_leg_part_3_1_simple"/>
          <geom pos="0.00446153 -0.112272 -0.072" quat="-0.5 -2.32051e-08 4.01924e-08 0.866025" type="mesh" rgba="0.647059 0.647059 0.647059 1" mesh="leg_assembly_right_1_leg_part_4_1_simple"/>
          <geom pos="-0.016195 -0.117667 -0.00108985" quat="-0.683013 0.683013 -0.183013 0.183013" type="mesh" rgba="0.498039 0.498039 0.498039 1" mesh="leg_assembly_right_1_rmd_x8_90_mock_2_outer_rmd_x8_90_1_simple"/>
          <body name="link_leg_assembly_right_1_rmd_x8_90_mock_2_inner_rmd_x8_90_1" pos="-0.07875 -0.136399 -0.01965" quat="-0.683013 -0.683013 0.183013 0.183013">
            <inertial pos="0.000314021 -0.00746488 0.0700513" quat="0.997762 0.0259608 0.0075854 -0.06115" mass="1.13901" diaginertia="0.00575132 0.00523933 0.00174755"/>
            <joint name="right hip roll" pos="0 0 0" axis="0 0 -1" range="-3.14159 3.14159"/>
            <geom type="mesh" rgba="0.980392 0.713726 0.00392157 1" mesh="leg_assembly_right_1_rmd_x8_90_mock_2_inner_rmd_x8_90_1_simple"/>
            <geom pos="-0.0216506 -0.0125 0.0035" quat="-1.64085e-08 0.707107 0.707107 -1.64085e-08" type="mesh" rgba="0.647059 0.647059 0.647059 1" mesh="leg_assembly_right_1_leg_part_5_right_2_simple"/>
            <geom pos="0.0448082 -0.02685 0.10844" quat="0.5 0.5 0.5 -0.5" type="mesh" rgba="0.498039 0.498039 0.498039 1" mesh="leg_assembly_right_1_rmd_x8_90_mock_3_outer_rmd_x8_90_1_simple"/>
            <body name="link_leg_assembly_right_1_rmd_x8_90_mock_3_inner_rmd_x8_90_1" pos="6.61991e-09 0.02065 0.127" quat="-0.5 0.5 -0.5 -0.5">
              <inertial pos="0.0449624 -0.0780024 -0.0105593" quat="0.342486 0.599201 -0.364314 0.625249" mass="0.88694" diaginertia="0.0089172 0.00801876 0.00354829"/>
              <joint name="right knee pitch" pos="0 0 0" axis="0 0 -1" range="-4.71239 4.71239"/>
              <geom type="mesh" rgba="0.980392 0.713726 0.00392157 1" mesh="leg_assembly_right_1_rmd_x8_90_mock_3_inner_rmd_x8_90_1_simple"/>
              <geom pos="0.0216506 0.0125 0.0035" quat="-2.00962e-08 0.866025 -0.5 1.16026e-08" type="mesh" rgba="0.647059 0.647059 0.647059 1" mesh="leg_assembly_right_1_leg_part_6_2_simple"/>
              <geom pos="0.111714 -0.219494 0.0121" quat="-0.104528 -2.36245e-08 1.36396e-08 0.994522" type="mesh" rgba="0.768627 0.886275 0.952941 1" mesh="leg_assembly_right_1_rmd_x4_24_mock_1_inner_rmd_x4_24_1_simple"/>
              <geom pos="0.0825 -0.142894 -0.074" quat="-2.00962e-08 0.866025 -0.5 1.16026e-08" type="mesh" rgba="0.647059 0.647059 0.647059 1" mesh="leg_assembly_right_1_leg_part_7_1_simple"/>
              <body name="link_leg_assembly_right_1_rmd_x4_24_mock_1_outer_rmd_x4_24_1" pos="0.123 -0.213042 -0.0129" quat="2.60501e-08 -0.104528 0.994522 -3.67176e-08">
                <inertial pos="-0.000520129 -0.0339665 0.0111351" quat="0.407253 0.363794 -0.597823 0.586861" mass="0.607709" diaginertia="0.0011136 0.00102813 0.00055403"/>
                <joint name="right ankle pitch" pos="0 0 0" axis="0 0 -1" range="-1.5708 2.18166"/>
                <geom type="mesh" rgba="0.917647 0.917647 0.917647 1" mesh="leg_assembly_right_1_rmd_x4_24_mock_1_outer_rmd_x4_24_1_simple"/>
                <geom pos="-0.01225 -0.0212176 -0.02" type="mesh" rgba="0.615686 0.811765 0.929412 1" mesh="right_foot_1_ankle_half_2_right_2_simple"/>
                <geom pos="0 -0.038 -0.02845" quat="-1.64085e-08 -0.707107 -1.64085e-08 0.707107" type="mesh" rgba="0.615686 0.811765 0.929412 1" mesh="right_foot_1_ankle_half_1_right_1_simple"/>
                <geom pos="-0.0335 -0.04705 0.01055" quat="0.707107 0 0.707107 0" type="mesh" rgba="0.917647 0.917647 0.917647 1" mesh="right_foot_1_rmd_x4_24_mock_1_outer_rmd_x4_24_1_simple"/>
                <body name="link_right_foot_1_rmd_x4_24_mock_1_inner_rmd_x4_24_1" pos="-0.0135 -0.07155 0.01055" quat="0.5 0.5 0.5 0.5">
                  <inertial pos="0.00584595 -0.0275033 -0.0114478" quat="0.459334 0.455838 0.540626 0.537538" mass="0.422846" diaginertia="0.00126194 0.00111472 0.000765745"/>
                  <joint name="right ankle roll" pos="0 0 0" axis="0 0 -1" range="-2.26893 -1.22173"/>
                  <geom type="mesh" rgba="0.768627 0.886275 0.952941 1" mesh="right_foot_1_rmd_x4_24_mock_1_inner_rmd_x4_24_1_simple"/>
                  <geom pos="0.00275746 -0.0127042 -0.025" quat="0.994522 0 0 0.104528" type="mesh" rgba="0.615686 0.811765 0.929412 1" mesh="right_foot_1_foot_1_simple"/>
                  <geom pos="0.0103956 -0.0489074 -0.0147699" quat="-0.0739128 -0.0739128 0.703233 0.703233" type="mesh" rgba="0.647059 0.647059 0.647059 1" mesh="right_foot_1_rubber_grip_3_simple"/>
                </body>
              </body>
            </body>
          </body>
        </body>
      </body>
      <body name="link_leg_assembly_left_1_rmd_x12_150_mock_1_inner_x12_150_1" pos="0.0235013 -9.74565e-08 -0.0519759" quat="-3.53553e-08 0.707107 -1.64085e-08 -0.707107">
        <inertial pos="0.00368751 -0.00038695 -0.0822654" quat="0.774702 0.00272359 0.00613594 0.632291" mass="0.882229" diaginertia="0.00246229 0.0024559 0.00104003"/>
        <joint name="left hip pitch" pos="0 0 0" axis="0 0 -1" range="-4.71239 4.71239"/>
        <geom type="mesh" rgba="0.231373 0.380392 0.705882 1" mesh="leg_assembly_left_1_rmd_x12_150_mock_1_inner_x12_150_1_simple"/>
        <geom pos="0 -0.0185 -0.023" type="mesh" rgba="0.647059 0.647059 0.647059 1" mesh="leg_assembly_left_1_leg_part_2_left_1_simple"/>
        <geom pos="0.0230618 0.0179298 -0.146308" quat="0.5 -0.5 0.5 -0.5" type="mesh" rgba="0.498039 0.498039 0.498039 1" mesh="leg_assembly_left_1_rmd_x8_90_mock_1_outer_rmd_x8_90_1_simple"/>
        <body name="link_leg_assembly_left_1_rmd_x8_90_mock_1_inner_rmd_x8_90_1" pos="-0.0244382 -0.000630373 -0.1015" quat="0.5 0.5 -0.5 -0.5">
          <inertial pos="-0.0374104 -0.0647967 -0.0203372" quat="0.673291 0.692606 -0.185564 -0.180396" mass="1.13448" diaginertia="0.00538424 0.00496198 0.00153842"/>
          <joint name="left hip yaw" pos="0 0 0" axis="0 0 -1" range="-1.0472 2.0944"/>
          <geom type="mesh" rgba="0.980392 0.713726 0.00392157 1" mesh="leg_assembly_left_1_rmd_x8_90_mock_1_inner_rmd_x8_90_1_simple"/>
          <geom pos="0.0216506 0.0125 0.0035" quat="-1.16026e-08 0.5 -0.866025 2.00962e-08" type="mesh" rgba="0.231373 0.380392 0.705882 1" mesh="leg_assembly_left_1_leg_part_3_1_simple"/>
          <geom pos="0.00446153 -0.112272 -0.072" quat="-0.5 -2.32051e-08 4.01924e-08 0.866025" type="mesh" rgba="0.647059 0.647059 0.647059 1" mesh="leg_assembly_left_1_leg_part_4_1_simple"/>
          <geom pos="-0.016195 -0.117667 -0.00108985" quat="-0.683013 0.683013 -0.183013 0.183013" type="mesh" rgba="0.498039 0.498039 0.498039 1" mesh="leg_assembly_left_1_rmd_x8_90_mock_2_outer_rmd_x8_90_1_simple"/>
          <body name="link_leg_assembly_left_1_rmd_x8_90_mock_2_inner_rmd_x8_90_1" pos="-0.07875 -0.136399 -0.01965" quat="-0.683013 -0.683013 0.183013 0.183013">
            <inertial pos="-0.00746487 0.000314022 0.0700513" quat="0.750096 -0.0216942 -0.0143413 0.660817" mass="1.13901" diaginertia="0.00575194 0.00523779 0.00174847"/>
            <joint name="left hip roll" pos="0 0 0" axis="0 0 -1" range="-3.14159 0"/>
            <geom type="mesh" rgba="0.980392 0.713726 0.00392157 1" mesh="leg_assembly_left_1_rmd_x8_90_mock_2_inner_rmd_x8_90_1_simple"/>
            <geom pos="0 0 0.0035" quat="0 -2.32051e-08 1 -2.32051e-08" type="mesh" rgba="0.647059 0.647059 0.647059 1" mesh="leg_assembly_left_1_let_part_5_left_1_simple"/>
            <geom pos="-0.02685 0.0448082 0.10844" quat="-4.92255e-08 -0.707107 -1.64085e-08 0.707107" type="mesh" rgba="0.498039 0.498039 0.498039 1" mesh="leg_assembly_left_1_rmd_x8_90_mock_3_outer_rmd_x8_90_1_simple"/>
            <body name="link_leg_assembly_left_1_rmd_x8_90_mock_3_inner_rmd_x8_90_1" pos="0.02065 8.89452e-09 0.127" quat="0.707107 -3.2817e-08 0.707107 0">
              <inertial pos="0.0449624 -0.0780024 -0.0105593" quat="0.342486 0.599201 -0.364314 0.625249" mass="0.88694" diaginertia="0.0089172 0.00801876 0.00354829"/>
              <joint name="left knee pitch" pos="0 0 0" axis="0 0 -1" range="-4.71239 4.71239"/>
              <geom type="mesh" rgba="0.980392 0.713726 0.00392157 1" mesh="leg_assembly_left_1_rmd_x8_90_mock_3_inner_rmd_x8_90_1_simple"/>
              <geom pos="0.0216506 0.0125 0.0035" quat="-2.00962e-08 0.866025 -0.5 1.16026e-08" type="mesh" rgba="0.647059 0.647059 0.647059 1" mesh="leg_assembly_left_1_leg_part_6_2_simple"/>
              <geom pos="0.111714 -0.219494 0.0121" quat="-0.104528 -2.36245e-08 1.36396e-08 0.994522" type="mesh" rgba="0.768627 0.886275 0.952941 1" mesh="leg_assembly_left_1_rmd_x4_24_mock_1_inner_rmd_x4_24_1_simple"/>
              <geom pos="0.0825 -0.142894 -0.074" quat="-2.00962e-08 0.866025 -0.5 1.16026e-08" type="mesh" rgba="0.647059 0.647059 0.647059 1" mesh="leg_assembly_left_1_leg_part_7_1_simple"/>
              <body name="link_leg_assembly_left_1_rmd_x4_24_mock_1_outer_rmd_x4_24_1" pos="0.123 -0.213042 -0.0129" quat="2.60501e-08 -0.104528 0.994522 -3.67176e-08">
                <inertial pos="0.000520119 -0.0339665 0.0111351" quat="0.409176 0.423549 -0.543798 0.597883" mass="0.60771" diaginertia="0.00111379 0.00104116 0.000540824"/>
                <joint name="left ankle pitch" pos="0 0 0" axis="0 0 -1" range="-1.5708 2.18166"/>
                <geom type="mesh" rgba="0.917647 0.917647 0.917647 1" mesh="leg_assembly_left_1_rmd_x4_24_mock_1_outer_rmd_x4_24_1_simple"/>
                <geom pos="0.01225 -0.0212176 -0.02" type="mesh" rgba="0.615686 0.811765 0.929412 1" mesh="left_foot_1_ankle_half_2_left_1_simple"/>
                <geom pos="0.0335 -0.04705 0.01055" quat="-1.64085e-08 0.707107 -1.64085e-08 -0.707107" type="mesh" rgba="0.917647 0.917647 0.917647 1" mesh="left_foot_1_rmd_x4_24_mock_1_outer_rmd_x4_24_1_simple"/>
                <geom pos="0 0.0145 0.04735" quat="0.707107 0 0.707107 0" type="mesh" rgba="0.615686 0.811765 0.929412 1" mesh="left_foot_1_ankle_half_1_left_2_simple"/>
                <body name="link_left_foot_1_rmd_x4_24_mock_1_inner_rmd_x4_24_1" pos="0.0135 -0.07155 0.01055" quat="-0.5 0.5 0.5 -0.5">
                  <inertial pos="0.00584595 -0.0275033 -0.0114478" quat="0.459334 0.455838 0.540626 0.537538" mass="0.422846" diaginertia="0.00126194 0.00111472 0.000765745"/>
                  <joint name="left ankle roll" pos="0 0 0" axis="0 0 -1" range="-2.26893 -1.22173"/>
                  <geom type="mesh" rgba="0.768627 0.886275 0.952941 1" mesh="left_foot_1_rmd_x4_24_mock_1_inner_rmd_x4_24_1_simple"/>
                  <geom pos="0.00275746 -0.0127042 -0.025" quat="0.994522 0 0 0.104528" type="mesh" rgba="0.615686 0.811765 0.929412 1" mesh="left_foot_1_foot_1_simple"/>
                  <geom pos="0.0103956 -0.0489074 -0.0147699" quat="0.703233 -0.703233 -0.0739128 0.0739128" type="mesh" rgba="0.647059 0.647059 0.647059 1" mesh="left_foot_1_rubber_grip_1_simple"/>
                </body>
              </body>
            </body>
          </body>
        </body>
      </body>
    </body>
  </worldbody>
</mujoco>
