<robot name="lower_limbs">
  <link name="link_leg_assembly_left_1_leg_part_1_2">
    <visual>
      <origin xyz="0 0 0" rpy="0 0 0" />
      <geometry>
        <mesh filename="./meshes/leg_assembly_left_1_leg_part_1_2_simple.stl" />
        </geometry>
      <material name="link_leg_assembly_left_1_leg_part_1_2_material">
        <color rgba="0.61568627 0.81176471 0.92941176 1" />
        </material>
      </visual>
    <collision>
      <origin xyz="0 0 0" rpy="0 0 0" />
      <geometry>
        <mesh filename="./meshes/leg_assembly_left_1_leg_part_1_2_simple.stl" />
        </geometry>
      </collision>
    <inertial>
      <mass value="0.18740424" />
      <inertia ixx="0.00086371009" iyy="0.00049678333" izz="0.00050512115" ixy="0" ixz="-8.1028268e-05" iyz="0" />
      <origin xyz="0 0 0" rpy="-3.1415129 0 3.1415282" />
      </inertial>
    </link>
  <link name="link_leg_assembly_right_1_leg_part_1_2">
    <visual>
      <origin xyz="0 0 0" rpy="0 0 0" />
      <geometry>
        <mesh filename="./meshes/leg_assembly_right_1_leg_part_1_2_simple.stl" />
        </geometry>
      <material name="link_leg_assembly_right_1_leg_part_1_2_material">
        <color rgba="0.61568627 0.81176471 0.92941176 1" />
        </material>
      </visual>
    <collision>
      <origin xyz="0 0 0" rpy="0 0 0" />
      <geometry>
        <mesh filename="./meshes/leg_assembly_right_1_leg_part_1_2_simple.stl" />
        </geometry>
      </collision>
    <inertial>
      <mass value="0.18740424" />
      <inertia ixx="0.00050512115" iyy="0.00086371009" izz="0.00049678333" ixy="8.1028268e-05" ixz="0" iyz="0" />
      <origin xyz="0.068999903 0.017024107 0.020998677" rpy="-0.21686582 -0.20732123 0.045338571" />
      </inertial>
    </link>
  <joint name="joint_fastened_4" type="fixed">
    <origin xyz="-0.020998677 -0.069000097 0.017024107" rpy="-1.5707963 0 1.5707963" />
    <parent link="link_leg_assembly_left_1_leg_part_1_2" />
    <child link="link_leg_assembly_right_1_leg_part_1_2" />
    </joint>
  <link name="link_part_1_1">
    <visual>
      <origin xyz="0 0 0" rpy="0 0 0" />
      <geometry>
        <mesh filename="./meshes/part_1_1_simple.stl" />
        </geometry>
      <material name="link_part_1_1_material">
        <color rgba="0.61568627 0.81176471 0.92941176 1" />
        </material>
      </visual>
    <collision>
      <origin xyz="0 0 0" rpy="0 0 0" />
      <geometry>
        <mesh filename="./meshes/part_1_1_simple.stl" />
        </geometry>
      </collision>
    <inertial>
      <mass value="0.001" />
      <inertia ixx="0" iyy="0" izz="0" ixy="0" ixz="0" iyz="0" />
      <origin xyz="-0.04879037 0.04879037 0" rpy="3.1415927 0 0" />
      </inertial>
    </link>
  <joint name="joint_fastened_10" type="fixed">
    <origin xyz="0.02779169 -0.048790465 0.050524107" rpy="3.1415927 0 -1.5707963" />
    <parent link="link_leg_assembly_left_1_leg_part_1_2" />
    <child link="link_part_1_1" />
    </joint>
  <link name="link_leg_assembly_left_1_rmd_x12_150_mock_1_outer_x12_150_1">
    <visual>
      <origin xyz="0 0 0" rpy="0 0 0" />
      <geometry>
        <mesh filename="./meshes/leg_assembly_left_1_rmd_x12_150_mock_1_outer_x12_150_1_simple.stl" />
        </geometry>
      <material name="link_leg_assembly_left_1_rmd_x12_150_mock_1_outer_x12_150_1_material">
        <color rgba="0.64705882 0.64705882 0.64705882 1" />
        </material>
      </visual>
    <collision>
      <origin xyz="0 0 0" rpy="0 0 0" />
      <geometry>
        <mesh filename="./meshes/leg_assembly_left_1_rmd_x12_150_mock_1_outer_x12_150_1_simple.stl" />
        </geometry>
      </collision>
    <inertial>
      <mass value="1.1505225" />
      <inertia ixx="0.0021889818" iyy="0.0013275542" izz="0.0013578926" ixy="0" ixz="0" iyz="0" />
      <origin xyz="-0.0071587856 -0.057541153 0.015897698" rpy="1.5714571 -0.00071109293 -1.5709195" />
      </inertial>
    </link>
  <joint name="joint_leg_assembly_left_1_fastened_12" type="fixed">
    <origin xyz="-0.00099867745 0.0071596031 0.0055805032" rpy="1.5707963 0 1.5707963" />
    <parent link="link_leg_assembly_left_1_leg_part_1_2" />
    <child link="link_leg_assembly_left_1_rmd_x12_150_mock_1_outer_x12_150_1" />
    </joint>
  <link name="link_leg_assembly_right_1_rmd_x12_150_mock_1_outer_x12_150_1">
    <visual>
      <origin xyz="0 0 0" rpy="0 0 0" />
      <geometry>
        <mesh filename="./meshes/leg_assembly_right_1_rmd_x12_150_mock_1_outer_x12_150_1_simple.stl" />
        </geometry>
      <material name="link_leg_assembly_right_1_rmd_x12_150_mock_1_outer_x12_150_1_material">
        <color rgba="0.64705882 0.64705882 0.64705882 1" />
        </material>
      </visual>
    <collision>
      <origin xyz="0 0 0" rpy="0 0 0" />
      <geometry>
        <mesh filename="./meshes/leg_assembly_right_1_rmd_x12_150_mock_1_outer_x12_150_1_simple.stl" />
        </geometry>
      </collision>
    <inertial>
      <mass value="1.1505225" />
      <inertia ixx="0.0021889818" iyy="0.0013275542" izz="0.0013578926" ixy="0" ixz="0" iyz="0" />
      <origin xyz="-0.0071587856 -0.057541153 0.015897698" rpy="1.5714571 -0.00071109293 -1.5709195" />
      </inertial>
    </link>
  <joint name="joint_leg_assembly_right_1_fastened_12" type="fixed">
    <origin xyz="0.0618403 0.011443604 0.02" rpy="0 0 3.1415927" />
    <parent link="link_leg_assembly_right_1_leg_part_1_2" />
    <child link="link_leg_assembly_right_1_rmd_x12_150_mock_1_outer_x12_150_1" />
    </joint>
  <link name="link_leg_assembly_left_1_rmd_x12_150_mock_1_inner_x12_150_1">
    <visual>
      <origin xyz="0 0 0" rpy="0 0 0" />
      <geometry>
        <mesh filename="./meshes/leg_assembly_left_1_rmd_x12_150_mock_1_inner_x12_150_1_simple.stl" />
        </geometry>
      <material name="link_leg_assembly_left_1_rmd_x12_150_mock_1_inner_x12_150_1_material">
        <color rgba="0.23137255 0.38039216 0.70588235 1" />
        </material>
      </visual>
    <collision>
      <origin xyz="0 0 0" rpy="0 0 0" />
      <geometry>
        <mesh filename="./meshes/leg_assembly_left_1_rmd_x12_150_mock_1_inner_x12_150_1_simple.stl" />
        </geometry>
      </collision>
    <inertial>
      <mass value="0.1494739" />
      <inertia ixx="4.1852816e-05" iyy="4.1852816e-05" izz="7.1701209e-05" ixy="0" ixz="0" iyz="0" />
      <origin xyz="0 0 -0.010858971" rpy="3.1415927 0 0" />
      </inertial>
    </link>
  <joint name="left hip pitch" type="revolute">
    <origin xyz="-0.0071596999 -0.057556396 0.0245" rpy="3.1415927 0 -1.5707963" />
    <parent link="link_leg_assembly_left_1_rmd_x12_150_mock_1_outer_x12_150_1" />
    <child link="link_leg_assembly_left_1_rmd_x12_150_mock_1_inner_x12_150_1" />
    <limit effort="150" velocity="25" lower="0.5" upper="2.69" />
    <axis xyz="0 0 -1" />
    </joint>
  <link name="link_leg_assembly_right_1_rmd_x12_150_mock_1_inner_x12_150_1">
    <visual>
      <origin xyz="0 0 0" rpy="0 0 0" />
      <geometry>
        <mesh filename="./meshes/leg_assembly_right_1_rmd_x12_150_mock_1_inner_x12_150_1_simple.stl" />
        </geometry>
      <material name="link_leg_assembly_right_1_rmd_x12_150_mock_1_inner_x12_150_1_material">
        <color rgba="0.23137255 0.38039216 0.70588235 1" />
        </material>
      </visual>
    <collision>
      <origin xyz="0 0 0" rpy="0 0 0" />
      <geometry>
        <mesh filename="./meshes/leg_assembly_right_1_rmd_x12_150_mock_1_inner_x12_150_1_simple.stl" />
        </geometry>
      </collision>
    <inertial>
      <mass value="0.1494739" />
      <inertia ixx="4.1852816e-05" iyy="4.1852816e-05" izz="7.1701209e-05" ixy="0" ixz="0" iyz="0" />
      <origin xyz="0 0 -0.010858971" rpy="3.1415927 0 0" />
      </inertial>
    </link>
  <joint name="right hip pitch" type="revolute">
    <origin xyz="-0.0071596999 -0.057556396 0.0245" rpy="3.1415927 0 -1.5707963" />
    <parent link="link_leg_assembly_right_1_rmd_x12_150_mock_1_outer_x12_150_1" />
    <child link="link_leg_assembly_right_1_rmd_x12_150_mock_1_inner_x12_150_1" />
    <limit effort="150" velocity="25" lower="-1" upper="1" />
    <axis xyz="0 0 -1" />
    </joint>
  <link name="link_leg_assembly_left_1_leg_part_2_left_1">
    <visual>
      <origin xyz="0 0 0" rpy="0 0 0" />
      <geometry>
        <mesh filename="./meshes/leg_assembly_left_1_leg_part_2_left_1_simple.stl" />
        </geometry>
      <material name="link_leg_assembly_left_1_leg_part_2_left_1_material">
        <color rgba="0.64705882 0.64705882 0.64705882 1" />
        </material>
      </visual>
    <collision>
      <origin xyz="0 0 0" rpy="0 0 0" />
      <geometry>
        <mesh filename="./meshes/leg_assembly_left_1_leg_part_2_left_1_simple.stl" />
        </geometry>
      </collision>
    <inertial>
      <mass value="0.23289661" />
      <inertia ixx="0.0009832984" iyy="0.0006932322" izz="0.00049537603" ixy="-2.5858642e-06" ixz="-3.4541587e-05" iyz="-9.3648936e-06" />
      <origin xyz="0.007274543 0.018387155 -0.063811708" rpy="-3.1004224 -0.044182126 -3.1413808" />
      </inertial>
    </link>
  <joint name="joint_leg_assembly_left_1_fastened_1" type="fixed">
    <origin xyz="0 -0.0185 -0.023" rpy="0 0 0" />
    <parent link="link_leg_assembly_left_1_rmd_x12_150_mock_1_inner_x12_150_1" />
    <child link="link_leg_assembly_left_1_leg_part_2_left_1" />
    </joint>
  <link name="link_leg_assembly_right_1_leg_part_2_right_1">
    <visual>
      <origin xyz="0 0 0" rpy="0 0 0" />
      <geometry>
        <mesh filename="./meshes/leg_assembly_right_1_leg_part_2_right_1_simple.stl" />
        </geometry>
      <material name="link_leg_assembly_right_1_leg_part_2_right_1_material">
        <color rgba="0.64705882 0.64705882 0.64705882 1" />
        </material>
      </visual>
    <collision>
      <origin xyz="0 0 0" rpy="0 0 0" />
      <geometry>
        <mesh filename="./meshes/leg_assembly_right_1_leg_part_2_right_1_simple.stl" />
        </geometry>
      </collision>
    <inertial>
      <mass value="0.23289667" />
      <inertia ixx="0.00098329864" iyy="0.00069323288" izz="0.00049537596" ixy="2.5855964e-06" ixz="-3.4541887e-05" iyz="9.3657742e-06" />
      <origin xyz="0.012062724 -0.0005173634 -0.063811736" rpy="3.1004173 -0.044187644 3.1413808" />
      </inertial>
    </link>
  <joint name="joint_leg_assembly_right_1_fastened_84" type="fixed">
    <origin xyz="0 0 -0.023" rpy="0 0 1.5707963" />
    <parent link="link_leg_assembly_right_1_rmd_x12_150_mock_1_inner_x12_150_1" />
    <child link="link_leg_assembly_right_1_leg_part_2_right_1" />
    </joint>
  <link name="link_leg_assembly_left_1_rmd_x8_90_mock_1_outer_rmd_x8_90_1">
    <visual>
      <origin xyz="0 0 0" rpy="0 0 0" />
      <geometry>
        <mesh filename="./meshes/leg_assembly_left_1_rmd_x8_90_mock_1_outer_rmd_x8_90_1_simple.stl" />
        </geometry>
      <material name="link_leg_assembly_left_1_rmd_x8_90_mock_1_outer_rmd_x8_90_1_material">
        <color rgba="0.49803922 0.49803922 0.49803922 1" />
        </material>
      </visual>
    <collision>
      <origin xyz="0 0 0" rpy="0 0 0" />
      <geometry>
        <mesh filename="./meshes/leg_assembly_left_1_rmd_x8_90_mock_1_outer_rmd_x8_90_1_simple.stl" />
        </geometry>
      </collision>
    <inertial>
      <mass value="0.49985879" />
      <inertia ixx="0.00048280871" iyy="0.00046437396" izz="0.00076940631" ixy="0" ixz="0" iyz="0" />
      <origin xyz="0.018560146 -0.044808157 -0.019942948" rpy="0 1.5707963 0" />
      </inertial>
    </link>
  <joint name="joint_leg_assembly_left_1_fastened_2" type="fixed">
    <origin xyz="0.023061848 0.036429774 -0.12330816" rpy="-1.5707963 0 -1.5707963" />
    <parent link="link_leg_assembly_left_1_leg_part_2_left_1" />
    <child link="link_leg_assembly_left_1_rmd_x8_90_mock_1_outer_rmd_x8_90_1" />
    </joint>
  <link name="link_leg_assembly_right_1_rmd_x8_90_mock_1_outer_rmd_x8_90_1">
    <visual>
      <origin xyz="0 0 0" rpy="0 0 0" />
      <geometry>
        <mesh filename="./meshes/leg_assembly_right_1_rmd_x8_90_mock_1_outer_rmd_x8_90_1_simple.stl" />
        </geometry>
      <material name="link_leg_assembly_right_1_rmd_x8_90_mock_1_outer_rmd_x8_90_1_material">
        <color rgba="0.49803922 0.49803922 0.49803922 1" />
        </material>
      </visual>
    <collision>
      <origin xyz="0 0 0" rpy="0 0 0" />
      <geometry>
        <mesh filename="./meshes/leg_assembly_right_1_rmd_x8_90_mock_1_outer_rmd_x8_90_1_simple.stl" />
        </geometry>
      </collision>
    <inertial>
      <mass value="0.49985879" />
      <inertia ixx="0.00048280871" iyy="0.00046437396" izz="0.00076940631" ixy="0" ixz="0" iyz="0" />
      <origin xyz="0.018560146 0.044808157 -0.019942948" rpy="0 1.5707963 0" />
      </inertial>
    </link>
  <joint name="joint_leg_assembly_right_1_fastened_85" type="fixed">
    <origin xyz="0.02785 0.018560146 -0.033691843" rpy="-1.5707963 0 -1.5707963" />
    <parent link="link_leg_assembly_right_1_leg_part_2_right_1" />
    <child link="link_leg_assembly_right_1_rmd_x8_90_mock_1_outer_rmd_x8_90_1" />
    </joint>
  <link name="link_leg_assembly_left_1_rmd_x8_90_mock_1_inner_rmd_x8_90_1">
    <visual>
      <origin xyz="0 0 0" rpy="0 0 0" />
      <geometry>
        <mesh filename="./meshes/leg_assembly_left_1_rmd_x8_90_mock_1_inner_rmd_x8_90_1_simple.stl" />
        </geometry>
      <material name="link_leg_assembly_left_1_rmd_x8_90_mock_1_inner_rmd_x8_90_1_material">
        <color rgba="0.98039216 0.71372549 0.0039215686 1" />
        </material>
      </visual>
    <collision>
      <origin xyz="0 0 0" rpy="0 0 0" />
      <geometry>
        <mesh filename="./meshes/leg_assembly_left_1_rmd_x8_90_mock_1_inner_rmd_x8_90_1_simple.stl" />
        </geometry>
      </collision>
    <inertial>
      <mass value="0.35017331" />
      <inertia ixx="0.00012756556" iyy="0.00012756556" izz="0.00022624974" ixy="0" ixz="0" iyz="0" />
      <origin xyz="0 0 -0.0084776592" rpy="3.1415927 0 0" />
      </inertial>
    </link>
  <joint name="left hip yaw" type="revolute">
    <origin xyz="0.018560146 -0.044808157 -0.0475" rpy="3.1415927 0 0" />
    <parent link="link_leg_assembly_left_1_rmd_x8_90_mock_1_outer_rmd_x8_90_1" />
    <child link="link_leg_assembly_left_1_rmd_x8_90_mock_1_inner_rmd_x8_90_1" />
    <limit effort="90" velocity="40" lower="0.5" upper="1.19" />
    <axis xyz="0 0 -1" />
    </joint>
  <link name="link_leg_assembly_right_1_rmd_x8_90_mock_1_inner_rmd_x8_90_1">
    <visual>
      <origin xyz="0 0 0" rpy="0 0 0" />
      <geometry>
        <mesh filename="./meshes/leg_assembly_right_1_rmd_x8_90_mock_1_inner_rmd_x8_90_1_simple.stl" />
        </geometry>
      <material name="link_leg_assembly_right_1_rmd_x8_90_mock_1_inner_rmd_x8_90_1_material">
        <color rgba="0.98039216 0.71372549 0.0039215686 1" />
        </material>
      </visual>
    <collision>
      <origin xyz="0 0 0" rpy="0 0 0" />
      <geometry>
        <mesh filename="./meshes/leg_assembly_right_1_rmd_x8_90_mock_1_inner_rmd_x8_90_1_simple.stl" />
        </geometry>
      </collision>
    <inertial>
      <mass value="0.35017331" />
      <inertia ixx="0.00012756556" iyy="0.00012756556" izz="0.00022624974" ixy="0" ixz="0" iyz="0" />
      <origin xyz="0 0 -0.0084776592" rpy="3.1415927 0 0" />
      </inertial>
    </link>
  <joint name="right hip yaw" type="revolute">
    <origin xyz="0.018560146 0.044808157 -0.0475" rpy="3.1415927 0 0" />
    <parent link="link_leg_assembly_right_1_rmd_x8_90_mock_1_outer_rmd_x8_90_1" />
    <child link="link_leg_assembly_right_1_rmd_x8_90_mock_1_inner_rmd_x8_90_1" />
    <limit effort="90" velocity="40" lower="-2.2" upper="-1" />
    <axis xyz="0 0 -1" />
    </joint>
  <link name="link_leg_assembly_left_1_leg_part_3_1">
    <visual>
      <origin xyz="0 0 0" rpy="0 0 0" />
      <geometry>
        <mesh filename="./meshes/leg_assembly_left_1_leg_part_3_1_simple.stl" />
        </geometry>
      <material name="link_leg_assembly_left_1_leg_part_3_1_material">
        <color rgba="0.23137255 0.38039216 0.70588235 1" />
        </material>
      </visual>
    <collision>
      <origin xyz="0 0 0" rpy="0 0 0" />
      <geometry>
        <mesh filename="./meshes/leg_assembly_left_1_leg_part_3_1_simple.stl" />
        </geometry>
      </collision>
    <inertial>
      <mass value="0.1914504" />
      <inertia ixx="0.00043556748" iyy="0.00039339846" izz="0.00050360511" ixy="0" ixz="9.6383147e-05" iyz="0" />
      <origin xyz="0.097659108 0.01250002 0.01745093" rpy="-3.1415924 0 -3.1415927" />
      </inertial>
    </link>
  <joint name="joint_leg_assembly_left_1_fastened_3" type="fixed">
    <origin xyz="0.021650635 0.0125 0.0035" rpy="3.1415927 0 -2.0943951" />
    <parent link="link_leg_assembly_left_1_rmd_x8_90_mock_1_inner_rmd_x8_90_1" />
    <child link="link_leg_assembly_left_1_leg_part_3_1" />
    </joint>
  <link name="link_leg_assembly_right_1_leg_part_3_1">
    <visual>
      <origin xyz="0 0 0" rpy="0 0 0" />
      <geometry>
        <mesh filename="./meshes/leg_assembly_right_1_leg_part_3_1_simple.stl" />
        </geometry>
      <material name="link_leg_assembly_right_1_leg_part_3_1_material">
        <color rgba="0.23137255 0.38039216 0.70588235 1" />
        </material>
      </visual>
    <collision>
      <origin xyz="0 0 0" rpy="0 0 0" />
      <geometry>
        <mesh filename="./meshes/leg_assembly_right_1_leg_part_3_1_simple.stl" />
        </geometry>
      </collision>
    <inertial>
      <mass value="0.1914504" />
      <inertia ixx="0.00043556748" iyy="0.00039339846" izz="0.00050360511" ixy="0" ixz="9.6383147e-05" iyz="0" />
      <origin xyz="0.097659108 0.01250002 0.01745093" rpy="-3.1415924 0 -3.1415927" />
      </inertial>
    </link>
  <joint name="joint_leg_assembly_right_1_fastened_3" type="fixed">
    <origin xyz="0.021650635 0.0125 0.0035" rpy="3.1415927 0 -2.0943951" />
    <parent link="link_leg_assembly_right_1_rmd_x8_90_mock_1_inner_rmd_x8_90_1" />
    <child link="link_leg_assembly_right_1_leg_part_3_1" />
    </joint>
  <link name="link_leg_assembly_left_1_leg_part_4_1">
    <visual>
      <origin xyz="0 0 0" rpy="0 0 0" />
      <geometry>
        <mesh filename="./meshes/leg_assembly_left_1_leg_part_4_1_simple.stl" />
        </geometry>
      <material name="link_leg_assembly_left_1_leg_part_4_1_material">
        <color rgba="0.64705882 0.64705882 0.64705882 1" />
        </material>
      </visual>
    <collision>
      <origin xyz="0 0 0" rpy="0 0 0" />
      <geometry>
        <mesh filename="./meshes/leg_assembly_left_1_leg_part_4_1_simple.stl" />
        </geometry>
      </collision>
    <inertial>
      <mass value="0.09299573" />
      <inertia ixx="8.6209079e-05" iyy="0.00017860969" izz="0.00025876717" ixy="0" ixz="0" iyz="0" />
      <origin xyz="-0.037174443 -0.060000019 -0.0098354041" rpy="0 0 0.0017096165" />
      </inertial>
    </link>
  <joint name="joint_leg_assembly_left_1_fastened_4" type="fixed">
    <origin xyz="0.11665064 -0.0475 0.0755" rpy="3.1415927 0 0" />
    <parent link="link_leg_assembly_left_1_leg_part_3_1" />
    <child link="link_leg_assembly_left_1_leg_part_4_1" />
    </joint>
  <link name="link_leg_assembly_left_1_rmd_x8_90_mock_2_outer_rmd_x8_90_1">
    <visual>
      <origin xyz="0 0 0" rpy="0 0 0" />
      <geometry>
        <mesh filename="./meshes/leg_assembly_left_1_rmd_x8_90_mock_2_outer_rmd_x8_90_1_simple.stl" />
        </geometry>
      <material name="link_leg_assembly_left_1_rmd_x8_90_mock_2_outer_rmd_x8_90_1_material">
        <color rgba="0.49803922 0.49803922 0.49803922 1" />
        </material>
      </visual>
    <collision>
      <origin xyz="0 0 0" rpy="0 0 0" />
      <geometry>
        <mesh filename="./meshes/leg_assembly_left_1_rmd_x8_90_mock_2_outer_rmd_x8_90_1_simple.stl" />
        </geometry>
      </collision>
    <inertial>
      <mass value="0.49985879" />
      <inertia ixx="0.00048280871" iyy="0.00046437396" izz="0.00076940631" ixy="0" ixz="0" iyz="0" />
      <origin xyz="-0.044808157 0.018560146 -0.019942948" rpy="0 1.5707963 0" />
      </inertial>
    </link>
  <joint name="joint_leg_assembly_left_1_fastened_5" type="fixed">
    <origin xyz="0.13165064 -0.032308157 0.0045898535" rpy="1.5707963 0 -1.5707963" />
    <parent link="link_leg_assembly_left_1_leg_part_3_1" />
    <child link="link_leg_assembly_left_1_rmd_x8_90_mock_2_outer_rmd_x8_90_1" />
    </joint>
  <link name="link_leg_assembly_right_1_leg_part_4_1">
    <visual>
      <origin xyz="0 0 0" rpy="0 0 0" />
      <geometry>
        <mesh filename="./meshes/leg_assembly_right_1_leg_part_4_1_simple.stl" />
        </geometry>
      <material name="link_leg_assembly_right_1_leg_part_4_1_material">
        <color rgba="0.64705882 0.64705882 0.64705882 1" />
        </material>
      </visual>
    <collision>
      <origin xyz="0 0 0" rpy="0 0 0" />
      <geometry>
        <mesh filename="./meshes/leg_assembly_right_1_leg_part_4_1_simple.stl" />
        </geometry>
      </collision>
    <inertial>
      <mass value="0.09299573" />
      <inertia ixx="8.6209079e-05" iyy="0.00017860969" izz="0.00025876717" ixy="0" ixz="0" iyz="0" />
      <origin xyz="-0.037174443 -0.060000019 -0.0098354041" rpy="0 0 0.0017096165" />
      </inertial>
    </link>
  <joint name="joint_leg_assembly_right_1_fastened_4" type="fixed">
    <origin xyz="0.11665064 -0.0475 0.0755" rpy="3.1415927 0 0" />
    <parent link="link_leg_assembly_right_1_leg_part_3_1" />
    <child link="link_leg_assembly_right_1_leg_part_4_1" />
    </joint>
  <link name="link_leg_assembly_right_1_rmd_x8_90_mock_2_outer_rmd_x8_90_1">
    <visual>
      <origin xyz="0 0 0" rpy="0 0 0" />
      <geometry>
        <mesh filename="./meshes/leg_assembly_right_1_rmd_x8_90_mock_2_outer_rmd_x8_90_1_simple.stl" />
        </geometry>
      <material name="link_leg_assembly_right_1_rmd_x8_90_mock_2_outer_rmd_x8_90_1_material">
        <color rgba="0.49803922 0.49803922 0.49803922 1" />
        </material>
      </visual>
    <collision>
      <origin xyz="0 0 0" rpy="0 0 0" />
      <geometry>
        <mesh filename="./meshes/leg_assembly_right_1_rmd_x8_90_mock_2_outer_rmd_x8_90_1_simple.stl" />
        </geometry>
      </collision>
    <inertial>
      <mass value="0.49985879" />
      <inertia ixx="0.00048280871" iyy="0.00046437396" izz="0.00076940631" ixy="0" ixz="0" iyz="0" />
      <origin xyz="-0.044808157 0.018560146 -0.019942948" rpy="0 1.5707963 0" />
      </inertial>
    </link>
  <joint name="joint_leg_assembly_right_1_fastened_5" type="fixed">
    <origin xyz="0.13165064 -0.032308157 0.0045898535" rpy="1.5707963 0 -1.5707963" />
    <parent link="link_leg_assembly_right_1_leg_part_3_1" />
    <child link="link_leg_assembly_right_1_rmd_x8_90_mock_2_outer_rmd_x8_90_1" />
    </joint>
  <link name="link_leg_assembly_left_1_rmd_x8_90_mock_2_inner_rmd_x8_90_1">
    <visual>
      <origin xyz="0 0 0" rpy="0 0 0" />
      <geometry>
        <mesh filename="./meshes/leg_assembly_left_1_rmd_x8_90_mock_2_inner_rmd_x8_90_1_simple.stl" />
        </geometry>
      <material name="link_leg_assembly_left_1_rmd_x8_90_mock_2_inner_rmd_x8_90_1_material">
        <color rgba="0.98039216 0.71372549 0.0039215686 1" />
        </material>
      </visual>
    <collision>
      <origin xyz="0 0 0" rpy="0 0 0" />
      <geometry>
        <mesh filename="./meshes/leg_assembly_left_1_rmd_x8_90_mock_2_inner_rmd_x8_90_1_simple.stl" />
        </geometry>
      </collision>
    <inertial>
      <mass value="0.35017331" />
      <inertia ixx="0.00012756556" iyy="0.00012756556" izz="0.00022624974" ixy="0" ixz="0" iyz="0" />
      <origin xyz="0 0 -0.0084776592" rpy="3.1415927 0 0" />
      </inertial>
    </link>
  <joint name="left hip roll" type="revolute">
    <origin xyz="-0.044808157 0.018560146 -0.0475" rpy="3.1415927 0 0" />
    <parent link="link_leg_assembly_left_1_rmd_x8_90_mock_2_outer_rmd_x8_90_1" />
    <child link="link_leg_assembly_left_1_rmd_x8_90_mock_2_inner_rmd_x8_90_1" />
    <limit effort="90" velocity="40" lower="-0.5" upper="0.5" />
    <axis xyz="0 0 -1" />
    </joint>
  <link name="link_leg_assembly_right_1_rmd_x8_90_mock_2_inner_rmd_x8_90_1">
    <visual>
      <origin xyz="0 0 0" rpy="0 0 0" />
      <geometry>
        <mesh filename="./meshes/leg_assembly_right_1_rmd_x8_90_mock_2_inner_rmd_x8_90_1_simple.stl" />
        </geometry>
      <material name="link_leg_assembly_right_1_rmd_x8_90_mock_2_inner_rmd_x8_90_1_material">
        <color rgba="0.98039216 0.71372549 0.0039215686 1" />
        </material>
      </visual>
    <collision>
      <origin xyz="0 0 0" rpy="0 0 0" />
      <geometry>
        <mesh filename="./meshes/leg_assembly_right_1_rmd_x8_90_mock_2_inner_rmd_x8_90_1_simple.stl" />
        </geometry>
      </collision>
    <inertial>
      <mass value="0.35017331" />
      <inertia ixx="0.00012756556" iyy="0.00012756556" izz="0.00022624974" ixy="0" ixz="0" iyz="0" />
      <origin xyz="0 0 -0.0084776592" rpy="3.1415927 0 0" />
      </inertial>
    </link>
  <joint name="right hip roll" type="revolute">
    <origin xyz="-0.044808157 0.018560146 -0.0475" rpy="3.1415927 0 0" />
    <parent link="link_leg_assembly_right_1_rmd_x8_90_mock_2_outer_rmd_x8_90_1" />
    <child link="link_leg_assembly_right_1_rmd_x8_90_mock_2_inner_rmd_x8_90_1" />
    <limit effort="90" velocity="40" lower="-2.39" upper="-1" />
    <axis xyz="0 0 -1" />
    </joint>
  <link name="link_leg_assembly_left_1_let_part_5_left_1">
    <visual>
      <origin xyz="0 0 0" rpy="0 0 0" />
      <geometry>
        <mesh filename="./meshes/leg_assembly_left_1_let_part_5_left_1_simple.stl" />
        </geometry>
      <material name="link_leg_assembly_left_1_let_part_5_left_1_material">
        <color rgba="0.64705882 0.64705882 0.64705882 1" />
        </material>
      </visual>
    <collision>
      <origin xyz="0 0 0" rpy="0 0 0" />
      <geometry>
        <mesh filename="./meshes/leg_assembly_left_1_let_part_5_left_1_simple.stl" />
        </geometry>
      </collision>
    <inertial>
      <mass value="0.28898133" />
      <inertia ixx="0.0013254719" iyy="0.0007160887" izz="0.00083314579" ixy="0" ixz="-5.4255244e-05" iyz="-2.9416279e-05" />
      <origin xyz="0.017475327 0.0012376983 -0.063202954" rpy="1.3266757 -0.10647641 1.5930957" />
      </inertial>
    </link>
  <joint name="joint_leg_assembly_left_1_fastened_92" type="fixed">
    <origin xyz="0 0 0.0035" rpy="3.1415927 0 3.1415927" />
    <parent link="link_leg_assembly_left_1_rmd_x8_90_mock_2_inner_rmd_x8_90_1" />
    <child link="link_leg_assembly_left_1_let_part_5_left_1" />
    </joint>
  <link name="link_leg_assembly_right_1_leg_part_5_right_2">
    <visual>
      <origin xyz="0 0 0" rpy="0 0 0" />
      <geometry>
        <mesh filename="./meshes/leg_assembly_right_1_leg_part_5_right_2_simple.stl" />
        </geometry>
      <material name="link_leg_assembly_right_1_leg_part_5_right_2_material">
        <color rgba="0.64705882 0.64705882 0.64705882 1" />
        </material>
      </visual>
    <collision>
      <origin xyz="0 0 0" rpy="0 0 0" />
      <geometry>
        <mesh filename="./meshes/leg_assembly_right_1_leg_part_5_right_2_simple.stl" />
        </geometry>
      </collision>
    <inertial>
      <mass value="0.28898136" />
      <inertia ixx="0.0013254721" iyy="0.00071608889" izz="0.00083314581" ixy="0" ixz="5.4255301e-05" iyz="-2.941628e-05" />
      <origin xyz="-0.0049753287 0.022888327 -0.063202967" rpy="-1.8149174 -0.10647643 1.5930959" />
      </inertial>
    </link>
  <joint name="joint_leg_assembly_right_1_fastened_6" type="fixed">
    <origin xyz="-0.021650635 -0.0125 0.0035" rpy="3.1415927 0 1.5707963" />
    <parent link="link_leg_assembly_right_1_rmd_x8_90_mock_2_inner_rmd_x8_90_1" />
    <child link="link_leg_assembly_right_1_leg_part_5_right_2" />
    </joint>
  <link name="link_leg_assembly_left_1_rmd_x8_90_mock_3_outer_rmd_x8_90_1">
    <visual>
      <origin xyz="0 0 0" rpy="0 0 0" />
      <geometry>
        <mesh filename="./meshes/leg_assembly_left_1_rmd_x8_90_mock_3_outer_rmd_x8_90_1_simple.stl" />
        </geometry>
      <material name="link_leg_assembly_left_1_rmd_x8_90_mock_3_outer_rmd_x8_90_1_material">
        <color rgba="0.49803922 0.49803922 0.49803922 1" />
        </material>
      </visual>
    <collision>
      <origin xyz="0 0 0" rpy="0 0 0" />
      <geometry>
        <mesh filename="./meshes/leg_assembly_left_1_rmd_x8_90_mock_3_outer_rmd_x8_90_1_simple.stl" />
        </geometry>
      </collision>
    <inertial>
      <mass value="0.49985879" />
      <inertia ixx="0.00048280871" iyy="0.00046437396" izz="0.00076940631" ixy="0" ixz="0" iyz="0" />
      <origin xyz="-0.018560146 0.044808157 -0.019942948" rpy="0 1.5707963 0" />
      </inertial>
    </link>
  <joint name="joint_leg_assembly_left_1_fastened_91" type="fixed">
    <origin xyz="0.02685 0.044808157 -0.10493985" rpy="-3.1415927 -1.5707963 0" />
    <parent link="link_leg_assembly_left_1_let_part_5_left_1" />
    <child link="link_leg_assembly_left_1_rmd_x8_90_mock_3_outer_rmd_x8_90_1" />
    </joint>
  <link name="link_leg_assembly_right_1_rmd_x8_90_mock_3_outer_rmd_x8_90_1">
    <visual>
      <origin xyz="0 0 0" rpy="0 0 0" />
      <geometry>
        <mesh filename="./meshes/leg_assembly_right_1_rmd_x8_90_mock_3_outer_rmd_x8_90_1_simple.stl" />
        </geometry>
      <material name="link_leg_assembly_right_1_rmd_x8_90_mock_3_outer_rmd_x8_90_1_material">
        <color rgba="0.49803922 0.49803922 0.49803922 1" />
        </material>
      </visual>
    <collision>
      <origin xyz="0 0 0" rpy="0 0 0" />
      <geometry>
        <mesh filename="./meshes/leg_assembly_right_1_rmd_x8_90_mock_3_outer_rmd_x8_90_1_simple.stl" />
        </geometry>
      </collision>
    <inertial>
      <mass value="0.49985879" />
      <inertia ixx="0.00048280871" iyy="0.00046437396" izz="0.00076940631" ixy="0" ixz="0" iyz="0" />
      <origin xyz="-0.018560146 -0.044808157 -0.019942948" rpy="0 1.5707963 0" />
      </inertial>
    </link>
  <joint name="joint_leg_assembly_right_1_fastened_7" type="fixed">
    <origin xyz="-0.01435 0.066458792 -0.10493985" rpy="0 -1.5707963 0" />
    <parent link="link_leg_assembly_right_1_leg_part_5_right_2" />
    <child link="link_leg_assembly_right_1_rmd_x8_90_mock_3_outer_rmd_x8_90_1" />
    </joint>
  <link name="link_leg_assembly_left_1_rmd_x8_90_mock_3_inner_rmd_x8_90_1">
    <visual>
      <origin xyz="0 0 0" rpy="0 0 0" />
      <geometry>
        <mesh filename="./meshes/leg_assembly_left_1_rmd_x8_90_mock_3_inner_rmd_x8_90_1_simple.stl" />
        </geometry>
      <material name="link_leg_assembly_left_1_rmd_x8_90_mock_3_inner_rmd_x8_90_1_material">
        <color rgba="0.98039216 0.71372549 0.0039215686 1" />
        </material>
      </visual>
    <collision>
      <origin xyz="0 0 0" rpy="0 0 0" />
      <geometry>
        <mesh filename="./meshes/leg_assembly_left_1_rmd_x8_90_mock_3_inner_rmd_x8_90_1_simple.stl" />
        </geometry>
      </collision>
    <inertial>
      <mass value="0.35017331" />
      <inertia ixx="0.00012756556" iyy="0.00012756556" izz="0.00022624974" ixy="0" ixz="0" iyz="0" />
      <origin xyz="0 0 -0.0084776592" rpy="3.1415927 0 0" />
      </inertial>
    </link>
  <joint name="left knee pitch" type="revolute">
    <origin xyz="-0.018560146 0.044808157 -0.0475" rpy="3.1415927 0 0" />
    <parent link="link_leg_assembly_left_1_rmd_x8_90_mock_3_outer_rmd_x8_90_1" />
    <child link="link_leg_assembly_left_1_rmd_x8_90_mock_3_inner_rmd_x8_90_1" />
    <limit effort="90" velocity="40" lower="0.5" upper="2.5" />
    <axis xyz="0 0 -1" />
    </joint>
  <link name="link_leg_assembly_right_1_rmd_x8_90_mock_3_inner_rmd_x8_90_1">
    <visual>
      <origin xyz="0 0 0" rpy="0 0 0" />
      <geometry>
        <mesh filename="./meshes/leg_assembly_right_1_rmd_x8_90_mock_3_inner_rmd_x8_90_1_simple.stl" />
        </geometry>
      <material name="link_leg_assembly_right_1_rmd_x8_90_mock_3_inner_rmd_x8_90_1_material">
        <color rgba="0.98039216 0.71372549 0.0039215686 1" />
        </material>
      </visual>
    <collision>
      <origin xyz="0 0 0" rpy="0 0 0" />
      <geometry>
        <mesh filename="./meshes/leg_assembly_right_1_rmd_x8_90_mock_3_inner_rmd_x8_90_1_simple.stl" />
        </geometry>
      </collision>
    <inertial>
      <mass value="0.35017331" />
      <inertia ixx="0.00012756556" iyy="0.00012756556" izz="0.00022624974" ixy="0" ixz="0" iyz="0" />
      <origin xyz="0 0 -0.0084776592" rpy="3.1415927 0 0" />
      </inertial>
    </link>
  <joint name="right knee pitch" type="revolute">
    <origin xyz="-0.018560146 -0.044808157 -0.0475" rpy="3.1415927 0 0" />
    <parent link="link_leg_assembly_right_1_rmd_x8_90_mock_3_outer_rmd_x8_90_1" />
    <child link="link_leg_assembly_right_1_rmd_x8_90_mock_3_inner_rmd_x8_90_1" />
    <limit effort="90" velocity="40" lower="1.54" upper="3" />
    <axis xyz="0 0 -1" />
    </joint>
  <link name="link_leg_assembly_left_1_leg_part_6_2">
    <visual>
      <origin xyz="0 0 0" rpy="0 0 0" />
      <geometry>
        <mesh filename="./meshes/leg_assembly_left_1_leg_part_6_2_simple.stl" />
        </geometry>
      <material name="link_leg_assembly_left_1_leg_part_6_2_material">
        <color rgba="0.64705882 0.64705882 0.64705882 1" />
        </material>
      </visual>
    <collision>
      <origin xyz="0 0 0" rpy="0 0 0" />
      <geometry>
        <mesh filename="./meshes/leg_assembly_left_1_leg_part_6_2_simple.stl" />
        </geometry>
      </collision>
    <inertial>
      <mass value="0.2603138" />
      <inertia ixx="0.0015840914" iyy="0.0014071286" izz="0.00033656987" ixy="0" ixz="0" iyz="-3.7789678e-05" />
      <origin xyz="0.11365727 0.025000061 -0.016168544" rpy="1.5707984 0.035240553 3.1415909" />
      </inertial>
    </link>
  <joint name="joint_leg_assembly_left_1_fastened_8" type="fixed">
    <origin xyz="0.021650635 0.0125 0.0035" rpy="3.1415927 0 -1.0471976" />
    <parent link="link_leg_assembly_left_1_rmd_x8_90_mock_3_inner_rmd_x8_90_1" />
    <child link="link_leg_assembly_left_1_leg_part_6_2" />
    </joint>
  <link name="link_leg_assembly_right_1_leg_part_6_2">
    <visual>
      <origin xyz="0 0 0" rpy="0 0 0" />
      <geometry>
        <mesh filename="./meshes/leg_assembly_right_1_leg_part_6_2_simple.stl" />
        </geometry>
      <material name="link_leg_assembly_right_1_leg_part_6_2_material">
        <color rgba="0.64705882 0.64705882 0.64705882 1" />
        </material>
      </visual>
    <collision>
      <origin xyz="0 0 0" rpy="0 0 0" />
      <geometry>
        <mesh filename="./meshes/leg_assembly_right_1_leg_part_6_2_simple.stl" />
        </geometry>
      </collision>
    <inertial>
      <mass value="0.2603138" />
      <inertia ixx="0.0015840914" iyy="0.0014071286" izz="0.00033656987" ixy="0" ixz="0" iyz="-3.7789678e-05" />
      <origin xyz="0.11365727 0.025000061 -0.016168544" rpy="1.5707984 0.035240553 3.1415909" />
      </inertial>
    </link>
  <joint name="joint_leg_assembly_right_1_fastened_8" type="fixed">
    <origin xyz="0.021650635 0.0125 0.0035" rpy="3.1415927 0 -1.0471976" />
    <parent link="link_leg_assembly_right_1_rmd_x8_90_mock_3_inner_rmd_x8_90_1" />
    <child link="link_leg_assembly_right_1_leg_part_6_2" />
    </joint>
  <link name="link_leg_assembly_left_1_rmd_x4_24_mock_1_inner_rmd_x4_24_1">
    <visual>
      <origin xyz="0 0 0" rpy="0 0 0" />
      <geometry>
        <mesh filename="./meshes/leg_assembly_left_1_rmd_x4_24_mock_1_inner_rmd_x4_24_1_simple.stl" />
        </geometry>
      <material name="link_leg_assembly_left_1_rmd_x4_24_mock_1_inner_rmd_x4_24_1_material">
        <color rgba="0.76862745 0.88627451 0.95294118 1" />
        </material>
      </visual>
    <collision>
      <origin xyz="0 0 0" rpy="0 0 0" />
      <geometry>
        <mesh filename="./meshes/leg_assembly_left_1_rmd_x4_24_mock_1_inner_rmd_x4_24_1_simple.stl" />
        </geometry>
      </collision>
    <inertial>
      <mass value="0.14016004" />
      <inertia ixx="1.7993604e-05" iyy="1.7993604e-05" izz="2.1433066e-05" ixy="0" ixz="0" iyz="0" />
      <origin xyz="-0.012380881 -0.0039640631 -0.012592975" rpy="3.1415927 0 0" />
      </inertial>
    </link>
  <joint name="joint_leg_assembly_left_1_fastened_9" type="fixed">
    <origin xyz="0.24594415 0.03799988 -0.0086" rpy="3.1415927 0 1.8849556" />
    <parent link="link_leg_assembly_left_1_leg_part_6_2" />
    <child link="link_leg_assembly_left_1_rmd_x4_24_mock_1_inner_rmd_x4_24_1" />
    </joint>
  <link name="link_leg_assembly_left_1_leg_part_7_1">
    <visual>
      <origin xyz="0 0 0" rpy="0 0 0" />
      <geometry>
        <mesh filename="./meshes/leg_assembly_left_1_leg_part_7_1_simple.stl" />
        </geometry>
      <material name="link_leg_assembly_left_1_leg_part_7_1_material">
        <color rgba="0.64705882 0.64705882 0.64705882 1" />
        </material>
      </visual>
    <collision>
      <origin xyz="0 0 0" rpy="0 0 0" />
      <geometry>
        <mesh filename="./meshes/leg_assembly_left_1_leg_part_7_1_simple.stl" />
        </geometry>
      </collision>
    <inertial>
      <mass value="0.13629252" />
      <inertia ixx="0.00077482859" iyy="0.00083176156" izz="6.5891346e-05" ixy="0" ixz="-1.3659634e-06" iyz="0" />
      <origin xyz="-0.049159962 0.00040712793 0.0099933584" rpy="-1.5864856 -1.5688485 -3.1278361" />
      </inertial>
    </link>
  <joint name="joint_leg_assembly_left_1_fastened_11" type="fixed">
    <origin xyz="0.165 0.025 0.0775" rpy="0 0 0" />
    <parent link="link_leg_assembly_left_1_leg_part_6_2" />
    <child link="link_leg_assembly_left_1_leg_part_7_1" />
    </joint>
  <link name="link_leg_assembly_right_1_rmd_x4_24_mock_1_inner_rmd_x4_24_1">
    <visual>
      <origin xyz="0 0 0" rpy="0 0 0" />
      <geometry>
        <mesh filename="./meshes/leg_assembly_right_1_rmd_x4_24_mock_1_inner_rmd_x4_24_1_simple.stl" />
        </geometry>
      <material name="link_leg_assembly_right_1_rmd_x4_24_mock_1_inner_rmd_x4_24_1_material">
        <color rgba="0.76862745 0.88627451 0.95294118 1" />
        </material>
      </visual>
    <collision>
      <origin xyz="0 0 0" rpy="0 0 0" />
      <geometry>
        <mesh filename="./meshes/leg_assembly_right_1_rmd_x4_24_mock_1_inner_rmd_x4_24_1_simple.stl" />
        </geometry>
      </collision>
    <inertial>
      <mass value="0.14016004" />
      <inertia ixx="1.7993604e-05" iyy="1.7993604e-05" izz="2.1433066e-05" ixy="0" ixz="0" iyz="0" />
      <origin xyz="-0.012380881 -0.0039640631 -0.012592975" rpy="3.1415927 0 0" />
      </inertial>
    </link>
  <joint name="joint_leg_assembly_right_1_fastened_9" type="fixed">
    <origin xyz="0.24594415 0.03799988 -0.0086" rpy="3.1415927 0 1.8849556" />
    <parent link="link_leg_assembly_right_1_leg_part_6_2" />
    <child link="link_leg_assembly_right_1_rmd_x4_24_mock_1_inner_rmd_x4_24_1" />
    </joint>
  <link name="link_leg_assembly_right_1_leg_part_7_1">
    <visual>
      <origin xyz="0 0 0" rpy="0 0 0" />
      <geometry>
        <mesh filename="./meshes/leg_assembly_right_1_leg_part_7_1_simple.stl" />
        </geometry>
      <material name="link_leg_assembly_right_1_leg_part_7_1_material">
        <color rgba="0.64705882 0.64705882 0.64705882 1" />
        </material>
      </visual>
    <collision>
      <origin xyz="0 0 0" rpy="0 0 0" />
      <geometry>
        <mesh filename="./meshes/leg_assembly_right_1_leg_part_7_1_simple.stl" />
        </geometry>
      </collision>
    <inertial>
      <mass value="0.13629252" />
      <inertia ixx="0.00077482859" iyy="0.00083176156" izz="6.5891346e-05" ixy="0" ixz="-1.3659634e-06" iyz="0" />
      <origin xyz="-0.049159962 0.00040712793 0.0099933584" rpy="-1.5864856 -1.5688485 -3.1278361" />
      </inertial>
    </link>
  <joint name="joint_leg_assembly_right_1_fastened_11" type="fixed">
    <origin xyz="0.165 0.025 0.0775" rpy="0 0 0" />
    <parent link="link_leg_assembly_right_1_leg_part_6_2" />
    <child link="link_leg_assembly_right_1_leg_part_7_1" />
    </joint>
  <link name="link_leg_assembly_left_1_rmd_x4_24_mock_1_outer_rmd_x4_24_1">
    <visual>
      <origin xyz="0 0 0" rpy="0 0 0" />
      <geometry>
        <mesh filename="./meshes/leg_assembly_left_1_rmd_x4_24_mock_1_outer_rmd_x4_24_1_simple.stl" />
        </geometry>
      <material name="link_leg_assembly_left_1_rmd_x4_24_mock_1_outer_rmd_x4_24_1_material">
        <color rgba="0.91764706 0.91764706 0.91764706 1" />
        </material>
      </visual>
    <collision>
      <origin xyz="0 0 0" rpy="0 0 0" />
      <geometry>
        <mesh filename="./meshes/leg_assembly_left_1_rmd_x4_24_mock_1_outer_rmd_x4_24_1_simple.stl" />
        </geometry>
      </collision>
    <inertial>
      <mass value="0.23995036" />
      <inertia ixx="0.00010773939" iyy="0.00010552777" izz="0.0001024819" ixy="0" ixz="0" iyz="0" />
      <origin xyz="0 0 0.010478263" rpy="3.1415926 0 0" />
      </inertial>
    </link>
  <joint name="left ankle pitch" type="revolute">
    <origin xyz="-0.012380881 -0.0039640631 -0.025" rpy="3.1415927 0 0" />
    <parent link="link_leg_assembly_left_1_rmd_x4_24_mock_1_inner_rmd_x4_24_1" />
    <child link="link_leg_assembly_left_1_rmd_x4_24_mock_1_outer_rmd_x4_24_1" />
    <limit effort="24" velocity="40" lower="-0.8" upper="0.6" />
    <axis xyz="0 0 -1" />
    </joint>
  <link name="link_leg_assembly_right_1_rmd_x4_24_mock_1_outer_rmd_x4_24_1">
    <visual>
      <origin xyz="0 0 0" rpy="0 0 0" />
      <geometry>
        <mesh filename="./meshes/leg_assembly_right_1_rmd_x4_24_mock_1_outer_rmd_x4_24_1_simple.stl" />
        </geometry>
      <material name="link_leg_assembly_right_1_rmd_x4_24_mock_1_outer_rmd_x4_24_1_material">
        <color rgba="0.91764706 0.91764706 0.91764706 1" />
        </material>
      </visual>
    <collision>
      <origin xyz="0 0 0" rpy="0 0 0" />
      <geometry>
        <mesh filename="./meshes/leg_assembly_right_1_rmd_x4_24_mock_1_outer_rmd_x4_24_1_simple.stl" />
        </geometry>
      </collision>
    <inertial>
      <mass value="0.23995036" />
      <inertia ixx="0.00010773939" iyy="0.00010552777" izz="0.0001024819" ixy="0" ixz="0" iyz="0" />
      <origin xyz="0 0 0.010478263" rpy="3.1415926 0 0" />
      </inertial>
    </link>
  <joint name="right ankle pitch" type="revolute">
    <origin xyz="-0.012380881 -0.0039640631 -0.025" rpy="3.1415927 0 0" />
    <parent link="link_leg_assembly_right_1_rmd_x4_24_mock_1_inner_rmd_x4_24_1" />
    <child link="link_leg_assembly_right_1_rmd_x4_24_mock_1_outer_rmd_x4_24_1" />
    <limit effort="24" velocity="40" lower="0" upper="1.5" />
    <axis xyz="0 0 -1" />
    </joint>
  <link name="link_left_foot_1_ankle_half_2_left_1">
    <visual>
      <origin xyz="0 0 0" rpy="0 0 0" />
      <geometry>
        <mesh filename="./meshes/left_foot_1_ankle_half_2_left_1_simple.stl" />
        </geometry>
      <material name="link_left_foot_1_ankle_half_2_left_1_material">
        <color rgba="0.61568627 0.81176471 0.92941176 1" />
        </material>
      </visual>
    <collision>
      <origin xyz="0 0 0" rpy="0 0 0" />
      <geometry>
        <mesh filename="./meshes/left_foot_1_ankle_half_2_left_1_simple.stl" />
        </geometry>
      </collision>
    <inertial>
      <mass value="0.059239193" />
      <inertia ixx="0.00010763354" iyy="8.5716546e-05" izz="4.6394488e-05" ixy="-5.2541989e-06" ixz="-2.8474635e-06" iyz="-1.2537404e-05" />
      <origin xyz="0.020458789 -0.0024653048 0.03371754" rpy="-2.837802 -0.21366074 1.5044724" />
      </inertial>
    </link>
  <joint name="joint_fastened_3" type="fixed">
    <origin xyz="0.01225 -0.021217622 -0.02" rpy="0 0 0" />
    <parent link="link_leg_assembly_left_1_rmd_x4_24_mock_1_outer_rmd_x4_24_1" />
    <child link="link_left_foot_1_ankle_half_2_left_1" />
    </joint>
  <link name="link_right_foot_1_ankle_half_2_right_2">
    <visual>
      <origin xyz="0 0 0" rpy="0 0 0" />
      <geometry>
        <mesh filename="./meshes/right_foot_1_ankle_half_2_right_2_simple.stl" />
        </geometry>
      <material name="link_right_foot_1_ankle_half_2_right_2_material">
        <color rgba="0.61568627 0.81176471 0.92941176 1" />
        </material>
      </visual>
    <collision>
      <origin xyz="0 0 0" rpy="0 0 0" />
      <geometry>
        <mesh filename="./meshes/right_foot_1_ankle_half_2_right_2_simple.stl" />
        </geometry>
      </collision>
    <inertial>
      <mass value="0.05923903" />
      <inertia ixx="0.00010763343" iyy="8.5716153e-05" izz="4.6394894e-05" ixy="5.2543284e-06" ixz="2.8476195e-06" iyz="-1.2537683e-05" />
      <origin xyz="-0.020458855 -0.002465438 0.033717679" rpy="0.30380165 -0.21366139 1.5044685" />
      </inertial>
    </link>
  <joint name="joint_fastened_2" type="fixed">
    <origin xyz="-0.01225 -0.021217622 -0.02" rpy="0 0 0" />
    <parent link="link_leg_assembly_right_1_rmd_x4_24_mock_1_outer_rmd_x4_24_1" />
    <child link="link_right_foot_1_ankle_half_2_right_2" />
    </joint>
  <link name="link_left_foot_1_rmd_x4_24_mock_1_outer_rmd_x4_24_1">
    <visual>
      <origin xyz="0 0 0" rpy="0 0 0" />
      <geometry>
        <mesh filename="./meshes/left_foot_1_rmd_x4_24_mock_1_outer_rmd_x4_24_1_simple.stl" />
        </geometry>
      <material name="link_left_foot_1_rmd_x4_24_mock_1_outer_rmd_x4_24_1_material">
        <color rgba="0.91764706 0.91764706 0.91764706 1" />
        </material>
      </visual>
    <collision>
      <origin xyz="0 0 0" rpy="0 0 0" />
      <geometry>
        <mesh filename="./meshes/left_foot_1_rmd_x4_24_mock_1_outer_rmd_x4_24_1_simple.stl" />
        </geometry>
      </collision>
    <inertial>
      <mass value="0.23995036" />
      <inertia ixx="0.0001024819" iyy="0.00010552777" izz="0.00010773939" ixy="0" ixz="0" iyz="0" />
      <origin xyz="0 0.0245 0.030478263" rpy="3.1415927 0 0" />
      </inertial>
    </link>
  <joint name="joint_left_foot_1_fastened_3" type="fixed">
    <origin xyz="0.02125 -0.025832378 0.03055" rpy="3.1415927 1.5707963 0" />
    <parent link="link_left_foot_1_ankle_half_2_left_1" />
    <child link="link_left_foot_1_rmd_x4_24_mock_1_outer_rmd_x4_24_1" />
    </joint>
  <link name="link_left_foot_1_ankle_half_1_left_2">
    <visual>
      <origin xyz="0 0 0" rpy="0 0 0" />
      <geometry>
        <mesh filename="./meshes/left_foot_1_ankle_half_1_left_2_simple.stl" />
        </geometry>
      <material name="link_left_foot_1_ankle_half_1_left_2_material">
        <color rgba="0.61568627 0.81176471 0.92941176 1" />
        </material>
      </visual>
    <collision>
      <origin xyz="0 0 0" rpy="0 0 0" />
      <geometry>
        <mesh filename="./meshes/left_foot_1_ankle_half_1_left_2_simple.stl" />
        </geometry>
      </collision>
    <inertial>
      <mass value="0.068569669" />
      <inertia ixx="9.0276596e-05" iyy="0.00012909937" izz="6.5925457e-05" ixy="-9.6384392e-06" ixz="1.3588096e-05" iyz="3.1694887e-06" />
      <origin xyz="0.034099695 -0.044693335 -0.034222531" rpy="-1.1305633 -0.099417776 1.7791323" />
      </inertial>
    </link>
  <joint name="joint_left_foot_1_fastened_2" type="fixed">
    <origin xyz="-0.01225 0.035717622 0.06735" rpy="0 1.5707963 0" />
    <parent link="link_left_foot_1_ankle_half_2_left_1" />
    <child link="link_left_foot_1_ankle_half_1_left_2" />
    </joint>
  <link name="link_right_foot_1_ankle_half_1_right_1">
    <visual>
      <origin xyz="0 0 0" rpy="0 0 0" />
      <geometry>
        <mesh filename="./meshes/right_foot_1_ankle_half_1_right_1_simple.stl" />
        </geometry>
      <material name="link_right_foot_1_ankle_half_1_right_1_material">
        <color rgba="0.61568627 0.81176471 0.92941176 1" />
        </material>
      </visual>
    <collision>
      <origin xyz="0 0 0" rpy="0 0 0" />
      <geometry>
        <mesh filename="./meshes/right_foot_1_ankle_half_1_right_1_simple.stl" />
        </geometry>
      </collision>
    <inertial>
      <mass value="0.068569427" />
      <inertia ixx="9.0276293e-05" iyy="0.00012909903" izz="6.5925372e-05" ixy="-9.6384478e-06" ixz="1.3587977e-05" iyz="3.1695211e-06" />
      <origin xyz="-0.041700371 -0.0078066908 -0.034222553" rpy="-1.1305629 0.099418714 -1.779132" />
      </inertial>
    </link>
  <joint name="joint_right_foot_1_fastened_2" type="fixed">
    <origin xyz="0.01225 -0.016782378 -0.00845" rpy="-3.1415927 1.5707963 0" />
    <parent link="link_right_foot_1_ankle_half_2_right_2" />
    <child link="link_right_foot_1_ankle_half_1_right_1" />
    </joint>
  <link name="link_right_foot_1_rmd_x4_24_mock_1_outer_rmd_x4_24_1">
    <visual>
      <origin xyz="0 0 0" rpy="0 0 0" />
      <geometry>
        <mesh filename="./meshes/right_foot_1_rmd_x4_24_mock_1_outer_rmd_x4_24_1_simple.stl" />
        </geometry>
      <material name="link_right_foot_1_rmd_x4_24_mock_1_outer_rmd_x4_24_1_material">
        <color rgba="0.91764706 0.91764706 0.91764706 1" />
        </material>
      </visual>
    <collision>
      <origin xyz="0 0 0" rpy="0 0 0" />
      <geometry>
        <mesh filename="./meshes/right_foot_1_rmd_x4_24_mock_1_outer_rmd_x4_24_1_simple.stl" />
        </geometry>
      </collision>
    <inertial>
      <mass value="0.23995036" />
      <inertia ixx="0.0001024819" iyy="0.00010552777" izz="0.00010773939" ixy="0" ixz="0" iyz="0" />
      <origin xyz="0 -0.0245 0.030478263" rpy="-3.1415927 0 0" />
      </inertial>
    </link>
  <joint name="joint_right_foot_1_fastened_3" type="fixed">
    <origin xyz="-0.02125 -0.025832378 0.03055" rpy="0 1.5707963 0" />
    <parent link="link_right_foot_1_ankle_half_2_right_2" />
    <child link="link_right_foot_1_rmd_x4_24_mock_1_outer_rmd_x4_24_1" />
    </joint>
  <link name="link_left_foot_1_rmd_x4_24_mock_1_inner_rmd_x4_24_1">
    <visual>
      <origin xyz="0 0 0" rpy="0 0 0" />
      <geometry>
        <mesh filename="./meshes/left_foot_1_rmd_x4_24_mock_1_inner_rmd_x4_24_1_simple.stl" />
        </geometry>
      <material name="link_left_foot_1_rmd_x4_24_mock_1_inner_rmd_x4_24_1_material">
        <color rgba="0.76862745 0.88627451 0.95294118 1" />
        </material>
      </visual>
    <collision>
      <origin xyz="0 0 0" rpy="0 0 0" />
      <geometry>
        <mesh filename="./meshes/left_foot_1_rmd_x4_24_mock_1_inner_rmd_x4_24_1_simple.stl" />
        </geometry>
      </collision>
    <inertial>
      <mass value="0.14016004" />
      <inertia ixx="1.7993604e-05" iyy="1.7993604e-05" izz="2.1433066e-05" ixy="0" ixz="0" iyz="0" />
      <origin xyz="0 0 -0.012407025" rpy="3.1415927 0 0" />
      </inertial>
    </link>
  <joint name="left ankle roll" type="revolute">
    <origin xyz="0 0.0245 0.02" rpy="0 0 -1.5707963" />
    <parent link="link_left_foot_1_rmd_x4_24_mock_1_outer_rmd_x4_24_1" />
    <child link="link_left_foot_1_rmd_x4_24_mock_1_inner_rmd_x4_24_1" />
    <limit effort="24" velocity="40" lower="1" upper="2.3" />
    <axis xyz="0 0 -1" />
    </joint>
  <link name="link_right_foot_1_rmd_x4_24_mock_1_inner_rmd_x4_24_1">
    <visual>
      <origin xyz="0 0 0" rpy="0 0 0" />
      <geometry>
        <mesh filename="./meshes/right_foot_1_rmd_x4_24_mock_1_inner_rmd_x4_24_1_simple.stl" />
        </geometry>
      <material name="link_right_foot_1_rmd_x4_24_mock_1_inner_rmd_x4_24_1_material">
        <color rgba="0.76862745 0.88627451 0.95294118 1" />
        </material>
      </visual>
    <collision>
      <origin xyz="0 0 0" rpy="0 0 0" />
      <geometry>
        <mesh filename="./meshes/right_foot_1_rmd_x4_24_mock_1_inner_rmd_x4_24_1_simple.stl" />
        </geometry>
      </collision>
    <inertial>
      <mass value="0.14016004" />
      <inertia ixx="1.7993604e-05" iyy="1.7993604e-05" izz="2.1433066e-05" ixy="0" ixz="0" iyz="0" />
      <origin xyz="0 0 -0.012407025" rpy="3.1415927 0 0" />
      </inertial>
    </link>
  <joint name="right ankle roll" type="revolute">
    <origin xyz="0 -0.0245 0.02" rpy="0 0 1.5707963" />
    <parent link="link_right_foot_1_rmd_x4_24_mock_1_outer_rmd_x4_24_1" />
    <child link="link_right_foot_1_rmd_x4_24_mock_1_inner_rmd_x4_24_1" />
    <limit effort="24" velocity="40" lower="1" upper="2.3" />
    <axis xyz="0 0 -1" />
    </joint>
  <link name="link_left_foot_1_foot_1">
    <visual>
      <origin xyz="0 0 0" rpy="0 0 0" />
      <geometry>
        <mesh filename="./meshes/left_foot_1_foot_1_simple.stl" />
        </geometry>
      <material name="link_left_foot_1_foot_1_material">
        <color rgba="0.61568627 0.81176471 0.92941176 1" />
        </material>
      </visual>
    <collision>
      <origin xyz="0 0 0" rpy="0 0 0" />
      <geometry>
        <mesh filename="./meshes/left_foot_1_foot_1_simple.stl" />
        </geometry>
      </collision>
    <inertial>
      <mass value="0.17605931" />
      <inertia ixx="0.00073778745" iyy="0.0008258149" izz="0.00014200789" ixy="0" ixz="0" iyz="-2.634086e-05" />
      <origin xyz="-5.5967987e-05 -0.022887017 0.016327716" rpy="1.6092414 -4.5641467e-06 1.5323467" />
      </inertial>
    </link>
  <joint name="joint_left_foot_1_fastened_1" type="fixed">
    <origin xyz="0.0027574609 -0.012704189 -0.025" rpy="0 0 0.20943951" />
    <parent link="link_left_foot_1_rmd_x4_24_mock_1_inner_rmd_x4_24_1" />
    <child link="link_left_foot_1_foot_1" />
    </joint>
  <link name="link_right_foot_1_foot_1">
    <visual>
      <origin xyz="0 0 0" rpy="0 0 0" />
      <geometry>
        <mesh filename="./meshes/right_foot_1_foot_1_simple.stl" />
        </geometry>
      <material name="link_right_foot_1_foot_1_material">
        <color rgba="0.61568627 0.81176471 0.92941176 1" />
        </material>
      </visual>
    <collision>
      <origin xyz="0 0 0" rpy="0 0 0" />
      <geometry>
        <mesh filename="./meshes/right_foot_1_foot_1_simple.stl" />
        </geometry>
      </collision>
    <inertial>
      <mass value="0.17605931" />
      <inertia ixx="0.00073778745" iyy="0.0008258149" izz="0.00014200789" ixy="0" ixz="0" iyz="-2.634086e-05" />
      <origin xyz="-5.5967987e-05 -0.022887017 0.016327716" rpy="1.6092414 -4.5641467e-06 1.5323467" />
      </inertial>
    </link>
  <joint name="joint_right_foot_1_fastened_1" type="fixed">
    <origin xyz="0.0027574609 -0.012704189 -0.025" rpy="0 0 0.20943951" />
    <parent link="link_right_foot_1_rmd_x4_24_mock_1_inner_rmd_x4_24_1" />
    <child link="link_right_foot_1_foot_1" />
    </joint>
  <link name="link_left_foot_1_rubber_grip_1">
    <visual>
      <origin xyz="0 0 0" rpy="0 0 0" />
      <geometry>
        <mesh filename="./meshes/left_foot_1_rubber_grip_1_simple.stl" />
        </geometry>
      <material name="link_left_foot_1_rubber_grip_1_material">
        <color rgba="0.64705882 0.64705882 0.64705882 1" />
        </material>
      </visual>
    <collision>
      <origin xyz="0 0 0" rpy="0 0 0" />
      <geometry>
        <mesh filename="./meshes/left_foot_1_rubber_grip_1_simple.stl" />
        </geometry>
      </collision>
    <inertial>
      <mass value="0.1066265" />
      <inertia ixx="0.00042074027" iyy="8.2933746e-05" izz="0.00050331416" ixy="0" ixz="0" iyz="0" />
      <origin xyz="0 0 -0.00225" rpy="0 0 3.1415927" />
      </inertial>
    </link>
  <joint name="joint_left_foot_1_fastened_4" type="fixed">
    <origin xyz="-5.5854428e-05 -0.03700012 0.010230079" rpy="-1.5707963 0 0" />
    <parent link="link_left_foot_1_foot_1" />
    <child link="link_left_foot_1_rubber_grip_1" />
    </joint>
  <link name="link_right_foot_1_rubber_grip_3">
    <visual>
      <origin xyz="0 0 0" rpy="0 0 0" />
      <geometry>
        <mesh filename="./meshes/right_foot_1_rubber_grip_3_simple.stl" />
        </geometry>
      <material name="link_right_foot_1_rubber_grip_3_material">
        <color rgba="0.64705882 0.64705882 0.64705882 1" />
        </material>
      </visual>
    <collision>
      <origin xyz="0 0 0" rpy="0 0 0" />
      <geometry>
        <mesh filename="./meshes/right_foot_1_rubber_grip_3_simple.stl" />
        </geometry>
      </collision>
    <inertial>
      <mass value="0.1066265" />
      <inertia ixx="0.00042074027" iyy="8.2933746e-05" izz="0.00050331416" ixy="0" ixz="0" iyz="0" />
      <origin xyz="0 0 -0.00225" rpy="3.1415927 0 0" />
      </inertial>
    </link>
  <joint name="joint_right_foot_1_fastened_25" type="fixed">
    <origin xyz="-5.5854428e-05 -0.03700012 0.010230079" rpy="1.5707963 0 3.1415927" />
    <parent link="link_right_foot_1_foot_1" />
    <child link="link_right_foot_1_rubber_grip_3" />
    </joint>
  </robot>