<robot name="z-02_urdf_assembly">
  <link name="base">
    <inertial>
      <origin rpy="0 0 0" xyz="0 0 0" />
      <mass value="0.001" />
      <inertia ixx="0.000001" ixy="0" ixz="0" iyy="0.000001" iyz="0" izz="0.000001" />
    </inertial>
  </link>
  <joint name="floating_base" type="fixed">
    <origin rpy="0 0 1.57" xyz="0 0 0" />
    <parent link="base" />
    <child link="Document" />
  </joint>
  <link name="Document">
    <visual>
      <origin xyz="0 0 0" rpy="0 0 0" />
      <geometry>
        <mesh filename="meshes/Document.stl" />
      </geometry>
      <material name="Document_material">
        <color rgba="0.62745098 0.62745098 0.62745098 1" />
      </material>
    </visual>
    <collision>
      <origin xyz="0 0 0" rpy="0 0 0" />
      <geometry>
        <mesh filename="meshes/Document.stl" />
      </geometry>
    </collision>
    <inertial>
      <mass value="1.036095351" />
      <inertia ixx="0.0041051581726122555" iyy="0.00499407372279508" izz="0.0016217392901018604" ixy="3.0778910361335223e-07" ixz="9.317258502038564e-06" iyz="3.5159645566016793e-06" />
      <origin xyz="-6.301056610551814e-06 -0.0006489828639665926 0.011002543604443386" rpy="0 0 0" />
    </inertial>
  </link>
  <joint name="left_shoulder_yaw" type="fixed">
    <origin xyz="0.057194730000000006 0.016280631268824133 0.021094319501615166" rpy="1.5707963000000003 0.0 0.0" />
    <parent link="Document" />
    <child link="Z-BOT2_MASTER-v24_DEC07-ASSY_v3" />
    <limit effort="80" velocity="5" lower="-0.17453293" upper="1.3962634" />
    <axis xyz="0 0 1" />
  </joint>
  <link name="Z-BOT2_MASTER-v24_DEC07-ASSY_v3">
    <visual>
      <origin xyz="0 0 0" rpy="0 0 0" />
      <geometry>
        <mesh filename="meshes/Z-BOT2_MASTER-v24_DEC07-ASSY_v3.stl" />
      </geometry>
      <material name="Z-BOT2_MASTER-v24_DEC07-ASSY_v3_material">
        <color rgba="0.62745098 0.62745098 0.62745098 1" />
      </material>
    </visual>
    <collision>
      <origin xyz="0 0 0" rpy="0 0 0" />
      <geometry>
        <mesh filename="meshes/Z-BOT2_MASTER-v24_DEC07-ASSY_v3.stl" />
      </geometry>
    </collision>
    <inertial>
      <mass value="0.016645284" />
      <inertia ixx="6.141928e-06" iyy="6.4517898e-06" izz="3.0831053e-06" ixy="0" ixz="0" iyz="0" />
      <origin xyz="0.0068887927 0.0010424427 0.018824989" rpy="0 0 0" />
    </inertial>
  </link>
  <joint name="right_shoulder_yaw" type="fixed">
    <origin xyz="-0.056366071000000004 0.016280631268824133 0.021094319501615166" rpy="1.5707963000000003 0.0 0.0" />
    <parent link="Document" />
    <child link="Z-BOT2_MASTER-v24_DEC07-ASSY_v3_2" />
    <limit effort="80" velocity="5" lower="-1.3962634" upper="0.17453293" />
    <axis xyz="0 0 1" />
  </joint>
  <link name="Z-BOT2_MASTER-v24_DEC07-ASSY_v3_2">
    <visual>
      <origin xyz="0 0 0" rpy="0 0 0" />
      <geometry>
        <mesh filename="meshes/Z-BOT2_MASTER-v24_DEC07-ASSY_v3_2.stl" />
      </geometry>
      <material name="Z-BOT2_MASTER-v24_DEC07-ASSY_v3_material_2">
        <color rgba="0.62745098 0.62745098 0.62745098 1" />
      </material>
    </visual>
    <collision>
      <origin xyz="0 0 0" rpy="0 0 0" />
      <geometry>
        <mesh filename="meshes/Z-BOT2_MASTER-v24_DEC07-ASSY_v3_2.stl" />
      </geometry>
    </collision>
    <inertial>
      <mass value="0.016645284" />
      <inertia ixx="6.141928e-06" iyy="6.4517898e-06" izz="3.0831053e-06" ixy="0" ixz="0" iyz="0" />
      <origin xyz="-0.0068887927 0.0010424427 0.018824989" rpy="0 0 0" />
    </inertial>
  </link>
  <joint name="left_shoulder_pitch" type="fixed">
    <origin xyz="0.017067737 -0.0048184479 0.018826238" rpy="3.1415927 1.5707963 0" />
    <parent link="Z-BOT2_MASTER-v24_DEC07-ASSY_v3" />
    <child link="SERVO-DUAL_v2_2" />
    <limit effort="80" velocity="5" lower="-3.1415927" upper="3.1415927" />
    <axis xyz="0 0 1" />
  </joint>
  <link name="SERVO-DUAL_v2_2">
    <visual>
      <origin xyz="0 0 0" rpy="0 0 0" />
      <geometry>
        <mesh filename="meshes/SERVO-DUAL_v2_2.stl" />
      </geometry>
      <material name="SERVO-DUAL_v2_2_material">
        <color rgba="0.30196078 0.30196078 0.30196078 1" />
      </material>
    </visual>
    <collision>
      <origin xyz="0 0 0" rpy="0 0 0" />
      <geometry>
        <mesh filename="meshes/SERVO-DUAL_v2_2.stl" />
      </geometry>
    </collision>
    <inertial>
      <mass value="0.166182934" />
      <inertia ixx="0.00014745158112563277" iyy="4.704048609556774e-05" izz="0.0001500208560268181" ixy="1.101476496841408e-08" ixz="-4.575168767446372e-09" iyz="1.4591893934912943e-05" />
      <origin xyz="-5.23974518749368e-06 0.022437503048931388 -0.022558959465722693" rpy="0 0 0" />
    </inertial>
  </link>
  <joint name="right_shoulder_pitch" type="fixed">
    <origin xyz="-0.017067737 -0.0048184479 0.018826238" rpy="0 1.5707963 0" />
    <parent link="Z-BOT2_MASTER-v24_DEC07-ASSY_v3_2" />
    <child link="SERVO-DUAL_v2_2_2" />
    <limit effort="80" velocity="5" lower="-3.1415927" upper="3.1415927" />
    <axis xyz="0 0 1" />
  </joint>
  <link name="SERVO-DUAL_v2_2_2">
    <visual>
      <origin xyz="0 0 0" rpy="0 0 0" />
      <geometry>
        <mesh filename="meshes/SERVO-DUAL_v2_2_2.stl" />
      </geometry>
      <material name="SERVO-DUAL_v2_2_material_2">
        <color rgba="0.30196078 0.30196078 0.30196078 1" />
      </material>
    </visual>
    <collision>
      <origin xyz="0 0 0" rpy="0 0 0" />
      <geometry>
        <mesh filename="meshes/SERVO-DUAL_v2_2_2.stl" />
      </geometry>
    </collision>
    <inertial>
      <mass value="0.166182928" />
      <inertia ixx="0.00014745157524545483" iyy="4.704048314909991e-05" izz="0.00015002085504036314" ixy="-1.0990524312047364e-08" ixz="-4.5650995077005355e-09" iyz="-1.4591892127950152e-05" />
      <origin xyz="-5.228213859961644e-06 -0.022437502592218266 -0.022558958843997945" rpy="0 0 0" />
    </inertial>
  </link>
  <joint name="left_hip_roll" type="revolute">
    <origin xyz="0.042980284550000004 -0.00014490883999999926 -0.0579460267" rpy="-3.1415926071795863 0.0 0.0" />
    <parent link="Document" />
    <child link="Z-BOT2_MASTER-v24_DEC07-ASSY_v3_3" />
    <limit effort="10" velocity="10" lower="-1.0471976" upper="1.0471976" />
    <axis xyz="0 0 1" />
  </joint>
  <link name="Z-BOT2_MASTER-v24_DEC07-ASSY_v3_3">
    <visual>
      <origin xyz="0 0 0" rpy="0 0 0" />
      <geometry>
        <mesh filename="meshes/Z-BOT2_MASTER-v24_DEC07-ASSY_v3_3.stl" />
      </geometry>
      <material name="Z-BOT2_MASTER-v24_DEC07-ASSY_v3_material_3">
        <color rgba="0.8 0.8 0.8 1" />
      </material>
    </visual>
    <collision>
      <origin xyz="0 0 0" rpy="0 0 0" />
      <geometry>
        <mesh filename="meshes/Z-BOT2_MASTER-v24_DEC07-ASSY_v3_3.stl" />
      </geometry>
    </collision>
    <inertial>
      <mass value="0.030093227" />
      <inertia ixx="1.8927511e-05" iyy="1.7632467e-05" izz="1.2096329e-05" ixy="0" ixz="4.0801976e-06" iyz="0" />
      <origin xyz="0.003708429 -0.0055025463 0.035439109" rpy="0 0 0" />
    </inertial>
  </link>
  <joint name="right_hip_roll" type="revolute">
    <origin xyz="-0.04269607545 -0.00014490883999999926 -0.0579460267" rpy="-3.1415926071795863 0.0 0.0" />
    <parent link="Document" />
    <child link="Z-BOT2_MASTER-v24_DEC07-ASSY_v3_4" />
    <limit effort="10" velocity="10" lower="-1.0471976" upper="1.0471976" />
    <axis xyz="0 0 1" />
  </joint>
  <link name="Z-BOT2_MASTER-v24_DEC07-ASSY_v3_4">
    <visual>
      <origin xyz="0 0 0" rpy="0 0 0" />
      <geometry>
        <mesh filename="meshes/Z-BOT2_MASTER-v24_DEC07-ASSY_v3_4.stl" />
      </geometry>
      <material name="Z-BOT2_MASTER-v24_DEC07-ASSY_v3_material_4">
        <color rgba="0.8 0.8 0.8 1" />
      </material>
    </visual>
    <collision>
      <origin xyz="0 0 0" rpy="0 0 0" />
      <geometry>
        <mesh filename="meshes/Z-BOT2_MASTER-v24_DEC07-ASSY_v3_4.stl" />
      </geometry>
    </collision>
    <inertial>
      <mass value="0.030093227" />
      <inertia ixx="1.8927511e-05" iyy="1.7632467e-05" izz="1.2096329e-05" ixy="0" ixz="-4.0801976e-06" iyz="0" />
      <origin xyz="-0.003708429 -0.0055025463 0.035439109" rpy="0 0 0" />
    </inertial>
  </link>
  <joint name="left_hip_yaw" type="revolute">
    <origin xyz="0.0082500076 -0.024599356 0.056607331" rpy="1.5707963 0 0" />
    <parent link="Z-BOT2_MASTER-v24_DEC07-ASSY_v3_3" />
    <child link="SERVO-DUAL_v2" />
    <limit effort="10" velocity="10" lower="-1.9198622" upper="0.17453293" />
    <axis xyz="0 0 1" />
  </joint>
  <link name="SERVO-DUAL_v2">
    <visual>
      <origin xyz="0 0 0" rpy="0 0 0" />
      <geometry>
        <mesh filename="meshes/SERVO-DUAL_v2.stl" />
      </geometry>
      <material name="SERVO-DUAL_v2_material">
        <color rgba="0.30196078 0.30196078 0.30196078 1" />
      </material>
    </visual>
    <collision>
      <origin xyz="0 0 0" rpy="0 0 0" />
      <geometry>
        <mesh filename="meshes/SERVO-DUAL_v2.stl" />
      </geometry>
    </collision>
    <inertial>
      <mass value="0.110875259" />
      <inertia ixx="2.0082041642401514e-05" iyy="3.093554980930408e-05" izz="2.9843187051073468e-05" ixy="-4.3887872956710996e-07" ixz="1.573888783312909e-08" iyz="1.2607639348054293e-07" />
      <origin xyz="-0.012521986654375197 0.0023534085536117723 -0.019171972966076156" rpy="0 0 0" />
    </inertial>
  </link>
  <joint name="right_hip_yaw" type="revolute">
    <origin xyz="-0.0082500076 -0.024599356 0.056607331" rpy="1.5707963 0 0" />
    <parent link="Z-BOT2_MASTER-v24_DEC07-ASSY_v3_4" />
    <child link="SERVO-DUAL_v2(Mirror)" />
    <limit effort="10" velocity="10" lower="-0.17453293" upper="1.9198622" />
    <axis xyz="0 0 1" />
  </joint>
  <link name="SERVO-DUAL_v2(Mirror)">
    <visual>
      <origin xyz="0 0 0" rpy="0 0 0" />
      <geometry>
        <mesh filename="meshes/SERVO-DUAL_v2(Mirror).stl" />
      </geometry>
      <material name="SERVO-DUAL_v2(Mirror)_material">
        <color rgba="0.30196078 0.30196078 0.30196078 1" />
      </material>
    </visual>
    <collision>
      <origin xyz="0 0 0" rpy="0 0 0" />
      <geometry>
        <mesh filename="meshes/SERVO-DUAL_v2(Mirror).stl" />
      </geometry>
    </collision>
    <inertial>
      <mass value="0.110875424" />
      <inertia ixx="2.0082068589297553e-05" iyy="3.093561352041919e-05" izz="2.9843261643005322e-05" ixy="4.3888550767222746e-07" ixz="-1.5739186368287152e-08" iyz="1.2607687052107328e-07" />
      <origin xyz="0.012522012630617392 0.0023534050513711736 -0.019171971137877844" rpy="0 0 0" />
    </inertial>
  </link>
  <joint name="left_elbow_yaw" type="fixed">
    <origin xyz="-0.018825 0.09368378999999999 -0.023450655999999997" rpy="3.1415926071795868 1.5707963 0.0" />
    <parent link="SERVO-DUAL_v2_2" />
    <child link="SERVO-DUAL_v2_1" />
    <limit effort="80" velocity="5" lower="-2.268928" upper="1.5707963" />
    <axis xyz="0 0 1" />
  </joint>
  <link name="SERVO-DUAL_v2_1">
    <visual>
      <origin xyz="0 0 0" rpy="0 0 0" />
      <geometry>
        <mesh filename="meshes/SERVO-DUAL_v2_1.stl" />
      </geometry>
      <material name="SERVO-DUAL_v2_1_material">
        <color rgba="0.30196078 0.30196078 0.30196078 1" />
      </material>
    </visual>
    <collision>
      <origin xyz="0 0 0" rpy="0 0 0" />
      <geometry>
        <mesh filename="meshes/SERVO-DUAL_v2_1.stl" />
      </geometry>
    </collision>
    <inertial>
      <mass value="0.16598466899999997" />
      <inertia ixx="0.00022275363463669602" iyy="4.101543227184327e-05" izz="0.0002224049715256991" ixy="1.318997955611982e-05" ixz="1.2509188012658966e-07" iyz="-1.2059097866296363e-06" />
      <origin xyz="0.0010206056648273394 -0.03464834204895933 -0.01879921966049792" rpy="0 0 0" />
    </inertial>
  </link>
  <joint name="right_elbow_yaw" type="fixed">
    <origin xyz="-0.018825 -0.09368378999999999 -0.023450655999999997" rpy="0.0 -1.5707963 0.0" />
    <parent link="SERVO-DUAL_v2_2_2" />
    <child link="SERVO-DUAL_v2(Mirror)_1" />
    <limit effort="80" velocity="5" lower="-1.5707963" upper="2.268928" />
    <axis xyz="0 0 1" />
  </joint>
  <link name="SERVO-DUAL_v2(Mirror)_1">
    <visual>
      <origin xyz="0 0 0" rpy="0 0 0" />
      <geometry>
        <mesh filename="meshes/SERVO-DUAL_v2(Mirror)_1.stl" />
      </geometry>
      <material name="SERVO-DUAL_v2(Mirror)_1_material">
        <color rgba="0.30196078 0.30196078 0.30196078 1" />
      </material>
    </visual>
    <collision>
      <origin xyz="0 0 0" rpy="0 0 0" />
      <geometry>
        <mesh filename="meshes/SERVO-DUAL_v2(Mirror)_1.stl" />
      </geometry>
    </collision>
    <inertial>
      <mass value="0.165984684" />
      <inertia ixx="0.00022275363377838954" iyy="4.10154424558348e-05" izz="0.00022240497609514077" ixy="-1.3189979665861809e-05" ixz="-1.2509157971351732e-07" iyz="-1.2059069169824075e-06" />
      <origin xyz="-0.0010206055117974893 -0.03464834167066351 -0.018799220900350654" rpy="0 0 0" />
    </inertial>
  </link>
  <joint name="left_hip_pitch" type="revolute">
    <origin xyz="0.010290707000000003 0.0316618118359243 -0.02465886601719911" rpy="3.141592626794896 -1.5707962889011906 0.0" />
    <parent link="SERVO-DUAL_v2" />
    <child link="SERVO-DUAL_v2_5" />
    <limit effort="10" velocity="10" lower="-1.8325957" upper="1.7453293" />
    <axis xyz="0 0 1" />
  </joint>
  <link name="SERVO-DUAL_v2_5">
    <visual>
      <origin xyz="0 0 0" rpy="0 0 0" />
      <geometry>
        <mesh filename="meshes/SERVO-DUAL_v2_5.stl" />
      </geometry>
      <material name="SERVO-DUAL_v2_5_material">
        <color rgba="0.30196078 0.30196078 0.30196078 1" />
      </material>
    </visual>
    <collision>
      <origin xyz="0 0 0" rpy="0 0 0" />
      <geometry>
        <mesh filename="meshes/SERVO-DUAL_v2_5.stl" />
      </geometry>
    </collision>
    <inertial>
      <mass value="0.145867171" />
      <inertia ixx="0.0001744094718404329" iyy="3.5936258845101883e-05" izz="0.00016410272594014215" ixy="7.623180832137564e-06" ixz="-7.077679541571516e-09" iyz="-9.852184108612934e-07" />
      <origin xyz="-0.00013581280563679777 -0.0317215069528968 -0.018757270302702335" rpy="0 0 0" />
    </inertial>
  </link>
  <joint name="right_hip_pitch" type="revolute">
    <origin xyz="-0.010290707000000003 0.0316618118359243 -0.02465886601719911" rpy="2.6794896194407875e-08 -1.5707962889011906 0.0" />
    <parent link="SERVO-DUAL_v2(Mirror)" />
    <child link="SERVO-DUAL_v2(Mirror)_4" />
    <limit effort="10" velocity="10" lower="-1.7453293" upper="1.8325957" />
    <axis xyz="0 0 1" />
  </joint>
  <link name="SERVO-DUAL_v2(Mirror)_4">
    <visual>
      <origin xyz="0 0 0" rpy="0 0 0" />
      <geometry>
        <mesh filename="meshes/SERVO-DUAL_v2(Mirror)_4.stl" />
      </geometry>
      <material name="SERVO-DUAL_v2(Mirror)_4_material">
        <color rgba="0.30196078 0.30196078 0.30196078 1" />
      </material>
    </visual>
    <collision>
      <origin xyz="0 0 0" rpy="0 0 0" />
      <geometry>
        <mesh filename="meshes/SERVO-DUAL_v2(Mirror)_4.stl" />
      </geometry>
    </collision>
    <inertial>
      <mass value="0.145867186" />
      <inertia ixx="0.00017440947615313942" iyy="3.593626203671354e-05" izz="0.00016410272863765939" ixy="-7.623175249423514e-06" ixz="-7.0773421433566116e-09" iyz="9.852132617307133e-07" />
      <origin xyz="-0.00013581360743505558 0.031721507146148624 -0.018757271350358127" rpy="0 0 0" />
    </inertial>
  </link>
  <joint name="left_knee_pitch" type="revolute">
    <origin xyz="0.021500004396296457 -0.10043832342856604 -0.000289528907266242" rpy="-4.6410205422728156e-08 0.0 4.6410206666284834e-08" />
    <parent link="SERVO-DUAL_v2_5" />
    <child link="SERVO-DUAL_v2_4" />
    <limit effort="10" velocity="10" lower="0" upper="1.57" />
    <axis xyz="0 0 1" />
  </joint>
  <link name="SERVO-DUAL_v2_4">
    <visual>
      <origin xyz="0 0 0" rpy="0 0 0" />
      <geometry>
        <mesh filename="meshes/SERVO-DUAL_v2_4.stl" />
      </geometry>
      <material name="SERVO-DUAL_v2_4_material">
        <color rgba="0.30196078 0.30196078 0.30196078 1" />
      </material>
    </visual>
    <collision>
      <origin xyz="0 0 0" rpy="0 0 0" />
      <geometry>
        <mesh filename="meshes/SERVO-DUAL_v2_4.stl" />
      </geometry>
    </collision>
    <inertial>
      <mass value="0.226937274" />
      <inertia ixx="0.00033878361732221743" iyy="4.055313487461693e-05" izz="0.0003254574965999928" ixy="-1.317270960435597e-06" ixz="-9.770369371449451e-08" iyz="-3.4088928779210623e-07" />
      <origin xyz="-0.000995612509096428 -0.0509787727876512 -0.01868209857263046" rpy="0 0 0" />
    </inertial>
  </link>
  <joint name="right_knee_pitch" type="revolute">
    <origin xyz="0.021499999495586064 0.10043832500000001 -0.00028952709273386" rpy="0.0 0.0 0.0" />
    <parent link="SERVO-DUAL_v2(Mirror)_4" />
    <child link="SERVO-DUAL_v2(Mirror)_3" />
    <limit effort="10" velocity="10" lower="-1.57" upper="0" />
    <axis xyz="0 0 1" />
  </joint>
  <link name="SERVO-DUAL_v2(Mirror)_3">
    <visual>
      <origin xyz="0 0 0" rpy="0 0 0" />
      <geometry>
        <mesh filename="meshes/SERVO-DUAL_v2(Mirror)_3.stl" />
      </geometry>
      <material name="SERVO-DUAL_v2(Mirror)_3_material">
        <color rgba="0.30196078 0.30196078 0.30196078 1" />
      </material>
    </visual>
    <collision>
      <origin xyz="0 0 0" rpy="0 0 0" />
      <geometry>
        <mesh filename="meshes/SERVO-DUAL_v2(Mirror)_3.stl" />
      </geometry>
    </collision>
    <inertial>
      <mass value="0.22693714599999998" />
      <inertia ixx="0.00033878356765952984" iyy="4.055312079632098e-05" izz="0.00032545743896338097" ixy="1.3172037169304147e-06" ixz="-9.770298324197433e-08" iyz="3.408806862640461e-07" />
      <origin xyz="-0.0009956043417224001 0.050978759891611165 -0.01868209918931309" rpy="0 0 0" />
    </inertial>
  </link>
  <joint name="left_ankle_pitch" type="revolute">
    <origin xyz="-3.6496522071854942e-09 -0.09960050419999995 -6.451933117575595e-05" rpy="-3.1415926071795863 0.0 0.0" />
    <parent link="SERVO-DUAL_v2_4" />
    <child link="Z-BOT2_MASTER-v24_DEC07-ASSY_v3_5" />
    <limit effort="10" velocity="10" lower="-1.5707963" upper="1.5707963" />
    <axis xyz="0 0 1" />
  </joint>
  <link name="Z-BOT2_MASTER-v24_DEC07-ASSY_v3_5">
    <visual>
      <origin xyz="0 0 0" rpy="0 0 0" />
      <geometry>
        <mesh filename="meshes/Z-BOT2_MASTER-v24_DEC07-ASSY_v3_5.stl" />
      </geometry>
      <material name="Z-BOT2_MASTER-v24_DEC07-ASSY_v3_material_5">
        <color rgba="0.8 0.8 0.8 1" />
      </material>
    </visual>
    <collision>
      <origin xyz="0 0 0" rpy="0 0 0" />
      <geometry>
        <mesh filename="meshes/Z-BOT2_MASTER-v24_DEC07-ASSY_v3_5.stl" />
      </geometry>
    </collision>
    <inertial>
      <mass value="0.102093376" />
      <inertia ixx="2.8393290606474754e-05" iyy="9.765741142892553e-05" izz="8.484074883540023e-05" ixy="3.435791525833484e-06" ixz="1.1457631652961936e-13" iyz="-2.706531013169219e-13" />
      <origin xyz="-0.014527584256445226 0.027884153101814156 0.018824999720177517" rpy="0 0 0" />
    </inertial>
  </link>
  <joint name="right_ankle_pitch" type="revolute">
    <origin xyz="-8.175391336129323e-10 0.09960050362638555 -6.451866882414142e-05" rpy="-3.141592653589792 0.0 -4.641020678874952e-08" />
    <parent link="SERVO-DUAL_v2(Mirror)_3" />
    <child link="Z-BOT2_MASTER-v24_DEC07-ASSY_v3_6" />
    <limit effort="10" velocity="10" lower="-1.5707963" upper="1.5707963" />
    <axis xyz="0 0 1" />
  </joint>
  <link name="Z-BOT2_MASTER-v24_DEC07-ASSY_v3_6">
    <visual>
      <origin xyz="0 0 0" rpy="0 0 0" />
      <geometry>
        <mesh filename="meshes/Z-BOT2_MASTER-v24_DEC07-ASSY_v3_6.stl" />
      </geometry>
      <material name="Z-BOT2_MASTER-v24_DEC07-ASSY_v3_material_6">
        <color rgba="0.8 0.8 0.8 1" />
      </material>
    </visual>
    <collision>
      <origin xyz="0 0 0" rpy="0 0 0" />
      <geometry>
        <mesh filename="meshes/Z-BOT2_MASTER-v24_DEC07-ASSY_v3_6.stl" />
      </geometry>
    </collision>
    <inertial>
      <mass value="0.102093376" />
      <inertia ixx="2.8393289294573086e-05" iyy="9.765740998356845e-05" izz="8.48407460781415e-05" ixy="-3.435792790891147e-06" ixz="1.1457618676082183e-13" iyz="2.7065305145396204e-13" />
      <origin xyz="-0.01452757971399573 -0.02788415135640247 0.018824999720177517" rpy="0 0 0" />
    </inertial>
  </link>
</robot>