<robot name="assembly_1">
  <link name="base">
    <inertial>
      <origin rpy="0 0 0" xyz="0 0 0" />
      <mass value="0.001" />
      <inertia ixx="0.000001" ixy="0" ixz="0" iyy="0.000001" iyz="0" izz="0.000001" />
    </inertial>
  </link>
  <joint name="floating_base" type="fixed">
    <origin rpy="0 0 0" xyz="0 0 0" />
    <parent link="base" />
    <child link="Z-BOT2_MASTER-BODY-SKELETON" />
  </joint>
  <link name="Z-BOT2_MASTER-BODY-SKELETON">
    <visual>
      <origin xyz="0 0 0" rpy="0 0 0" />
      <geometry>
        <mesh filename="meshes/Z-BOT2_MASTER-BODY-SKELETON.stl" />
      </geometry>
      <material name="Z-BOT2_MASTER-BODY-SKELETON_material">
        <color rgba="0.49411765 0.62352941 0.74901961 1" />
      </material>
    </visual>
    <collision>
      <origin xyz="0 0 0" rpy="0 0 0" />
      <geometry>
        <mesh filename="meshes/Z-BOT2_MASTER-BODY-SKELETON.stl" />
      </geometry>
    </collision>
    <inertial>
      <mass value="0.9136450087000001" />
      <inertia ixx="0.0019092996766599693" iyy="0.002184634512748622" izz="0.0012151676761097646" ixy="2.8666813574136795e-06" ixz="2.3961839496462867e-06" iyz="-1.830875634531815e-05" />
      <origin xyz="-0.0004166262396016088 0.009512038808338058 -0.04754341827767616" rpy="0 0 0" />
    </inertial>
  </link>
  <joint name="right_shoulder_yaw" type="fixed">
    <origin xyz="-0.055994975 0.02778973027464769 -0.009527810430333267" rpy="1.5707963999999996 0.0 0.0" />
    <parent link="Z-BOT2_MASTER-BODY-SKELETON" />
    <child link="Z-BOT2-MASTER-SHOULDER2" />
    <limit effort="80" velocity="5" lower="-1.2217305" upper="0.34906585" />
    <axis xyz="0 0 1" />
  </joint>
  <link name="Z-BOT2-MASTER-SHOULDER2">
    <visual>
      <origin xyz="0 0 0" rpy="0 0 0" />
      <geometry>
        <mesh filename="meshes/Z-BOT2-MASTER-SHOULDER2.stl" />
      </geometry>
      <material name="Z-BOT2-MASTER-SHOULDER2_material">
        <color rgba="0.36470588 0.36078431 0.74901961 1" />
      </material>
    </visual>
    <collision>
      <origin xyz="0 0 0" rpy="0 0 0" />
      <geometry>
        <mesh filename="meshes/Z-BOT2-MASTER-SHOULDER2.stl" />
      </geometry>
    </collision>
    <inertial>
      <mass value="0.0083497418" />
      <inertia ixx="2.5707931e-06" iyy="2.7020206e-06" izz="1.0334138e-06" ixy="0" ixz="0" iyz="0" />
      <origin xyz="-0.012788045 0.0013741162 0.018800156" rpy="0 0 0" />
    </inertial>
  </link>
  <joint name="left_shoulder_yaw" type="fixed">
    <origin xyz="0.055995025000000004 0.02778973027464769 -0.009527810430333267" rpy="1.5707963999999996 0.0 0.0" />
    <parent link="Z-BOT2_MASTER-BODY-SKELETON" />
    <child link="Z-BOT2-MASTER-SHOULDER2_1" />
    <limit effort="80" velocity="5" lower="-0.34906585" upper="1.2217305" />
    <axis xyz="0 0 1" />
  </joint>
  <link name="Z-BOT2-MASTER-SHOULDER2_1">
    <visual>
      <origin xyz="0 0 0" rpy="0 0 0" />
      <geometry>
        <mesh filename="meshes/Z-BOT2-MASTER-SHOULDER2_1.stl" />
      </geometry>
      <material name="Z-BOT2-MASTER-SHOULDER2_1_material">
        <color rgba="0.36470588 0.36078431 0.74901961 1" />
      </material>
    </visual>
    <collision>
      <origin xyz="0 0 0" rpy="0 0 0" />
      <geometry>
        <mesh filename="meshes/Z-BOT2-MASTER-SHOULDER2_1.stl" />
      </geometry>
    </collision>
    <inertial>
      <mass value="0.0083497418" />
      <inertia ixx="2.5707931e-06" iyy="2.7020206e-06" izz="1.0334138e-06" ixy="0" ixz="0" iyz="0" />
      <origin xyz="0.012788045 0.0013741162 0.018799844" rpy="0 0 0" />
    </inertial>
  </link>
  <joint name="right_hip_roll" type="revolute">
    <origin xyz="-0.043008175 0.007649730000000001 -0.1218181485" rpy="0.0 0.0 0.0" />
    <parent link="Z-BOT2_MASTER-BODY-SKELETON" />
    <child link="U-HIP_1" />
    <limit effort="10" velocity="10" lower="-1.0472" upper="1.0472" />
    <axis xyz="0 0 1" />
  <dynamics damping="0.0" friction="0.0" /></joint>
  <link name="U-HIP_1">
    <visual>
      <origin xyz="0 0 0" rpy="0 0 0" />
      <geometry>
        <mesh filename="meshes/U-HIP_1.stl" />
      </geometry>
      <material name="U-HIP_1_material">
        <color rgba="0.49803922 0.49803922 0.49803922 1" />
      </material>
    </visual>
    <collision>
      <origin xyz="0 0 0" rpy="0 0 0" />
      <geometry>
        <mesh filename="meshes/U-HIP_1.stl" />
      </geometry>
    </collision>
    <inertial>
      <mass value="0.016331226" />
      <inertia ixx="9.9452566e-06" iyy="1.0376698e-05" izz="6.5404758e-06" ixy="1.5271461e-06" ixz="2.774808e-06" iyz="-1.3241267e-06" />
      <origin xyz="-0.0011526894 -0.0043982909 0.0020038104" rpy="0 0 0" />
    </inertial>
  </link>
  <joint name="left_hip_roll" type="revolute">
    <origin xyz="0.042868184999999996 0.007649730000000002 -0.1218181485" rpy="0.0 0.0 0.0" />
    <parent link="Z-BOT2_MASTER-BODY-SKELETON" />
    <child link="U-HIP" />
    <limit effort="10" velocity="10" lower="-1.0472" upper="1.0472" />
    <axis xyz="0 0 1" />
  <dynamics damping="0.0" friction="0.0" /></joint>
  <link name="U-HIP">
    <visual>
      <origin xyz="0 0 0" rpy="0 0 0" />
      <geometry>
        <mesh filename="meshes/U-HIP.stl" />
      </geometry>
      <material name="U-HIP_material">
        <color rgba="0.98039216 0.71372549 0.0039215686 1" />
      </material>
    </visual>
    <collision>
      <origin xyz="0 0 0" rpy="0 0 0" />
      <geometry>
        <mesh filename="meshes/U-HIP.stl" />
      </geometry>
    </collision>
    <inertial>
      <mass value="0.016331226" />
      <inertia ixx="9.9507684e-06" iyy="1.0371187e-05" izz="6.5404758e-06" ixy="-1.5279145e-06" ixz="-2.7724145e-06" iyz="-1.3291308e-06" />
      <origin xyz="0.0011606228 -0.0043962041 0.0020038104" rpy="0 0 0" />
    </inertial>
  </link>
  <joint name="right_shoulder_pitch" type="fixed">
    <origin xyz="-0.019845 -0.0049 0.0188" rpy="0 1.5707963 0" />
    <parent link="Z-BOT2-MASTER-SHOULDER2" />
    <child link="FK-AP-019-25T_11_5" />
    <limit effort="80" velocity="5" lower="-3.1415927" upper="3.1415927" />
    <axis xyz="0 0 1" />
  </joint>
  <link name="FK-AP-019-25T_11_5">
    <visual>
      <origin xyz="0 0 0" rpy="0 0 0" />
      <geometry>
        <mesh filename="meshes/FK-AP-019-25T_11_5.stl" />
      </geometry>
      <material name="FK-AP-019-25T_11_5_material">
        <color rgba="0.74901961 0.49803922 0.7254902 1" />
      </material>
    </visual>
    <collision>
      <origin xyz="0 0 0" rpy="0 0 0" />
      <geometry>
        <mesh filename="meshes/FK-AP-019-25T_11_5.stl" />
      </geometry>
    </collision>
    <inertial>
      <mass value="0.1004122084" />
      <inertia ixx="0.00013786473571967666" iyy="2.793801468791839e-05" izz="0.0001385790730393699" ixy="-7.898897637563668e-07" ixz="-2.7726520578895463e-08" iyz="-3.286001172186808e-06" />
      <origin xyz="-0.00029864805326697746 -0.038135467117496845 -0.01871982217311639" rpy="0 0 0" />
    </inertial>
  </link>
  <joint name="left_shoulder_pitch" type="fixed">
    <origin xyz="0.019845 -0.0049 0.0188" rpy="3.1415927 1.5707963 0" />
    <parent link="Z-BOT2-MASTER-SHOULDER2_1" />
    <child link="FK-AP-019-25T_11_16" />
    <limit effort="80" velocity="5" lower="-3.1415927" upper="3.1415927" />
    <axis xyz="0 0 1" />
  </joint>
  <link name="FK-AP-019-25T_11_16">
    <visual>
      <origin xyz="0 0 0" rpy="0 0 0" />
      <geometry>
        <mesh filename="meshes/FK-AP-019-25T_11_16.stl" />
      </geometry>
      <material name="FK-AP-019-25T_11_16_material">
        <color rgba="0.74901961 0.49803922 0.7254902 1" />
      </material>
    </visual>
    <collision>
      <origin xyz="0 0 0" rpy="0 0 0" />
      <geometry>
        <mesh filename="meshes/FK-AP-019-25T_11_16.stl" />
      </geometry>
    </collision>
    <inertial>
      <mass value="0.10041221239999999" />
      <inertia ixx="0.00013786837950800407" iyy="2.7935398342427822e-05" izz="0.00013857861479514466" ixy="6.684024841454568e-07" ixz="-2.600436872051235e-08" iyz="3.2481130530637766e-06" />
      <origin xyz="-0.00026287853888481944 0.03813579427693401 -0.018710878932692247" rpy="0 0 0" />
    </inertial>
  </link>
  <joint name="right_hip_yaw" type="revolute">
    <origin xyz="-3.3737499e-05 0.018699632 -0.019" rpy="-1.5707963 0 0.0018041779" />
    <parent link="U-HIP_1" />
    <child link="WJ-DP00-0002-FK-AP-020_7_10" />
    <limit effort="10" velocity="10" lower="-0.174533" upper="1.91986" />
    <axis xyz="0 0 1" />
  <dynamics damping="0.0" friction="0.0" /></joint>
  <link name="WJ-DP00-0002-FK-AP-020_7_10">
    <visual>
      <origin xyz="0 0 0" rpy="0 0 0" />
      <geometry>
        <mesh filename="meshes/WJ-DP00-0002-FK-AP-020_7_10.stl" />
      </geometry>
      <material name="WJ-DP00-0002-FK-AP-020_7_10_material">
        <color rgba="1 0 0 1" />
      </material>
    </visual>
    <collision>
      <origin xyz="0 0 0" rpy="0 0 0" />
      <geometry>
        <mesh filename="meshes/WJ-DP00-0002-FK-AP-020_7_10.stl" />
      </geometry>
    </collision>
    <inertial>
      <mass value="0.042114023" />
      <inertia ixx="1.1197633718907809e-05" iyy="1.4574195889610136e-05" izz="1.4881390750897595e-05" ixy="-1.1550243183247097e-08" ixz="-5.602611614873795e-10" iyz="-1.3838838146619406e-07" />
      <origin xyz="0.012721436701996934 0.0050409885939520765 -0.01896256070064125" rpy="0 0 0" />
    </inertial>
  </link>
  <joint name="left_hip_yaw" type="revolute">
    <origin xyz="0 0.018699662 -0.019" rpy="-1.5707963 0 0" />
    <parent link="U-HIP" />
    <child link="SJ-WK00-0021TOPCABINETCASE_104_7" />
    <limit effort="10" velocity="10" lower="-1.91986" upper="0.174533" />
    <axis xyz="0 0 1" />
  <dynamics damping="0.0" friction="0.0" /></joint>
  <link name="SJ-WK00-0021TOPCABINETCASE_104_7">
    <visual>
      <origin xyz="0 0 0" rpy="0 0 0" />
      <geometry>
        <mesh filename="meshes/SJ-WK00-0021TOPCABINETCASE_104_7.stl" />
      </geometry>
      <material name="SJ-WK00-0021TOPCABINETCASE_104_7_material">
        <color rgba="0.61568627 0.81176471 0.92941176 1" />
      </material>
    </visual>
    <collision>
      <origin xyz="0 0 0" rpy="0 0 0" />
      <geometry>
        <mesh filename="meshes/SJ-WK00-0021TOPCABINETCASE_104_7.stl" />
      </geometry>
    </collision>
    <inertial>
      <mass value="0.042114028" />
      <inertia ixx="1.1188566400924921e-05" iyy="1.4574196889912927e-05" izz="1.4872324132616104e-05" ixy="1.1531873443300542e-08" ixz="5.602611865840846e-10" iyz="-1.3816828574824826e-07" />
      <origin xyz="-0.012721436699566902 0.005062299759024853 -0.01896256072975652" rpy="0 0 0" />
    </inertial>
  </link>
  <joint name="right_hip_pitch" type="revolute">
    <origin xyz="0.0302 0.032000000747204306 -0.01869999899057799" rpy="-5.358979280578589e-08 1.5707962464102065 0.0" />
    <parent link="WJ-DP00-0002-FK-AP-020_7_10" />
    <child link="SJ-WK00-0023BOTTOMCASE_12_12" />
    <limit effort="10" velocity="10" lower="-1.74533" upper="1.8326" />
    <axis xyz="0 0 1" />
  <dynamics damping="0.0" friction="0.0" /></joint>
  <link name="SJ-WK00-0023BOTTOMCASE_12_12">
    <visual>
      <origin xyz="0 0 0" rpy="0 0 0" />
      <geometry>
        <mesh filename="meshes/SJ-WK00-0023BOTTOMCASE_12_12.stl" />
      </geometry>
      <material name="SJ-WK00-0023BOTTOMCASE_12_12_material">
        <color rgba="0.64705882 0.64705882 0.64705882 1" />
      </material>
    </visual>
    <collision>
      <origin xyz="0 0 0" rpy="0 0 0" />
      <geometry>
        <mesh filename="meshes/SJ-WK00-0023BOTTOMCASE_12_12.stl" />
      </geometry>
    </collision>
    <inertial>
      <mass value="0.068115593" />
      <inertia ixx="7.012287852075333e-05" iyy="2.068980544284503e-05" izz="6.205053242953887e-05" ixy="-2.927564697354628e-06" ixz="-5.2982241904157556e-08" iyz="-5.992349443476314e-07" />
      <origin xyz="0.0020920184216766165 0.03541696147119985 -0.018778301180469147" rpy="0 0 0" />
    </inertial>
  </link>
  <joint name="left_hip_pitch" type="revolute">
    <origin xyz="-0.0302 0.032000000747204306 -0.01869999899057799" rpy="1.5707963535897942 4.6410207010794124e-08 -1.5707963000000003" />
    <parent link="SJ-WK00-0021TOPCABINETCASE_104_7" />
    <child link="SJ-WK00-0023BOTTOMCASE_12_8" />
    <limit effort="10" velocity="10" lower="-1.8326" upper="1.74533" />
    <axis xyz="0 0 1" />
  <dynamics damping="0.0" friction="0.0" /></joint>
  <link name="SJ-WK00-0023BOTTOMCASE_12_8">
    <visual>
      <origin xyz="0 0 0" rpy="0 0 0" />
      <geometry>
        <mesh filename="meshes/SJ-WK00-0023BOTTOMCASE_12_8.stl" />
      </geometry>
      <material name="SJ-WK00-0023BOTTOMCASE_12_8_material">
        <color rgba="0.91764706 0.91764706 0.91764706 1" />
      </material>
    </visual>
    <collision>
      <origin xyz="0 0 0" rpy="0 0 0" />
      <geometry>
        <mesh filename="meshes/SJ-WK00-0023BOTTOMCASE_12_8.stl" />
      </geometry>
    </collision>
    <inertial>
      <mass value="0.068115596" />
      <inertia ixx="2.068609515465114e-05" iyy="7.011542487266963e-05" izz="6.205427730715078e-05" ixy="-2.9479561277325346e-06" ixz="2.444936044284692e-07" iyz="2.4069738615046206e-08" />
      <origin xyz="-0.03541696091962766 -0.0020788449573227344 -0.018975810146608638" rpy="0 0 0" />
    </inertial>
  </link>
  <joint name="right_elbow_yaw" type="fixed">
    <origin xyz="0.018490802801497393 -0.09300556993952785 -0.018300660954374583" rpy="-0.0011742071795850747 -1.5707962301843608 0.0" />
    <parent link="FK-AP-019-25T_11_5" />
    <child link="L-ARM_1" />
    <limit effort="80" velocity="5" lower="-1.5707963" upper="2.0943951" />
    <axis xyz="0 0 1" />
  </joint>
  <link name="L-ARM_1">
    <visual>
      <origin xyz="0 0 0" rpy="0 0 0" />
      <geometry>
        <mesh filename="meshes/L-ARM_1.stl" />
      </geometry>
      <material name="L-ARM_1_material">
        <color rgba="0.62745098 0.62745098 0.62745098 1" />
      </material>
    </visual>
    <collision>
      <origin xyz="0 0 0" rpy="0 0 0" />
      <geometry>
        <mesh filename="meshes/L-ARM_1.stl" />
      </geometry>
    </collision>
    <inertial>
      <mass value="0.0930900236" />
      <inertia ixx="0.00011001700359143364" iyy="2.9247567069129307e-05" izz="0.00010368076576248044" ixy="9.332762738072622e-06" ixz="6.113414789033546e-07" iyz="-2.0376786280224577e-07" />
      <origin xyz="-0.00012477265526906009 -0.05710840277632375 0.01941155227441689" rpy="0 0 0" />
    </inertial>
  </link>
  <joint name="left_elbow_yaw" type="fixed">
    <origin xyz="0.01859999985563785 0.09298379323429216 -0.018300646603477883" rpy="-3.1415926071795846 1.570796230184361 0.0" />
    <parent link="FK-AP-019-25T_11_16" />
    <child link="R-ARM-1" />
    <limit effort="80" velocity="5" lower="-2.0943951" upper="1.5707963" />
    <axis xyz="0 0 1" />
  </joint>
  <link name="R-ARM-1">
    <visual>
      <origin xyz="0 0 0" rpy="0 0 0" />
      <geometry>
        <mesh filename="meshes/R-ARM-1.stl" />
      </geometry>
      <material name="R-ARM-1_material">
        <color rgba="0.64705882 0.64705882 0.64705882 1" />
      </material>
    </visual>
    <collision>
      <origin xyz="0 0 0" rpy="0 0 0" />
      <geometry>
        <mesh filename="meshes/R-ARM-1.stl" />
      </geometry>
    </collision>
    <inertial>
      <mass value="0.0930898796" />
      <inertia ixx="0.00011002298520777148" iyy="2.9205203701993145e-05" izz="0.00010366685695061695" ixy="-9.35188387360817e-06" ixz="-5.612043995177176e-07" iyz="1.1974630339507258e-07" />
      <origin xyz="0.00011569753847098593 -0.05711155604821049 0.019478170985148098" rpy="0 0 0" />
    </inertial>
  </link>
  <joint name="right_knee_pitch" type="revolute">
    <origin xyz="-0.010000010500000002 0.099999999 0.0004600000000000021" rpy="0.0 0.0 0.0" />
    <parent link="SJ-WK00-0023BOTTOMCASE_12_12" />
    <child link="SJ-WK00-0023BOTTOMCASE_12_13" />
    <limit effort="10" velocity="10" lower="-0.174533" upper="2.96706" />
    <axis xyz="0 0 1" />
  <dynamics damping="0.0" friction="0.0" /></joint>
  <link name="SJ-WK00-0023BOTTOMCASE_12_13">
    <visual>
      <origin xyz="0 0 0" rpy="0 0 0" />
      <geometry>
        <mesh filename="meshes/SJ-WK00-0023BOTTOMCASE_12_13.stl" />
      </geometry>
      <material name="SJ-WK00-0023BOTTOMCASE_12_13_material">
        <color rgba="0.97254902 0.52941176 0.0039215686 1" />
      </material>
    </visual>
    <collision>
      <origin xyz="0 0 0" rpy="0 0 0" />
      <geometry>
        <mesh filename="meshes/SJ-WK00-0023BOTTOMCASE_12_13.stl" />
      </geometry>
    </collision>
    <inertial>
      <mass value="0.081325173" />
      <inertia ixx="0.00011613787613505829" iyy="1.9681728653873174e-05" izz="0.00011088218454349295" ixy="-1.273194428782452e-07" ixz="-3.458822381830822e-14" iyz="-1.7549857062266403e-12" />
      <origin xyz="9.449920903926388e-05 0.04999989059129782 -0.01906109987411233" rpy="0 0 0" />
    </inertial>
  </link>
  <joint name="left_knee_pitch" type="revolute">
    <origin xyz="-0.1 0.010000000082118056 -5.999906019330356e-05" rpy="9.282041357749903e-08 0.0 0.0" />
    <parent link="SJ-WK00-0023BOTTOMCASE_12_8" />
    <child link="WJ-DP00-0002-FK-AP-020_7_8" />
    <limit effort="10" velocity="10" lower="-0.174533" upper="2.96706" />
    <axis xyz="0 0 1" />
  <dynamics damping="0.0" friction="0.0" /></joint>
  <link name="WJ-DP00-0002-FK-AP-020_7_8">
    <visual>
      <origin xyz="0 0 0" rpy="0 0 0" />
      <geometry>
        <mesh filename="meshes/WJ-DP00-0002-FK-AP-020_7_8.stl" />
      </geometry>
      <material name="WJ-DP00-0002-FK-AP-020_7_8_material">
        <color rgba="1 0 0 1" />
      </material>
    </visual>
    <collision>
      <origin xyz="0 0 0" rpy="0 0 0" />
      <geometry>
        <mesh filename="meshes/WJ-DP00-0002-FK-AP-020_7_8.stl" />
      </geometry>
    </collision>
    <inertial>
      <mass value="0.081325175" />
      <inertia ixx="3.189811903650542e-05" iyy="0.00010392147993517378" izz="0.0001108821789968365" ixy="-3.124213068704546e-05" ixz="-3.211118387890393e-13" iyz="-5.557258015832274e-14" />
      <origin xyz="0.046738267645292965 0.017763230145704155 -0.01906110037793112" rpy="0 0 0" />
    </inertial>
  </link>
  <joint name="right_gripper" type="fixed">
    <origin xyz="-0.011451791834 -0.06635827004390536 0.037039996637536134" rpy="-3.1415925143591727 0.0 0.0" />
    <parent link="L-ARM_1" />
    <child link="FINGER_1" />
    <limit effort="80" velocity="5" lower="-0.34906585" upper="0.87266463" />
    <axis xyz="0 0 1" />
  </joint>
  <link name="FINGER_1">
    <visual>
      <origin xyz="0 0 0" rpy="0 0 0" />
      <geometry>
        <mesh filename="meshes/FINGER_1.stl" />
      </geometry>
      <material name="FINGER_1_material">
        <color rgba="0.62745098 0.62745098 0.62745098 1" />
      </material>
    </visual>
    <collision>
      <origin xyz="0 0 0" rpy="0 0 0" />
      <geometry>
        <mesh filename="meshes/FINGER_1.stl" />
      </geometry>
    </collision>
    <inertial>
      <mass value="0.023485225999999998" />
      <inertia ixx="1.1001038068388435e-05" iyy="4.546969978728605e-06" izz="7.760390545852399e-06" ixy="-2.6356330000404333e-08" ixz="1.1770472324704787e-12" iyz="-3.5611904461049065e-11" />
      <origin xyz="-0.011478001022272701 0.03357210260959615 0.018799561485067146" rpy="0 0 0" />
    </inertial>
  </link>
  <joint name="left_gripper" type="fixed">
    <origin xyz="0.011451791834 -0.06635826991859772 0.03613999603753614" rpy="-3.1415925143591727 0.0 0.0" />
    <parent link="R-ARM-1" />
    <child link="FINGER_1_1" />
    <limit effort="80" velocity="5" lower="-0.87266463" upper="0.34906585" />
    <axis xyz="0 0 1" />
  </joint>
  <link name="FINGER_1_1">
    <visual>
      <origin xyz="0 0 0" rpy="0 0 0" />
      <geometry>
        <mesh filename="meshes/FINGER_1_1.stl" />
      </geometry>
      <material name="FINGER_1_1_material">
        <color rgba="0.62745098 0.62745098 0.62745098 1" />
      </material>
    </visual>
    <collision>
      <origin xyz="0 0 0" rpy="0 0 0" />
      <geometry>
        <mesh filename="meshes/FINGER_1_1.stl" />
      </geometry>
    </collision>
    <inertial>
      <mass value="0.023485229" />
      <inertia ixx="1.1039230869605936e-05" iyy="4.508781089685024e-06" izz="7.760390958054012e-06" ixy="1.0328586345067903e-07" ixz="4.474217334949162e-13" iyz="3.5243066283251986e-11" />
      <origin xyz="0.010726467165069713 0.033819718092105794 0.01879970934794886" rpy="0 0 0" />
    </inertial>
  </link>
  <joint name="right_ankle_pitch" type="revolute">
    <origin xyz="0.00018899753000000026 0.09999981929420682 1.3467926079924197e-09" rpy="-3.141592607179586 0.0 0.0" />
    <parent link="SJ-WK00-0023BOTTOMCASE_12_13" />
    <child link="FOOT_1" />
    <limit effort="10" velocity="10" lower="-1.5708" upper="1.5708" />
    <axis xyz="0 0 1" />
  <dynamics damping="0.0" friction="0.01" /></joint>
  <link name="FOOT_1">
    <visual>
      <origin xyz="0 0 0" rpy="0 0 0" />
      <geometry>
        <mesh filename="meshes/FOOT_1.stl" />
      </geometry>
      <material name="FOOT_1_material">
        <color rgba="0.62745098 0.62745098 0.62745098 1" />
      </material>
    </visual>
    <collision>
      <origin xyz="0 0 0" rpy="0 0 0" />
      <geometry>
        <mesh filename="meshes/FOOT_1.stl" />
      </geometry>
    </collision>
    <inertial>
      <mass value="0.054831945" />
      <inertia ixx="1.0902010863567692e-05" iyy="4.0196855639828154e-05" izz="3.534988107829514e-05" ixy="4.691951376056149e-07" ixz="-3.268305232520682e-08" iyz="-5.92360965411062e-11" />
      <origin xyz="0.01446036517196384 -0.026077538374261734 0.018699992978997913" rpy="0 0 0" />
    </inertial>
  </link>
  <joint name="left_ankle_pitch" type="revolute">
    <origin xyz="0.09347657200000001 0.03552647508420684 3.347702670630781e-11" rpy="-3.141592653589792 4.6410207010794124e-08 -1.5707963" />
    <parent link="WJ-DP00-0002-FK-AP-020_7_8" />
    <child link="FOOT" />
    <limit effort="10" velocity="10" lower="-1.5708" upper="1.5708" />
    <axis xyz="0 0 1" />
  <dynamics damping="0.0" friction="0.01" /></joint>
  <link name="FOOT">
    <visual>
      <origin xyz="0 0 0" rpy="0 0 0" />
      <geometry>
        <mesh filename="meshes/FOOT.stl" />
      </geometry>
      <material name="FOOT_material">
        <color rgba="0.62745098 0.62745098 0.62745098 1" />
      </material>
    </visual>
    <collision>
      <origin xyz="0 0 0" rpy="0 0 0" />
      <geometry>
        <mesh filename="meshes/FOOT.stl" />
      </geometry>
    </collision>
    <inertial>
      <mass value="0.054831927" />
      <inertia ixx="4.019136088025877e-05" iyy="1.090737668029298e-05" izz="3.534999626052283e-05" ixy="5.069888064643943e-07" ixz="4.283151198779812e-12" iyz="-1.680951821367123e-12" />
      <origin xyz="-0.0261049897441042 0.01441075482570927 0.018699986810396793" rpy="0 0 0" />
    </inertial>
  </link>
</robot>