<mujoco model="z-bot2_al_limits">
  <option iterations="50" timestep="0.001" solver="PGS" gravity="0 0 -9.81" />

  <compiler angle="radian" meshdir="meshes" eulerseq="zyx" autolimits="true" />

  <default>
    <joint limited="true" armature="0.008" frictionloss="0.013" />
    <geom condim="4" contype="1" conaffinity="15" friction="0.9 0.2 0.2" solref="0.001 2" />
    <motor ctrllimited="true" />
    <equality solref="0.001 2" />
    <default class="visualgeom">
      <geom material="visualgeom" condim="1" contype="0" conaffinity="0" />
    </default>
  </default>

  <asset>
    <mesh name="Z-BOT2_MASTER-BODY-SKELETON" file="Z-BOT2_MASTER-BODY-SKELETON.stl"/>
    <mesh name="Z-BOT2-MASTER-SHOULDER2" file="Z-BOT2-MASTER-SHOULDER2.stl"/>
    <mesh name="Z-BOT2-MASTER-SHOULDER2_2" file="Z-BOT2-MASTER-SHOULDER2_2.stl"/>
    <mesh name="U-HIP-L" file="U-HIP-L.stl"/>
    <mesh name="U-HIP-R" file="U-HIP-R.stl"/>
    <mesh name="3215_1Flange" file="3215_1Flange.stl"/>
    <mesh name="3215_1Flange_2" file="3215_1Flange_2.stl"/>
    <mesh name="3215_BothFlange" file="3215_BothFlange.stl"/>
    <mesh name="3215_BothFlange_2" file="3215_BothFlange_2.stl"/>
    <mesh name="3215_BothFlange_3" file="3215_BothFlange_3.stl"/>
    <mesh name="3215_BothFlange_4" file="3215_BothFlange_4.stl"/>
    <mesh name="R-ARM-MIRROR-1" file="R-ARM-MIRROR-1.stl"/>
    <mesh name="L-ARM-MIRROR_1" file="L-ARM-MIRROR_1.stl"/>
    <mesh name="3215_BothFlange_5" file="3215_BothFlange_5.stl"/>
    <mesh name="3215_BothFlange_6" file="3215_BothFlange_6.stl"/>
    <mesh name="FINGER_1" file="FINGER_1.stl"/>
    <mesh name="FINGER_1_2" file="FINGER_1_2.stl"/>
    <mesh name="FOOT" file="FOOT.stl"/>
    <mesh name="FOOT_2" file="FOOT_2.stl"/>
        <texture name="texplane" type="2d" builtin="checker" rgb1=".0 .0 .0" rgb2=".8 .8 .8" width="100" height="100" />
    <material name="matplane" reflectance="0." texture="texplane" texrepeat="1 1" texuniform="true" />
    <material name="visualgeom" rgba="0.5 0.9 0.2 1" />
  </asset>

  <worldbody>
      <light directional="true" diffuse="0.4 0.4 0.4" specular="0.1 0.1 0.1" pos="0 0 5.0" dir="0 0 -1" castshadow="false" />
    <light directional="true" diffuse="0.6 0.6 0.6" specular="0.2 0.2 0.2" pos="0 0 4" dir="0 0 -1" />
    <geom name="ground" type="plane" pos="0 0 0" size="100 100 0.001" quat="1 0 0 0" material="matplane" condim="3" conaffinity="15" />
    <camera name="fixed" pos="0 -3.0 0.5" xyaxes="1 0 0 0 0 1" />
    <camera name="track" mode="trackcom" pos="0 -3.0 0.5" xyaxes="1 0 0 0 0 1" />

    <body name="Z-BOT2_MASTER-BODY-SKELETON">
      <freejoint name="root" />
      <site name="imu" size="0.01" pos="0 0 0" />
      <inertial pos="-8.68153e-05 0.00960053 -0.0589276" quat="0.707354 -0.00845854 0.000660632 0.706809" mass="2.42118" diaginertia="0.0213218 0.0124974 0.0110819"/>
      <geom type="mesh" rgba="0.494118 0.623529 0.74902 1" mesh="Z-BOT2_MASTER-BODY-SKELETON"/>
      <geom pos="0.055995 -0.00960999 -0.00952781" quat="1.64085e-08 1.64085e-08 -0.707107 -0.707107" type="mesh" rgba="0.364706 0.360784 0.74902 1" mesh="Z-BOT2-MASTER-SHOULDER2"/>
      <geom pos="0.07584 0.00919001 -0.0144278" quat="3.2817e-08 0.707107 -1.89469e-08 -0.707107" type="mesh" rgba="0.74902 0.498039 0.72549 1" mesh="3215_1Flange"/>
      <geom pos="0.0944404 -0.00960971 -0.107412" quat="0.5 0.5 -0.5 0.5" type="mesh" rgba="0.647059 0.647059 0.647059 1" mesh="R-ARM-MIRROR-1"/>
      <geom pos="0.106219 -0.00986943 -0.173617" quat="0.122788 -0.122788 0.696364 0.696364" type="mesh" rgba="0.627451 0.627451 0.627451 1" mesh="FINGER_1"/>
      <geom pos="-0.055995 -0.00960999 -0.00952781" quat="0.707107 -0.707107 -3.2817e-08 3.2817e-08" type="mesh" rgba="0.364706 0.360784 0.74902 1" mesh="Z-BOT2-MASTER-SHOULDER2_2"/>
      <geom pos="-0.07584 0.00919001 -0.0144278" quat="0.707107 -3.53553e-08 0.707107 4.92255e-08" type="mesh" rgba="0.74902 0.498039 0.72549 1" mesh="3215_1Flange_2"/>
      <geom pos="-0.0944403 -0.00960971 -0.107412" quat="0.707107 -0.707107 -4.48288e-08 3.9752e-08" type="mesh" rgba="0.627451 0.627451 0.627451 1" mesh="L-ARM-MIRROR_1"/>
      <geom pos="-0.106219 -0.00986943 -0.173617" quat="0.696364 -0.696364 0.122788 0.122788" type="mesh" rgba="0.627451 0.627451 0.627451 1" mesh="FINGER_1_2"/>
      <body name="U-HIP-L" pos="0.0428082 0.00773508 -0.0844184" quat="0 2.32051e-08 1 2.32051e-08">
        <inertial pos="-0.00116062 -0.0043962 0.0353962" quat="0.921476 0.220762 0.207667 0.242942" mass="0.0471324" diaginertia="3.44774e-05 3.0413e-05 1.26353e-05"/>
        <joint name="L_Hip_Roll" pos="0 0 0" axis="0 0 1" range="-0.7 0.7" actuatorfrcrange="-1.91 1.91" frictionloss="0.1"/>
        <geom type="mesh" rgba="0.768627 0.886275 0.952941 1" mesh="U-HIP-L"/>
        <body name="3215_BothFlange" pos="0 0.0186997 0.0564" quat="0.707107 -0.707107 0 0">
          <inertial pos="0.0123316 -0.00899712 -0.0185084" quat="0.145714 0.695819 0.101439 0.695926" mass="0.0682953" diaginertia="2.54323e-05 2.35496e-05 1.92309e-05"/>
          <joint name="L_Hip_Yaw" pos="0 0 0" axis="0 0 1" range="-1.54 0.157" actuatorfrcrange="-1.91 1.91" frictionloss="0.1"/>
          <geom type="mesh" rgba="1 0 0 1" mesh="3215_BothFlange"/>
          <body name="3215_BothFlange_3" pos="-0.00739965 -0.032 -0.0179" quat="0.5 0.5 -0.5 -0.5">
            <inertial pos="0.0436622 -0.00285684 -0.0185251" quat="0.501297 0.512271 0.501533 0.484504" mass="0.143337" diaginertia="0.000148209 0.000127579 4.86495e-05"/>
            <joint name="L_Hip_Pitch" pos="0 0 0" axis="0 0 1" range="-1.54 1" actuatorfrcrange="-1.91 1.91" frictionloss="0.1"/>
            <geom type="mesh" rgba="1 0 0 1" mesh="3215_BothFlange_3"/>
            <body name="3215_BothFlange_5" pos="0.1 0.01 -0.000259724" quat="1 2.32051e-08 2.32051e-08 0">
              <inertial pos="0.05 2.60326e-09 -0.0179884" quat="0.49947 0.500681 0.50053 0.499318" mass="0.128213" diaginertia="0.000154386 0.000145408 3.53654e-05"/>
              <joint name="L_Knee_Pitch" pos="0 0 0" axis="0 0 1" range="0 1.57" actuatorfrcrange="-1.91 1.91" frictionloss="0.1"/>
              <geom type="mesh" rgba="1 0 0 1" mesh="3215_BothFlange_5"/>
              <body name="FOOT" pos="0.1 3.36408e-09 -0.000199995" quat="-1.64085e-08 -0.707107 -0.707107 1.64085e-08">
                <inertial pos="-0.0150779 0.0278353 0.0187" quat="0.507219 0.507219 0.492675 0.492675" mass="0.27814" diaginertia="0.000205404 0.000181871 4.48069e-05"/>
                <joint name="L_Ankle_Pitch" pos="0 0 0" axis="0 0 1" range="-0.9 0.9" actuatorfrcrange="-1.91 1.91" frictionloss="0.1"/>
                <geom type="mesh" rgba="0.627451 0.627451 0.627451 1" mesh="FOOT"/>
              </body>
            </body>
          </body>
        </body>
      </body>
      <body name="U-HIP-R" pos="-0.0428681 0.00773508 -0.0844184" quat="0 2.32051e-08 1 2.32051e-08">
        <inertial pos="0.00116062 -0.0043962 0.0353962" quat="0.921476 0.220762 -0.207667 -0.242942" mass="0.0471324" diaginertia="3.44774e-05 3.0413e-05 1.26353e-05"/>
        <joint name="R_Hip_Roll" pos="0 0 0" axis="0 0 1" range="-0.7 0.7" actuatorfrcrange="-1.91 1.91" frictionloss="0.1"/>
        <geom type="mesh" rgba="0.768627 0.886275 0.952941 1" mesh="U-HIP-R"/>
        <body name="3215_BothFlange_2" pos="0 -0.0186997 0.0564" quat="0.707107 -0.707107 0 0">
          <inertial pos="-0.0123316 -0.00898328 0.0178111" quat="0.0705026 0.700607 0.114113 0.700826" mass="0.0682953" diaginertia="2.5341e-05 2.36252e-05 1.92157e-05"/>
         <joint name="R_Hip_Yaw" pos="0 0 0" axis="0 0 -1" range="-1.54 0.157" actuatorfrcrange="-1.91 1.91" frictionloss="0.1"/>git
          <geom type="mesh" rgba="1 0 0 1" mesh="3215_BothFlange_2"/>
          <body name="3215_BothFlange_4" pos="0.00739966 -0.032 0.0188997" quat="0.5 -0.5 0.5 -0.5">
            <inertial pos="0.0436622 0.00286343 -0.0185366" quat="0.484624 0.501567 0.512165 0.501256" mass="0.143337" diaginertia="0.000148208 0.000127573 4.86473e-05"/>
            <joint name="R_Hip_Pitch" pos="0 0 0" axis="0 0 1" range="-1 1.54" actuatorfrcrange="-1.91 1.91" frictionloss="0.1"/>
            <geom type="mesh" rgba="1 0 0 1" mesh="3215_BothFlange_4"/>
            <body name="3215_BothFlange_6" pos="0.1 -0.01 -0.000259715" quat="1 2.32051e-08 -2.32051e-08 0">
              <inertial pos="0.05 2.88121e-09 -0.0178883" quat="0.500076 0.500076 0.499924 0.499924" mass="0.128213" diaginertia="0.000154544 0.000145407 3.5524e-05"/>
              <joint name="R_Knee_Pitch" pos="0 0 0" axis="0 0 1" range="-1.57 0" actuatorfrcrange="-1.91 1.91" frictionloss="0.1"/>
              <geom type="mesh" rgba="1 0 0 1" mesh="3215_BothFlange_6"/>
              <body name="FOOT_2" pos="0.1 3.36408e-09 4.73152e-09" quat="1.64085e-08 -0.707107 0.707107 -4.92255e-08">
                <inertial pos="-0.0150779 -0.0278353 0.0187" quat="0.492675 0.492675 0.507219 0.507219" mass="0.27814" diaginertia="0.000205404 0.000181871 4.48069e-05"/>
                <joint name="R_Ankle_Pitch" pos="0 0 0" axis="0 0 1" range="-0.9 0.9" actuatorfrcrange="-1.91 1.91" frictionloss="0.1"/>
                <geom type="mesh" rgba="0.627451 0.627451 0.627451 1" mesh="FOOT_2"/>
              </body>
            </body>
          </body>
        </body>
      </body>
    </body>
  </worldbody>


 <actuator>
    <!-- <position name="L_Hip_Roll" joint="L_Hip_Roll" inheritrange="1" />
    <position name="L_Hip_Yaw" joint="L_Hip_Yaw" inheritrange="1" />
    <position name="L_Hip_Pitch" joint="L_Hip_Pitch" inheritrange="1" />
    <position name="L_Knee_Pitch" joint="L_Knee_Pitch" inheritrange="1" />
    <position name="L_Ankle_Pitch" joint="L_Ankle_Pitch" inheritrange="1" />
    <position name="R_Hip_Roll" joint="R_Hip_Roll" inheritrange="1" />
    <position name="R_Hip_Yaw" joint="R_Hip_Yaw" inheritrange="1" />
    <position name="R_Hip_Pitch" joint="R_Hip_Pitch" inheritrange="1" />
    <position name="R_Knee_Pitch" joint="R_Knee_Pitch" inheritrange="1" />
    <position name="R_Ankle_Pitch" joint="R_Ankle_Pitch" inheritrange="1" /> 
    -->

    <motor name="L_Hip_Roll" joint="L_Hip_Roll" ctrllimited="true" ctrlrange="-10 10" gear="1" />
    <motor name="L_Hip_Yaw" joint="L_Hip_Yaw" ctrllimited="true" ctrlrange="-10 10" gear="1" />
    <motor name="L_Hip_Pitch" joint="L_Hip_Pitch" ctrllimited="true" ctrlrange="-10 10" gear="1" />
    <motor name="L_Knee_Pitch" joint="L_Knee_Pitch" ctrllimited="true" ctrlrange="-10 10" gear="1" />
    <motor name="L_Ankle_Pitch" joint="L_Ankle_Pitch" ctrllimited="true" ctrlrange="-10 10" gear="1" />
    <motor name="R_Hip_Roll" joint="R_Hip_Roll" ctrllimited="true" ctrlrange="-10 10" gear="1" />
    <motor name="R_Hip_Yaw" joint="R_Hip_Yaw" ctrllimited="true" ctrlrange="-10 10" gear="1" />
    <motor name="R_Hip_Pitch" joint="R_Hip_Pitch" ctrllimited="true" ctrlrange="-10 10" gear="1" />
    <motor name="R_Knee_Pitch" joint="R_Knee_Pitch" ctrllimited="true" ctrlrange="-10 10" gear="1" />
    <motor name="R_Ankle_Pitch" joint="R_Ankle_Pitch" ctrllimited="true" ctrlrange="-10 10" gear="1" />
 
  </actuator>

  <sensor>
    <framequat name="orientation" objtype="site" noise="0.001" objname="imu" />
    <gyro name="angular-velocity" site="imu" noise="0.005" cutoff="34.9" />
    <accelerometer name='linear-acceleration' site='imu' noise='0.005' cutoff='157'/>
    <magnetometer  name='magnetometer'        site='imu'/>
  </sensor>

  <keyframe>
    <key name="default"  qpos="0 0 0.37  1. 0.0 0.0 0.0  0.0 0.0 -0.689 1.44 0.747 0.0 0.0 0.689 -1.44 -0.747"/>
    <key name="standing" qpos="0 0 0.407 1. 0.0 0.0 0.0  0.0 0.0 0.0 0 0  0 0.0 0.0    0.0 0.0"/>
  </keyframe>
</mujoco>
