<robot name="assembly_1">
  <link name="base">
    <inertial>
      <origin rpy="0 0 0" xyz="0 0 0" />
      <mass value="0.001" />
      <inertia ixx="0.000001" ixy="0" ixz="0" iyy="0.000001" iyz="0" izz="0.000001" />
    </inertial>
  </link>
  <joint name="floating_base" type="fixed">
    <origin rpy="0 0 0" xyz="0 0 0" />
    <parent link="base" />
    <child link="Z-BOT2_MASTER-BODY-SKELETON" />
  </joint>
  <link name="Z-BOT2_MASTER-BODY-SKELETON">
    <visual>
      <origin xyz="0 0 0" rpy="0 0 0" />
      <geometry>
        <mesh filename="meshes/Z-BOT2_MASTER-BODY-SKELETON.stl" />
      </geometry>
      <material name="Z-BOT2_MASTER-BODY-SKELETON_material">
        <color rgba="0.49411765 0.62352941 0.74901961 1" />
      </material>
    </visual>
    <collision>
      <origin xyz="0 0 0" rpy="0 0 0" />
      <geometry>
        <mesh filename="meshes/Z-BOT2_MASTER-BODY-SKELETON.stl" />
      </geometry>
    </collision>
    <inertial>
      <mass value="1.5916352207" />
      <inertia ixx="0.0036302949956171114" iyy="0.004145298346457156" izz="0.0025406345168328833" ixy="7.664658594702625e-06" ixz="7.530793879865667e-06" iyz="-6.0571524521709215e-05" />
      <origin xyz="-0.0004717077766015265 0.010226167319200534 -0.04013604544506424" rpy="0 0 0" />
    </inertial>
  </link>
  <joint name="right_shoulder_yaw" type="fixed">
    <origin xyz="-0.055994975 0.02778973027464769 -0.009527810430333267" rpy="1.5707963999999996 0.0 0.0" />
    <parent link="Z-BOT2_MASTER-BODY-SKELETON" />
    <child link="Z-BOT2-MASTER-SHOULDER2" />
    <limit effort="80" velocity="5" lower="-1.2217305" upper="0.34906585" />
    <axis xyz="0 0 1" />
  </joint>
  <link name="Z-BOT2-MASTER-SHOULDER2">
    <visual>
      <origin xyz="0 0 0" rpy="0 0 0" />
      <geometry>
        <mesh filename="meshes/Z-BOT2-MASTER-SHOULDER2.stl" />
      </geometry>
      <material name="Z-BOT2-MASTER-SHOULDER2_material">
        <color rgba="0.36470588 0.36078431 0.74901961 1" />
      </material>
    </visual>
    <collision>
      <origin xyz="0 0 0" rpy="0 0 0" />
      <geometry>
        <mesh filename="meshes/Z-BOT2-MASTER-SHOULDER2.stl" />
      </geometry>
    </collision>
    <inertial>
      <mass value="0.0240976" />
      <inertia ixx="7.4193846e-06" iyy="7.798111e-06" izz="2.9824626e-06" ixy="0" ixz="0" iyz="0" />
      <origin xyz="-0.012788045 0.0013741162 0.018800156" rpy="0 0 0" />
    </inertial>
  </link>
  <joint name="left_shoulder_yaw" type="fixed">
    <origin xyz="0.055995025000000004 0.02778973027464769 -0.009527810430333267" rpy="1.5707963999999996 0.0 0.0" />
    <parent link="Z-BOT2_MASTER-BODY-SKELETON" />
    <child link="Z-BOT2-MASTER-SHOULDER2_1" />
    <limit effort="80" velocity="5" lower="-0.34906585" upper="1.2217305" />
    <axis xyz="0 0 1" />
  </joint>
  <link name="Z-BOT2-MASTER-SHOULDER2_1">
    <visual>
      <origin xyz="0 0 0" rpy="0 0 0" />
      <geometry>
        <mesh filename="meshes/Z-BOT2-MASTER-SHOULDER2_1.stl" />
      </geometry>
      <material name="Z-BOT2-MASTER-SHOULDER2_1_material">
        <color rgba="0.36470588 0.36078431 0.74901961 1" />
      </material>
    </visual>
    <collision>
      <origin xyz="0 0 0" rpy="0 0 0" />
      <geometry>
        <mesh filename="meshes/Z-BOT2-MASTER-SHOULDER2_1.stl" />
      </geometry>
    </collision>
    <inertial>
      <mass value="0.0240976" />
      <inertia ixx="7.4193846e-06" iyy="7.798111e-06" izz="2.9824626e-06" ixy="0" ixz="0" iyz="0" />
      <origin xyz="0.012788045 0.0013741162 0.018799844" rpy="0 0 0" />
    </inertial>
  </link>
  <joint name="right_hip_roll" type="revolute">
    <origin xyz="-0.043008175 0.007649730000000001 -0.1218181485" rpy="0.0 0.0 0.0" />
    <parent link="Z-BOT2_MASTER-BODY-SKELETON" />
    <child link="U-HIP_1" />
    <limit effort="10" velocity="10" lower="-1.0472" upper="1.0472" />
    <axis xyz="0 0 1" />
  <dynamics damping="0.0" friction="0.0" /></joint>
  <link name="U-HIP_1">
    <visual>
      <origin xyz="0 0 0" rpy="0 0 0" />
      <geometry>
        <mesh filename="meshes/U-HIP_1.stl" />
      </geometry>
      <material name="U-HIP_1_material">
        <color rgba="0.49803922 0.49803922 0.49803922 1" />
      </material>
    </visual>
    <collision>
      <origin xyz="0 0 0" rpy="0 0 0" />
      <geometry>
        <mesh filename="meshes/U-HIP_1.stl" />
      </geometry>
    </collision>
    <inertial>
      <mass value="0.047132399" />
      <inertia ixx="2.8702303e-05" iyy="2.9947457e-05" izz="1.8876006e-05" ixy="4.4073885e-06" ixz="8.0081775e-06" iyz="-3.8214685e-06" />
      <origin xyz="-0.0011526894 -0.0043982909 0.0020038104" rpy="0 0 0" />
    </inertial>
  </link>
  <joint name="left_hip_roll" type="revolute">
    <origin xyz="0.042868184999999996 0.007649730000000002 -0.1218181485" rpy="0.0 0.0 0.0" />
    <parent link="Z-BOT2_MASTER-BODY-SKELETON" />
    <child link="U-HIP" />
    <limit effort="10" velocity="10" lower="-1.0472" upper="1.0472" />
    <axis xyz="0 0 1" />
  <dynamics damping="0.0" friction="0.0" /></joint>
  <link name="U-HIP">
    <visual>
      <origin xyz="0 0 0" rpy="0 0 0" />
      <geometry>
        <mesh filename="meshes/U-HIP.stl" />
      </geometry>
      <material name="U-HIP_material">
        <color rgba="0.98039216 0.71372549 0.0039215686 1" />
      </material>
    </visual>
    <collision>
      <origin xyz="0 0 0" rpy="0 0 0" />
      <geometry>
        <mesh filename="meshes/U-HIP.stl" />
      </geometry>
    </collision>
    <inertial>
      <mass value="0.047132399" />
      <inertia ixx="2.871821e-05" iyy="2.9931549e-05" izz="1.8876006e-05" ixy="-4.4096062e-06" ixz="-8.0012699e-06" iyz="-3.8359105e-06" />
      <origin xyz="0.0011606228 -0.0043962041 0.0020038104" rpy="0 0 0" />
    </inertial>
  </link>
  <joint name="right_shoulder_pitch" type="fixed">
    <origin xyz="-0.019845 -0.0049 0.0188" rpy="0 1.5707963 0" />
    <parent link="Z-BOT2-MASTER-SHOULDER2" />
    <child link="FK-AP-019-25T_11_5" />
    <limit effort="80" velocity="5" lower="-3.1415927" upper="3.1415927" />
    <axis xyz="0 0 1" />
  </joint>
  <link name="FK-AP-019-25T_11_5">
    <visual>
      <origin xyz="0 0 0" rpy="0 0 0" />
      <geometry>
        <mesh filename="meshes/FK-AP-019-25T_11_5.stl" />
      </geometry>
      <material name="FK-AP-019-25T_11_5_material">
        <color rgba="0.74901961 0.49803922 0.7254902 1" />
      </material>
    </visual>
    <collision>
      <origin xyz="0 0 0" rpy="0 0 0" />
      <geometry>
        <mesh filename="meshes/FK-AP-019-25T_11_5.stl" />
      </geometry>
    </collision>
    <inertial>
      <mass value="0.1408833515" />
      <inertia ixx="0.000154152345869379" iyy="4.662190992727495e-05" izz="0.00015595641799693116" ixy="-1.7464927229047775e-06" ixz="-6.464013679518296e-08" iyz="-9.229943166826548e-06" />
      <origin xyz="-0.00023348251515803385 -0.028005716191538133 -0.019847135983077906" rpy="0 0 0" />
    </inertial>
  </link>
  <joint name="left_shoulder_pitch" type="fixed">
    <origin xyz="0.019845 -0.0049 0.0188" rpy="3.1415927 1.5707963 0" />
    <parent link="Z-BOT2-MASTER-SHOULDER2_1" />
    <child link="FK-AP-019-25T_11_16" />
    <limit effort="80" velocity="5" lower="-3.1415927" upper="3.1415927" />
    <axis xyz="0 0 1" />
  </joint>
  <link name="FK-AP-019-25T_11_16">
    <visual>
      <origin xyz="0 0 0" rpy="0 0 0" />
      <geometry>
        <mesh filename="meshes/FK-AP-019-25T_11_16.stl" />
      </geometry>
      <material name="FK-AP-019-25T_11_16_material">
        <color rgba="0.74901961 0.49803922 0.7254902 1" />
      </material>
    </visual>
    <collision>
      <origin xyz="0 0 0" rpy="0 0 0" />
      <geometry>
        <mesh filename="meshes/FK-AP-019-25T_11_16.stl" />
      </geometry>
    </collision>
    <inertial>
      <mass value="0.1408833525" />
      <inertia ixx="0.0001541573970382367" iyy="4.661886211407575e-05" izz="0.0001559562836540137" ixy="1.618632606853853e-06" ixz="-6.431525660223596e-08" iyz="9.211630122024593e-06" />
      <origin xyz="-0.0002030806504241258 0.02800597229003001 -0.019844668159711042" rpy="0 0 0" />
    </inertial>
  </link>
  <joint name="right_hip_yaw" type="revolute">
    <origin xyz="-3.3737499e-05 0.018699632 -0.019" rpy="-1.5707963 0 0.0018041779" />
    <parent link="U-HIP_1" />
    <child link="WJ-DP00-0002-FK-AP-020_7_10" />
    <limit effort="10" velocity="10" lower="-0.174533" upper="1.91986" />
    <axis xyz="0 0 1" />
  <dynamics damping="0.0" friction="0.0" /></joint>
  <link name="WJ-DP00-0002-FK-AP-020_7_10">
    <visual>
      <origin xyz="0 0 0" rpy="0 0 0" />
      <geometry>
        <mesh filename="meshes/WJ-DP00-0002-FK-AP-020_7_10.stl" />
      </geometry>
      <material name="WJ-DP00-0002-FK-AP-020_7_10_material">
        <color rgba="1 0 0 1" />
      </material>
    </visual>
    <collision>
      <origin xyz="0 0 0" rpy="0 0 0" />
      <geometry>
        <mesh filename="meshes/WJ-DP00-0002-FK-AP-020_7_10.stl" />
      </geometry>
    </collision>
    <inertial>
      <mass value="0.045121525999999995" />
      <inertia ixx="1.1467057931933392e-05" iyy="1.5408629936776894e-05" izz="1.596509642734979e-05" ixy="-1.2033215078969472e-08" ixz="-5.836884080803909e-10" iyz="-1.4417502452714832e-07" />
      <origin xyz="0.012756102149950384 0.013603595612444223 -0.018547219129262164" rpy="0 0 0" />
    </inertial>
  </link>
  <joint name="left_hip_yaw" type="revolute">
    <origin xyz="0 0.018699662 -0.019" rpy="-1.5707963 0 0" />
    <parent link="U-HIP" />
    <child link="SJ-WK00-0021TOPCABINETCASE_104_7" />
    <limit effort="10" velocity="10" lower="-1.91986" upper="0.174533" />
    <axis xyz="0 0 1" />
  <dynamics damping="0.0" friction="0.0" /></joint>
  <link name="SJ-WK00-0021TOPCABINETCASE_104_7">
    <visual>
      <origin xyz="0 0 0" rpy="0 0 0" />
      <geometry>
        <mesh filename="meshes/SJ-WK00-0021TOPCABINETCASE_104_7.stl" />
      </geometry>
      <material name="SJ-WK00-0021TOPCABINETCASE_104_7_material">
        <color rgba="0.61568627 0.81176471 0.92941176 1" />
      </material>
    </visual>
    <collision>
      <origin xyz="0 0 0" rpy="0 0 0" />
      <geometry>
        <mesh filename="meshes/SJ-WK00-0021TOPCABINETCASE_104_7.stl" />
      </geometry>
    </collision>
    <inertial>
      <mass value="0.045121527999999994" />
      <inertia ixx="1.1457611381912953e-05" iyy="1.5408630337655687e-05" izz="1.5955650176462713e-05" ixy="1.2014078171850916e-08" ixz="5.836884809194242e-10" iyz="-1.4394573705090883e-07" />
      <origin xyz="-0.012756102147506622 0.013611288248109579 -0.01854721915854193" rpy="0 0 0" />
    </inertial>
  </link>
  <joint name="right_hip_pitch" type="revolute">
    <origin xyz="0.0302 0.032000000747204306 -0.01869999899057799" rpy="-5.358979280578589e-08 1.5707962464102065 0.0" />
    <parent link="WJ-DP00-0002-FK-AP-020_7_10" />
    <child link="SJ-WK00-0023BOTTOMCASE_12_12" />
    <limit effort="10" velocity="10" lower="-1.74533" upper="1.8326" />
    <axis xyz="0 0 1" />
  <dynamics damping="0.0" friction="0.0" /></joint>
  <link name="SJ-WK00-0023BOTTOMCASE_12_12">
    <visual>
      <origin xyz="0 0 0" rpy="0 0 0" />
      <geometry>
        <mesh filename="meshes/SJ-WK00-0023BOTTOMCASE_12_12.stl" />
      </geometry>
      <material name="SJ-WK00-0023BOTTOMCASE_12_12_material">
        <color rgba="0.64705882 0.64705882 0.64705882 1" />
      </material>
    </visual>
    <collision>
      <origin xyz="0 0 0" rpy="0 0 0" />
      <geometry>
        <mesh filename="meshes/SJ-WK00-0023BOTTOMCASE_12_12.stl" />
      </geometry>
    </collision>
    <inertial>
      <mass value="0.120162816" />
      <inertia ixx="0.00011119942912727132" iyy="4.35730718242839e-05" izz="9.230498641875082e-05" ixy="-1.79623990151393e-07" ixz="-4.136285963254142e-08" iyz="-5.096469771815035e-07" />
      <origin xyz="0.0034131609150334845 0.04986381109293299 -0.018505154255758775" rpy="0 0 0" />
    </inertial>
  </link>
  <joint name="left_hip_pitch" type="revolute">
    <origin xyz="-0.0302 0.032000000747204306 -0.01869999899057799" rpy="1.5707963535897942 4.6410207010794124e-08 -1.5707963000000003" />
    <parent link="SJ-WK00-0021TOPCABINETCASE_104_7" />
    <child link="SJ-WK00-0023BOTTOMCASE_12_8" />
    <limit effort="10" velocity="10" lower="-1.8326" upper="1.74533" />
    <axis xyz="0 0 1" />
  <dynamics damping="0.0" friction="0.0" /></joint>
  <link name="SJ-WK00-0023BOTTOMCASE_12_8">
    <visual>
      <origin xyz="0 0 0" rpy="0 0 0" />
      <geometry>
        <mesh filename="meshes/SJ-WK00-0023BOTTOMCASE_12_8.stl" />
      </geometry>
      <material name="SJ-WK00-0023BOTTOMCASE_12_8_material">
        <color rgba="0.91764706 0.91764706 0.91764706 1" />
      </material>
    </visual>
    <collision>
      <origin xyz="0 0 0" rpy="0 0 0" />
      <geometry>
        <mesh filename="meshes/SJ-WK00-0023BOTTOMCASE_12_8.stl" />
      </geometry>
    </collision>
    <inertial>
      <mass value="0.120162817" />
      <inertia ixx="4.357025950662993e-05" iyy="0.00011119425028208937" izz="9.230735635044803e-05" ixy="-1.925307505605285e-07" ixz="4.678129026675985e-08" iyz="8.74733170914427e-09" />
      <origin xyz="-0.04986381088208059 -0.0034102765126529733 -0.018828274368304445" rpy="0 0 0" />
    </inertial>
  </link>
  <joint name="right_elbow_yaw" type="fixed">
    <origin xyz="0.018490802801497393 -0.09300556993952785 -0.018300660954374583" rpy="-0.0011742071795850747 -1.5707962301843608 0.0" />
    <parent link="FK-AP-019-25T_11_5" />
    <child link="L-ARM_1" />
    <limit effort="80" velocity="5" lower="-1.5707963" upper="2.0943951" />
    <axis xyz="0 0 1" />
  </joint>
  <link name="L-ARM_1">
    <visual>
      <origin xyz="0 0 0" rpy="0 0 0" />
      <geometry>
        <mesh filename="meshes/L-ARM_1.stl" />
      </geometry>
      <material name="L-ARM_1_material">
        <color rgba="0.62745098 0.62745098 0.62745098 1" />
      </material>
    </visual>
    <collision>
      <origin xyz="0 0 0" rpy="0 0 0" />
      <geometry>
        <mesh filename="meshes/L-ARM_1.stl" />
      </geometry>
    </collision>
    <inertial>
      <mass value="0.1697714245" />
      <inertia ixx="0.00021755780858965086" iyy="5.684147661540873e-05" izz="0.00019930955688960046" ixy="2.226057384066212e-05" ixz="2.951381275395214e-06" iyz="9.428338905839929e-07" />
      <origin xyz="0.001995818108992696 -0.051430034344113945 0.01968007371756068" rpy="0 0 0" />
    </inertial>
  </link>
  <joint name="left_elbow_yaw" type="fixed">
    <origin xyz="0.01859999985563785 0.09298379323429216 -0.018300646603477883" rpy="-3.1415926071795846 1.570796230184361 0.0" />
    <parent link="FK-AP-019-25T_11_16" />
    <child link="R-ARM-1" />
    <limit effort="80" velocity="5" lower="-2.0943951" upper="1.5707963" />
    <axis xyz="0 0 1" />
  </joint>
  <link name="R-ARM-1">
    <visual>
      <origin xyz="0 0 0" rpy="0 0 0" />
      <geometry>
        <mesh filename="meshes/R-ARM-1.stl" />
      </geometry>
      <material name="R-ARM-1_material">
        <color rgba="0.64705882 0.64705882 0.64705882 1" />
      </material>
    </visual>
    <collision>
      <origin xyz="0 0 0" rpy="0 0 0" />
      <geometry>
        <mesh filename="meshes/R-ARM-1.stl" />
      </geometry>
    </collision>
    <inertial>
      <mass value="0.1697709975" />
      <inertia ixx="0.00021755050496273748" iyy="5.681362943667684e-05" izz="0.000199303219842173" ixy="-2.2260337516723314e-05" ixz="-2.9142963979352063e-06" iyz="1.301614138099032e-06" />
      <origin xyz="-0.001997729758646413 -0.051430599921448085 0.019716604537413206" rpy="0 0 0" />
    </inertial>
  </link>
  <joint name="right_knee_pitch" type="revolute">
    <origin xyz="-0.010000010500000002 0.099999999 0.0004600000000000021" rpy="0.0 0.0 0.0" />
    <parent link="SJ-WK00-0023BOTTOMCASE_12_12" />
    <child link="SJ-WK00-0023BOTTOMCASE_12_13" />
    <limit effort="10" velocity="10" lower="-0.174533" upper="2.96706" />
    <axis xyz="0 0 1" />
  <dynamics damping="0.0" friction="0.0" /></joint>
  <link name="SJ-WK00-0023BOTTOMCASE_12_13">
    <visual>
      <origin xyz="0 0 0" rpy="0 0 0" />
      <geometry>
        <mesh filename="meshes/SJ-WK00-0023BOTTOMCASE_12_13.stl" />
      </geometry>
      <material name="SJ-WK00-0023BOTTOMCASE_12_13_material">
        <color rgba="0.97254902 0.52941176 0.0039215686 1" />
      </material>
    </visual>
    <collision>
      <origin xyz="0 0 0" rpy="0 0 0" />
      <geometry>
        <mesh filename="meshes/SJ-WK00-0023BOTTOMCASE_12_13.stl" />
      </geometry>
    </collision>
    <inertial>
      <mass value="0.081865261" />
      <inertia ixx="6.925128911844195e-05" iyy="2.564087694951645e-05" izz="6.393044885037816e-05" ixy="-4.9242667199167035e-08" ixz="-3.7419804208227185e-14" iyz="-3.906674756829595e-12" />
      <origin xyz="9.450092767628554e-05 0.049999853248664294 -0.01878722609840844" rpy="0 0 0" />
    </inertial>
  </link>
  <joint name="left_knee_pitch" type="revolute">
    <origin xyz="-0.1 0.010000000082118056 -5.999906019330356e-05" rpy="9.282041357749903e-08 0.0 0.0" />
    <parent link="SJ-WK00-0023BOTTOMCASE_12_8" />
    <child link="WJ-DP00-0002-FK-AP-020_7_8" />
    <limit effort="10" velocity="10" lower="-0.174533" upper="2.96706" />
    <axis xyz="0 0 1" />
  <dynamics damping="0.0" friction="0.0" /></joint>
  <link name="WJ-DP00-0002-FK-AP-020_7_8">
    <visual>
      <origin xyz="0 0 0" rpy="0 0 0" />
      <geometry>
        <mesh filename="meshes/WJ-DP00-0002-FK-AP-020_7_8.stl" />
      </geometry>
      <material name="WJ-DP00-0002-FK-AP-020_7_8_material">
        <color rgba="1 0 0 1" />
      </material>
    </visual>
    <collision>
      <origin xyz="0 0 0" rpy="0 0 0" />
      <geometry>
        <mesh filename="meshes/WJ-DP00-0002-FK-AP-020_7_8.stl" />
      </geometry>
    </collision>
    <inertial>
      <mass value="0.081865261" />
      <inertia ixx="3.116153540698499e-05" iyy="6.373062569385707e-05" izz="6.393044561015512e-05" ixy="-1.33551234220519e-05" ixz="-2.4237516126490235e-12" iyz="-1.0080231819719615e-12" />
      <origin xyz="0.0467382333772487 0.01776321540186806 -0.01878722666189501" rpy="0 0 0" />
    </inertial>
  </link>
  <joint name="right_gripper" type="fixed">
    <origin xyz="-0.011451791834 -0.06635827004390536 0.037039996637536134" rpy="-3.1415925143591727 0.0 0.0" />
    <parent link="L-ARM_1" />
    <child link="FINGER_1" />
    <limit effort="80" velocity="5" lower="-0.34906585" upper="0.87266463" />
    <axis xyz="0 0 1" />
  </joint>
  <link name="FINGER_1">
    <visual>
      <origin xyz="0 0 0" rpy="0 0 0" />
      <geometry>
        <mesh filename="meshes/FINGER_1.stl" />
      </geometry>
      <material name="FINGER_1_material">
        <color rgba="0.62745098 0.62745098 0.62745098 1" />
      </material>
    </visual>
    <collision>
      <origin xyz="0 0 0" rpy="0 0 0" />
      <geometry>
        <mesh filename="meshes/FINGER_1.stl" />
      </geometry>
    </collision>
    <inertial>
      <mass value="0.045310716" />
      <inertia ixx="2.353805518638389e-05" iyy="1.0427918195992692e-05" izz="1.6623371680484835e-05" ixy="2.7631121255331006e-06" ixz="1.7779555573406367e-12" iyz="-5.327199138027944e-11" />
      <origin xyz="-0.011324313647822635 0.02905538636712616 0.01879948129171579" rpy="0 0 0" />
    </inertial>
  </link>
  <joint name="left_gripper" type="fixed">
    <origin xyz="0.011451791834 -0.06635826991859772 0.03613999603753614" rpy="-3.1415925143591727 0.0 0.0" />
    <parent link="R-ARM-1" />
    <child link="FINGER_1_1" />
    <limit effort="80" velocity="5" lower="-0.87266463" upper="0.34906585" />
    <axis xyz="0 0 1" />
  </joint>
  <link name="FINGER_1_1">
    <visual>
      <origin xyz="0 0 0" rpy="0 0 0" />
      <geometry>
        <mesh filename="meshes/FINGER_1_1.stl" />
      </geometry>
      <material name="FINGER_1_1_material">
        <color rgba="0.62745098 0.62745098 0.62745098 1" />
      </material>
    </visual>
    <collision>
      <origin xyz="0 0 0" rpy="0 0 0" />
      <geometry>
        <mesh filename="meshes/FINGER_1_1.stl" />
      </geometry>
    </collision>
    <inertial>
      <mass value="0.045310724000000004" />
      <inertia ixx="2.3654746740030112e-05" iyy="1.0311233853059686e-05" izz="1.6623372091239476e-05" ixy="-2.4680723938859205e-06" ixz="6.52072194677929e-13" iyz="5.271762512268374e-11" />
      <origin xyz="0.01067354339388106 0.02930069796239446 0.01879978865836815" rpy="0 0 0" />
    </inertial>
  </link>
  <joint name="right_ankle_pitch" type="revolute">
    <origin xyz="0.00018899753000000026 0.09999981929420682 1.3467926079924197e-09" rpy="-3.141592607179586 0.0 0.0" />
    <parent link="SJ-WK00-0023BOTTOMCASE_12_13" />
    <child link="FOOT_1" />
    <limit effort="10" velocity="10" lower="-1.5708" upper="1.5708" />
    <axis xyz="0 0 1" />
  <dynamics damping="0.0" friction="0.01" /></joint>
  <link name="FOOT_1">
    <visual>
      <origin xyz="0 0 0" rpy="0 0 0" />
      <geometry>
        <mesh filename="meshes/FOOT_1.stl" />
      </geometry>
      <material name="FOOT_1_material">
        <color rgba="0.62745098 0.62745098 0.62745098 1" />
      </material>
    </visual>
    <collision>
      <origin xyz="0 0 0" rpy="0 0 0" />
      <geometry>
        <mesh filename="meshes/FOOT_1.stl" />
      </geometry>
    </collision>
    <inertial>
      <mass value="0.096390725" />
      <inertia ixx="2.3450069612523988e-05" iyy="6.978937423001742e-05" izz="5.959636251743274e-05" ixy="3.5264461980791924e-06" ixz="-3.268376253336344e-08" iyz="-5.740424757335317e-11" />
      <origin xyz="0.013462410440043033 -0.023503500990304915 0.01869998738311388" rpy="0 0 0" />
    </inertial>
  </link>
  <joint name="left_ankle_pitch" type="revolute">
    <origin xyz="0.09347657200000001 0.03552647508420684 3.347702670630781e-11" rpy="-3.141592653589792 4.6410207010794124e-08 -1.5707963" />
    <parent link="WJ-DP00-0002-FK-AP-020_7_8" />
    <child link="FOOT" />
    <limit effort="10" velocity="10" lower="-1.5708" upper="1.5708" />
    <axis xyz="0 0 1" />
  <dynamics damping="0.0" friction="0.01" /></joint>
  <link name="FOOT">
    <visual>
      <origin xyz="0 0 0" rpy="0 0 0" />
      <geometry>
        <mesh filename="meshes/FOOT.stl" />
      </geometry>
      <material name="FOOT_material">
        <color rgba="0.62745098 0.62745098 0.62745098 1" />
      </material>
    </visual>
    <collision>
      <origin xyz="0 0 0" rpy="0 0 0" />
      <geometry>
        <mesh filename="meshes/FOOT.stl" />
      </geometry>
    </collision>
    <inertial>
      <mass value="0.096390673" />
      <inertia ixx="6.977577639142842e-05" iyy="2.3463517729235008e-05" izz="5.9596473720615954e-05" ixy="3.6145341830580945e-06" ixz="7.081236086336525e-12" iyz="-2.7596526130307363e-12" />
      <origin xyz="-0.023529058880212384 0.013417697511934504 0.01869997826916326" rpy="0 0 0" />
    </inertial>
  </link>
</robot>