<?xml version="1.0" ?>
<robot name="k-bot_sim">
  <link name="base">
    <inertial>
      <origin rpy="0 0 0" xyz="0 0 0"/>
      <mass value="0.001"/>
      <inertia ixx="1e-06" ixy="0" ixz="0" iyy="1e-06" iyz="0" izz="1e-06"/>
    </inertial>
  </link>
  <joint name="floating_base" type="fixed">
    <origin rpy="1.57 0.00 0.00" xyz="0.0 0.0009999996829318347 0"/>
    <parent link="base"/>
    <child link="body1-part"/>
  </joint>
  <link name="body1-part">
    <visual name="body1-part_visual">
      <origin xyz="0 0 0" rpy="0 0 0"/>
      <geometry name="body1-part_geometry">
        <mesh filename="meshes/body1-part.stl"/>
      </geometry>
      <material name="body1-part_material">
        <color rgba="1 1 1 1"/>
      </material>
    </visual>
    <collision name="body1-part_collision">
      <origin xyz="0 0 0" rpy="0 0 0"/>
      <geometry name="body1-part_collision_geometry">
        <mesh filename="meshes/body1-part_collision.stl"/>
      </geometry>
    </collision>
    <inertial name="body1-part_inertial">
      <mass value="9.12867194"/>
      <inertia ixx="0.3817317070996115" iyy="0.08948278412800938" izz="0.3036879156417055" ixy="-0.0002466105148896706" ixz="1.3224535492732261e-05" iyz="-0.0001717391752494108"/>
      <origin xyz="-0.0007972140109553247 -0.2153665612094006 -9.374815759446822e-05" rpy="0 0 0"/>
    </inertial>
  </link>
  <joint name="imu_link" type="fixed" dont_collapse="true">
    <origin xyz="0.039989396 -0.12791044000000001 -2.6794896579307448e-11" rpy="-1.5707963 0 0"/>
    <parent link="body1-part"/>
    <child link="imu"/>
  </joint>
  <link name="imu">
    <visual name="imu_visual">
      <origin xyz="0 0 0" rpy="0 0 0"/>
      <geometry name="imu_geometry">
        <mesh filename="meshes/imu.stl"/>
      </geometry>
      <material name="imu_material">
        <color rgba="0.61568627 0.81176471 0.92941176 1"/>
      </material>
    </visual>
    <inertial name="imu_inertial">
      <mass value="0.01"/>
      <inertia ixx="1.1408333e-06" iyy="1.1408333e-06" izz="2.0416667e-06" ixy="0" ixz="0" iyz="0"/>
      <origin xyz="-0.0075 0 0.006" rpy="0 0 0"/>
    </inertial>
  </link>
  <joint name="left_shoulder_pitch_03" type="fixed">
    <origin xyz="-1.0603758999999933e-05 0.018089562004361112 0.18849980999999996" rpy="3.1415926071795868 -2.220446049250313e-15 3.1415926071795868"/>
    <parent link="body1-part"/>
    <child link="shoulder"/>
    <limit effort="60" velocity="6.283" lower="0" upper="3.1415927"/>
    <axis xyz="0 0 1"/>
  </joint>
  <link name="shoulder">
    <visual name="shoulder_visual">
      <origin xyz="0 0 0" rpy="0 0 0"/>
      <geometry name="shoulder_geometry">
        <mesh filename="meshes/shoulder.stl"/>
      </geometry>
      <material name="shoulder_material">
        <color rgba="1 1 1 1"/>
      </material>
    </visual>
    <collision name="shoulder_collision">
      <origin xyz="0 0 0" rpy="0 0 0"/>
      <geometry name="shoulder_collision_geometry">
        <mesh filename="meshes/shoulder.convex.stl"/>
      </geometry>
    </collision>
    <inertial name="shoulder_inertial">
      <mass value="1.1073556900000001"/>
      <inertia ixx="0.0014805078716798393" iyy="0.0010392374551579696" izz="0.0009859290096334028" ixy="1.626881849380477e-08" ixz="-3.0782402894908276e-06" iyz="6.3351533514103366e-09"/>
      <origin xyz="-0.0021439510530744978 5.4982726779193186e-05 -0.06648326479994976" rpy="0 0 0"/>
    </inertial>
  </link>
  <joint name="right_shoulder_pitch_03" type="fixed">
    <origin xyz="-1.0603759e-05 0.018089564 -0.18850019" rpy="0.0 0.0 -3.1415926071795863"/>
    <parent link="body1-part"/>
    <child link="shoulder_2"/>
    <limit effort="60" velocity="6.283" lower="-3.1415927" upper="0"/>
    <axis xyz="0 0 1"/>
  </joint>
  <link name="shoulder_2">
    <visual name="shoulder_visual_2">
      <origin xyz="0 0 0" rpy="0 0 0"/>
      <geometry name="shoulder_geometry_2">
        <mesh filename="meshes/shoulder_2.stl"/>
      </geometry>
      <material name="shoulder_material_2">
        <color rgba="1 1 1 1"/>
      </material>
    </visual>
    <collision name="shoulder_collision_2">
      <origin xyz="0 0 0" rpy="0 0 0"/>
      <geometry name="shoulder_collision_geometry_2">
        <mesh filename="meshes/shoulder_2.convex.stl"/>
      </geometry>
    </collision>
    <inertial name="shoulder_inertial_2">
      <mass value="1.10735447"/>
      <inertia ixx="0.0014805055513914607" iyy="0.0010392363644282426" izz="0.0009859285690821402" ixy="-1.621342836843456e-08" ixz="-3.0782381364669895e-06" iyz="-6.313362198399286e-09"/>
      <origin xyz="-0.00214394616645963 -5.498714744706848e-05 -0.06648329999671351" rpy="0 0 0"/>
    </inertial>
  </link>
  <joint name="left_shoulder_roll_03" type="fixed">
    <origin xyz="0.023511964 5.6278358217861975e-05 -0.06749999990621787" rpy="1.5707963 0.0 1.5707963"/>
    <parent link="shoulder"/>
    <child link="arm1_top"/>
    <limit effort="60" velocity="6.283" lower="-3.6302848" upper="0.47996554"/>
    <axis xyz="0 0 -1"/>
  </joint>
  <link name="arm1_top">
    <visual name="arm1_top_visual">
      <origin xyz="0 0 0" rpy="0 0 0"/>
      <geometry name="arm1_top_geometry">
        <mesh filename="meshes/arm1_top.stl"/>
      </geometry>
      <material name="arm1_top_material">
        <color rgba="0.89803922 0.91764706 0.92941176 1"/>
      </material>
    </visual>
    <collision name="arm1_top_collision">
      <origin xyz="0 0 0" rpy="0 0 0"/>
      <geometry name="arm1_top_collision_geometry">
        <mesh filename="meshes/arm1_top_collision.stl"/>
      </geometry>
    </collision>
    <inertial name="arm1_top_inertial">
      <mass value="0.5727323900000001"/>
      <inertia ixx="0.00045281536968184283" iyy="0.0010755180431184983" izz="0.0010349421770212762" ixy="3.099319168992167e-08" ixz="-0.000195415179046849" iyz="6.8108635082006405e-09"/>
      <origin xyz="-0.09948603961018607 -1.163023470429744e-06 -0.019082499611823907" rpy="0 0 0"/>
    </inertial>
  </link>
  <joint name="right_shoulder_roll_03" type="fixed">
    <origin xyz="0.023511963999999996 -5.627835821786203e-05 -0.06749999985980766" rpy="1.5707963999999996 -2.220446049250313e-16 -1.5707963000000003"/>
    <parent link="shoulder_2"/>
    <child link="arm1_top_2"/>
    <limit effort="60" velocity="6.283" lower="-0.47996554" upper="3.6302848"/>
    <axis xyz="0 0 1"/>
  </joint>
  <link name="arm1_top_2">
    <visual name="arm1_top_2_visual">
      <origin xyz="0 0 0" rpy="0 0 0"/>
      <geometry name="arm1_top_2_geometry">
        <mesh filename="meshes/arm1_top_2.stl"/>
      </geometry>
      <material name="arm1_top_2_material">
        <color rgba="0.89803922 0.91764706 0.92941176 1"/>
      </material>
    </visual>
    <collision name="arm1_top_2_collision">
      <origin xyz="0 0 0" rpy="0 0 0"/>
      <geometry name="arm1_top_2_collision_geometry">
        <mesh filename="meshes/arm1_top_2_collision.stl"/>
      </geometry>
    </collision>
    <inertial name="arm1_top_2_inertial">
      <mass value="0.57273186"/>
      <inertia ixx="0.00045281497091044417" iyy="0.0010755170174298718" izz="0.0010349414496449352" ixy="2.8936136529413266e-08" ixz="0.0001954159355517661" iyz="-6.3598192451400854e-09"/>
      <origin xyz="-0.0994860712208834 -1.0854900129017722e-06 0.0180824641107766" rpy="0 0 0"/>
    </inertial>
  </link>
  <joint name="left_hip_pitch_04" type="revolute">
    <origin xyz="-1.0608550148631657e-05 -0.43201043164593794 0.0887000068648673" rpy="-3.1415925071795874 4.641020678874952e-08 -3.1415926535897913"/>
    <parent link="body1-part"/>
    <child link="leg0_shell"/>
    <limit effort="120" velocity="6.283" lower="-2.0943953" upper="2.0943953"/>
    <axis xyz="0 0 1"/>
  </joint>
  <link name="leg0_shell">
    <visual name="leg0_shell_visual">
      <origin xyz="0 0 0" rpy="0 0 0"/>
      <geometry name="leg0_shell_geometry">
        <mesh filename="meshes/leg0_shell.stl"/>
      </geometry>
      <material name="leg0_shell_material">
        <color rgba="0.89803922 0.91764706 0.92941176 1"/>
      </material>
    </visual>
    <collision name="leg0_shell_collision">
      <origin xyz="0 0 0" rpy="0 0 0"/>
      <geometry name="leg0_shell_collision_geometry">
        <mesh filename="meshes/leg0_shell.convex.stl"/>
      </geometry>
    </collision>
    <inertial name="leg0_shell_inertial">
      <mass value="1.3234480570000002"/>
      <inertia ixx="0.0018858182013085161" iyy="0.001424832171389183" izz="0.0012997049050806671" ixy="-4.528695728174104e-12" ixz="7.006193648128378e-06" iyz="-9.656589772176694e-13"/>
      <origin xyz="-0.003746324486178213 -5.30704079226868e-10 -0.06812512159159122" rpy="0 0 0"/>
    </inertial>
  </link>
  <joint name="right_hip_pitch_04" type="revolute">
    <origin xyz="-1.0600293772844438e-05 -0.4320104468591277 -0.08919999313513188" rpy="9.99999991702083e-08 4.641020678874952e-08 -3.1415926535897913"/>
    <parent link="body1-part"/>
    <child link="leg0_shell_2"/>
    <limit effort="120" velocity="6.283" lower="-2.0943953" upper="2.0943953"/>
    <axis xyz="0 0 1"/>
  </joint>
  <link name="leg0_shell_2">
    <visual name="leg0_shell_visual_2">
      <origin xyz="0 0 0" rpy="0 0 0"/>
      <geometry name="leg0_shell_geometry_2">
        <mesh filename="meshes/leg0_shell_2.stl"/>
      </geometry>
      <material name="leg0_shell_material_2">
        <color rgba="0.89803922 0.91764706 0.92941176 1"/>
      </material>
    </visual>
    <collision name="leg0_shell_collision_2">
      <origin xyz="0 0 0" rpy="0 0 0"/>
      <geometry name="leg0_shell_collision_geometry_2">
        <mesh filename="meshes/leg0_shell_2.convex.stl"/>
      </geometry>
    </collision>
    <inertial name="leg0_shell_inertial_2">
      <mass value="1.3234480570000002"/>
      <inertia ixx="0.0018858182013085161" iyy="0.001424832171389183" izz="0.0012997049050806671" ixy="-4.528695728174104e-12" ixz="7.006193648128378e-06" iyz="-9.656589772176694e-13"/>
      <origin xyz="-0.003746324486178213 -5.30704079226868e-10 -0.06762512159159122" rpy="0 0 0"/>
    </inertial>
  </link>
  <joint name="left_shoulder_yaw_02" type="fixed">
    <origin xyz="-0.14049999999999996 -1.5083317163881439e-09 -0.023499999129165863" rpy="-1.5707963535897926 -2.6794894969484062e-08 -1.5707962803846895"/>
    <parent link="arm1_top"/>
    <child link="arm2_shell"/>
    <limit effort="17" velocity="12.566" lower="-1.5707963" upper="1.5707963"/>
    <axis xyz="0 0 1"/>
  </joint>
  <link name="arm2_shell">
    <visual name="arm2_shell_visual">
      <origin xyz="0 0 0" rpy="0 0 0"/>
      <geometry name="arm2_shell_geometry">
        <mesh filename="meshes/arm2_shell.stl"/>
      </geometry>
      <material name="arm2_shell_material">
        <color rgba="0.89803922 0.91764706 0.92941176 1"/>
      </material>
    </visual>
    <collision name="arm2_shell_collision">
      <origin xyz="0 0 0" rpy="0 0 0"/>
      <geometry name="arm2_shell_collision_geometry">
        <mesh filename="meshes/arm2_shell_collision.stl"/>
      </geometry>
    </collision>
    <inertial name="arm2_shell_inertial">
      <mass value="0.51067762"/>
      <inertia ixx="0.0006753518437663356" iyy="0.0005324861864496071" izz="0.0002548209726832716" ixy="0.0" ixz="-5.869105846462616e-06" iyz="0.0"/>
      <origin xyz="-0.0063392296102198434 0.0 -0.0904821109301573" rpy="0 0 0"/>
    </inertial>
  </link>
  <joint name="right_shoulder_yaw_02" type="fixed">
    <origin xyz="-0.14049999999999999 4.64102069112142e-11 0.02249999912916586" rpy="-3.1415926071795863 1.5707963 0.0"/>
    <parent link="arm1_top_2"/>
    <child link="arm2_shell_2"/>
    <limit effort="17" velocity="12.566" lower="-1.5707963" upper="1.5707963"/>
    <axis xyz="0 0 -1"/>
  </joint>
  <link name="arm2_shell_2">
    <visual name="arm2_shell_visual_2">
      <origin xyz="0 0 0" rpy="0 0 0"/>
      <geometry name="arm2_shell_geometry_2">
        <mesh filename="meshes/arm2_shell_2.stl"/>
      </geometry>
      <material name="arm2_shell_material_2">
        <color rgba="0.89803922 0.91764706 0.92941176 1"/>
      </material>
    </visual>
    <collision name="arm2_shell_collision_2">
      <origin xyz="0 0 0" rpy="0 0 0"/>
      <geometry name="arm2_shell_collision_geometry_2">
        <mesh filename="meshes/arm2_shell_2_collision.stl"/>
      </geometry>
    </collision>
    <inertial name="arm2_shell_inertial_2">
      <mass value="0.51067762"/>
      <inertia ixx="0.0005324861845826297" iyy="0.000675351841899358" izz="0.00025482097268327166" ixy="-2.591463103359651e-12" ixz="9.334887806097578e-13" iyz="5.8691032549994485e-06"/>
      <origin xyz="-2.431455634827428e-10 -0.006339229610219842 0.08998211068701173" rpy="0 0 0"/>
    </inertial>
  </link>
  <joint name="left_hip_roll_03" type="revolute">
    <origin xyz="0.027499999999999972 -1.543386042968109e-09 -0.06950000154338605" rpy="-1.5707963 0.0 1.5707963"/>
    <parent link="leg0_shell"/>
    <child link="leg1_shell"/>
    <limit effort="60" velocity="6.283" lower="-3.7088249" upper="0.8726648"/>
    <axis xyz="0 0 1"/>
  </joint>
  <link name="leg1_shell">
    <visual name="leg1_shell_visual">
      <origin xyz="0 0 0" rpy="0 0 0"/>
      <geometry name="leg1_shell_geometry">
        <mesh filename="meshes/leg1_shell.stl"/>
      </geometry>
      <material name="leg1_shell_material">
        <color rgba="0.89803922 0.91764706 0.92941176 1"/>
      </material>
    </visual>
    <collision name="leg1_shell_collision">
      <origin xyz="0 0 0" rpy="0 0 0"/>
      <geometry name="leg1_shell_collision_geometry">
        <mesh filename="meshes/leg1_shell_collision.stl"/>
      </geometry>
    </collision>
    <inertial name="leg1_shell_inertial">
      <mass value="1.2643519300000001"/>
      <inertia ixx="0.001480722299407104" iyy="0.0024857502211153284" izz="0.002413187112415161" ixy="-1.8022158654617094e-05" ixz="0.0002898210604994088" iyz="-1.8263226520453171e-06"/>
      <origin xyz="-0.11252357996383634 0.0005288807919385997 0.025258644134954013" rpy="0 0 0"/>
    </inertial>
  </link>
  <joint name="right_hip_roll_03" type="revolute">
    <origin xyz="0.027499999999999972 -1.5433860431346424e-09 -0.06900000154338605" rpy="1.5707963 -4.641020634466031e-08 -1.5707963535897922"/>
    <parent link="leg0_shell_2"/>
    <child link="leg1_shell3"/>
    <limit effort="60" velocity="6.283" lower="-0.8726648" upper="3.7088249"/>
    <axis xyz="0 0 1"/>
  </joint>
  <link name="leg1_shell3">
    <visual name="leg1_shell3_visual">
      <origin xyz="0 0 0" rpy="0 0 0"/>
      <geometry name="leg1_shell3_geometry">
        <mesh filename="meshes/leg1_shell3.stl"/>
      </geometry>
      <material name="leg1_shell3_material">
        <color rgba="0.89803922 0.91764706 0.92941176 1"/>
      </material>
    </visual>
    <collision name="leg1_shell3_collision">
      <origin xyz="0 0 0" rpy="0 0 0"/>
      <geometry name="leg1_shell3_collision_geometry">
        <mesh filename="meshes/leg1_shell3_collision.stl"/>
      </geometry>
    </collision>
    <inertial name="leg1_shell3_inertial">
      <mass value="1.26435173"/>
      <inertia ixx="0.0014807220164984244" iyy="0.002485749979629834" izz="0.002413186730835335" ixy="1.802236851510111e-05" ixz="0.00028982126672702426" iyz="1.8263915020547572e-06"/>
      <origin xyz="-0.11252358418706353 -0.0005288879516895658 0.02525863895910433" rpy="0 0 0"/>
    </inertial>
  </link>
  <joint name="left_elbow_02" type="fixed">
    <origin xyz="-0.027 -4.64102069112142e-11 -0.09799999974544849" rpy="-3.1415926071795863 -1.5707963 0.0"/>
    <parent link="arm2_shell"/>
    <child link="arm3_shell"/>
    <limit effort="17" velocity="12.566" lower="-2.5307274" upper="0"/>
    <axis xyz="0 0 1"/>
  </joint>
  <link name="arm3_shell">
    <visual name="arm3_shell_visual">
      <origin xyz="0 0 0" rpy="0 0 0"/>
      <geometry name="arm3_shell_geometry">
        <mesh filename="meshes/arm3_shell.stl"/>
      </geometry>
      <material name="arm3_shell_material">
        <color rgba="0.89803922 0.91764706 0.92941176 1"/>
      </material>
    </visual>
    <collision name="arm3_shell_collision">
      <origin xyz="0 0 0" rpy="0 0 0"/>
      <geometry name="arm3_shell_collision_geometry">
        <mesh filename="meshes/arm3_shell.convex.stl"/>
      </geometry>
    </collision>
    <inertial name="arm3_shell_inertial">
      <mass value="0.5785364000000001"/>
      <inertia ixx="0.00042811744536643573" iyy="0.0013539990986906295" izz="0.0013317921733241934" ixy="-2.616182402256878e-14" ixz="0.00014431151914258368" iyz="4.4457625073285856e-13"/>
      <origin xyz="-0.14016867364356536 -3.717439453122118e-10 0.019432851288742756" rpy="0 0 0"/>
    </inertial>
  </link>
  <joint name="right_elbow_02" type="fixed">
    <origin xyz="2.0814131093671585e-10 -0.027000000000000003 0.0975" rpy="-1.5707963071795865 1.5707963 0.0"/>
    <parent link="arm2_shell_2"/>
    <child link="arm3_shell2"/>
    <limit effort="17" velocity="12.566" lower="0" upper="2.5307274"/>
    <axis xyz="0 0 1"/>
  </joint>
  <link name="arm3_shell2">
    <visual name="arm3_shell2_visual">
      <origin xyz="0 0 0" rpy="0 0 0"/>
      <geometry name="arm3_shell2_geometry">
        <mesh filename="meshes/arm3_shell2.stl"/>
      </geometry>
      <material name="arm3_shell2_material">
        <color rgba="0.89803922 0.91764706 0.92941176 1"/>
      </material>
    </visual>
    <collision name="arm3_shell2_collision">
      <origin xyz="0 0 0" rpy="0 0 0"/>
      <geometry name="arm3_shell2_collision_geometry">
        <mesh filename="meshes/arm3_shell2.convex.stl"/>
      </geometry>
    </collision>
    <inertial name="arm3_shell2_inertial">
      <mass value="0.5785364000000001"/>
      <inertia ixx="0.00042811744536643573" iyy="0.0013539990986906295" izz="0.0013317921733241934" ixy="-2.616182402256878e-14" ixz="0.00014431151914258368" iyz="4.4457625073285856e-13"/>
      <origin xyz="-0.14016867364356536 -3.717439453122118e-10 0.019432851288742756" rpy="0 0 0"/>
    </inertial>
  </link>
  <joint name="left_hip_yaw_03" type="revolute">
    <origin xyz="-0.15749999999999997 0.00011981393 0.027499998456613956" rpy="-0.0 1.5707963 0.0"/>
    <parent link="leg1_shell"/>
    <child link="leg2_shell"/>
    <limit effort="60" velocity="6.283" lower="-2.0943953" upper="2.0943953"/>
    <axis xyz="0 0 1"/>
  </joint>
  <link name="leg2_shell">
    <visual name="leg2_shell_visual">
      <origin xyz="0 0 0" rpy="0 0 0"/>
      <geometry name="leg2_shell_geometry">
        <mesh filename="meshes/leg2_shell.stl"/>
      </geometry>
      <material name="leg2_shell_material">
        <color rgba="0.89803922 0.91764706 0.92941176 1"/>
      </material>
    </visual>
    <collision name="leg2_shell_collision">
      <origin xyz="0 0 0" rpy="0 0 0"/>
      <geometry name="leg2_shell_collision_geometry">
        <mesh filename="meshes/leg2_shell_collision.stl"/>
      </geometry>
    </collision>
    <inertial name="leg2_shell_inertial">
      <mass value="1.820922667"/>
      <inertia ixx="0.003118121982315594" iyy="0.004225341330146898" izz="0.0020643672406963944" ixy="-6.676045962463134e-09" ixz="-2.2416298133304992e-08" iyz="-3.3507405748121275e-05"/>
      <origin xyz="4.0855477721508534e-07 0.0005316844118462806 -0.13730778343676694" rpy="0 0 0"/>
    </inertial>
  </link>
  <joint name="right_hip_yaw_03" type="revolute">
    <origin xyz="-0.15749999999999997 -0.00011981393000000101 0.027499998536998718" rpy="-3.1415926535897922 -1.5707962732050302 0.0"/>
    <parent link="leg1_shell3"/>
    <child link="leg2_shell_2"/>
    <limit effort="60" velocity="6.283" lower="-2.0943953" upper="2.0943953"/>
    <axis xyz="0 0 1"/>
  </joint>
  <link name="leg2_shell_2">
    <visual name="leg2_shell_visual_2">
      <origin xyz="0 0 0" rpy="0 0 0"/>
      <geometry name="leg2_shell_geometry_2">
        <mesh filename="meshes/leg2_shell_2.stl"/>
      </geometry>
      <material name="leg2_shell_material_2">
        <color rgba="0.89803922 0.91764706 0.92941176 1"/>
      </material>
    </visual>
    <collision name="leg2_shell_collision_2">
      <origin xyz="0 0 0" rpy="0 0 0"/>
      <geometry name="leg2_shell_collision_geometry_2">
        <mesh filename="meshes/leg2_shell_2_collision.stl"/>
      </geometry>
    </collision>
    <inertial name="leg2_shell_inertial_2">
      <mass value="1.820922667"/>
      <inertia ixx="0.003118121982315594" iyy="0.004225341330146898" izz="0.0020643672406963944" ixy="-6.676045962463134e-09" ixz="-2.2416298133304992e-08" iyz="-3.3507405748121275e-05"/>
      <origin xyz="4.0855477721508534e-07 0.0005316844118462806 -0.13730778343676694" rpy="0 0 0"/>
    </inertial>
  </link>
  <joint name="left_wrist_02" type="fixed">
    <origin xyz="-0.18249999999999997 -1.5083317163881439e-09 0.021500000870834136" rpy="-1.5707963535897926 -2.6794894969484062e-08 -1.5707962803846895"/>
    <parent link="arm3_shell"/>
    <child link="hand_shell"/>
    <limit effort="17" velocity="12.566" lower="-3.1415927" upper="3.1415927"/>
    <axis xyz="0 0 1"/>
  </joint>
  <link name="hand_shell">
    <visual name="hand_shell_visual">
      <origin xyz="0 0 0" rpy="0 0 0"/>
      <geometry name="hand_shell_geometry">
        <mesh filename="meshes/hand_shell.stl"/>
      </geometry>
      <material name="hand_shell_material">
        <color rgba="0.89803922 0.91764706 0.92941176 1"/>
      </material>
    </visual>
    <collision name="hand_shell_collision">
      <origin xyz="0 0 0" rpy="0 0 0"/>
      <geometry name="hand_shell_collision_geometry">
        <mesh filename="meshes/hand_shell.convex.stl"/>
      </geometry>
    </collision>
    <inertial name="hand_shell_inertial">
      <mass value="0.7930633560000001"/>
      <inertia ixx="0.002033598085511773" iyy="0.0028694095214354134" izz="0.0012795940143811779" ixy="-5.175045781118732e-07" ixz="-2.323267344282338e-05" iyz="3.5517121016370314e-06"/>
      <origin xyz="0.000708974660250137 0.00012975738648229475 -0.074657370365049" rpy="0 0 0"/>
    </inertial>
  </link>
  <joint name="right_wrist_02" type="fixed">
    <origin xyz="-0.18249999999999997 -1.5083317161660992e-09 0.021500000870834136" rpy="1.5707963535897933 -2.679489807810853e-08 1.5707963732051022"/>
    <parent link="arm3_shell2"/>
    <child link="hand_shell_2"/>
    <limit effort="17" velocity="12.566" lower="-3.1415927" upper="3.1415927"/>
    <axis xyz="0 0 1"/>
  </joint>
  <link name="hand_shell_2">
    <visual name="hand_shell_visual_2">
      <origin xyz="0 0 0" rpy="0 0 0"/>
      <geometry name="hand_shell_geometry_2">
        <mesh filename="meshes/hand_shell_2.stl"/>
      </geometry>
      <material name="hand_shell_material_2">
        <color rgba="0.89803922 0.91764706 0.92941176 1"/>
      </material>
    </visual>
    <collision name="hand_shell_collision_2">
      <origin xyz="0 0 0" rpy="0 0 0"/>
      <geometry name="hand_shell_collision_geometry_2">
        <mesh filename="meshes/hand_shell_2.convex.stl"/>
      </geometry>
    </collision>
    <inertial name="hand_shell_inertial_2">
      <mass value="0.7930633560000001"/>
      <inertia ixx="0.002033598085511773" iyy="0.0028694095214354134" izz="0.0012795940143811779" ixy="-5.175045781118732e-07" ixz="-2.323267344282338e-05" iyz="3.5517121016370314e-06"/>
      <origin xyz="0.000708974660250137 0.00012975738648229475 -0.074657370365049" rpy="0 0 0"/>
    </inertial>
  </link>
  <joint name="left_knee_04" type="revolute">
    <origin xyz="0.0 -0.026999999999999993 -0.14250000111820607" rpy="1.5707963999999996 0.0 0.0"/>
    <parent link="leg2_shell"/>
    <child link="leg3_shell1"/>
    <limit effort="120" velocity="6.283" lower="-0.523599" upper="2.6179941"/>
    <axis xyz="0 0 -1"/>
  </joint>
  <link name="leg3_shell1">
    <visual name="leg3_shell1_visual">
      <origin xyz="0 0 0" rpy="0 0 0"/>
      <geometry name="leg3_shell1_geometry">
        <mesh filename="meshes/leg3_shell1.stl"/>
      </geometry>
      <material name="leg3_shell1_material">
        <color rgba="0.89803922 0.91764706 0.92941176 1"/>
      </material>
    </visual>
    <collision name="leg3_shell1_collision">
      <origin xyz="0 0 0" rpy="0 0 0"/>
      <geometry name="leg3_shell1_collision_geometry">
        <mesh filename="meshes/leg3_shell1_collision.stl"/>
      </geometry>
    </collision>
    <inertial name="leg3_shell1_inertial">
      <mass value="1.10995541"/>
      <inertia ixx="0.006739845799719679" iyy="0.001012730687089295" izz="0.006745576240125188" ixy="6.159162149120938e-05" ixz="-1.699359215617402e-05" iyz="1.3074784844620735e-05"/>
      <origin xyz="0.0010978724929563855 -0.13132151953133744 -0.023162295394724867" rpy="0 0 0"/>
    </inertial>
  </link>
  <joint name="right_knee_04" type="revolute">
    <origin xyz="0.0 -0.026999999999999993 -0.14250000111820607" rpy="1.5707963999999996 0.0 0.0"/>
    <parent link="leg2_shell_2"/>
    <child link="leg3_shell11"/>
    <limit effort="120" velocity="6.283" lower="-2.6179941" upper="0.523599"/>
    <axis xyz="0 0 -1"/>
  </joint>
  <link name="leg3_shell11">
    <visual name="leg3_shell11_visual">
      <origin xyz="0 0 0" rpy="0 0 0"/>
      <geometry name="leg3_shell11_geometry">
        <mesh filename="meshes/leg3_shell11.stl"/>
      </geometry>
      <material name="leg3_shell11_material">
        <color rgba="0.89803922 0.91764706 0.92941176 1"/>
      </material>
    </visual>
    <collision name="leg3_shell11_collision">
      <origin xyz="0 0 0" rpy="0 0 0"/>
      <geometry name="leg3_shell11_collision_geometry">
        <mesh filename="meshes/leg3_shell11_collision.stl"/>
      </geometry>
    </collision>
    <inertial name="leg3_shell11_inertial">
      <mass value="1.10996161"/>
      <inertia ixx="0.006739857987300133" iyy="0.0010127351585175947" izz="0.006745588887673965" ixy="-6.15973246606697e-05" ixz="1.6994436331084193e-05" iyz="1.307451589253059e-05"/>
      <origin xyz="-0.0010979208720722662 -0.13132176227251938 -0.023162198059025228" rpy="0 0 0"/>
    </inertial>
  </link>
  <joint name="right_ankle_02" type="revolute">
    <origin xyz="2.153907282807268e-18 -0.3000000000464102 -0.035500000000000004" rpy="3.1415927 0 3.1415927"/>
    <parent link="leg3_shell11"/>
    <child link="foot3"/>
    <limit effort="17" velocity="12.566" lower="-1.2217307" upper="1.2217307"/>
    <axis xyz="0 0 -1"/>
  </joint>
  <link name="foot3">
    <visual name="foot3_visual">
      <origin xyz="0 0 0" rpy="0 0 0"/>
      <geometry name="foot3_geometry">
        <mesh filename="meshes/foot3.stl"/>
      </geometry>
      <material name="foot3_material">
        <color rgba="0.89803922 0.91764706 0.92941176 1"/>
      </material>
    </visual>
    <collision name="foot3_collision">
      <origin xyz="0 0 0" rpy="0 0 0"/>
      <geometry name="foot3_collision_geometry">
        <mesh filename="meshes/foot3.convex.stl"/>
      </geometry>
    </collision>
    <inertial name="foot3_inertial">
      <mass value="0.58209108"/>
      <inertia ixx="0.0002838753748975717" iyy="0.00218822676565083" izz="0.002023734835894537" ixy="3.9780111288661e-05" ixz="3.349573310652279e-05" iyz="-3.862324128656251e-06"/>
      <origin xyz="0.02134992304317914 -0.019418963220724724 -0.023723771995791686" rpy="0 0 0"/>
    </inertial>
  </link>
  <joint name="left_ankle_02" type="revolute">
    <origin xyz="0.0 -0.30000000013923045 0.009499991182060727" rpy="9.282041333256967e-08 0.0 0.0"/>
    <parent link="leg3_shell1"/>
    <child link="foot1"/>
    <limit effort="17" velocity="12.566" lower="-1.2217307" upper="1.2217307"/>
    <axis xyz="0 0 -1"/>
  </joint>
  <link name="foot1">
    <visual name="foot1_visual">
      <origin xyz="0 0 0" rpy="0 0 0"/>
      <geometry name="foot1_geometry">
        <mesh filename="meshes/foot1.stl"/>
      </geometry>
      <material name="foot1_material">
        <color rgba="0.89803922 0.91764706 0.92941176 1"/>
      </material>
    </visual>
    <collision name="foot1_collision">
      <origin xyz="0 0 0" rpy="0 0 0"/>
      <geometry name="foot1_collision_geometry">
        <mesh filename="meshes/foot1.convex.stl"/>
      </geometry>
    </collision>
    <inertial name="foot1_inertial">
      <mass value="0.58209124"/>
      <inertia ixx="0.0002838753702978436" iyy="0.002188226940492543" izz="0.0020237350419067264" ixy="3.9780235731382326e-05" ixz="-3.349583633130496e-05" iyz="3.862347414317424e-06"/>
      <origin xyz="0.02134990704811795 -0.019418958531554592 -0.019276222305656024" rpy="0 0 0"/>
    </inertial>
  </link>
</robot>
