<?xml version="1.0" ?>
<robot name="k-bot-v2">
  <link name="base">
    <inertial>
      <origin rpy="0 0 0" xyz="0 0 0"/>
      <mass value="0.001"/>
      <inertia ixx="1e-06" ixy="0" ixz="0" iyy="1e-06" iyz="0" izz="1e-06"/>
    </inertial>
  </link>
  <joint name="floating_base" type="fixed">
    <origin rpy="0.00 0.00 0.00" xyz="0.0 0.0009999996829318347 -7.963267107333194e-07"/>
    <parent link="base"/>
    <child link="TORSO_BOTTOM_1"/>
  </joint>
  <link name="TORSO_BOTTOM_1">
    <visual name="TORSO_BOTTOM_1_visual">
      <origin xyz="0 0 0" rpy="0 0 0"/>
      <geometry name="TORSO_BOTTOM_1_geometry">
        <mesh filename="meshes/TORSO_BOTTOM_1.stl"/>
      </geometry>
      <material name="TORSO_BOTTOM_1_material">
        <color rgba="0.97254902 0.52941176 0.0039215686 1"/>
      </material>
    </visual>
    <collision name="TORSO_BOTTOM_1_collision">
      <origin xyz="0 0 0" rpy="0 0 0"/>
      <geometry name="TORSO_BOTTOM_1_collision_geometry">
        <mesh filename="meshes/TORSO_BOTTOM_1.stl"/>
      </geometry>
    </collision>
    <inertial name="TORSO_BOTTOM_1_inertial">
      <mass value="13.061691293"/>
      <inertia ixx="0.3591473987651503" iyy="0.3953487792126659" izz="0.06505518478105819" ixy="6.629025741877432e-05" ixz="-3.5519382641948125e-05" iyz="0.0003660094618944637"/>
      <origin xyz="0.0006523810858182181 -0.0019805513154017122 0.13169976657485213" rpy="0 0 0"/>
    </inertial>
  </link>
  <joint name="left_hip_pitch_04" type="revolute">
    <origin xyz="-0.056495156388220724 1.548108519327779e-05 -0.07179286928519331" rpy="-1.5707963 4.6410206566704915e-08 -1.5707963535897922"/>
    <parent link="TORSO_BOTTOM_1"/>
    <child link="L_Hip_Yoke_Drive"/>
    <limit effort="120" velocity="6.283" lower="-1.5707963" upper="1.9198622"/>
    <axis xyz="0 0 1"/>
  </joint>
  <link name="L_Hip_Yoke_Drive">
    <visual name="L_Hip_Yoke_Drive_visual">
      <origin xyz="0 0 0" rpy="0 0 0"/>
      <geometry name="L_Hip_Yoke_Drive_geometry">
        <mesh filename="meshes/L_Hip_Yoke_Drive.stl"/>
      </geometry>
      <material name="L_Hip_Yoke_Drive_material">
        <color rgba="0.2627451 0.28235294 0.30196078 1"/>
      </material>
    </visual>
    <collision name="L_Hip_Yoke_Drive_collision">
      <origin xyz="0 0 0" rpy="0 0 0"/>
      <geometry name="L_Hip_Yoke_Drive_collision_geometry">
        <mesh filename="meshes/L_Hip_Yoke_Drive.stl"/>
      </geometry>
    </collision>
    <inertial name="L_Hip_Yoke_Drive_inertial">
      <mass value="0.850879618"/>
      <inertia ixx="0.0014184140251395465" iyy="0.0017691788017342189" izz="0.0019825403974594504" ixy="9.111829983020253e-05" ixz="-0.00012070936874722659" iyz="0.00026552966769775844"/>
      <origin xyz="-0.008180615777367948 0.0017840253123379952 -0.03211871678440863" rpy="0 0 0"/>
    </inertial>
  </link>
  <joint name="right_hip_pitch_04" type="revolute">
    <origin xyz="0.0565048409105324 1.547891480672564e-05 -0.07179286928519331" rpy="1.5707963 -4.641020634466031e-08 -1.5707963535897922"/>
    <parent link="TORSO_BOTTOM_1"/>
    <child link="R_Hip_Yoke_Drive"/>
    <limit effort="120" velocity="6.283" lower="-1.9198622" upper="1.5707963"/>
    <axis xyz="0 0 1"/>
  </joint>
  <link name="R_Hip_Yoke_Drive">
    <visual name="R_Hip_Yoke_Drive_visual">
      <origin xyz="0 0 0" rpy="0 0 0"/>
      <geometry name="R_Hip_Yoke_Drive_geometry">
        <mesh filename="meshes/R_Hip_Yoke_Drive.stl"/>
      </geometry>
      <material name="R_Hip_Yoke_Drive_material">
        <color rgba="0.2627451 0.28235294 0.30196078 1"/>
      </material>
    </visual>
    <collision name="R_Hip_Yoke_Drive_collision">
      <origin xyz="0 0 0" rpy="0 0 0"/>
      <geometry name="R_Hip_Yoke_Drive_collision_geometry">
        <mesh filename="meshes/R_Hip_Yoke_Drive.stl"/>
      </geometry>
    </collision>
    <inertial name="R_Hip_Yoke_Drive_inertial">
      <mass value="0.8508816880000001"/>
      <inertia ixx="0.0014209208005698268" iyy="0.0017717385892818019" izz="0.001980283631065328" ixy="-9.246727819993663e-05" ixz="-0.00011802066495809474" iyz="-0.00026657104283751333"/>
      <origin xyz="-0.008192454378784339 -0.0017616406090224307 -0.032183643127408824" rpy="0 0 0"/>
    </inertial>
  </link>
  <joint name="right_shoulder_pitch_03" type="fixed">
    <origin xyz="0.12395483289078238 -0.002148124546924123 0.338707134112055" rpy="1.5707963071795872 -4.6410206566704915e-08 -1.5707963535897917"/>
    <parent link="TORSO_BOTTOM_1"/>
    <child link="R_SHLDR_YAW-A"/>
    <limit effort="60" velocity="6.283" lower="-3.4906585" upper="1.9198622"/>
    <axis xyz="0 0 1"/>
  </joint>
  <link name="R_SHLDR_YAW-A">
    <visual name="R_SHLDR_YAW-A_visual">
      <origin xyz="0 0 0" rpy="0 0 0"/>
      <geometry name="R_SHLDR_YAW-A_geometry">
        <mesh filename="meshes/R_SHLDR_YAW-A.stl"/>
      </geometry>
      <material name="R_SHLDR_YAW-A_material">
        <color rgba="0.97254902 0.52941176 0.0039215686 1"/>
      </material>
    </visual>
    <collision name="R_SHLDR_YAW-A_collision">
      <origin xyz="0 0 0" rpy="0 0 0"/>
      <geometry name="R_SHLDR_YAW-A_collision_geometry">
        <mesh filename="meshes/R_SHLDR_YAW-A.stl"/>
      </geometry>
    </collision>
    <inertial name="R_SHLDR_YAW-A_inertial">
      <mass value="0.38816839110000007"/>
      <inertia ixx="0.0006642980330859071" iyy="0.0008736859213093423" izz="0.000749846622332919" ixy="3.6138702019625217e-06" ixz="1.3060682064639775e-05" iyz="1.418612073712983e-06"/>
      <origin xyz="0.007270334877790527 0.00010250544009193658 -0.04298091275185955" rpy="0 0 0"/>
    </inertial>
  </link>
  <joint name="left_shoulder_pitch_03" type="fixed">
    <origin xyz="-0.12394516500822303 -0.0021481216530753566 0.3387071333530755" rpy="-1.5707963 4.6410206566704915e-08 -1.5707963535897922"/>
    <parent link="TORSO_BOTTOM_1"/>
    <child link="L_SHLDR_YAW-A_"/>
    <limit effort="60" velocity="6.283" lower="-3.4906585" upper="1.9198622"/>
    <axis xyz="0 0 1"/>
  </joint>
  <link name="L_SHLDR_YAW-A_">
    <visual name="L_SHLDR_YAW-A__visual">
      <origin xyz="0 0 0" rpy="0 0 0"/>
      <geometry name="L_SHLDR_YAW-A__geometry">
        <mesh filename="meshes/L_SHLDR_YAW-A_.stl"/>
      </geometry>
      <material name="L_SHLDR_YAW-A__material">
        <color rgba="0.23137255 0.38039216 0.70588235 1"/>
      </material>
    </visual>
    <collision name="L_SHLDR_YAW-A__collision">
      <origin xyz="0 0 0" rpy="0 0 0"/>
      <geometry name="L_SHLDR_YAW-A__collision_geometry">
        <mesh filename="meshes/L_SHLDR_YAW-A_.stl"/>
      </geometry>
    </collision>
    <inertial name="L_SHLDR_YAW-A__inertial">
      <mass value="0.3881656491"/>
      <inertia ixx="0.0006642956133699661" iyy="0.0008736839151392586" izz="0.0007498435353391363" ixy="-3.6146147099033966e-06" ixz="1.3062314419526681e-05" iyz="-1.4186715126309422e-06"/>
      <origin xyz="0.007270341214786868 -0.00010237647746921621 -0.042980971148385214" rpy="0 0 0"/>
    </inertial>
  </link>
  <joint name="left_hip_roll_03" type="revolute">
    <origin xyz="-0.02425 0.03 -0.0660000000267949" rpy="0 -1.5707963 0"/>
    <parent link="L_Hip_Yoke_Drive"/>
    <child link="L_Hip_Yaw_RS03"/>
    <limit effort="60" velocity="6.283" lower="-0.20943951" upper="2.6179939"/>
    <axis xyz="0 0 1"/>
  </joint>
  <link name="L_Hip_Yaw_RS03">
    <visual name="L_Hip_Yaw_RS03_visual">
      <origin xyz="0 0 0" rpy="0 0 0"/>
      <geometry name="L_Hip_Yaw_RS03_geometry">
        <mesh filename="meshes/L_Hip_Yaw_RS03.stl"/>
      </geometry>
      <material name="L_Hip_Yaw_RS03_material">
        <color rgba="0.97254902 0.52941176 0.0039215686 1"/>
      </material>
    </visual>
    <collision name="L_Hip_Yaw_RS03_collision">
      <origin xyz="0 0 0" rpy="0 0 0"/>
      <geometry name="L_Hip_Yaw_RS03_collision_geometry">
        <mesh filename="meshes/L_Hip_Yaw_RS03.stl"/>
      </geometry>
    </collision>
    <inertial name="L_Hip_Yaw_RS03_inertial">
      <mass value="2.67808146"/>
      <inertia ixx="0.011223661667652615" iyy="0.003913470265973227" izz="0.011748024206866164" ixy="6.276794543921215e-06" ixz="9.780045683993612e-06" iyz="-0.0005033033832567847"/>
      <origin xyz="8.629312978396952e-05 0.054853058590216504 -0.027274199443530538" rpy="0 0 0"/>
    </inertial>
  </link>
  <joint name="right_hip_roll_03" type="revolute">
    <origin xyz="-0.024250000000000004 -0.030000000046410204 -0.0659999999732051" rpy="3.1415927 1.5707963 0"/>
    <parent link="R_Hip_Yoke_Drive"/>
    <child link="L_Hip_Yaw_RS03_2"/>
    <limit effort="60" velocity="6.283" lower="-2.6179939" upper="0.20943951"/>
    <axis xyz="0 0 1"/>
  </joint>
  <link name="L_Hip_Yaw_RS03_2">
    <visual name="L_Hip_Yaw_RS03_visual_2">
      <origin xyz="0 0 0" rpy="0 0 0"/>
      <geometry name="L_Hip_Yaw_RS03_geometry_2">
        <mesh filename="meshes/L_Hip_Yaw_RS03_2.stl"/>
      </geometry>
      <material name="L_Hip_Yaw_RS03_material_2">
        <color rgba="0.97254902 0.52941176 0.0039215686 1"/>
      </material>
    </visual>
    <collision name="L_Hip_Yaw_RS03_collision_2">
      <origin xyz="0 0 0" rpy="0 0 0"/>
      <geometry name="L_Hip_Yaw_RS03_collision_geometry_2">
        <mesh filename="meshes/L_Hip_Yaw_RS03_2.stl"/>
      </geometry>
    </collision>
    <inertial name="L_Hip_Yaw_RS03_inertial_2">
      <mass value="2.67807848"/>
      <inertia ixx="0.011210213637211346" iyy="0.003917948953890383" izz="0.011754306957604812" ixy="1.6547230429103996e-05" ixz="-1.2126067850967451e-05" iyz="-0.0005060637422820512"/>
      <origin xyz="-0.00010253388914313968 0.0548350699932074 -0.027269266133648693" rpy="0 0 0"/>
    </inertial>
  </link>
  <joint name="right_shoulder_roll_03" type="fixed">
    <origin xyz="-0.02425 0.0 -0.0800000000267949" rpy="0 -1.5707963 0"/>
    <parent link="R_SHLDR_YAW-A"/>
    <child link="RS03"/>
    <limit effort="60" velocity="6.283" lower="-1.6580628" upper="0.48869219"/>
    <axis xyz="0 0 1"/>
  </joint>
  <link name="RS03">
    <visual name="RS03_visual">
      <origin xyz="0 0 0" rpy="0 0 0"/>
      <geometry name="RS03_geometry">
        <mesh filename="meshes/RS03.stl"/>
      </geometry>
      <material name="RS03_material">
        <color rgba="0.97254902 0.52941176 0.0039215686 1"/>
      </material>
    </visual>
    <collision name="RS03_collision">
      <origin xyz="0 0 0" rpy="0 0 0"/>
      <geometry name="RS03_collision_geometry">
        <mesh filename="meshes/RS03.stl"/>
      </geometry>
    </collision>
    <inertial name="RS03_inertial">
      <mass value="1.8646100800999998"/>
      <inertia ixx="0.0075098914311835996" iyy="0.0021012862106297237" izz="0.007938562916300443" ixy="-0.0006294375665310775" ixz="-1.7227380826624815e-06" iyz="8.906159495576759e-06"/>
      <origin xyz="-0.0052177909488822765 -0.042723028642503706 -0.0299485598560192" rpy="0 0 0"/>
    </inertial>
  </link>
  <joint name="left_shoulder_roll_03" type="fixed">
    <origin xyz="-0.02425 -2.6794896579307448e-11 -0.0800000000267949" rpy="-1.5707963 0 1.5707963"/>
    <parent link="L_SHLDR_YAW-A_"/>
    <child link="RS03_2"/>
    <limit effort="60" velocity="6.283" lower="-0.48869219" upper="1.6580628"/>
    <axis xyz="0 0 1"/>
  </joint>
  <link name="RS03_2">
    <visual name="RS03_visual_2">
      <origin xyz="0 0 0" rpy="0 0 0"/>
      <geometry name="RS03_geometry_2">
        <mesh filename="meshes/RS03_2.stl"/>
      </geometry>
      <material name="RS03_material_2">
        <color rgba="0.97254902 0.52941176 0.0039215686 1"/>
      </material>
    </visual>
    <collision name="RS03_collision_2">
      <origin xyz="0 0 0" rpy="0 0 0"/>
      <geometry name="RS03_collision_geometry_2">
        <mesh filename="meshes/RS03_2.stl"/>
      </geometry>
    </collision>
    <inertial name="RS03_inertial_2">
      <mass value="1.8646094401000002"/>
      <inertia ixx="0.002117089966846184" iyy="0.0074993663964198105" izz="0.007956235818653661" ixy="-0.0006636269747626453" ixz="3.024790780798619e-05" iyz="8.701130305624066e-06"/>
      <origin xyz="0.0426874649098865 0.005364201672817688 -0.030194760612173667" rpy="0 0 0"/>
    </inertial>
  </link>
  <joint name="right_hip_yaw_03" type="revolute">
    <origin xyz="8.900090130537314e-09 0.14300000421300732 -0.025249999952628055" rpy="-1.5707963071795867 -4.6410206566704915e-08 3.141592560769381"/>
    <parent link="L_Hip_Yaw_RS03_2"/>
    <child link="R_Femur_Lower_Drive"/>
    <limit effort="60" velocity="6.283" lower="-1.5707963" upper="1.9198622"/>
    <axis xyz="0 0 1"/>
  </joint>
  <link name="R_Femur_Lower_Drive">
    <visual name="R_Femur_Lower_Drive_visual">
      <origin xyz="0 0 0" rpy="0 0 0"/>
      <geometry name="R_Femur_Lower_Drive_geometry">
        <mesh filename="meshes/R_Femur_Lower_Drive.stl"/>
      </geometry>
      <material name="R_Femur_Lower_Drive_material">
        <color rgba="0.49803922 0.49803922 0.49803922 1"/>
      </material>
    </visual>
    <collision name="R_Femur_Lower_Drive_collision">
      <origin xyz="0 0 0" rpy="0 0 0"/>
      <geometry name="R_Femur_Lower_Drive_collision_geometry">
        <mesh filename="meshes/R_Femur_Lower_Drive.stl"/>
      </geometry>
    </collision>
    <inertial name="R_Femur_Lower_Drive_inertial">
      <mass value="2.5458089619999997"/>
      <inertia ixx="0.017543258007624945" iyy="0.015965378132556877" izz="0.0043901051570052665" ixy="0.00017558320099919758" ixz="-0.001031698413189701" iyz="0.001613083098030859"/>
      <origin xyz="-0.0008479213381278404 0.011563430463445904 -0.1645473478551726" rpy="0 0 0"/>
    </inertial>
  </link>
  <joint name="right_shoulder_yaw_02" type="fixed">
    <origin xyz="-0.013027815851142209 -0.14250000289956488 -0.030245284794312124" rpy="1.5707963996335306 -0.008726650000000058 3.141592595346938"/>
    <parent link="RS03"/>
    <child link="R_BICEP_LOWER-DRIVE"/>
    <limit effort="17" velocity="12.566" lower="-1.7453293" upper="1.7453293"/>
    <axis xyz="0 0 1"/>
  </joint>
  <link name="R_BICEP_LOWER-DRIVE">
    <visual name="R_BICEP_LOWER-DRIVE_visual">
      <origin xyz="0 0 0" rpy="0 0 0"/>
      <geometry name="R_BICEP_LOWER-DRIVE_geometry">
        <mesh filename="meshes/R_BICEP_LOWER-DRIVE.stl"/>
      </geometry>
      <material name="R_BICEP_LOWER-DRIVE_material">
        <color rgba="0.61568627 0.81176471 0.92941176 1"/>
      </material>
    </visual>
    <collision name="R_BICEP_LOWER-DRIVE_collision">
      <origin xyz="0 0 0" rpy="0 0 0"/>
      <geometry name="R_BICEP_LOWER-DRIVE_collision_geometry">
        <mesh filename="meshes/R_BICEP_LOWER-DRIVE.stl"/>
      </geometry>
    </collision>
    <inertial name="R_BICEP_LOWER-DRIVE_inertial">
      <mass value="0.84293946"/>
      <inertia ixx="0.0028029712426870146" iyy="0.002621816955415604" izz="0.0009050928071385421" ixy="-2.129762098906347e-05" ixz="0.00018605305518487155" iyz="0.00014532043231286243"/>
      <origin xyz="-0.0002516982430851186 0.0027596156182569755 -0.0983836419020131" rpy="0 0 0"/>
    </inertial>
  </link>
  <joint name="left_shoulder_yaw_02" type="fixed">
    <origin xyz="0.14250000111248584 0.012713926047757364 -0.03020093770906647" rpy="-1.5707962267948243 -2.6794896301751692e-08 1.5707963267948966"/>
    <parent link="RS03_2"/>
    <child link="L_BICEP_LOWER_DRIVE"/>
    <limit effort="17" velocity="12.566" lower="-1.7453293" upper="1.7453293"/>
    <axis xyz="0 0 1"/>
  </joint>
  <link name="L_BICEP_LOWER_DRIVE">
    <visual name="L_BICEP_LOWER_DRIVE_visual">
      <origin xyz="0 0 0" rpy="0 0 0"/>
      <geometry name="L_BICEP_LOWER_DRIVE_geometry">
        <mesh filename="meshes/L_BICEP_LOWER_DRIVE.stl"/>
      </geometry>
      <material name="L_BICEP_LOWER_DRIVE_material">
        <color rgba="0.23137255 0.38039216 0.70588235 1"/>
      </material>
    </visual>
    <collision name="L_BICEP_LOWER_DRIVE_collision">
      <origin xyz="0 0 0" rpy="0 0 0"/>
      <geometry name="L_BICEP_LOWER_DRIVE_collision_geometry">
        <mesh filename="meshes/L_BICEP_LOWER_DRIVE.stl"/>
      </geometry>
    </collision>
    <inertial name="L_BICEP_LOWER_DRIVE_inertial">
      <mass value="0.8427538800000001"/>
      <inertia ixx="0.0028260312171053126" iyy="0.0026341960750257474" izz="0.0009154778059838686" ixy="2.4694966792567638e-05" ixz="0.00018582736467473118" iyz="-0.00017128387261541682"/>
      <origin xyz="-0.000252958007022258 -0.003597008713631938 -0.09862439369890269" rpy="0 0 0"/>
    </inertial>
  </link>
  <joint name="left_hip_yaw_03" type="revolute">
    <origin xyz="8.737654313262573e-09 0.1430000033427469 -0.025250003435317102" rpy="-1.5707962071795865 0.0 3.1415926071795863"/>
    <parent link="L_Hip_Yaw_RS03"/>
    <child link="L_Femur_Lower_Drive"/>
    <limit effort="60" velocity="6.283" lower="-1.5707963" upper="1.9198622"/>
    <axis xyz="0 0 1"/>
  </joint>
  <link name="L_Femur_Lower_Drive">
    <visual name="L_Femur_Lower_Drive_visual">
      <origin xyz="0 0 0" rpy="0 0 0"/>
      <geometry name="L_Femur_Lower_Drive_geometry">
        <mesh filename="meshes/L_Femur_Lower_Drive.stl"/>
      </geometry>
      <material name="L_Femur_Lower_Drive_material">
        <color rgba="0.49803922 0.49803922 0.49803922 1"/>
      </material>
    </visual>
    <collision name="L_Femur_Lower_Drive_collision">
      <origin xyz="0 0 0" rpy="0 0 0"/>
      <geometry name="L_Femur_Lower_Drive_collision_geometry">
        <mesh filename="meshes/L_Femur_Lower_Drive.stl"/>
      </geometry>
    </collision>
    <inertial name="L_Femur_Lower_Drive_inertial">
      <mass value="2.4603065899999996"/>
      <inertia ixx="0.017150400219543865" iyy="0.015566118116192048" izz="0.004223259197204856" ixy="-0.00015413661936377422" ixz="0.0008942999968457732" iyz="0.001604494673625525"/>
      <origin xyz="-0.00018240469371031163 0.011335105648022809 -0.16248139381226717" rpy="0 0 0"/>
    </inertial>
  </link>
  <joint name="left_elbow_02" type="fixed">
    <origin xyz="-0.019000000085993334 -0.00999752800444823 -0.13702813751982898" rpy="1.570796400123929 -0.09599312679489658 1.570796324214841"/>
    <parent link="L_BICEP_LOWER_DRIVE"/>
    <child link="L_FOREARM_UPPER_STRUCTURAL"/>
    <limit effort="17" velocity="12.566" lower="-2.5307274" upper="0"/>
    <axis xyz="0 0 1"/>
  </joint>
  <link name="L_FOREARM_UPPER_STRUCTURAL">
    <visual name="L_FOREARM_UPPER_STRUCTURAL_visual">
      <origin xyz="0 0 0" rpy="0 0 0"/>
      <geometry name="L_FOREARM_UPPER_STRUCTURAL_geometry">
        <mesh filename="meshes/L_FOREARM_UPPER_STRUCTURAL.stl"/>
      </geometry>
      <material name="L_FOREARM_UPPER_STRUCTURAL_material">
        <color rgba="0.64705882 0.64705882 0.64705882 1"/>
      </material>
    </visual>
    <collision name="L_FOREARM_UPPER_STRUCTURAL_collision">
      <origin xyz="0 0 0" rpy="0 0 0"/>
      <geometry name="L_FOREARM_UPPER_STRUCTURAL_collision_geometry">
        <mesh filename="meshes/L_FOREARM_UPPER_STRUCTURAL.stl"/>
      </geometry>
    </collision>
    <inertial name="L_FOREARM_UPPER_STRUCTURAL_inertial">
      <mass value="0.6491781400000001"/>
      <inertia ixx="0.0013609365738054247" iyy="0.0007193784296669726" izz="0.0013478330524201334" ixy="4.180794483620586e-05" ixz="-1.4830425049735462e-05" iyz="8.229355894988428e-05"/>
      <origin xyz="0.016156114069715417 -0.05753942796815662 0.015153293785799422" rpy="0 0 0"/>
    </inertial>
  </link>
  <joint name="left_knee_04" type="revolute">
    <origin xyz="-0.02099999837519743 0.020999999640192304 -0.21200000204019234" rpy="1.5707963 0.0 1.5707963"/>
    <parent link="L_Femur_Lower_Drive"/>
    <child link="L-TIBIA-INNER_"/>
    <limit effort="120" velocity="6.283" lower="0" upper="2.6703538"/>
    <axis xyz="0 0 1"/>
  </joint>
  <link name="L-TIBIA-INNER_">
    <visual name="L-TIBIA-INNER__visual">
      <origin xyz="0 0 0" rpy="0 0 0"/>
      <geometry name="L-TIBIA-INNER__geometry">
        <mesh filename="meshes/L-TIBIA-INNER_.stl"/>
      </geometry>
      <material name="L-TIBIA-INNER__material">
        <color rgba="0.97254902 0.52941176 0.0039215686 1"/>
      </material>
    </visual>
    <collision name="L-TIBIA-INNER__collision">
      <origin xyz="0 0 0" rpy="0 0 0"/>
      <geometry name="L-TIBIA-INNER__collision_geometry">
        <mesh filename="meshes/L-TIBIA-INNER_.stl"/>
      </geometry>
    </collision>
    <inertial name="L-TIBIA-INNER__inertial">
      <mass value="1.850531369"/>
      <inertia ixx="0.01704648524159625" iyy="0.0030029416535673347" izz="0.01721855594741047" ixy="-3.440814584191332e-05" ixz="0.0001027766039433787" iyz="0.00030559040389285775"/>
      <origin xyz="-0.02191489092668439 -0.1024317711742123 0.018775336907083367" rpy="0 0 0"/>
    </inertial>
  </link>
  <joint name="right_knee_04" type="revolute">
    <origin xyz="0.021099998493035996 0.02034023431476345 -0.212648350120343" rpy="-1.5707962070772346 -0.08726646299999974 1.5707962976557508"/>
    <parent link="R_Femur_Lower_Drive"/>
    <child link="R-TIBIA-INNER_"/>
    <limit effort="120" velocity="6.283" lower="-2.6005406" upper="0.078539816"/>
    <axis xyz="0 0 1"/>
  </joint>
  <link name="R-TIBIA-INNER_">
    <visual name="R-TIBIA-INNER__visual">
      <origin xyz="0 0 0" rpy="0 0 0"/>
      <geometry name="R-TIBIA-INNER__geometry">
        <mesh filename="meshes/R-TIBIA-INNER_.stl"/>
      </geometry>
      <material name="R-TIBIA-INNER__material">
        <color rgba="0.97254902 0.52941176 0.0039215686 1"/>
      </material>
    </visual>
    <collision name="R-TIBIA-INNER__collision">
      <origin xyz="0 0 0" rpy="0 0 0"/>
      <geometry name="R-TIBIA-INNER__collision_geometry">
        <mesh filename="meshes/R-TIBIA-INNER_.stl"/>
      </geometry>
    </collision>
    <inertial name="R-TIBIA-INNER__inertial">
      <mass value="1.8505552620000003"/>
      <inertia ixx="0.01699559491827396" iyy="0.002983977255465123" izz="0.017155484867086228" ixy="0.00023804519959614516" ixz="6.12635225506719e-05" iyz="-0.00033000215228796596"/>
      <origin xyz="-0.022770140893696382 0.10287936723890725 0.018824476368744097" rpy="0 0 0"/>
    </inertial>
  </link>
  <joint name="right_elbow_02" type="fixed">
    <origin xyz="-0.01900000056016338 0.010007317759360172 -0.13702727562463635" rpy="-1.5707963646886025 -2.6794893859261038e-08 -1.5707962535897928"/>
    <parent link="R_BICEP_LOWER-DRIVE"/>
    <child link="R_FOREARM_UPPER_STRUCTURAL"/>
    <limit effort="17" velocity="12.566" lower="0" upper="2.5307274"/>
    <axis xyz="0 0 1"/>
  </joint>
  <link name="R_FOREARM_UPPER_STRUCTURAL">
    <visual name="R_FOREARM_UPPER_STRUCTURAL_visual">
      <origin xyz="0 0 0" rpy="0 0 0"/>
      <geometry name="R_FOREARM_UPPER_STRUCTURAL_geometry">
        <mesh filename="meshes/R_FOREARM_UPPER_STRUCTURAL.stl"/>
      </geometry>
      <material name="R_FOREARM_UPPER_STRUCTURAL_material">
        <color rgba="0.61568627 0.81176471 0.92941176 1"/>
      </material>
    </visual>
    <collision name="R_FOREARM_UPPER_STRUCTURAL_collision">
      <origin xyz="0 0 0" rpy="0 0 0"/>
      <geometry name="R_FOREARM_UPPER_STRUCTURAL_collision_geometry">
        <mesh filename="meshes/R_FOREARM_UPPER_STRUCTURAL.stl"/>
      </geometry>
    </collision>
    <inertial name="R_FOREARM_UPPER_STRUCTURAL_inertial">
      <mass value="0.6491800400000001"/>
      <inertia ixx="0.001359715877502022" iyy="0.0007182268603835769" izz="0.00134781146237228" ixy="-4.1846890212545286e-05" ixz="-1.4597843187092314e-05" iyz="-7.807241983487332e-05"/>
      <origin xyz="0.01615538627318021 0.05754082175552143 0.014849609597869016" rpy="0 0 0"/>
    </inertial>
  </link>
  <joint name="left_ankle_02" type="revolute">
    <origin xyz="-0.026 -0.2925 0.003" rpy="0 0 0"/>
    <parent link="L-TIBIA-INNER_"/>
    <child link="L_LEG-FOOT"/>
    <limit effort="17" velocity="12.566" lower="-0.78539816" upper="0.29670597"/>
    <axis xyz="0 0 1"/>
  </joint>
  <link name="L_LEG-FOOT">
    <visual name="L_LEG-FOOT_visual">
      <origin xyz="0 0 0" rpy="0 0 0"/>
      <geometry name="L_LEG-FOOT_geometry">
        <mesh filename="meshes/L_LEG-FOOT.stl"/>
      </geometry>
      <material name="L_LEG-FOOT_material">
        <color rgba="0.64705882 0.64705882 0.64705882 1"/>
      </material>
    </visual>
    <collision name="L_LEG-FOOT_collision">
      <origin xyz="0 0 0" rpy="0 0 0"/>
      <geometry name="L_LEG-FOOT_collision_geometry">
        <mesh filename="meshes/L_LEG-FOOT.stl"/>
      </geometry>
    </collision>
    <inertial name="L_LEG-FOOT_inertial">
      <mass value="0.49274898"/>
      <inertia ixx="0.000283460072103993" iyy="0.0015602901762423707" izz="0.0014852293364640238" ixy="-8.505864662651985e-05" ixz="2.1392937702987948e-05" iyz="1.8360568463946685e-05"/>
      <origin xyz="-0.013264731378632117 -0.028577932561279933 0.011944367356908027" rpy="0 0 0"/>
    </inertial>
  </link>
  <joint name="left_wrist_02" type="fixed">
    <origin xyz="0.017350000572946937 -0.10300000033493621 0.017999999565063794" rpy="-1.5707963071795865 -1.5707963 0.0"/>
    <parent link="L_FOREARM_UPPER_STRUCTURAL"/>
    <child link="L_EndEff_Mount_1"/>
    <limit effort="17" velocity="12.566" lower="-1.5707963" upper="1.5707963"/>
    <axis xyz="0 0 1"/>
  </joint>
  <link name="L_EndEff_Mount_1">
    <visual name="L_EndEff_Mount_1_visual">
      <origin xyz="0 0 0" rpy="0 0 0"/>
      <geometry name="L_EndEff_Mount_1_geometry">
        <mesh filename="meshes/L_EndEff_Mount_1.stl"/>
      </geometry>
      <material name="L_EndEff_Mount_1_material">
        <color rgba="0.61568627 0.81176471 0.92941176 1"/>
      </material>
    </visual>
    <collision name="L_EndEff_Mount_1_collision">
      <origin xyz="0 0 0" rpy="0 0 0"/>
      <geometry name="L_EndEff_Mount_1_collision_geometry">
        <mesh filename="meshes/L_EndEff_Mount_1.stl"/>
      </geometry>
    </collision>
    <inertial name="L_EndEff_Mount_1_inertial">
      <mass value="0.17958563"/>
      <inertia ixx="0.00010237335" iyy="0.00011019776" izz="8.8324157e-05" ixy="0" ixz="5.6389034e-06" iyz="0"/>
      <origin xyz="-0.0058748036 0 -0.030963262" rpy="0 0 0"/>
    </inertial>
  </link>
  <joint name="right_ankle_02" type="revolute">
    <origin xyz="-0.025999999999999995 0.292499995396667 0.03300001483027525" rpy="9.282041333256967e-08 0.0 0.0"/>
    <parent link="R-TIBIA-INNER_"/>
    <child link="R_FOOT_LEG"/>
    <limit effort="17" velocity="12.566" lower="-0.29670597" upper="0.78539816"/>
    <axis xyz="0 0 1"/>
  </joint>
  <link name="R_FOOT_LEG">
    <visual name="R_FOOT_LEG_visual">
      <origin xyz="0 0 0" rpy="0 0 0"/>
      <geometry name="R_FOOT_LEG_geometry">
        <mesh filename="meshes/R_FOOT_LEG.stl"/>
      </geometry>
      <material name="R_FOOT_LEG_material">
        <color rgba="0.98039216 0.71372549 0.0039215686 1"/>
      </material>
    </visual>
    <collision name="R_FOOT_LEG_collision">
      <origin xyz="0 0 0" rpy="0 0 0"/>
      <geometry name="R_FOOT_LEG_collision_geometry">
        <mesh filename="meshes/R_FOOT_LEG.stl"/>
      </geometry>
    </collision>
    <inertial name="R_FOOT_LEG_inertial">
      <mass value="0.49274876"/>
      <inertia ixx="0.00028346008822660693" iyy="0.0015602907888710874" izz="0.0014852299783467086" ixy="8.505861650821186e-05" ixz="2.1392910325931817e-05" iyz="-1.836049313227581e-05"/>
      <origin xyz="-0.013264732279278421 0.02857794219894329 -0.01605560559482646" rpy="0 0 0"/>
    </inertial>
  </link>
  <joint name="right_wrist_02" type="fixed">
    <origin xyz="0.017349999519873475 0.10300000033493621 0.017999999565063797" rpy="1.5707963999999996 1.5707963000000005 0.0"/>
    <parent link="R_FOREARM_UPPER_STRUCTURAL"/>
    <child link="L_EndEff_Mount_2"/>
    <limit effort="17" velocity="12.566" lower="-1.5707963" upper="1.5707963"/>
    <axis xyz="0 0 1"/>
  </joint>
  <link name="L_EndEff_Mount_2">
    <visual name="L_EndEff_Mount_2_visual">
      <origin xyz="0 0 0" rpy="0 0 0"/>
      <geometry name="L_EndEff_Mount_2_geometry">
        <mesh filename="meshes/L_EndEff_Mount_2.stl"/>
      </geometry>
      <material name="L_EndEff_Mount_2_material">
        <color rgba="0.61568627 0.81176471 0.92941176 1"/>
      </material>
    </visual>
    <collision name="L_EndEff_Mount_2_collision">
      <origin xyz="0 0 0" rpy="0 0 0"/>
      <geometry name="L_EndEff_Mount_2_collision_geometry">
        <mesh filename="meshes/L_EndEff_Mount_2.stl"/>
      </geometry>
    </collision>
    <inertial name="L_EndEff_Mount_2_inertial">
      <mass value="0.17958624"/>
      <inertia ixx="0.00010237367" iyy="0.00011019788" izz="8.8324394e-05" ixy="0" ixz="-5.6388594e-06" iyz="0"/>
      <origin xyz="0.0058748187 0 -0.030963304" rpy="0 0 0"/>
    </inertial>
  </link>
</robot>
