<?xml version="1.0" ?>
<robot name="k-bot-v2">
  <link name="base">
    <inertial>
      <origin rpy="0 0 0" xyz="0 0 0"/>
      <mass value="0.001"/>
      <inertia ixx="1e-06" ixy="0" ixz="0" iyy="1e-06" iyz="0" izz="1e-06"/>
    </inertial>
  </link>
  <joint name="floating_base" type="fixed">
    <origin rpy="0.00 0.00 0.00" xyz="0 0 0"/>
    <parent link="base"/>
    <child link="TORSO_BOTTOM_1"/>
  </joint>
  <link name="TORSO_BOTTOM_1">
    <visual name="TORSO_BOTTOM_1_visual">
      <origin xyz="0 0 0" rpy="0 0 0"/>
      <geometry name="TORSO_BOTTOM_1_geometry">
        <mesh filename="meshes/TORSO_BOTTOM_1.stl"/>
      </geometry>
      <material name="TORSO_BOTTOM_1_material">
        <color rgba="0.97254902 0.52941176 0.0039215686 1"/>
      </material>
    </visual>
    <collision name="TORSO_BOTTOM_1_collision">
      <origin xyz="0 0 0" rpy="0 0 0"/>
      <geometry name="TORSO_BOTTOM_1_collision_geometry">
        <mesh filename="meshes/TORSO_BOTTOM_1.stl"/>
      </geometry>
    </collision>
    <inertial name="TORSO_BOTTOM_1_inertial">
      <mass value="12.978877711"/>
      <inertia ixx="0.3560986703361081" iyy="0.3913419084280843" izz="0.06393143863468188" ixy="6.683571274366279e-05" ixz="-3.612026580063636e-05" iyz="0.0005799106348977131"/>
      <origin xyz="0.0006560670951245929 -0.0019285109384503934 0.1304726591973753" rpy="0 0 0"/>
    </inertial>
  </link>
  <joint name="left_hip_pitch_04" type="revolute">
    <origin xyz="-0.054995157299999986 1.547895499903862e-05 -0.07179286924500096" rpy="-1.5707963 0.0 -1.5707963"/>
    <parent link="TORSO_BOTTOM_1"/>
    <child link="L_Hip_Yoke_Drive"/>
    <limit effort="120" velocity="6.283" lower="-2.0071" upper="2.3562"/>
    <axis xyz="0 0 1"/>
  </joint>
  <link name="L_Hip_Yoke_Drive">
    <visual name="L_Hip_Yoke_Drive_visual">
      <origin xyz="0 0 0" rpy="0 0 0"/>
      <geometry name="L_Hip_Yoke_Drive_geometry">
        <mesh filename="meshes/L_Hip_Yoke_Drive.stl"/>
      </geometry>
      <material name="L_Hip_Yoke_Drive_material">
        <color rgba="0.2627451 0.28235294 0.30196078 1"/>
      </material>
    </visual>
    <collision name="L_Hip_Yoke_Drive_collision">
      <origin xyz="0 0 0" rpy="0 0 0"/>
      <geometry name="L_Hip_Yoke_Drive_collision_geometry">
        <mesh filename="meshes/L_Hip_Yoke_Drive.stl"/>
      </geometry>
    </collision>
    <inertial name="L_Hip_Yoke_Drive_inertial">
      <mass value="0.8572125079999999"/>
      <inertia ixx="0.0014121257660934506" iyy="0.0017831439302213438" izz="0.0019632580797031445" ixy="9.37030661410975e-05" ixz="-0.00012018180009341965" iyz="0.00025867842302921293"/>
      <origin xyz="-0.008131954236117098 0.0025025026036906294 -0.0338738806943653" rpy="0 0 0"/>
    </inertial>
  </link>
  <joint name="right_hip_pitch_04" type="revolute">
    <origin xyz="0.055004842699999994 1.5480000000005212e-05 -0.07179286924500096" rpy="1.5707963 -2.6794896523796297e-08 -1.5707963267948961"/>
    <parent link="TORSO_BOTTOM_1"/>
    <child link="R_Hip_Yoke_Drive"/>
    <limit effort="120" velocity="6.283" lower="-2.3562" upper="2.0071"/>
    <axis xyz="0 0 1"/>
  </joint>
  <link name="R_Hip_Yoke_Drive">
    <visual name="R_Hip_Yoke_Drive_visual">
      <origin xyz="0 0 0" rpy="0 0 0"/>
      <geometry name="R_Hip_Yoke_Drive_geometry">
        <mesh filename="meshes/R_Hip_Yoke_Drive.stl"/>
      </geometry>
      <material name="R_Hip_Yoke_Drive_material">
        <color rgba="0.2627451 0.28235294 0.30196078 1"/>
      </material>
    </visual>
    <collision name="R_Hip_Yoke_Drive_collision">
      <origin xyz="0 0 0" rpy="0 0 0"/>
      <geometry name="R_Hip_Yoke_Drive_collision_geometry">
        <mesh filename="meshes/R_Hip_Yoke_Drive.stl"/>
      </geometry>
    </collision>
    <inertial name="R_Hip_Yoke_Drive_inertial">
      <mass value="0.8572137980000001"/>
      <inertia ixx="0.001417157514309729" iyy="0.00178314777543158" izz="0.0019682930127679667" ixy="-8.881116059860948e-05" ixz="-0.00012017967129925466" iyz="-0.00026187314383706176"/>
      <origin xyz="-0.00813193591840892 -0.0026076379116605824 -0.03387392275442471" rpy="0 0 0"/>
    </inertial>
  </link>
  <joint name="left_shoulder_pitch_03" type="fixed">
    <origin xyz="0.12295483289078238 -0.002148124520129227 0.3387071341316703" rpy="1.570796392820413 2.220446049250313e-16 1.5707963000000003"/>
    <parent link="TORSO_BOTTOM_1"/>
    <child link="R_SHLDR_YAW-A"/>
    <axis xyz="0 0 1"/>
  </joint>
  <link name="R_SHLDR_YAW-A">
    <visual name="R_SHLDR_YAW-A_visual">
      <origin xyz="0 0 0" rpy="0 0 0"/>
      <geometry name="R_SHLDR_YAW-A_geometry">
        <mesh filename="meshes/R_SHLDR_YAW-A.stl"/>
      </geometry>
      <material name="R_SHLDR_YAW-A_material">
        <color rgba="0.97254902 0.52941176 0.0039215686 1"/>
      </material>
    </visual>
    <collision name="R_SHLDR_YAW-A_collision">
      <origin xyz="0 0 0" rpy="0 0 0"/>
      <geometry name="R_SHLDR_YAW-A_collision_geometry">
        <mesh filename="meshes/R_SHLDR_YAW-A.stl"/>
      </geometry>
    </collision>
    <inertial name="R_SHLDR_YAW-A_inertial">
      <mass value="0.38816839110000007"/>
      <inertia ixx="0.0006642980360020297" iyy="0.0008736859035238626" izz="0.0007498466016313168" ixy="-3.6138701328812517e-06" ixz="1.306067640719083e-05" iyz="-1.4186119956351242e-06"/>
      <origin xyz="-0.007270334256917293 0.00010250544009193658 0.04298091297841596" rpy="0 0 0"/>
    </inertial>
  </link>
  <joint name="right_shoulder_pitch_03" type="fixed">
    <origin xyz="-0.12294516500822303 -0.002148121679870253 0.3387071333798704" rpy="-1.5707963 4.6410206566704915e-08 -1.5707963535897922"/>
    <parent link="TORSO_BOTTOM_1"/>
    <child link="L_SHLDR_YAW-A_"/>
    <axis xyz="0 0 1"/>
  </joint>
  <link name="L_SHLDR_YAW-A_">
    <visual name="L_SHLDR_YAW-A__visual">
      <origin xyz="0 0 0" rpy="0 0 0"/>
      <geometry name="L_SHLDR_YAW-A__geometry">
        <mesh filename="meshes/L_SHLDR_YAW-A_.stl"/>
      </geometry>
      <material name="L_SHLDR_YAW-A__material">
        <color rgba="0.23137255 0.38039216 0.70588235 1"/>
      </material>
    </visual>
    <collision name="L_SHLDR_YAW-A__collision">
      <origin xyz="0 0 0" rpy="0 0 0"/>
      <geometry name="L_SHLDR_YAW-A__collision_geometry">
        <mesh filename="meshes/L_SHLDR_YAW-A_.stl"/>
      </geometry>
    </collision>
    <inertial name="L_SHLDR_YAW-A__inertial">
      <mass value="0.3930797391"/>
      <inertia ixx="0.0006744828258263383" iyy="0.0008841271984884561" izz="0.0007516975029349002" ixy="-3.6109546943351697e-06" ixz="1.4634822773617765e-05" iyz="-1.4405223092671548e-06"/>
      <origin xyz="0.0071782291732983335 -0.00010109684279684824 -0.04443114506542755" rpy="0 0 0"/>
    </inertial>
  </link>
  <joint name="left_hip_roll_03" type="revolute">
    <origin xyz="-0.02525 0.0305 -0.068" rpy="0 -1.5707963 0"/>
    <parent link="L_Hip_Yoke_Drive"/>
    <child link="L_Hip_Yaw_RS03"/>
    <limit effort="60" velocity="6.283" lower="-0.6457" upper="3.0543"/>
    <axis xyz="0 0 1"/>
  </joint>
  <link name="L_Hip_Yaw_RS03">
    <visual name="L_Hip_Yaw_RS03_visual">
      <origin xyz="0 0 0" rpy="0 0 0"/>
      <geometry name="L_Hip_Yaw_RS03_geometry">
        <mesh filename="meshes/L_Hip_Yaw_RS03.stl"/>
      </geometry>
      <material name="L_Hip_Yaw_RS03_material">
        <color rgba="0.97254902 0.52941176 0.0039215686 1"/>
      </material>
    </visual>
    <collision name="L_Hip_Yaw_RS03_collision">
      <origin xyz="0 0 0" rpy="0 0 0"/>
      <geometry name="L_Hip_Yaw_RS03_collision_geometry">
        <mesh filename="meshes/L_Hip_Yaw_RS03.stl"/>
      </geometry>
    </collision>
    <inertial name="L_Hip_Yaw_RS03_inertial">
      <mass value="2.67808146"/>
      <inertia ixx="0.011223661667652615" iyy="0.003913470265973227" izz="0.011748024206866164" ixy="6.276794543921215e-06" ixz="9.780045683993612e-06" iyz="-0.0005033033832567847"/>
      <origin xyz="8.629312978396952e-05 0.054853058590216504 -0.027274199443530538" rpy="0 0 0"/>
    </inertial>
  </link>
  <joint name="right_hip_roll_03" type="revolute">
    <origin xyz="-0.02525 -0.0305 -0.068" rpy="3.1415927 1.5707963 0"/>
    <parent link="R_Hip_Yoke_Drive"/>
    <child link="L_Hip_Yaw_RS03_2"/>
    <limit effort="60" velocity="6.283" lower="-3.0543" upper="0.6457"/>
    <axis xyz="0 0 1"/>
  </joint>
  <link name="L_Hip_Yaw_RS03_2">
    <visual name="L_Hip_Yaw_RS03_visual_2">
      <origin xyz="0 0 0" rpy="0 0 0"/>
      <geometry name="L_Hip_Yaw_RS03_geometry_2">
        <mesh filename="meshes/L_Hip_Yaw_RS03_2.stl"/>
      </geometry>
      <material name="L_Hip_Yaw_RS03_material_2">
        <color rgba="0.97254902 0.52941176 0.0039215686 1"/>
      </material>
    </visual>
    <collision name="L_Hip_Yaw_RS03_collision_2">
      <origin xyz="0 0 0" rpy="0 0 0"/>
      <geometry name="L_Hip_Yaw_RS03_collision_geometry_2">
        <mesh filename="meshes/L_Hip_Yaw_RS03_2.stl"/>
      </geometry>
    </collision>
    <inertial name="L_Hip_Yaw_RS03_inertial_2">
      <mass value="2.67807848"/>
      <inertia ixx="0.011210213637211346" iyy="0.003917948953890383" izz="0.011754306957604812" ixy="1.6547230429103996e-05" ixz="-1.2126067850967451e-05" iyz="-0.0005060637422820512"/>
      <origin xyz="-0.00010253388914313968 0.0548350699932074 -0.027269266133648693" rpy="0 0 0"/>
    </inertial>
  </link>
  <joint name="right_shoulder_roll_03" type="fixed">
    <origin xyz="0.02525 0 0.08" rpy="0 1.5707963 0"/>
    <parent link="R_SHLDR_YAW-A"/>
    <child link="RS03"/>
    <axis xyz="0 0 1"/>
  </joint>
  <link name="RS03">
    <visual name="RS03_visual">
      <origin xyz="0 0 0" rpy="0 0 0"/>
      <geometry name="RS03_geometry">
        <mesh filename="meshes/RS03.stl"/>
      </geometry>
      <material name="RS03_material">
        <color rgba="0.97254902 0.52941176 0.0039215686 1"/>
      </material>
    </visual>
    <collision name="RS03_collision">
      <origin xyz="0 0 0" rpy="0 0 0"/>
      <geometry name="RS03_collision_geometry">
        <mesh filename="meshes/RS03.stl"/>
      </geometry>
    </collision>
    <inertial name="RS03_inertial">
      <mass value="1.8646100800999998"/>
      <inertia ixx="0.0075098914311835996" iyy="0.0021012862106297237" izz="0.007938562916300443" ixy="-0.0006294375665310775" ixz="-1.7227380826624815e-06" iyz="8.906159495576759e-06"/>
      <origin xyz="-0.0052177909488822765 -0.042723028642503706 -0.0299485598560192" rpy="0 0 0"/>
    </inertial>
  </link>
  <joint name="left_shoulder_roll_03" type="fixed">
    <origin xyz="-0.02525 0 -0.082" rpy="-1.5707963 0 1.5707963"/>
    <parent link="L_SHLDR_YAW-A_"/>
    <child link="RS03_2"/>
    <axis xyz="0 0 1"/>
  </joint>
  <link name="RS03_2">
    <visual name="RS03_visual_2">
      <origin xyz="0 0 0" rpy="0 0 0"/>
      <geometry name="RS03_geometry_2">
        <mesh filename="meshes/RS03_2.stl"/>
      </geometry>
      <material name="RS03_material_2">
        <color rgba="0.97254902 0.52941176 0.0039215686 1"/>
      </material>
    </visual>
    <collision name="RS03_collision_2">
      <origin xyz="0 0 0" rpy="0 0 0"/>
      <geometry name="RS03_collision_geometry_2">
        <mesh filename="meshes/RS03_2.stl"/>
      </geometry>
    </collision>
    <inertial name="RS03_inertial_2">
      <mass value="1.8646094401000002"/>
      <inertia ixx="0.002117089966846184" iyy="0.0074993663964198105" izz="0.007956235818653661" ixy="-0.0006636269747626453" ixz="3.024790780798619e-05" iyz="8.701130305624066e-06"/>
      <origin xyz="0.0426874649098865 0.005364201672817688 -0.030194760612173667" rpy="0 0 0"/>
    </inertial>
  </link>
  <joint name="right_hip_yaw_03" type="revolute">
    <origin xyz="8.807269719079969e-09 0.14200000421300732 -0.025249999933012746" rpy="-1.5707963071795867 -4.6410206566704915e-08 3.141592560769381"/>
    <parent link="L_Hip_Yaw_RS03_2"/>
    <child link="R_Femur_Lower_Drive"/>
    <limit effort="60" velocity="6.283" lower="-2.0071" upper="2.3562"/>
    <axis xyz="0 0 1"/>
  </joint>
  <link name="R_Femur_Lower_Drive">
    <visual name="R_Femur_Lower_Drive_visual">
      <origin xyz="0 0 0" rpy="0 0 0"/>
      <geometry name="R_Femur_Lower_Drive_geometry">
        <mesh filename="meshes/R_Femur_Lower_Drive.stl"/>
      </geometry>
      <material name="R_Femur_Lower_Drive_material">
        <color rgba="0.49803922 0.49803922 0.49803922 1"/>
      </material>
    </visual>
    <collision name="R_Femur_Lower_Drive_collision">
      <origin xyz="0 0 0" rpy="0 0 0"/>
      <geometry name="R_Femur_Lower_Drive_collision_geometry">
        <mesh filename="meshes/R_Femur_Lower_Drive.stl"/>
      </geometry>
    </collision>
    <inertial name="R_Femur_Lower_Drive_inertial">
      <mass value="2.45867164"/>
      <inertia ixx="0.0170968564892804" iyy="0.015513626047310571" izz="0.004226302775028244" ixy="0.0001496080415245086" ixz="-0.00087728253744911" iyz="0.0016116019634469297"/>
      <origin xyz="0.00039172721505503517 0.011451477956148549 -0.162413967263142" rpy="0 0 0"/>
    </inertial>
  </link>
  <joint name="right_shoulder_yaw_02" type="fixed">
    <origin xyz="-0.013027815793534982 -0.14150000289956488 -0.030245284867147983" rpy="1.5707963996335306 -0.008726650000000058 3.141592595346938"/>
    <parent link="RS03"/>
    <child link="R_BICEP_LOWER-DRIVE"/>
    <axis xyz="0 0 1"/>
  </joint>
  <link name="R_BICEP_LOWER-DRIVE">
    <visual name="R_BICEP_LOWER-DRIVE_visual">
      <origin xyz="0 0 0" rpy="0 0 0"/>
      <geometry name="R_BICEP_LOWER-DRIVE_geometry">
        <mesh filename="meshes/R_BICEP_LOWER-DRIVE.stl"/>
      </geometry>
      <material name="R_BICEP_LOWER-DRIVE_material">
        <color rgba="0.61568627 0.81176471 0.92941176 1"/>
      </material>
    </visual>
    <collision name="R_BICEP_LOWER-DRIVE_collision">
      <origin xyz="0 0 0" rpy="0 0 0"/>
      <geometry name="R_BICEP_LOWER-DRIVE_collision_geometry">
        <mesh filename="meshes/R_BICEP_LOWER-DRIVE.stl"/>
      </geometry>
    </collision>
    <inertial name="R_BICEP_LOWER-DRIVE_inertial">
      <mass value="0.84293946"/>
      <inertia ixx="0.0028029712426870146" iyy="0.002621816955415604" izz="0.0009050928071385421" ixy="-2.129762098906347e-05" ixz="0.00018605305518487155" iyz="0.00014532043231286243"/>
      <origin xyz="-0.0002516982430851186 0.0027596156182569755 -0.0983836419020131" rpy="0 0 0"/>
    </inertial>
  </link>
  <joint name="left_shoulder_yaw_02" type="fixed">
    <origin xyz="0.14150000111248584 0.012713926047757361 -0.0302009376090664" rpy="-1.5707962267948243 -2.6794896301751692e-08 1.5707963267948966"/>
    <parent link="RS03_2"/>
    <child link="L_BICEP_LOWER_DRIVE"/>
    <axis xyz="0 0 1"/>
  </joint>
  <link name="L_BICEP_LOWER_DRIVE">
    <visual name="L_BICEP_LOWER_DRIVE_visual">
      <origin xyz="0 0 0" rpy="0 0 0"/>
      <geometry name="L_BICEP_LOWER_DRIVE_geometry">
        <mesh filename="meshes/L_BICEP_LOWER_DRIVE.stl"/>
      </geometry>
      <material name="L_BICEP_LOWER_DRIVE_material">
        <color rgba="0.23137255 0.38039216 0.70588235 1"/>
      </material>
    </visual>
    <collision name="L_BICEP_LOWER_DRIVE_collision">
      <origin xyz="0 0 0" rpy="0 0 0"/>
      <geometry name="L_BICEP_LOWER_DRIVE_collision_geometry">
        <mesh filename="meshes/L_BICEP_LOWER_DRIVE.stl"/>
      </geometry>
    </collision>
    <inertial name="L_BICEP_LOWER_DRIVE_inertial">
      <mass value="0.8427538800000001"/>
      <inertia ixx="0.0028260312171053126" iyy="0.0026341960750257474" izz="0.0009154778059838686" ixy="2.4694966792567638e-05" ixz="0.00018582736467473118" iyz="-0.00017128387261541682"/>
      <origin xyz="-0.000252958007022258 -0.003597008713631938 -0.09862439369890269" rpy="0 0 0"/>
    </inertial>
  </link>
  <joint name="left_hip_yaw_03" type="revolute">
    <origin xyz="8.691244106351359e-09 0.1420000033427469 -0.02525000331570179" rpy="-1.5707962071795865 0.0 3.1415926071795863"/>
    <parent link="L_Hip_Yaw_RS03"/>
    <child link="L_Femur_Lower_Drive"/>
    <limit effort="60" velocity="6.283" lower="-2.0071" upper="2.3562"/>
    <axis xyz="0 0 1"/>
  </joint>
  <link name="L_Femur_Lower_Drive">
    <visual name="L_Femur_Lower_Drive_visual">
      <origin xyz="0 0 0" rpy="0 0 0"/>
      <geometry name="L_Femur_Lower_Drive_geometry">
        <mesh filename="meshes/L_Femur_Lower_Drive.stl"/>
      </geometry>
      <material name="L_Femur_Lower_Drive_material">
        <color rgba="0.49803922 0.49803922 0.49803922 1"/>
      </material>
    </visual>
    <collision name="L_Femur_Lower_Drive_collision">
      <origin xyz="0 0 0" rpy="0 0 0"/>
      <geometry name="L_Femur_Lower_Drive_collision_geometry">
        <mesh filename="meshes/L_Femur_Lower_Drive.stl"/>
      </geometry>
    </collision>
    <inertial name="L_Femur_Lower_Drive_inertial">
      <mass value="2.46030659"/>
      <inertia ixx="0.01712475925813052" iyy="0.015541886970567971" izz="0.004230455612483035" ixy="-0.0001493656705734685" ixz="0.0008699185475137966" iyz="0.0016121604959534025"/>
      <origin xyz="-0.0003674106146914035 0.011449985750236792 -0.16233175014691012" rpy="0 0 0"/>
    </inertial>
  </link>
  <joint name="left_elbow_02" type="fixed">
    <origin xyz="-0.018000000085993336 -0.009997528000000009 -0.13702813759282043" rpy="1.570796400123929 -0.09599312679489658 1.570796324214841"/>
    <parent link="L_BICEP_LOWER_DRIVE"/>
    <child link="L_FOREARM_UPPER_STRUCTURAL"/>
    <axis xyz="0 0 1"/>
  </joint>
  <link name="L_FOREARM_UPPER_STRUCTURAL">
    <visual name="L_FOREARM_UPPER_STRUCTURAL_visual">
      <origin xyz="0 0 0" rpy="0 0 0"/>
      <geometry name="L_FOREARM_UPPER_STRUCTURAL_geometry">
        <mesh filename="meshes/L_FOREARM_UPPER_STRUCTURAL.stl"/>
      </geometry>
      <material name="L_FOREARM_UPPER_STRUCTURAL_material">
        <color rgba="0.64705882 0.64705882 0.64705882 1"/>
      </material>
    </visual>
    <collision name="L_FOREARM_UPPER_STRUCTURAL_collision">
      <origin xyz="0 0 0" rpy="0 0 0"/>
      <geometry name="L_FOREARM_UPPER_STRUCTURAL_collision_geometry">
        <mesh filename="meshes/L_FOREARM_UPPER_STRUCTURAL.stl"/>
      </geometry>
    </collision>
    <inertial name="L_FOREARM_UPPER_STRUCTURAL_inertial">
      <mass value="0.6491781400000001"/>
      <inertia ixx="0.0013609365738054247" iyy="0.0007193784296669726" izz="0.0013478330524201334" ixy="4.180794483620586e-05" ixz="-1.4830425049735462e-05" iyz="8.229355894988428e-05"/>
      <origin xyz="0.016156114069715417 -0.05753942796815662 0.015153293785799422" rpy="0 0 0"/>
    </inertial>
  </link>
  <joint name="right_knee_04" type="revolute">
    <origin xyz="0.01960000043966463 0.02099999926046087 -0.21199999521668364" rpy="-1.5707963648333498 -0.08726647320510428 1.5707963033152696"/>
    <parent link="R_Femur_Lower_Drive"/>
    <child link="R-TIBIA-INNER_"/>
    <limit effort="120" velocity="6.283" lower="-0.4363" upper="3.1067"/>
    <axis xyz="0 0 1"/>
  </joint>
  <link name="R-TIBIA-INNER_">
    <visual name="R-TIBIA-INNER__visual">
      <origin xyz="0 0 0" rpy="0 0 0"/>
      <geometry name="R-TIBIA-INNER__geometry">
        <mesh filename="meshes/R-TIBIA-INNER_.stl"/>
      </geometry>
      <material name="R-TIBIA-INNER__material">
        <color rgba="0.97254902 0.52941176 0.0039215686 1"/>
      </material>
    </visual>
    <collision name="R-TIBIA-INNER__collision">
      <origin xyz="0 0 0" rpy="0 0 0"/>
      <geometry name="R-TIBIA-INNER__collision_geometry">
        <mesh filename="meshes/R-TIBIA-INNER_.stl"/>
      </geometry>
    </collision>
    <inertial name="R-TIBIA-INNER__inertial">
      <mass value="1.8377962330000002"/>
      <inertia ixx="0.016712798873531134" iyy="0.003090037744891356" izz="0.01697840235189485" ixy="0.0012779431278330438" ixz="0.00012661944096701365" iyz="-0.00034379634243273706"/>
      <origin xyz="-0.03066269548610658 0.09984931132198185 0.018866757855306084" rpy="0 0 0"/>
    </inertial>
  </link>
  <joint name="right_elbow_02" type="fixed">
    <origin xyz="-0.018000000560163383 0.010007317832565275 -0.13702727566253006" rpy="-1.5707963646886025 -2.6794893859261038e-08 -1.5707962535897928"/>
    <parent link="R_BICEP_LOWER-DRIVE"/>
    <child link="R_FOREARM_UPPER_STRUCTURAL"/>
    <axis xyz="0 0 1"/>
  </joint>
  <link name="R_FOREARM_UPPER_STRUCTURAL">
    <visual name="R_FOREARM_UPPER_STRUCTURAL_visual">
      <origin xyz="0 0 0" rpy="0 0 0"/>
      <geometry name="R_FOREARM_UPPER_STRUCTURAL_geometry">
        <mesh filename="meshes/R_FOREARM_UPPER_STRUCTURAL.stl"/>
      </geometry>
      <material name="R_FOREARM_UPPER_STRUCTURAL_material">
        <color rgba="0.61568627 0.81176471 0.92941176 1"/>
      </material>
    </visual>
    <collision name="R_FOREARM_UPPER_STRUCTURAL_collision">
      <origin xyz="0 0 0" rpy="0 0 0"/>
      <geometry name="R_FOREARM_UPPER_STRUCTURAL_collision_geometry">
        <mesh filename="meshes/R_FOREARM_UPPER_STRUCTURAL.stl"/>
      </geometry>
    </collision>
    <inertial name="R_FOREARM_UPPER_STRUCTURAL_inertial">
      <mass value="0.6491800400000001"/>
      <inertia ixx="0.001359715877502022" iyy="0.0007182268603835769" izz="0.00134781146237228" ixy="-4.1846890212545286e-05" ixz="-1.4597843187092314e-05" iyz="-7.807241983487332e-05"/>
      <origin xyz="0.01615538627318021 0.05754082175552143 0.014849609597869016" rpy="0 0 0"/>
    </inertial>
  </link>
  <joint name="left_knee_04" type="revolute">
    <origin xyz="-0.01960000553314603 0.021000000739539275 -0.2119999974504628" rpy="1.5707963999999999 2.220446049250313e-16 1.5707963"/>
    <parent link="L_Femur_Lower_Drive"/>
    <child link="L-TIBIA-INNER_"/>
    <limit effort="120" velocity="6.283" lower="-0.4363" upper="3.1067"/>
    <axis xyz="0 0 1"/>
  </joint>
  <link name="L-TIBIA-INNER_">
    <visual name="L-TIBIA-INNER__visual">
      <origin xyz="0 0 0" rpy="0 0 0"/>
      <geometry name="L-TIBIA-INNER__geometry">
        <mesh filename="meshes/L-TIBIA-INNER_.stl"/>
      </geometry>
      <material name="L-TIBIA-INNER__material">
        <color rgba="0.97254902 0.52941176 0.0039215686 1"/>
      </material>
    </visual>
    <collision name="L-TIBIA-INNER__collision">
      <origin xyz="0 0 0" rpy="0 0 0"/>
      <geometry name="L-TIBIA-INNER__collision_geometry">
        <mesh filename="meshes/L-TIBIA-INNER_.stl"/>
      </geometry>
    </collision>
    <inertial name="L-TIBIA-INNER__inertial">
      <mass value="1.83777299"/>
      <inertia ixx="0.016835989808113072" iyy="0.0030240850997571406" izz="0.017028515346863907" ixy="1.2865867379715503e-07" ixz="0.0001121525809009944" iyz="0.0003332627233157439"/>
      <origin xyz="-0.021579089437132732 -0.10164829769989914 0.0188172719311646" rpy="0 0 0"/>
    </inertial>
  </link>
  <joint name="left_wrist_02" type="fixed">
    <origin xyz="0.017350000553331628 -0.10200000033493621 0.017999999565063794" rpy="-1.5707963071795865 -1.5707963 0.0"/>
    <parent link="L_FOREARM_UPPER_STRUCTURAL"/>
    <child link="L_EndEff_Mount_1"/>
    <axis xyz="0 0 1"/>
  </joint>
  <link name="L_EndEff_Mount_1">
    <visual name="L_EndEff_Mount_1_visual">
      <origin xyz="0 0 0" rpy="0 0 0"/>
      <geometry name="L_EndEff_Mount_1_geometry">
        <mesh filename="meshes/L_EndEff_Mount_1.stl"/>
      </geometry>
      <material name="L_EndEff_Mount_1_material">
        <color rgba="0.61568627 0.81176471 0.92941176 1"/>
      </material>
    </visual>
    <collision name="L_EndEff_Mount_1_collision">
      <origin xyz="0 0 0" rpy="0 0 0"/>
      <geometry name="L_EndEff_Mount_1_collision_geometry">
        <mesh filename="meshes/L_EndEff_Mount_1.stl"/>
      </geometry>
    </collision>
    <inertial name="L_EndEff_Mount_1_inertial">
      <mass value="0.17958563"/>
      <inertia ixx="0.00010237335" iyy="0.00011019776" izz="8.8324157e-05" ixy="0" ixz="5.6389034e-06" iyz="0"/>
      <origin xyz="-0.0058748036 0 -0.030963262" rpy="0 0 0"/>
    </inertial>
  </link>
  <joint name="left_ankle_02" type="revolute">
    <origin xyz="-0.026 -0.2925 0.004" rpy="0 0 0"/>
    <parent link="L-TIBIA-INNER_"/>
    <child link="L_LEG-FOOT"/>
    <limit effort="17" velocity="12.566" lower="-1.2217" upper="0.7330"/>
    <axis xyz="0 0 1"/>
  </joint>
  <link name="L_LEG-FOOT">
    <visual name="L_LEG-FOOT_visual">
      <origin xyz="0 0 0" rpy="0 0 0"/>
      <geometry name="L_LEG-FOOT_geometry">
        <mesh filename="meshes/L_LEG-FOOT.stl"/>
      </geometry>
      <material name="L_LEG-FOOT_material">
        <color rgba="0.64705882 0.64705882 0.64705882 1"/>
      </material>
    </visual>
    <collision name="L_LEG-FOOT_collision">
      <origin xyz="0 0 0" rpy="0 0 0"/>
      <geometry name="L_LEG-FOOT_collision_geometry">
        <mesh filename="meshes/L_LEG-FOOT.stl"/>
      </geometry>
    </collision>
    <inertial name="L_LEG-FOOT_inertial">
      <mass value="0.49274898"/>
      <inertia ixx="0.000283460072103993" iyy="0.0015602901762423707" izz="0.0014852293364640238" ixy="-8.505864662651985e-05" ixz="2.1392937702987948e-05" iyz="1.8360568463946685e-05"/>
      <origin xyz="-0.013264731378632117 -0.028577932561279933 0.011944367356908027" rpy="0 0 0"/>
    </inertial>
  </link>
  <joint name="right_ankle_02" type="revolute">
    <origin xyz="-0.051394117 0.289120901 0.034" rpy="0.0 0.0 0.087266463"/>
    <parent link="R-TIBIA-INNER_"/>
    <child link="R_FOOT_LEG"/>
    <limit effort="17" velocity="12.566" lower="-0.7330" upper="1.2217"/>
    <axis xyz="0 0 1"/>
  </joint>
  <link name="R_FOOT_LEG">
    <visual name="R_FOOT_LEG_visual">
      <origin xyz="0 0 0" rpy="0 0 0"/>
      <geometry name="R_FOOT_LEG_geometry">
        <mesh filename="meshes/R_FOOT_LEG.stl"/>
      </geometry>
      <material name="R_FOOT_LEG_material">
        <color rgba="0.98039216 0.71372549 0.0039215686 1"/>
      </material>
    </visual>
    <collision name="R_FOOT_LEG_collision">
      <origin xyz="0 0 0" rpy="0 0 0"/>
      <geometry name="R_FOOT_LEG_collision_geometry">
        <mesh filename="meshes/R_FOOT_LEG.stl"/>
      </geometry>
    </collision>
    <inertial name="R_FOOT_LEG_inertial">
      <mass value="0.49274876"/>
      <inertia ixx="0.00028346008822660693" iyy="0.0015602907888710874" izz="0.0014852299783467086" ixy="8.505861650821186e-05" ixz="2.1392910325931817e-05" iyz="-1.836049313227581e-05"/>
      <origin xyz="-0.013264732279278421 0.02857794219894329 -0.01605560559482646" rpy="0 0 0"/>
    </inertial>
  </link>
  <joint name="right_wrist_02" type="fixed">
    <origin xyz="0.017349999446668374 0.10200000033493621 0.017999999565063794" rpy="1.5707963999999996 1.5707963000000005 0.0"/>
    <parent link="R_FOREARM_UPPER_STRUCTURAL"/>
    <child link="L_EndEff_Mount_2"/>
    <axis xyz="0 0 1"/>
  </joint>
  <link name="L_EndEff_Mount_2">
    <visual name="L_EndEff_Mount_2_visual">
      <origin xyz="0 0 0" rpy="0 0 0"/>
      <geometry name="L_EndEff_Mount_2_geometry">
        <mesh filename="meshes/L_EndEff_Mount_2.stl"/>
      </geometry>
      <material name="L_EndEff_Mount_2_material">
        <color rgba="0.61568627 0.81176471 0.92941176 1"/>
      </material>
    </visual>
    <collision name="L_EndEff_Mount_2_collision">
      <origin xyz="0 0 0" rpy="0 0 0"/>
      <geometry name="L_EndEff_Mount_2_collision_geometry">
        <mesh filename="meshes/L_EndEff_Mount_2.stl"/>
      </geometry>
    </collision>
    <inertial name="L_EndEff_Mount_2_inertial">
      <mass value="0.17958624"/>
      <inertia ixx="0.00010237367" iyy="0.00011019788" izz="8.8324394e-05" ixy="0" ixz="-5.6388594e-06" iyz="0"/>
      <origin xyz="0.0058748187 0 -0.030963304" rpy="0 0 0"/>
    </inertial>
  </link>
</robot>
