<robot name="kbot">
  <link name="base">
    <inertial>
      <origin rpy="0 0 0" xyz="0 0 0"/>
      <mass value="0.001"/>
      <inertia ixx="0.000001" ixy="0" ixz="0" iyy="0.000001" iyz="0" izz="0.000001"/>
    </inertial>
  </link>
  <joint name="floating_base" type="fixed">
    <origin rpy="-1.57 3.14 0" xyz="0 0 0"/>
    <parent link="base"/>
    <child link="body1-part"/>
  </joint>
  <link name="body1-part">
    <visual>
      <origin xyz="0 0 0" rpy="0 0 0"/>
      <geometry>
        <mesh filename="meshes/body1-part.stl"/>
      </geometry>
      <material name="body1-part_material">
        <color rgba="1 1 1 1"/>
      </material>
    </visual>
    <collision>
      <origin xyz="0 0 0" rpy="0 0 0"/>
      <geometry>
        <mesh filename="meshes/body1-part.stl"/>
      </geometry>
    </collision>
    <inertial>
      <mass value="11.417627727"/>
      <inertia ixx="0.5999083516993914" iyy="0.11036796524213266" izz="0.5097317878090031" ixy="0.008267685111984325" ixz="2.5827664262885333e-06" iyz="-0.0002480364319152404"/>
      <origin xyz="-0.0030205706440076343 -0.1594728810161352 -0.00012751185828538186" rpy="0 0 0"/>
    </inertial>
  </link>
  <joint name="L_shoulder_y" type="revolute">
    <origin xyz="-1.0603759e-05 0.018089562050771318 0.18749980999999996" rpy="3.1415926071795868 -2.220446049250313e-15 3.1415926071795868"/>
    <parent link="body1-part"/>
    <child link="shoulder"/>
    <limit effort="80" velocity="5" lower="0" upper="3.1415927"/>
    <axis xyz="0 0 1"/>
  </joint>
  <link name="shoulder">
    <visual>
      <origin xyz="0 0 0" rpy="0 0 0"/>
      <geometry>
        <mesh filename="meshes/shoulder.stl"/>
      </geometry>
      <material name="shoulder_material">
        <color rgba="1 1 1 1"/>
      </material>
    </visual>
    <collision>
      <origin xyz="0 0 0" rpy="0 0 0"/>
      <geometry>
        <mesh filename="meshes/shoulder.stl"/>
      </geometry>
    </collision>
    <inertial>
      <mass value="1.10769407"/>
      <inertia ixx="0.001482119975775339" iyy="0.0010408512352939995" izz="0.0009860091656447958" ixy="1.6247468564122567e-08" ixz="-3.1279807919019336e-06" iyz="6.454824186323744e-09"/>
      <origin xyz="-0.002143291631555535 5.498303797115525e-05 -0.06646243607358847" rpy="0 0 0"/>
    </inertial>
  </link>
  <joint name="R_shoulder_y" type="revolute">
    <origin xyz="-1.0603759e-05 0.018089564 -0.18750019" rpy="0.0 0.0 -3.1415926071795863"/>
    <parent link="body1-part"/>
    <child link="shoulder_2"/>
    <limit effort="80" velocity="5" lower="-3.1415927" upper="0"/>
    <axis xyz="0 0 1"/>
  </joint>
  <link name="shoulder_2">
    <visual>
      <origin xyz="0 0 0" rpy="0 0 0"/>
      <geometry>
        <mesh filename="meshes/shoulder_2.stl"/>
      </geometry>
      <material name="shoulder_material_2">
        <color rgba="1 1 1 1"/>
      </material>
    </visual>
    <collision>
      <origin xyz="0 0 0" rpy="0 0 0"/>
      <geometry>
        <mesh filename="meshes/shoulder_2.stl"/>
      </geometry>
    </collision>
    <inertial>
      <mass value="1.10769287"/>
      <inertia ixx="0.0014821176689157921" iyy="0.0010408501146374892" izz="0.0009860087317400204" ixy="-1.6193110601740246e-08" ixz="-3.1279664688578613e-06" iyz="-6.433007602960686e-09"/>
      <origin xyz="-0.0021432871527224694 -5.498738075250492e-05 -0.0664624713194008" rpy="0 0 0"/>
    </inertial>
  </link>
  <joint name="L_shoulder_x" type="revolute">
    <origin xyz="0.022511964 5.627838501275897e-05 -0.06749999993301277" rpy="1.5707963 2.220446049250313e-16 1.5707963"/>
    <parent link="shoulder"/>
    <child link="arm1_top"/>
    <limit effort="80" velocity="5" lower="-0.47996554" upper="3.6302848"/>
    <axis xyz="0 0 -1"/>
  </joint>
  <link name="arm1_top">
    <visual>
      <origin xyz="0 0 0" rpy="0 0 0"/>
      <geometry>
        <mesh filename="meshes/arm1_top.stl"/>
      </geometry>
      <material name="arm1_top_material">
        <color rgba="0.89803922 0.91764706 0.92941176 1"/>
      </material>
    </visual>
    <collision>
      <origin xyz="0 0 0" rpy="0 0 0"/>
      <geometry>
        <mesh filename="meshes/arm1_top.stl"/>
      </geometry>
    </collision>
    <inertial>
      <mass value="0.6485195170000001"/>
      <inertia ixx="0.0005534340544495192" iyy="0.001294931504165387" izz="0.0012122867763442184" ixy="2.74317480147297e-09" ixz="-0.0002934973441160383" iyz="-1.2020658865489369e-08"/>
      <origin xyz="-0.10491673233892948 -2.224482447297966e-06 -0.02270232245867197" rpy="0 0 0"/>
    </inertial>
  </link>
  <joint name="R_shoulder_x" type="revolute">
    <origin xyz="0.022511964 -5.627838501275897e-05 -0.06749999993301277" rpy="1.5707963999999996 2.220446049250313e-16 -1.5707963000000003"/>
    <parent link="shoulder_2"/>
    <child link="arm1_top_2"/>
    <limit effort="80" velocity="5" lower="-0.47996554" upper="3.6302848"/>
    <axis xyz="0 0 1"/>
  </joint>
  <link name="arm1_top_2">
    <visual>
      <origin xyz="0 0 0" rpy="0 0 0"/>
      <geometry>
        <mesh filename="meshes/arm1_top_2.stl"/>
      </geometry>
      <material name="arm1_top_2_material">
        <color rgba="0.89803922 0.91764706 0.92941176 1"/>
      </material>
    </visual>
    <collision>
      <origin xyz="0 0 0" rpy="0 0 0"/>
      <geometry>
        <mesh filename="meshes/arm1_top_2.stl"/>
      </geometry>
    </collision>
    <inertial>
      <mass value="0.648518913"/>
      <inertia ixx="0.0005534337229653212" iyy="0.001294930169757423" izz="0.0012122856241893294" ixy="3.9483970889338744e-10" ixz="0.00029349804127191845" iyz="1.2665017999267616e-08"/>
      <origin xyz="-0.10491675895909988 -2.1578500229643037e-06 0.021702291176927777" rpy="0 0 0"/>
    </inertial>
  </link>
  <joint name="L_hip_y" type="revolute">
    <origin xyz="-1.0608503738440467e-05 -0.43201043179234816 0.08770000686486729" rpy="-3.1415925071795874 4.641020723283873e-08 -3.1415926535897913"/>
    <parent link="body1-part"/>
    <child link="leg0_shell"/>
    <limit effort="80" velocity="5" lower="-1.5707963" upper="1.5707963"/>
    <axis xyz="0 0 1"/>
  </joint>
  <link name="leg0_shell">
    <visual>
      <origin xyz="0 0 0" rpy="0 0 0"/>
      <geometry>
        <mesh filename="meshes/leg0_shell.stl"/>
      </geometry>
      <material name="leg0_shell_material">
        <color rgba="0.89803922 0.91764706 0.92941176 1"/>
      </material>
    </visual>
    <collision>
      <origin xyz="0 0 0" rpy="0 0 0"/>
      <geometry>
        <mesh filename="meshes/leg0_shell.stl"/>
      </geometry>
    </collision>
    <inertial>
      <mass value="1.3234480570000002"/>
      <inertia ixx="0.0018858182013085157" iyy="0.0014248321713891826" izz="0.0012997049050806665" ixy="-4.52869566177398e-12" ixz="7.0061936481283574e-06" iyz="-9.656589712159897e-13"/>
      <origin xyz="-0.003746324486178218 -5.307040759284793e-10 -0.06812512159159122" rpy="0 0 0"/>
    </inertial>
  </link>
  <joint name="R_hip_y" type="revolute">
    <origin xyz="-1.0600340183049505e-05 -0.4320104467591277 -0.08819999313513191" rpy="9.99999991702083e-08 4.641020723283873e-08 -3.1415926535897913"/>
    <parent link="body1-part"/>
    <child link="leg0_shell_2"/>
    <limit effort="80" velocity="5" lower="-1.5707963" upper="1.5707963"/>
    <axis xyz="0 0 1"/>
  </joint>
  <link name="leg0_shell_2">
    <visual>
      <origin xyz="0 0 0" rpy="0 0 0"/>
      <geometry>
        <mesh filename="meshes/leg0_shell_2.stl"/>
      </geometry>
      <material name="leg0_shell_material_2">
        <color rgba="0.89803922 0.91764706 0.92941176 1"/>
      </material>
    </visual>
    <collision>
      <origin xyz="0 0 0" rpy="0 0 0"/>
      <geometry>
        <mesh filename="meshes/leg0_shell_2.stl"/>
      </geometry>
    </collision>
    <inertial>
      <mass value="1.3234480570000002"/>
      <inertia ixx="0.0018858182013085157" iyy="0.0014248321713891826" izz="0.0012997049050806665" ixy="-4.52869566177398e-12" ixz="7.0061936481283574e-06" iyz="-9.656589712159897e-13"/>
      <origin xyz="-0.003746324486178218 -5.307040759284793e-10 -0.06762512159159122" rpy="0 0 0"/>
    </inertial>
  </link>
  <joint name="L_shoulder_z" type="revolute">
    <origin xyz="-0.13949999999999996 -1.461921509987972e-09 -0.023499999155960766" rpy="-4.641020604450648e-08 1.5707962732050293 0.0"/>
    <parent link="arm1_top"/>
    <child link="arm2_shell"/>
    <limit effort="80" velocity="5" lower="-1.5707963" upper="1.5707963"/>
    <axis xyz="0 0 1"/>
  </joint>
  <link name="arm2_shell">
    <visual>
      <origin xyz="0 0 0" rpy="0 0 0"/>
      <geometry>
        <mesh filename="meshes/arm2_shell.stl"/>
      </geometry>
      <material name="arm2_shell_material">
        <color rgba="0.89803922 0.91764706 0.92941176 1"/>
      </material>
    </visual>
    <collision>
      <origin xyz="0 0 0" rpy="0 0 0"/>
      <geometry>
        <mesh filename="meshes/arm2_shell.stl"/>
      </geometry>
    </collision>
    <inertial>
      <mass value="0.51101595"/>
      <inertia ixx="0.0006782501033956834" iyy="0.0005353980560191653" izz="0.000254883921623482" ixy="0.0" ixz="-6.066717667565759e-06" iyz="0.0"/>
      <origin xyz="-0.006335032352426245 0.0 -0.09042107492219607" rpy="0 0 0"/>
    </inertial>
  </link>
  <joint name="R_shoulder_z" type="revolute">
    <origin xyz="-0.13949999999999999 0.0 0.02249999915596076" rpy="-3.1415926071795863 1.5707963 0.0"/>
    <parent link="arm1_top_2"/>
    <child link="arm2_shell_2"/>
    <limit effort="80" velocity="5" lower="-1.5707963" upper="1.5707963"/>
    <axis xyz="0 0 -1"/>
  </joint>
  <link name="arm2_shell_2">
    <visual>
      <origin xyz="0 0 0" rpy="0 0 0"/>
      <geometry>
        <mesh filename="meshes/arm2_shell_2.stl"/>
      </geometry>
      <material name="arm2_shell_material_2">
        <color rgba="0.89803922 0.91764706 0.92941176 1"/>
      </material>
    </visual>
    <collision>
      <origin xyz="0 0 0" rpy="0 0 0"/>
      <geometry>
        <mesh filename="meshes/arm2_shell_2.stl"/>
      </geometry>
    </collision>
    <inertial>
      <mass value="0.51101595"/>
      <inertia ixx="0.0006782500996314132" iyy="0.000535398052254895" izz="0.000254883921623482" ixy="0.0" ixz="-6.066712483597235e-06" iyz="0.0"/>
      <origin xyz="0.006335032352426245 0.0 0.08992107443622689" rpy="0 0 0"/>
    </inertial>
  </link>
  <joint name="L_hip_x" type="revolute">
    <origin xyz="0.026499999999999965 -1.516591136963008e-09 -0.06950000151659115" rpy="-1.5707963 0.0 1.5707963"/>
    <parent link="leg0_shell"/>
    <child link="leg1_shell"/>
    <limit effort="80" velocity="5" lower="-0.34906585" upper="3.1852259"/>
    <axis xyz="0 0 1"/>
  </joint>
  <link name="leg1_shell">
    <visual>
      <origin xyz="0 0 0" rpy="0 0 0"/>
      <geometry>
        <mesh filename="meshes/leg1_shell.stl"/>
      </geometry>
      <material name="leg1_shell_material">
        <color rgba="0.89803922 0.91764706 0.92941176 1"/>
      </material>
    </visual>
    <collision>
      <origin xyz="0 0 0" rpy="0 0 0"/>
      <geometry>
        <mesh filename="meshes/leg1_shell.stl"/>
      </geometry>
    </collision>
    <inertial>
      <mass value="1.360769512"/>
      <inertia ixx="0.0016616954886228494" iyy="0.002821853448229639" izz="0.0028458063036535114" ixy="0.0001758148701161061" ixz="0.0003020245997305347" iyz="-9.5124528329072e-06"/>
      <origin xyz="-0.11647102759639932 0.0032311720350168987 0.025411038661602842" rpy="0 0 0"/>
    </inertial>
  </link>
  <joint name="R_hip_x" type="revolute">
    <origin xyz="0.026499999999999965 -1.516591136963008e-09 -0.06900000151659115" rpy="1.5707963 -4.641020678874952e-08 -1.5707963535897917"/>
    <parent link="leg0_shell_2"/>
    <child link="leg1_shell3"/>
    <limit effort="80" velocity="5" lower="-0.34906585" upper="3.1852259"/>
    <axis xyz="0 0 1"/>
  </joint>
  <link name="leg1_shell3">
    <visual>
      <origin xyz="0 0 0" rpy="0 0 0"/>
      <geometry>
        <mesh filename="meshes/leg1_shell3.stl"/>
      </geometry>
      <material name="leg1_shell3_material">
        <color rgba="0.89803922 0.91764706 0.92941176 1"/>
      </material>
    </visual>
    <collision>
      <origin xyz="0 0 0" rpy="0 0 0"/>
      <geometry>
        <mesh filename="meshes/leg1_shell3.stl"/>
      </geometry>
    </collision>
    <inertial>
      <mass value="1.360769362"/>
      <inertia ixx="0.0016616952587461726" iyy="0.00279725951718537" izz="0.0028212122544790225" ixy="-0.00016727034625066447" ixz="0.00030152306354767384" iyz="9.512542262690988e-06"/>
      <origin xyz="-0.11629451715520464 -0.0032311805394316336 0.02541103395361007" rpy="0 0 0"/>
    </inertial>
  </link>
  <joint name="L_elbow" type="revolute">
    <origin xyz="-0.026 0.0 -0.09799999977224338" rpy="-3.1415926071795863 -1.5707963 0.0"/>
    <parent link="arm2_shell"/>
    <child link="arm3_shell"/>
    <limit effort="80" velocity="5" lower="-2.5307274" upper="0"/>
    <axis xyz="0 0 1"/>
  </joint>
  <link name="arm3_shell">
    <visual>
      <origin xyz="0 0 0" rpy="0 0 0"/>
      <geometry>
        <mesh filename="meshes/arm3_shell.stl"/>
      </geometry>
      <material name="arm3_shell_material">
        <color rgba="0.89803922 0.91764706 0.92941176 1"/>
      </material>
    </visual>
    <collision>
      <origin xyz="0 0 0" rpy="0 0 0"/>
      <geometry>
        <mesh filename="meshes/arm3_shell.stl"/>
      </geometry>
    </collision>
    <inertial>
      <mass value="0.57887479"/>
      <inertia ixx="0.00042824885963562424" iyy="0.0013607750713956906" izz="0.001338486101760066" ixy="-4.378399131316926e-14" ixz="0.00014515232248489153" iyz="4.468061669140367e-13"/>
      <origin xyz="-0.14008673576280925 -3.715266367753273e-10 0.019422482836149137" rpy="0 0 0"/>
    </inertial>
  </link>
  <joint name="R_elbow" type="revolute">
    <origin xyz="0.026 0.0 0.09750000022775662" rpy="-3.1415926071795863 1.5707963 0.0"/>
    <parent link="arm2_shell_2"/>
    <child link="arm3_shell2"/>
    <limit effort="80" velocity="5" lower="0" upper="2.5307274"/>
    <axis xyz="0 0 1"/>
  </joint>
  <link name="arm3_shell2">
    <visual>
      <origin xyz="0 0 0" rpy="0 0 0"/>
      <geometry>
        <mesh filename="meshes/arm3_shell2.stl"/>
      </geometry>
      <material name="arm3_shell2_material">
        <color rgba="0.89803922 0.91764706 0.92941176 1"/>
      </material>
    </visual>
    <collision>
      <origin xyz="0 0 0" rpy="0 0 0"/>
      <geometry>
        <mesh filename="meshes/arm3_shell2.stl"/>
      </geometry>
    </collision>
    <inertial>
      <mass value="0.57887479"/>
      <inertia ixx="0.00042824885963562424" iyy="0.0013607750713956906" izz="0.001338486101760066" ixy="-4.378399131316926e-14" ixz="0.00014515232248489153" iyz="4.468061669140367e-13"/>
      <origin xyz="-0.14008673576280925 -3.715266367753273e-10 0.019422482836149137" rpy="0 0 0"/>
    </inertial>
  </link>
  <joint name="L_hip_z" type="revolute">
    <origin xyz="-0.15649999999999997 0.00011981393 0.02749999848340886" rpy="-0.0 1.5707963 0.0"/>
    <parent link="leg1_shell"/>
    <child link="leg2_shell"/>
    <limit effort="80" velocity="5" lower="-1.5707963" upper="1.5707963"/>
    <axis xyz="0 0 1"/>
  </joint>
  <link name="leg2_shell">
    <visual>
      <origin xyz="0 0 0" rpy="0 0 0"/>
      <geometry>
        <mesh filename="meshes/leg2_shell.stl"/>
      </geometry>
      <material name="leg2_shell_material">
        <color rgba="0.89803922 0.91764706 0.92941176 1"/>
      </material>
    </visual>
    <collision>
      <origin xyz="0 0 0" rpy="0 0 0"/>
      <geometry>
        <mesh filename="meshes/leg2_shell.stl"/>
      </geometry>
    </collision>
    <inertial>
      <mass value="1.820922667"/>
      <inertia ixx="0.003118121982315593" iyy="0.004225341330146897" izz="0.0020643672406963944" ixy="-6.676045962463132e-09" ixz="-2.2416298133304992e-08" iyz="-3.350740574812136e-05"/>
      <origin xyz="4.0855477721508534e-07 0.000531684411846282 -0.13730778343676694" rpy="0 0 0"/>
    </inertial>
  </link>
  <joint name="R_hip_z" type="revolute">
    <origin xyz="-0.15649999999999997 -0.00011981393 0.02749999848340886" rpy="-3.1415926535897922 -1.5707962732050305 0.0"/>
    <parent link="leg1_shell3"/>
    <child link="leg2_shell_2"/>
    <limit effort="80" velocity="5" lower="-1.5707963" upper="1.5707963"/>
    <axis xyz="0 0 1"/>
  </joint>
  <link name="leg2_shell_2">
    <visual>
      <origin xyz="0 0 0" rpy="0 0 0"/>
      <geometry>
        <mesh filename="meshes/leg2_shell_2.stl"/>
      </geometry>
      <material name="leg2_shell_material_2">
        <color rgba="0.89803922 0.91764706 0.92941176 1"/>
      </material>
    </visual>
    <collision>
      <origin xyz="0 0 0" rpy="0 0 0"/>
      <geometry>
        <mesh filename="meshes/leg2_shell_2.stl"/>
      </geometry>
    </collision>
    <inertial>
      <mass value="1.820922667"/>
      <inertia ixx="0.003118121982315593" iyy="0.004225341330146897" izz="0.0020643672406963944" ixy="-6.676045962463132e-09" ixz="-2.2416298133304992e-08" iyz="-3.350740574812136e-05"/>
      <origin xyz="4.0855477721508534e-07 0.000531684411846282 -0.13730778343676694" rpy="0 0 0"/>
    </inertial>
  </link>
  <joint name="L_wrist" type="revolute">
    <origin xyz="-0.18149999999999994 -1.461921509987972e-09 0.021500000844039233" rpy="-4.641020604450648e-08 1.5707962732050293 0.0"/>
    <parent link="arm3_shell"/>
    <child link="hand_shell"/>
    <limit effort="80" velocity="5" lower="0" upper="6.2831853"/>
    <axis xyz="0 0 1"/>
  </joint>
  <link name="hand_shell">
    <visual>
      <origin xyz="0 0 0" rpy="0 0 0"/>
      <geometry>
        <mesh filename="meshes/hand_shell.stl"/>
      </geometry>
      <material name="hand_shell_material">
        <color rgba="0.89803922 0.91764706 0.92941176 1"/>
      </material>
    </visual>
    <collision>
      <origin xyz="0 0 0" rpy="0 0 0"/>
      <geometry>
        <mesh filename="meshes/hand_shell.stl"/>
      </geometry>
    </collision>
    <inertial>
      <mass value="0.7933517460000001"/>
      <inertia ixx="0.002035289036126633" iyy="0.0028711006179816968" izz="0.001279636245454222" ixy="-5.174363969819452e-07" ixz="-2.321711817641545e-05" iyz="3.5513831423902756e-06"/>
      <origin xyz="0.0007087169571505654 0.00012971021920492218 -0.07462970584649938" rpy="0 0 0"/>
    </inertial>
  </link>
  <joint name="R_wrist" type="revolute">
    <origin xyz="-0.18149999999999994 -1.461921509987972e-09 0.021500000844039233" rpy="-4.641020604450648e-08 1.5707962732050293 0.0"/>
    <parent link="arm3_shell2"/>
    <child link="hand_shell_2"/>
    <limit effort="80" velocity="5" lower="0" upper="6.2831853"/>
    <axis xyz="0 0 1"/>
  </joint>
  <link name="hand_shell_2">
    <visual>
      <origin xyz="0 0 0" rpy="0 0 0"/>
      <geometry>
        <mesh filename="meshes/hand_shell_2.stl"/>
      </geometry>
      <material name="hand_shell_material_2">
        <color rgba="0.89803922 0.91764706 0.92941176 1"/>
      </material>
    </visual>
    <collision>
      <origin xyz="0 0 0" rpy="0 0 0"/>
      <geometry>
        <mesh filename="meshes/hand_shell_2.stl"/>
      </geometry>
    </collision>
    <inertial>
      <mass value="0.7933517460000001"/>
      <inertia ixx="0.002035289036126633" iyy="0.0028711006179816968" izz="0.001279636245454222" ixy="-5.174363969819452e-07" ixz="-2.321711817641545e-05" iyz="3.5513831423902756e-06"/>
      <origin xyz="0.0007087169571505654 0.00012971021920492218 -0.07462970584649938" rpy="0 0 0"/>
    </inertial>
  </link>
  <joint name="L_knee" type="revolute">
    <origin xyz="0.0 0.0342 -0.14250000009378214" rpy="1.5707963 0.0 0.0"/>
    <parent link="leg2_shell"/>
    <child link="leg3_shell2"/>
    <limit effort="80" velocity="5" lower="-1.57" upper="0" />
    <axis xyz="0 0 1"/>
  </joint>
  <link name="leg3_shell2">
    <visual>
      <origin xyz="0 0 0" rpy="0 0 0"/>
      <geometry>
        <mesh filename="meshes/leg3_shell2.stl"/>
      </geometry>
      <material name="leg3_shell2_material">
        <color rgba="0.89803922 0.91764706 0.92941176 1"/>
      </material>
    </visual>
    <collision>
      <origin xyz="0 0 0" rpy="0 0 0"/>
      <geometry>
        <mesh filename="meshes/leg3_shell2.stl"/>
      </geometry>
    </collision>
    <inertial>
      <mass value="1.179677561"/>
      <inertia ixx="0.0075280219401663686" iyy="0.0011236273981275156" izz="0.007505076656997992" ixy="6.871058258502185e-05" ixz="-1.92682149888721e-05" iyz="0.00022981113471710275"/>
      <origin xyz="0.0010329853873719736 -0.1254795525920513 0.03667110282750395" rpy="0 0 0"/>
    </inertial>
  </link>
  <joint name="R_knee" type="revolute">
    <origin xyz="0.0 0.0342 -0.14250000009378214" rpy="1.5707963 0.0 0.0"/>
    <parent link="leg2_shell_2"/>
    <child link="leg3_shell22"/>
    <limit effort="80" velocity="5" lower="0" upper="1.57" />
    <axis xyz="0 0 -1"/>
  </joint>
  <link name="leg3_shell22">
    <visual>
      <origin xyz="0 0 0" rpy="0 0 0"/>
      <geometry>
        <mesh filename="meshes/leg3_shell22.stl"/>
      </geometry>
      <material name="leg3_shell22_material">
        <color rgba="0.89803922 0.91764706 0.92941176 1"/>
      </material>
    </visual>
    <collision>
      <origin xyz="0 0 0" rpy="0 0 0"/>
      <geometry>
        <mesh filename="meshes/leg3_shell22.stl"/>
      </geometry>
    </collision>
    <inertial>
      <mass value="1.179683991"/>
      <inertia ixx="0.007528039668357469" iyy="0.0011236329917092309" izz="0.007505094295682782" ixy="-6.871642858641452e-05" ixz="1.9269189699938515e-05" iyz="0.00022981283551319127"/>
      <origin xyz="-0.0010330286803835712 -0.12547979367732118 0.036671195513248635" rpy="0 0 0"/>
    </inertial>
  </link>
  <joint name="R_ankle" type="revolute">
    <origin xyz="1.0767167917674625e-08 -0.29999999865410376 0.027200000000000002" rpy="-3.1415926071795868 0.0 -3.1415926071795868"/>
    <parent link="leg3_shell22"/>
    <child link="foot3"/>
    <limit effort="80" velocity="5" lower="-0.6981317" upper="0.6981317"/>
    <axis xyz="0 0 -1"/>
  </joint>
  <link name="foot3">
    <visual>
      <origin xyz="0 0 0" rpy="0 0 0"/>
      <geometry>
        <mesh filename="meshes/foot3.stl"/>
      </geometry>
      <material name="foot3_material">
        <color rgba="0.89803922 0.91764706 0.92941176 1"/>
      </material>
    </visual>
    <collision>
      <origin xyz="0 0 0" rpy="0 0 0"/>
      <geometry>
        <mesh filename="meshes/foot3.stl"/>
      </geometry>
    </collision>
    <inertial>
      <mass value="0.5457471700000001"/>
      <inertia ixx="0.00026065523975398483" iyy="0.0020289390726584825" izz="0.0018716018719932023" ixy="3.696933872469263e-05" ixz="3.095371968865274e-05" iyz="-3.6446932298433347e-06"/>
      <origin xyz="0.021026422150638727 -0.018472025092617035 -0.023695689532891605" rpy="0 0 0"/>
    </inertial>
  </link>
  <joint name="L_ankle" type="revolute">
    <origin xyz="0.0 -0.30000000004641003 0.07019999118206069" rpy="9.282041357749903e-08 0.0 0.0"/>
    <parent link="leg3_shell2"/>
    <child link="foot1"/>
    <limit effort="80" velocity="5" lower="-0.6981317" upper="0.6981317"/>
    <axis xyz="0 0 -1"/>
  </joint>
  <link name="foot1">
    <visual>
      <origin xyz="0 0 0" rpy="0 0 0"/>
      <geometry>
        <mesh filename="meshes/foot1.stl"/>
      </geometry>
      <material name="foot1_material">
        <color rgba="0.89803922 0.91764706 0.92941176 1"/>
      </material>
    </visual>
    <collision>
      <origin xyz="0 0 0" rpy="0 0 0"/>
      <geometry>
        <mesh filename="meshes/foot1.stl"/>
      </geometry>
    </collision>
    <inertial>
      <mass value="0.54574734"/>
      <inertia ixx="0.00026065523992286406" iyy="0.0020289393205482377" izz="0.0018716021578520194" ixy="3.696944831750269e-05" ixz="-3.095376367976456e-05" iyz="3.644697619567395e-06"/>
      <origin xyz="0.021026404502789257 -0.018472020400304597 -0.01930430937248649" rpy="0 0 0"/>
    </inertial>
  </link>
</robot>
